File: DATA&scripts/1.7-data/z/19/19_fracture_stress_data.csv
Strain,Fracture Stress (GPa)
-1.23378056083968e-16,1.27834332316389
0.000994999999999912,-2.66423986351063
0.00199499999999991,-1.08417772381107
0.00299499999999991,4.4918480375147
0.0039949999999999,1.31315153051441
0.0049949999999999,2.10686226517992
0.0059949999999999,5.90923657683624
0.00699499999999989,4.63979876633841
0.00799499999999989,6.4275940141359
0.00899499999999989,7.0170731122621
0.00999499999999988,6.21081343330467
0.0109949999999999,7.06142165518224
0.0119949999999999,8.06032848421666
0.0129949999999999,9.0425046885822
0.0139949999999999,9.93237672303308
0.0149949999999999,9.70537746130271
0.0159949999999999,9.9851161728076
0.0169949999999999,10.5339188988535
0.0179949999999999,11.3605015168303
0.0189949999999999,12.157726263653
0.0199949999999998,12.7452621406425
0.0209949999999998,12.8360112312537
0.0219949999999998,13.4389705398553
0.0229949999999998,13.9261832216325
0.0239949999999998,14.4445773585385
0.0249949999999998,15.21305428065
0.0259949999999998,15.3898348308885
0.0269949999999998,15.7814011441357
0.0279949999999998,16.6380651627657
0.0289949999999998,17.0096453016501
0.0299949999999998,17.5875156559465
0.0309949999999998,18.0907062455202
0.0319949999999998,18.5299450374416
0.0329949999999998,18.8419783320937
0.0339949999999998,19.6685112071087
0.0349949999999998,20.167132512028
0.0359949999999998,20.5528628398658
0.0369949999999998,21.0160780816313
0.0379949999999998,21.3642332615786
0.0389949999999998,21.8187973694937
0.0399949999999998,22.3728035293895
0.0409949999999998,22.8463783584223
0.0419949999999998,23.2800780907773
0.0429949999999998,23.812602410374
0.0439949999999998,24.359035070455
0.0449949999999998,24.6801715463855
0.0459949999999998,25.2007771627764
0.0469949999999998,25.7589774500145
0.0479949999999998,26.1243788746444
0.0489949999999998,26.6154310851548
0.0499949999999999,27.2603774957306
0.0509949999999997,27.4858991199032
0.0519949999999999,27.9320603843086
0.0529949999999999,28.5593758133322
0.0539949999999999,28.9006930264662
0.0549949999999999,29.4209105555047
0.0559949999999999,29.9966357832956
0.0569949999999999,30.28022497758
0.0579949999999999,30.7614309678886
0.0589949999999998,31.1617733913648
0.059995,31.6924907371228
0.060995,32.0028728177707
0.061995,32.4436261110797
0.062995,32.9660358564523
0.063995,33.3411444552426
0.064995,33.732205822949
0.065995,34.2915679658542
0.0669949999999999,34.6791386557455
0.0679949999999999,34.9301065187542
0.0689949999999999,35.3342021331902
0.0699949999999999,35.8635279263769
0.0709949999999999,36.2907564334124
0.0719949999999999,36.7777988172199
0.0729949999999999,37.1912162303849
0.0739949999999999,37.6306427381774
0.0749949999999999,37.884201721245
0.0759949999999999,38.3198447340618
0.0769949999999999,38.783647026716
0.0779949999999999,39.1298990669331
0.0789949999999999,39.519447644886
0.0799949999999999,39.8594012498732
0.0809949999999999,40.2930134700556
0.0819949999999999,40.6994177135969
0.0829949999999999,41.1219110629782
0.0839949999999999,41.4463606323402
0.0849949999999999,41.9215397333688
0.0859949999999999,42.1774122044433
0.0869949999999999,42.6965934961392
0.0879949999999999,42.9420189173285
0.0889949999999999,43.4543216126395
0.0899949999999999,43.7124407387062
0.0909949999999999,44.1865651097583
0.0919949999999999,44.4280318030711
0.0929949999999999,44.7609632278387
0.0939949999999999,45.0456265177541
0.0949949999999999,45.4857263326762
0.0959949999999999,45.8182320565792
0.0969949999999998,46.1789013947169
0.0979949999999998,46.5783939365435
0.0989949999999998,46.7861148930449
0.0999949999999998,47.2325024665163
0.100995,47.5435912099761
0.101995,47.946122094755
0.102995,48.2688339079655
0.103995,48.5854870692169
0.104995,48.9432359489479
0.105995,49.2370837997515
0.106995,49.5679834733236
0.107995,49.9227754097753
0.108995,50.2475153345761
0.109995,50.5099304997068
0.110995,50.7494136425866
0.111995,51.1540028369454
0.112995,51.3589858003092
0.113995,51.7726954302759
0.114995,52.0636386763727
0.115995,52.4055445891861
0.116995,52.6476152425819
0.117995,52.9742420466816
0.118995,53.2318403161638
0.119995,53.5878463518817
0.120995,53.7998847379998
0.121995,54.2337746381428
0.122995,54.4687631161925
0.123995,54.7476792963539
0.124995,54.9996434228077
0.125995,55.2726536280818
0.126995,55.5777040605383
0.127995,55.8358828474538
0.128995,56.0381376923993
0.129995,56.3728292384546
0.130995,56.6700379632464
0.131995,56.9701362060914
0.132995,57.1650823744569
0.133995,57.4738578786496
0.134995,57.7512024002712
0.135995,57.9836623863839
0.136995,58.1934677053041
0.137995,58.4636068766591
0.138995,58.6237602458654
0.139995,58.9484786773917
0.140995,59.021120040207
0.141995,59.3426663610713
0.142995,59.6728675800155
0.143995,59.9088878379254
0.144995,60.0968271765988
0.145995,60.4122932722308
0.146995,60.6025313190865
0.147995,60.8663707556372
0.148995,61.1540141959192
0.149995,61.3564100839756
0.150995,61.5222196132974
0.151995,61.7316312800211
0.152995,61.8263136299637
0.153995,62.1080028650695
0.154995,62.2823577444162
0.155995,62.5718249919024
0.156995,62.8390170168288
0.157995,63.0081259240849
0.158995,63.1150491328104
0.159995,63.4700686151276
0.160995,63.607865612711
0.161995,63.8134794859926
0.162995,63.9361278250555
0.163995,64.1505050314102
0.164995,64.2719181476221
0.165995,64.5431671047021
0.166995,64.7014007877363
0.167995,64.9174958700601
0.168995,65.0847396032072
0.169995,65.3653598009896
0.170995,65.4469172886219
0.171995,65.6891229272936
0.172995,65.7994661941451
0.173995,66.0320695112931
0.174995,66.146255460136
0.175995,66.354700625047
0.176995,66.4048760894494
0.177995,66.6843015953647
0.178995,66.7033328291838
0.179995,66.9232519109809
0.180995,67.0999716147833
0.181995,67.3007684046104
0.182995,67.5388730190791
0.183995,67.6001292183073
0.184995,67.8122012562023
0.185995,67.8127649654085
0.186995,68.0696910246297
0.187995,68.2092538898871
0.188995,68.2463682248182
0.189995,68.4480431881937
0.190995,68.6529709989601
0.191995,68.8711585718693
0.192995,68.9574078485161
0.193995,69.1653198188664
0.194995,69.2390855946897
0.195995,69.3832971037101
0.196995,69.5078621041713
0.197995,69.6468637019174
0.198995,69.7141999330018
0.199995,69.9002852803585
0.200995,69.9441759694225
0.201995,70.2371193636555
0.202995,70.2884644106981
0.203995,70.4390751699863
0.204995,70.5798854206202
0.205995,70.6987086400592
0.206995,70.7564664939909
0.207995,70.9758605996307
0.208995,71.0003213717708
0.209995,71.2435367006283
0.210995,71.2185378567656
0.211995,71.4796538390345
0.212995,71.4892090105676
0.213995,71.7145325408477
0.214995,71.6934134968216
0.215995,71.8940147797067
0.216995,71.9866842785866
0.217995,72.1641993243229
0.218995,72.2610976422034
0.219995,72.4023103680695
0.220995,72.5307475365444
0.221995,72.6226924093157
0.222995,72.7027764928752
0.223995,72.8466392848278
0.224995,72.9780355496423
0.225995,73.0246854406484
0.226995,73.2333348407746
0.227995,73.2870629546314
0.228995,73.4059166092422
0.229995,73.5188364342302
0.230995,73.6968670309264
0.231995,73.7636868985342
0.232995,73.8986657016731
0.233995,73.9269722762042
0.234995,74.0555115660315
0.235995,74.1266923786162
0.236995,74.3351819297917
0.237995,74.4101580709009
0.238995,74.5770816585885
0.239995,74.7880951582921
0.240995,74.8102346453962
0.241995,75.0255084177537
0.242995,75.0178878424061
0.243995,75.0865595962364
0.244995,75.2801890695969
0.245995,75.334815989364
0.246995,75.4895121524328
0.247995,75.6349840277465
0.248995,75.8416335844941
0.249995,75.9961120055814
0.250995,75.9754561620515
0.251995,76.229698350646
0.252995,76.2233429533708
0.253995,76.3985275422462
0.254995,76.5719009129705
0.255995,76.5561588146724
0.256995,76.8292416861077
0.257995,76.8276442663119
0.258995,77.2173264627206
0.259995,77.1676304899352
0.260995,77.4752356392064
0.261995,77.5458402384941
0.262995,77.6528081214466
0.263995,77.6994522141687
0.264995,77.9383783378092
0.265995,78.0535979095986
0.266995,78.2052206625408
0.267995,78.2724838629139
0.268995,78.4989125306131
0.269995,78.7160313033594
0.270995,78.9147803007989
0.271995,78.9247970153287
0.272995,79.3008806515253
0.273995,79.1608223891352
0.274995,79.5239941357482
0.275995,79.7364517413946
0.276995,79.871578770214
0.277995,80.0322333069715
0.278995,80.2468777178806
0.279995,80.2639042615125
0.280995,80.5637497942395
0.281995,80.6211087056424
0.282995,81.1437892637162
0.283995,81.3041856942681
0.284995,81.5439053406538
0.285995,81.6815784035388
0.286995,81.9207620124391
0.287995,82.0398260159377
0.288995,82.3784598995277
0.289995,82.4197285221161
0.290995,82.5922051951479
0.291995,82.9923070838137
0.292995,83.3667959474339
0.293995,83.5551940619705
0.294995,83.6826557341729
0.295995,84.1330741787113
0.296995,84.310597718782
0.297995,84.7158857047135
0.298995,84.964847130113
0.299995,85.2137904819782
0.300995,85.5183590886169
0.301995,85.8169734288791
0.302995,86.2015505123513
0.303995,86.276794072525
0.304995,86.9501157281435
0.305995,87.3967752901995
0.306995,87.540515930713
0.307995,88.1652153447898
0.308995,88.2658291642257
0.309995,88.822180496081
0.310995,89.3843077958535
0.311995,89.6298561912834
0.312995,89.8741170100805
0.313995,90.471777448139
0.314995,90.9033990613995
0.315995,91.4442438535033
0.316995,91.9218644931377
0.317995,92.0094162631128
0.318995,92.5396631849886
0.319995,93.3297125653704
0.320995,93.8478207497638
0.321995,94.2032349311344
0.322995,94.8564520600795
0.323995,95.4475511202387
0.324995,96.0440917179333
0.325995,96.5649935442668
0.326995,97.2538024039423
0.327995,97.8157460832811
0.328995,98.3430952023106
0.329995,98.9611005043803
0.330995,99.7045981731474
0.331995,100.052016113485
0.332995,100.753521758046
0.333995,101.297710016843
0.334995,102.019477841353
0.335995,102.680591933446
0.336995,103.281955283289
0.337995,104.006014906016
0.338995,104.989682009395
0.339995,105.626640997033
0.340995,106.02855944986
0.341995,106.966822629327
0.342995,107.758088448236
0.343995,108.414752361386
0.344995,108.96351727537
0.345995,109.915256715892
0.346995,110.494506584759
0.347995,111.583930270295
0.348995,112.135939281442
0.349995,112.910414190832
0.350995,113.593225979879
0.351995,114.395534747914
0.352995,115.257316664441
0.353995,116.260841090008
0.354995,116.721177606286
0.355995,117.546047700933
0.356995,118.438107738566
0.357995,119.54761091645
0.358995,120.280642330887
0.359995,120.91742586449
0.360995,121.924734337474
0.361995,122.483681365998
0.362995,123.880919052011
0.363995,124.646687961934
0.364995,125.482731287106
0.365995,126.653402274444
0.366995,127.363411343493
0.367995,128.301920621478
0.368995,129.555525893427
0.369995,130.371944993776
0.370995,131.190812303914
0.371995,132.134400746611
0.372995,133.548242530426
0.373995,134.10097844011
0.374995,135.334182555173
0.375995,136.640951184756
0.376995,137.712070066989
0.377995,136.516574726171
0.378995,128.227881450339
0.379995,120.235561251184
0.380995,113.714333285663
0.381995,108.528185832042
0.382995,103.742112145548
0.383995,98.8239500881434
0.384995,94.1309030957537
0.385995,89.4338325385793
0.386995,85.0163574578798
0.387995,80.84555278557
0.388995,76.9649979074022
0.389995,73.1933004869931
0.390995,69.6421620241306
0.391995,66.1851499604099
0.392995,63.0002068887755
0.393995,60.0447951808269
0.394995,57.394529047461
0.395995,55.0784040050238
0.396995,52.989027325335
0.397995,51.1534747448763
0.398995,49.5496812878641
0.399995,48.2509896096937
0.400995,47.02597142582
0.401995,45.8795029151008
0.402995,44.795542826719
0.403995,43.7323739354933
0.404995,42.6335375591252
0.405995,41.5903317762705
0.406995,40.6345065231416
0.407995,39.6783891031491
0.408995,38.7506536348522
0.409995,37.8636548981819
0.410995,37.0263544815391
0.411995,36.146133588569
0.412995,35.2806841386668
0.413995,34.417010230257
0.414995,33.6593112669556
0.415995,32.9077499379514
0.416995,32.1145733929936
0.417995,31.3700205247467
0.418995,30.5789030360516
0.419995,29.6409162438674
0.420995,28.5685640832178
0.421995,27.3925580989789
0.422995,26.1751140024458
0.423995,24.8562890615091
0.424995,23.4228384799472
0.425995,21.8673148976887
0.426995,20.2464023386173
0.427995,18.5169568500274
0.428995,16.6917943230307
0.429995,14.7103852320255
0.430995,12.6135654737296
0.431995,10.4081314192007
0.432995,8.11649826739454
0.433995,6.00445001154129
0.434995,4.111728401397
0.435995,2.18630558446187
0.436995,0.293047424785328
0.437995,-1.68128287690902
0.438995,-3.77845398903109
0.439995,-6.10076698300362
0.440995,-8.64915623800371
0.441995,-11.3129089255113
0.442995,-12.7904346267018
0.443995,-12.0065958055403
0.444995,-11.1004597284262
0.445995,-10.4834156836692
0.446995,-9.11747169322476
0.447995,-7.87438748810262
0.448995,-5.85265461190657
0.449995,-4.32373231293797
0.450995,-3.74575490103531
0.451995,-3.35287213840835
0.452995,-2.75122097226653
0.453995,-2.19690938108393
0.454995,-1.68147507892189
0.455995,-1.02115494873253
0.456995,-0.785455703825111
0.457995,-0.653479618683735
0.458995,-0.603192579655725
0.459995,-0.606665908135067
0.460995,-1.01838351828894
0.461995,-1.28869662027622
0.462995,-1.42511566814475
0.463995,-1.74969108622049
0.464995,-2.27682931928369
0.465995,-2.38765496319827
0.466995,-2.35856654156338
0.467995,-2.03746955907193
0.468995,-1.92673290620414
0.469995,-1.5150372021331
0.470995,-0.926377655696851
0.471995,-0.713163957096185
0.472995,-0.36014038866656
0.473995,-0.268888965506377
0.474995,-0.449437506645666
0.475995,-0.110885835157005
0.476995,-0.11483457385581
0.477995,-0.371387595084756
0.478995,-0.634244320835737
0.479995,-0.958437024516113
0.480995,-1.35292978386425
0.481995,-1.56752053158378
0.482995,-1.65728493746025
0.483995,-1.67209190985955
0.484995,-1.68265193561012
0.485995,-1.3424712265912
0.486995,-1.40648961847466
0.487995,-0.954660260933157
0.488995,-0.594704803141912
0.489995,-0.426500775368563
0.490995,-0.291800297450796
0.491995,-0.292025133412292
0.492995,-0.258471375951938
0.493995,-0.387034960387467
0.494995,-0.600520075316195
0.495995,-0.836050545622796
0.496995,-0.954215032576677
0.497995,-1.05388566381254
0.498995,-0.911990768848323
0.499995,-1.05939495066921
0.500995,-1.073624899873
0.501995,-0.956624876801073
0.502995,-0.809172320604941
0.503995,-0.583413130615739
0.504995,-0.213832060713625
0.505995,-0.081993610962444
0.506995,0.194430533714375
0.507995,-0.00494424111979568
0.508995,-0.0375027649145858
0.509995,-0.131128267272966
0.510995,-0.680857714488064
0.511995,-0.87653686447605
0.512995,-1.06095673489407
0.513995,-1.03106290300545
0.514995,-1.13435628535897
0.515995,-1.02427925094083
0.516995,-0.920036566778361
0.517995,-0.709474626155573
0.518995,-0.542560283689397
0.519995,-0.412680116717305
0.520995,-0.231426437178735
0.521995,-0.187555139997997
0.522995,-0.0509509953911453
0.523995,-0.0984086911252371
0.524995,0.0129798378772932
0.525995,0.0514981422460014
0.526995,0.0568385559740543
0.527995,0.139730026003274
0.528995,0.233066549754456
0.529995,0.37232138971349
0.530995,0.185041850350113
0.531995,0.119336853284518
0.532995,-0.220299671717495
0.533995,-0.191582955611527
0.534995,-0.329997577884222
0.535995,-0.282996691195821
0.536995,-0.544498231642137
0.537995,-0.544061398618526
0.538995,-0.65977618972757
0.539995,-0.502156950166294
0.540995,-0.540979644650494
0.541995,-0.344110303680176
0.542995,-0.359507294167358
0.543995,-0.243327789443228
0.544995,-0.371055521706332
0.545995,-0.494173873801795
0.546995,-0.282412533067693
0.547995,-0.350585925191927
0.548995,-0.264305514706355
0.549995,-0.210208033572689
0.550995,-0.106768620198741
0.551995,-0.0979717382335132
0.552995,-0.231756469374159
0.553995,-0.148642519479884
0.554995,-0.160149586825365
0.555995,-0.257820333038411
0.556995,-0.406508426026051
0.557995,-0.351569521861983
0.558995,-0.43020567377545
0.559995,-0.265873107794427
0.560995,-0.184192628007117
0.561995,-0.176057506227053
0.562995,0.000290446355433795
0.563995,0.0679938637688674
0.564995,0.0450681534137791
0.565995,0.188051677047436
0.566995,0.0812670868321752
0.567995,-0.0932817770440222
0.568995,-0.0917188869655093
0.569995,-0.0552766571255037
0.570995,-0.32475332634715
0.571995,-0.366435455257968
0.572995,-0.473106927598998
0.573995,-0.544113202567065
0.574995,-0.623914278021922
0.575995,-0.597353859943064
0.576995,-0.554314495598999
0.577995,-0.398448328578268
0.578995,-0.315901686457636
0.579995,-0.0793191880114774
0.580995,-0.0364071789584076
0.581995,0.0247045250092263
0.582995,0.156984969054809
0.583995,0.102093234928603
0.584995,0.0239602636372326
0.585995,-0.00832277186637859
0.586995,0.163262806184404
0.587995,0.239881130283814
0.588995,0.390616290730216
0.589995,0.277436931635215
0.590995,0.264139948311438
0.591995,0.0549264725786745
0.592995,0.0514656767053396
0.593995,0.0162365494121131
0.594995,-0.120307643071857
0.595995,-0.154150146236421
0.596995,-0.224195800894395
0.597995,-0.331527485945816
0.598995,-0.234707252473216
0.599995,-0.164420263339897
0.600995,0.0111447797190381
0.601995,0.124877316634061
0.602995,0.13525806967822
0.603995,-0.0525527085292112
0.604995,-0.0327147079846485
0.605995,-0.208824516594194
0.606995,-0.220989418057844
0.607995,-0.324792156359602
0.608995,-0.388983464844459
0.609995,-0.441376269550132
0.610995,-0.486195614232487
0.611995,-0.489805164913229
0.612995,-0.442495563206195
0.613995,-0.386128700794926
0.614995,-0.363751003466216
0.615995,-0.157399963622488
0.616995,-0.321649494207803
0.617995,-0.212712164131127
0.618995,-0.224513281857671
0.619995,-0.0719809291917341
0.620995,-0.075362797089003
0.621995,0.0797669246676898
0.622995,0.00455271920718103
0.623995,-0.0585435048114333
0.624995,0.0402222885729264
0.625995,-0.147055511408927
0.626995,-0.106630810848443
0.627995,-0.170916950239486
0.628995,-0.183246724054769
0.629995,-0.211612821489692
0.630995,-0.186740746595102
0.631995,-0.182459112242852
0.632995,-0.211306865584904
0.633995,-0.191195996445588
0.634995,-0.158537051335675
0.635995,-0.157841078319489
0.636995,-0.260997738392286
0.637995,-0.284386774189036
0.638995,-0.230842576546767
0.639995,-0.357065848008641
0.640995,-0.455411286363045
0.641995,-0.48175175893879
0.642995,-0.481673291939518
0.643995,-0.391966118114628
0.644995,-0.244483920091109
0.645995,-0.146148553413116
0.646995,-0.251597680130028
0.647995,-0.200768873044753
0.648995,-0.237352028685751
0.649995,-0.108227853865534
0.650995,-0.110360130763519
0.651995,-0.036142788840554
0.652995,-0.0319568215262315
0.653995,-0.135182271669874
0.654995,-0.203293559111085
0.655995,-0.262541664786539
0.656995,-0.243506456313942
0.657995,-0.233153652178251
0.658995,-0.168174597844916
0.659995,-0.153516186522035
0.660995,-0.0120736039113853
0.661995,0.0416810666284892
0.662995,0.24695005129177
0.663995,0.238716788998208
0.664995,0.18578566423515
0.665995,0.118448833708148
0.666995,0.0758013857771751
0.667995,0.0969568585182015
0.668995,0.0239195857817873
0.669995,0.0645878593028733
0.670995,-0.112559842994638
0.671995,-0.201319433857273
0.672995,-0.311612287579903
0.673995,-0.380794721312733
0.674995,-0.391813814592608
0.675995,-0.358847251084147
0.676995,-0.264382736944894
0.677995,-0.203126073560499
0.678995,-0.16924345997637
0.679995,-0.202572573442957
0.680995,-0.13176127207472
0.681995,0.00630770284113861
0.682995,0.214428560766761
0.683995,0.29410332869013
0.684995,0.277058445422705
0.685995,0.16649111888774
0.686995,0.121074779203287
0.687995,0.102811677124849
0.688995,0.1628895376592
0.689995,0.112254919012003
0.690995,0.135037766774192
0.691995,0.041817184834715
0.692995,-0.0713802943843978
0.693995,-0.0771096533461245
0.694995,-0.189097772124561
0.695995,-0.324110076352172
0.696995,-0.284149198291891
0.697995,-0.381277296135232
0.698995,-0.424981057805856
0.699995,-0.479272907985586
0.700995,-0.426957778539482
0.701995,-0.443837175432503
0.702995,-0.388387347714813
0.703995,-0.166682219862868
0.704995,-0.0683315982605879
0.705995,0.122424062505294
0.706995,0.229282576631747
0.707995,0.430419231973585
0.708995,0.385825343506381
0.709995,0.360904311555862
0.710995,0.198588824725604
0.711995,0.11993455945323
0.712995,-0.0310307113833726
0.713995,-0.0159316922833727
0.714995,-0.0504955767659373
0.715995,-0.0629109029291339
0.716995,-0.157653492722332
0.717995,-0.266995224429069
0.718995,-0.158117010111516
0.719995,-0.146633838499227
0.720995,-0.0663165590726707
0.721995,-0.0854764328924385
0.722995,0.0134919046229592
0.723995,-0.123254176663051
0.724995,-0.065213178722044
0.725995,-0.119846557554059
0.726995,-0.0544059734768903
0.727995,-0.142556432562388
0.728995,-0.130249945436965
0.729995,-0.110914510288138
0.730995,-0.0990071132154858
0.731995,-0.0062609337410742
0.732995,0.0412451404881325
0.733995,0.160728896225735
0.734995,0.0260918753296824
0.735995,0.157001062668645
0.736995,-0.024744278623418
0.737995,0.0649319430889007
0.738995,-0.0251730605762807
0.739995,-0.110783003089789
0.740995,-0.0766598546641701
0.741995,-0.126271455049451
0.742995,-0.0779001246359565
0.743995,-0.0644385960103022
0.744995,-0.0686644781417725
0.745995,-0.149278578625255
0.746995,-0.202496368658876
0.747995,-0.259729880005547
0.748995,-0.0543223564080713
0.749995,-0.114443726088783
0.750995,0.0260803530190704
0.751995,-0.0599229211226658
0.752995,-0.0502622040320496
0.753995,-0.0602057523952961
0.754995,0.110600446647804
0.755995,0.14665908615521
0.756995,0.205248657707908
0.757995,0.144176200356557
0.758995,0.142039233614757
0.759995,0.0394386465895078
0.760995,0.142204859927102
0.761995,0.0424817959554439
0.762995,0.0997770946923249
0.763995,0.0770133802987939
0.764995,0.0807115278678018
0.765995,0.00840053831766363