File: DATA&scripts/3.4-data/h/13/13_fracture_stress_data.csv
Strain,Fracture Stress (GPa)
2.0035752857691e-16,-0.749287259041256
0.000495000000000393,2.29960814593893
0.000995000000000384,-0.252762914121982
0.00149500000000038,2.79157490201213
0.00199500000000037,1.27418562984088
0.00249500000000036,1.69567444423379
0.00299500000000035,3.13671467868462
0.00349500000000034,1.20643412155389
0.00399500000000034,3.91375629216049
0.00449500000000033,0.760714648288466
0.00499500000000032,5.01496654373197
0.00549500000000031,1.38789421677667
0.0059950000000003,4.8715550433086
0.00649500000000029,2.72794231711758
0.00699500000000029,4.36857321986152
0.00749500000000028,4.10017261766777
0.00799500000000027,3.96127129316624
0.00849500000000026,5.2484339435832
0.00899500000000025,3.44452141125257
0.00949500000000024,6.55035763310699
0.00999500000000024,3.64140423722803
0.0104950000000002,6.59091666041477
0.0109950000000002,4.30499887269205
0.0114950000000002,6.90470593976684
0.0119950000000002,5.17035713016191
0.0124950000000002,6.54794761508856
0.0129950000000002,6.54194550267989
0.0134950000000002,6.20640630591914
0.0139950000000002,7.34365708397314
0.0144950000000002,6.17813302039656
0.0149950000000002,8.21381905985464
0.0154950000000001,6.25484422887769
0.0159950000000001,8.67521095956886
0.0164950000000001,6.8235965478151
0.0169950000000001,8.6913145316845
0.0174950000000001,7.50574782180208
0.0179950000000001,8.82267379782722
0.0184950000000001,8.42646281936902
0.0189950000000001,8.72426253015798
0.0194950000000001,9.21544440759702
0.0199950000000001,8.55048362355568
0.0204950000000001,10.0226036566927
0.0209950000000003,8.96410575848786
0.0214950000000002,10.3227542192657
0.0219950000000002,9.06643093442475
0.0224950000000002,10.7443856532475
0.0229950000000002,9.82022007853394
0.0234950000000002,10.7844650937462
0.0239950000000004,10.4481883594476
0.0244950000000004,10.9149610767005
0.0249950000000004,11.0839602198984
0.0254950000000004,11.0487337037279
0.0259950000000004,11.7539638117326
0.0264950000000004,11.1172524569475
0.0269950000000004,12.2144813951143
0.0274950000000003,11.5574299007271
0.0279950000000003,12.5214104998834
0.0284950000000003,11.8913894629983
0.0289950000000003,12.7015308298552
0.0294950000000003,12.3813123967826
0.0299950000000003,12.8768726491588
0.0304950000000003,13.0148321271797
0.0309950000000003,13.0203069346056
0.0314950000000003,13.5809566442138
0.0319950000000003,13.325245335239
0.0324950000000003,13.9676016951466
0.0329950000000003,13.5681759805165
0.0334950000000003,14.3763506262405
0.0339950000000002,14.0605741581167
0.0344950000000002,14.573956452956
0.0349950000000002,14.3856739374792
0.0354950000000002,14.9103691480247
0.0359950000000002,14.8987107026702
0.0364950000000002,15.0314774500114
0.0369950000000002,15.3050349872373
0.0374950000000002,15.3566838704795
0.0379950000000002,15.8395816603271
0.0384950000000002,15.5438876233312
0.0389950000000002,16.1587741115116
0.0394950000000002,15.9990781951817
0.0399950000000001,16.621070784202
0.0404950000000001,16.3579268179887
0.0409950000000001,16.8245467873535
0.0414950000000001,16.7996009192046
0.0419950000000001,17.0717894923858
0.0424950000000001,17.1208536752971
0.0429950000000001,17.2120776229492
0.0434950000000001,17.7131350412991
0.0439950000000001,17.4040920277767
0.0444950000000001,18.143978235788
0.0449950000000003,17.8400813813548
0.0454950000000003,18.4256337864621
0.0459950000000002,18.0615892027539
0.0464950000000002,18.760055896245
0.0469950000000002,18.5757027358839
0.0474950000000002,18.8702399684147
0.0479950000000004,18.9540099583607
0.0484950000000004,19.0676644408242
0.0489950000000004,19.4636790467495
0.0494950000000004,19.3445206819258
0.0499950000000004,19.9326801126121
0.0504950000000004,19.652567507061
0.0509950000000004,20.2834181444345
0.0514950000000004,20.024819049536
0.0519950000000003,20.4191125915715
0.0524950000000003,20.339068061101
0.0529950000000003,20.7030713308507
0.0534950000000003,20.8145854090133
0.0539950000000003,20.9531308175142
0.0544950000000003,21.1939488395174
0.0549950000000003,21.1976665607462
0.0554950000000003,21.5645918319825
0.0559950000000003,21.500453429714
0.0564950000000003,21.8901903203704
0.0569950000000003,21.8600656375615
0.0574950000000003,22.1180283596713
0.0579950000000002,22.1066245394194
0.0584950000000002,22.4958189873941
0.0589950000000002,22.5058500100883
0.0594950000000002,22.6947118467356
0.0599950000000002,22.8801375712551
0.0604950000000002,23.006387545554
0.0609950000000002,23.0183050951506
0.0614950000000002,23.2398631279342
0.0619950000000002,23.5097969671694
0.0624950000000002,23.5493600484391
0.0629950000000002,23.6898573044642
0.0634950000000002,23.7544435449751
0.0639950000000001,24.0404503549136
0.0644950000000001,24.1690127187076
0.0649950000000001,24.3703904174035
0.0654950000000001,24.2911842432812
0.0659950000000001,24.7046995696015
0.0664950000000001,24.7716300318502
0.0669950000000001,24.9067463368999
0.0674950000000001,24.9655291849641
0.0679950000000001,25.2650341598617
0.0684950000000001,25.3424560505845
0.0689950000000003,25.4439168261266
0.0694950000000003,25.654066110498
0.0699950000000003,25.7663094348939
0.0704950000000002,26.0152268626171
0.0709950000000004,26.0229016403224
0.0714950000000004,26.2572976491508
0.0719950000000004,26.2630021948629
0.0724950000000004,26.628283658664
0.0729950000000004,26.571272841193
0.0734950000000004,26.8533137160346
0.0739950000000004,26.9442611452258
0.0744950000000004,27.105529050575
0.0749950000000004,27.2296876136651
0.0754950000000004,27.3867359990776
0.0759950000000004,27.568827746538
0.0764950000000003,27.5501047513812
0.0769950000000003,27.8744889572577
0.0774950000000003,27.9470601799565
0.0779950000000003,28.2401370436413
0.0784950000000003,28.208243990499
0.0789950000000003,28.4801029645869
0.0794950000000003,28.5282806049491
0.0799950000000003,28.7610648176413
0.0804950000000003,28.788555916986
0.0809950000000003,28.9667245705242
0.0814950000000003,29.1287924115069
0.0819950000000003,29.1728812326409
0.0824950000000002,29.3638552532597
0.0829950000000002,29.3734708632455
0.0834950000000002,29.725005492673
0.0839950000000002,29.757847141319
0.0844950000000002,29.9666804134664
0.0849950000000002,29.9747594629642
0.0854950000000002,30.2340788094607
0.0859950000000002,30.3423108597042
0.0864950000000002,30.4910496688265
0.0869950000000002,30.6341408654824
0.0874950000000002,30.6454248490395
0.0879950000000002,30.7987125607061
0.0884950000000001,30.9315580508849
0.0889950000000001,31.151781111612
0.0894950000000001,31.1109906515573
0.0899950000000001,31.3994646313315
0.0904950000000001,31.4275565903451
0.0909950000000001,31.7331279662667
0.0914950000000001,31.6605172974137
0.0919950000000001,31.8252914283167
0.0924950000000001,31.929248444389
0.0929950000000001,32.1209501867308
0.0934950000000003,32.2306979868997
0.0939950000000003,32.3316313045331
0.0944950000000002,32.4941098414153
0.0949950000000002,32.5518622325105
0.0954950000000002,32.761309711771
0.0959950000000004,32.8387300681913
0.0964950000000004,32.982073526884
0.0969950000000004,33.0217179191065
0.0974950000000004,33.2338686991191
0.0979950000000004,33.2995861215146
0.0984950000000004,33.4101031573582
0.0989950000000004,33.5402488863455
0.0994950000000004,33.6932226779735
0.0999950000000004,33.8249394079355
0.100495,33.8185312765416
0.100995,33.9938373247506
0.101495,34.1238546114233
0.101995,34.2880789410876
0.102495,34.3155029162317
0.102995,34.4984779771997
0.103495,34.6114828271202
0.103995,34.7969149487894
0.104495,34.7887611848464
0.104995,34.9498305359173
0.105495,35.1023583941582
0.105995,35.2442445584742
0.106495,35.372494266258
0.106995,35.3920725941916
0.107495,35.5687395074443
0.107995,35.5958897437275
0.108495,35.8342128469657
0.108995,35.7679457780172
0.109495,36.039839011689
0.109995,36.0763272679476
0.110495,36.1805821712885
0.110995,36.2986969383598
0.111495,36.4761265989333
0.111995,36.521938273403
0.112495,36.5472723314459
0.112995,36.7440250667427
0.113495,36.8089493772338
0.113995,36.9918319043596
0.114495,37.0283268142951
0.114995,37.2056531688875
0.115495,37.1946227383497
0.115995,37.469629494012
0.116495,37.4864553078838
0.116995,37.5688672510442
0.117495,37.6171712365085
0.117995,37.794671238929
0.118495,37.9534429135041
0.118995,37.9760135171545
0.119495,38.1264917828134
0.119995,38.203888093202
0.120495,38.3672450666702
0.120995,38.3632610729391
0.121495,38.4504827919375
0.121995,38.5211043199123
0.122495,38.7303641084183
0.122995,38.7424704002674
0.123495,38.7889689494366
0.123995,38.9889643066268
0.124495,39.1239692704676
0.124995,39.2584865545839
0.125495,39.2625170870424
0.125995,39.3669516696313
0.126495,39.4715885872462
0.126995,39.6542298816747
0.127495,39.6393727414263
0.127995,39.7961853285182
0.128495,39.7795214912134
0.128995,39.934168479804
0.129495,40.0121804796889
0.129995,40.1884037423084
0.130495,40.2052485813581
0.130995,40.288364647534
0.131495,40.474143257831
0.131995,40.4783211686941
0.132495,40.5604539128442
0.132995,40.6340655399496
0.133495,40.7831661528407
0.133995,40.788479904921
0.134495,40.9376305148029
0.134995,41.006193136643
0.135495,41.1725564329844
0.135995,41.2298625898277
0.136495,41.3844052661246
0.136995,41.4149364807113
0.137495,41.5124757150664
0.137995,41.6596137141979
0.138495,41.6477949114654
0.138995,41.7304376319044
0.139495,41.7586836294942
0.139995,41.9431908714975
0.140495,41.9987774244443
0.140995,42.1341309903924
0.141495,42.0692871834485
0.141995,42.2766715732592
0.142495,42.3129096418687
0.142995,42.3891513686559
0.143495,42.4456458239241
0.143995,42.5856957918777
0.144495,42.6730696264857
0.144995,42.7848610704739
0.145495,42.8268749072566
0.145995,43.0038858866483
0.146495,43.0443675192222
0.146995,43.0436980536376
0.147495,43.1604166722212
0.147995,43.2786274832873
0.148495,43.3616008289293
0.148995,43.3408732185515
0.149495,43.4356090817229
0.149995,43.5278317297659
0.150495,43.6819653003298
0.150995,43.6781619933627
0.151495,43.7765196769408
0.151995,43.8329641610562
0.152495,43.9314156047483
0.152995,44.0076382388321
0.153495,44.0161057323462
0.153995,44.1753522418396
0.154495,44.1728740800529
0.154995,44.2835946567934
0.155495,44.2818114832885
0.155995,44.4677350028121
0.156495,44.4677789200331
0.156995,44.5861029051351
0.157495,44.6261365301434
0.157995,44.7052678435783
0.158495,44.7458348615568
0.158995,44.7856303559875
0.159495,44.9311881505255
0.159995,44.9729153818969
0.160495,45.0856211905351
0.160995,45.0817667219706
0.161495,45.2378061637632
0.161995,45.2809859886708
0.162495,45.3885863243766
0.162995,45.3928380509907
0.163495,45.4686441213822
0.163995,45.5356803691014
0.164495,45.6060175203536
0.164995,45.7145264963321
0.165495,45.6985501335133
0.165995,45.7528138576205
0.166495,45.7995204851854
0.166995,45.9800793298972
0.167495,45.9478081463752
0.167995,46.0311119543068
0.168495,46.0379077337906
0.168995,46.1324873751578
0.169495,46.2285825351609
0.169995,46.2077436406891
0.170495,46.3201614462527
0.170995,46.373428682575
0.171495,46.4963822808953
0.171995,46.499914367364
0.172495,46.6078353874542
0.172995,46.6553072285233
0.173495,46.7451264439326
0.173995,46.8141317074388
0.174495,46.8089109754061
0.174995,46.8745245179133
0.175495,46.9184795900668
0.175995,47.0654620665065
0.176495,47.0574586892822
0.176995,47.0835351609797
0.177495,47.1479403279766
0.177995,47.2556771592178
0.178495,47.2839346551108
0.178995,47.3115713520879
0.179495,47.3895063203959
0.179995,47.4695691447084
0.180495,47.5362114178716
0.180995,47.521434211873
0.181495,47.6398600710833
0.181995,47.6456018005096
0.182495,47.7741236971288
0.182995,47.74832779671
0.183495,47.8151418262699
0.183995,47.8974087283063
0.184495,47.9721252275073
0.184995,47.9922109658717
0.185495,48.0693764384672
0.185995,48.1489038182266
0.186495,48.1466976608973
0.186995,48.1680537520645
0.187495,48.3237292758931
0.187995,48.303981017186
0.188495,48.3551427878809
0.188995,48.387457693733
0.189495,48.4801643822555
0.189995,48.5412737261538
0.190495,48.4920824890193
0.190995,48.5958993285359
0.191495,48.6784477472062
0.191995,48.7169984202073
0.192495,48.7159914666683
0.192995,48.7553969388111
0.193495,48.8681868152787
0.193995,48.9082458013008
0.194495,48.9432427798033
0.194995,49.0245908570368
0.195495,49.0088712208122
0.195995,49.1175668243113
0.196495,49.1094032345901
0.196995,49.1941297782156
0.197495,49.2743609475606
0.197995,49.3302998379908
0.198495,49.2873688779424
0.198995,49.3284931362562
0.199495,49.439061066261
0.199995,49.3955633265954
0.200495,49.5358082702115
0.200995,49.4985019067333
0.201495,49.6069408417771
0.201995,49.5706441213122
0.202495,49.6645194874016
0.202995,49.7162677094221
0.203495,49.7784656405754
0.203995,49.7687904364785
0.204495,49.8254800297305
0.204995,49.9154798046417
0.205495,49.9548458262176
0.205995,50.0287042008991
0.206495,50.0063129948142
0.206995,50.1222616439133
0.207495,50.1072630513991
0.207995,50.1718117257843
0.208495,50.1721097714224
0.208995,50.2987964331872
0.209495,50.3040934789331
0.209995,50.3355313967128
0.210495,50.4127189320521
0.210995,50.490380308751
0.211495,50.5133112890426
0.211995,50.4424743831248
0.212495,50.618128710727
0.212995,50.6200265394538
0.213495,50.6870422565623
0.213995,50.612042536964
0.214495,50.760201801909
0.214995,50.7571637562208
0.215495,50.8422239865569
0.215995,50.858568997818
0.216495,50.9008050341257
0.216995,50.9301428972251
0.217495,50.9532760299881
0.217995,51.0519672812786
0.218495,51.0199577661848
0.218995,51.1369293626424
0.219495,51.0400428604497
0.219995,51.2297737371831
0.220495,51.247184120202
0.220995,51.3748110738905
0.221495,51.1984213929267
0.221995,51.3188693840971
0.222495,51.3870467022593
0.222995,51.5202428391969
0.223495,51.5117096825205
0.223995,51.463815440598
0.224495,51.5894286538611
0.224995,51.6409288781343
0.225495,51.6414144727515
0.225995,51.5713362705536
0.226495,51.6916671743011
0.226995,51.7186858927719
0.227495,51.842640702601
0.227995,51.805192609996
0.228495,51.8971580372129
0.228995,51.9704735562022
0.229495,51.9204597583676
0.229995,52.0023838680181
0.230495,51.9622671170088
0.230995,52.088700661622
0.231495,52.0910016779397
0.231995,52.1580026275092
0.232495,52.1400018103075
0.232995,52.3061169397276
0.233495,52.3156558469773
0.233995,52.3425465076827
0.234495,52.3425806259543
0.234995,52.4663128980641
0.235495,52.4439246282668
0.235995,52.5390405047407
0.236495,52.5334593848826
0.236995,52.6048982593045
0.237495,52.6036770030513
0.237995,52.5853819067427
0.238495,52.6813228741908
0.238995,52.7796433045081
0.239495,52.9177677993094
0.239995,52.7489610003023
0.240495,52.7943180813659
0.240995,52.8455629724671
0.241495,52.9913080657939
0.241995,52.9124852264734
0.242495,52.9306548569779
0.242995,53.1355587753269
0.243495,53.1327037363247
0.243995,53.1518120484152
0.244495,53.2229795272089
0.244995,53.2687906754336
0.245495,53.2909419069652
0.245995,53.3392222855851
0.246495,53.3185005987528
0.246995,53.4587775993325
0.247495,53.4280423673597
0.247995,53.5234430371158
0.248495,53.5434904541269
0.248995,53.6158383493903
0.249495,53.5627525767453
0.249995,53.6109442803591
0.250495,53.7410898530809
0.250995,53.7825825686907
0.251495,53.7587471955003
0.251995,53.8350306151961
0.252495,53.8967002633216
0.252995,53.849671708253
0.253495,54.0032009561731
0.253995,54.0486800376049
0.254495,54.0477079729396
0.254995,54.0919395352922
0.255495,54.1499791383553
0.255995,54.155466082695
0.256495,54.25965722148
0.256995,54.2029791821463
0.257495,54.3982844152702
0.257995,54.3700186048697
0.258495,54.3722251422144
0.258995,54.4591155528045
0.259495,54.417930067738
0.259995,54.6410145331537
0.260495,54.6511702992131
0.260995,54.7602384689565
0.261495,54.7824568345917
0.261995,54.850928136715
0.262495,54.8693731098073
0.262995,54.9013358955804
0.263495,54.7879997615365
0.263995,54.9535051863582
0.264495,55.0326777292297
0.264995,55.1595493626299
0.265495,55.1756859237333
0.265995,55.1011987496359
0.266495,55.1853995981999
0.266995,55.38923379725
0.267495,55.3652205659036
0.267995,55.2710226374861
0.268495,55.4249421951949
0.268995,55.4842319806282
0.269495,55.5487473630971
0.269995,55.6299642249313
0.270495,55.6747043819495
0.270995,55.7164123144259
0.271495,55.7870762775874
0.271995,55.9133793770691
0.272495,55.9061084196641
0.272995,56.0043211084353
0.273495,55.9646325784378
0.273995,56.0207117136325
0.274495,56.1059081240248
0.274995,56.2343472177242
0.275495,56.2590545254488
0.275995,56.2713998260614
0.276495,56.3524456509109
0.276995,56.3442639372448
0.277495,56.5191035778763
0.277995,56.5599786497445
0.278495,56.6513252882268
0.278995,56.6089633508162
0.279495,56.7135331455019
0.279995,56.733450845003
0.280495,56.7864236452348
0.280995,56.9558645146716
0.281495,57.0303771502631
0.281995,56.9264344015104
0.282495,57.2102585276536
0.282995,57.2267974308879
0.283495,57.3320054996664
0.283995,57.2942801178548
0.284495,57.3589129492076
0.284995,57.5638060761058
0.285495,57.742942932547
0.285995,57.6964179249711
0.286495,57.6876826310701
0.286995,57.7789595952931
0.287495,57.8122969652462
0.287995000000001,58.0509028112442
0.288495,58.0705101611447
0.288995,58.0896956747701
0.289495,58.2077682147634
0.289995,58.2866474758335
0.290495,58.3526121614707
0.290995,58.4192462983932
0.291495,58.4863437896028
0.291995,58.6941740414057
0.292495,58.7119280757462
0.292995,58.9403251244435
0.293495,58.9025211590299
0.293995,58.9769924513042
0.294495,59.1933813955327
0.294995,59.0659189160131
0.295495,59.1949955014569
0.295995,59.3484301264229
0.296495,59.4410670779183
0.296995,59.6392252528607
0.297495,59.6319424898797
0.297995,59.7398567856505
0.298495,59.8685421657155
0.298995,60.0164671959016
0.299495,60.0699556110142
0.299995,60.3061727618529
0.300495,60.1866690815926
0.300995,60.5898312482439
0.301495,60.5799152323695
0.301995,60.588540912762
0.302495,60.9339803879768
0.302995,60.9192192212949
0.303495,60.9674880819024
0.303995,61.1951989176079
0.304495,61.3137534050138
0.304995,61.3330371512354
0.305495,61.5182121900149
0.305995,61.632667179213
0.306495,61.7927821803353
0.306995,61.8252097949028
0.307495,61.9152069164258
0.307995,62.2237879162824
0.308495,62.3528343621226
0.308995,62.5584864485556
0.309495,62.6293503571532
0.309995,62.6234952517137
0.310495000000001,62.9170769286719
0.310995000000001,63.0686183318453
0.311495,63.2579086325233
0.311995,63.5245543151277
0.312495,63.4191020157329
0.312995,63.5575383240152
0.313495,63.9138568060969
0.313995,64.009790315867
0.314495,64.0807720188042
0.314995,64.3188854415825
0.315495,64.5549048675488
0.315995,64.8009301118137
0.316495,64.8589527325759
0.316995,64.966458878281
0.317495,65.3271681415578
0.317995,65.2172213036877
0.318495,65.3895485992527
0.318995,65.8421289209389
0.319495,66.0407023381046
0.319995,66.1742652763188
0.320495,66.2253685708008
0.320995,66.5073056265363
0.321495,66.6712090699526
0.321995,66.7780891681275
0.322495,67.051190927102
0.322995,67.2526741085084
0.323495,67.3987049043823
0.323995,67.8754422516025
0.324495,67.8250921386738
0.324995,68.032255849754
0.325495,68.4071777881073
0.325995,68.4085116584395
0.326495,68.7438643567123
0.326995,69.0567563722977
0.327495,69.0303688410699
0.327995,69.1833205220547
0.328495,69.4852571474178
0.328995,69.7107506490737
0.329495,70.0041682843165
0.329995,70.2085874743098
0.330495,70.3567860429441
0.330995,70.7283796068128
0.331495,70.6490853398381
0.331995,71.1529037276833
0.332495,71.3432264845284
0.332995,71.3767771765454
0.333495,71.8141269873783
0.333995,71.8491953205539
0.334495,72.2340514931542
0.334995,72.3315566603771
0.335495,72.8089311777743
0.335995,73.0252582672734
0.336495,73.02897883769
0.336995,73.5761574869632
0.337495,73.6158142555421
0.337995,74.0591789737023
0.338495,74.2746098191986
0.338995,74.5324650671486
0.339495,74.620282554512
0.339995,75.0976669444182
0.340495,75.1579156108627
0.340995,75.3925555853482
0.341495,75.9598692879734
0.341995,75.925340232796
0.342495,76.4467499864882
0.342995,76.3444848227468
0.343495,76.9718810160452
0.343995,76.960587781779
0.344495,77.4456611148313
0.344995,77.4448685983511
0.345495,77.7215241867439
0.345995,78.2359606387388
0.346495,78.2909313994045
0.346995,78.6486284750795
0.347495,78.8302861111257
0.347995,79.1941900272866
0.348495,79.5701868359813
0.348995,79.59559047743
0.349495,80.0798798289692
0.349995,80.3154070094919
0.350495,80.7418827918708
0.350995,80.574980232706
0.351495,81.2401108009024
0.351995,81.2714443017367
0.352495,81.7738319927394
0.352995,81.9458884072701
0.353495,82.2993439347158
0.353995,82.4589961001994
0.354495,82.8943122191054
0.354995,83.0400163898522
0.355495,83.5084482875699
0.355995,83.7200929363387
0.356495,84.0771767138468
0.356995,84.4009239961727
0.357495,84.8139820897953
0.357995,84.9422506208581
0.358495,85.1154698578574
0.358995,85.5875095376906
0.359495000000001,85.8063584085442
0.359995000000001,86.2095989455185
0.360495000000001,86.292124780057
0.360995,86.8853211496966
0.361495,87.4945054983377
0.361995,87.4361081942517
0.362495,87.576907664394
0.362995,88.0991156117629
0.363495,88.4729742850472
0.363995,88.879915934527
0.364495,89.1680253491803
0.364995,89.4167308944497
0.365495,89.6235330492809
0.365995,90.1224364845613
0.366495,90.4538345473894
0.366995,90.7547497736291
0.367495,91.0344925110784
0.367995,91.4082726074328
0.368495,91.9935351669635
0.368995,92.1985517477697
0.369495,92.5487703657169
0.369995,92.6712186690622
0.370495,93.3226084344764
0.370995,93.7334238177893
0.371495,94.059496670028
0.371995,94.4552330731713
0.372495,94.5570432568069
0.372995,94.8627344144931
0.373495,95.3492381129832
0.373995,95.9267643142351
0.374495,96.3412648238355
0.374995,96.8157620716757
0.375495,96.9038475285966
0.375995,97.3724508549109
0.376495,97.6459042328581
0.376995,98.0237843659627
0.377495,98.6699225765204
0.377995,98.9604515608548
0.378495,99.1589120546773
0.378995,99.6492977829573
0.379495,99.8360698124888
0.379995,99.3527661978108
0.380495,97.3028332193603
0.380995,93.0909968179529
0.381495,85.2540005479505
0.381995,75.7719770834383
0.382495,68.3039896295309
0.382995,61.2531724257884
0.383495,55.6736495893751
0.383995,50.5693010969662
0.384495,45.310341985653
0.384995,40.2110525810824
0.385495,36.0814524263504
0.385995,33.9206503122045
0.386495,32.2533247705026
0.386995,30.1516099739186
0.387495,28.3165651862088
0.387995,26.9128496337477
0.388495,26.0356276716691
0.388995,25.2808603499279
0.389495,24.5955187703505
0.389995,23.872038257152
0.390495,23.0738012675672
0.390995,22.1580281079924
0.391495,21.1290178865474
0.391995,20.1239187903233
0.392495,19.1790725336852
0.392995,18.2679644422552
0.393495,17.4710295081676
0.393995,16.7123099357808
0.394495,16.0024796008042
0.394995,15.4170465804029
0.395495,14.8374895121232
0.395995,14.1638503114027
0.396495,13.352950849565
0.396995,12.428390295412
0.397495,11.3813502914845
0.397995,10.2436960757261
0.398495,9.00372447702531
0.398995,7.64922684159691
0.399495,6.21282883594867
0.399995,4.68825846083152
0.400495,3.0691508748108
0.400995,1.37669310216078
0.401495,-0.457412298238375
0.401995,-2.34640512027278
0.402495,-4.13196660281769
0.402995,-5.82344229422717
0.403495,-7.49363581590384
0.403995,-8.74983402714583
0.404495,-8.26789490805104
0.404995,-6.68557464009337
0.405495,-5.5854773587699
0.405995,-4.37168043619759
0.406495,-3.76688030660272
0.406995,-3.47038869742967
0.407495,-2.99581788332293
0.407995,-2.82449733390758
0.408495,-2.79098298636069
0.408995,-2.52844539031748
0.409495,-2.27012091851664
0.409995,-1.98426279680146
0.410495,-1.633507112681
0.410995,-1.6222022809914
0.411495,-1.6209218669563
0.411995,-1.67331528315992
0.412495,-1.56619740600821
0.412995,-1.38364663460662
0.413495,-1.48914862633588
0.413995,-1.20149520232789
0.414495,-0.966839432696283
0.414995,-0.799379265172527
0.415495,-0.757673279790651
0.415995,-0.561923569905283
0.416495,-0.518838800616365
0.416995,-0.530311696106561
0.417495,-0.682006084931844
0.417995,-0.495630193187055
0.418495,-0.871956985817946
0.418995,-0.647778735592733
0.419495,-0.870756047847988
0.419995,-0.82707554948881
0.420495,-0.959872673235114
0.420995,-0.905465763006034
0.421495,-0.915910559691234
0.421995,-0.691793938641361
0.422495,-0.536931181813901
0.422995,-0.500387582850181
0.423495,-0.198384621945675
0.423995,-0.165519680768526
0.424495,0.0150301571556412
0.424995,-0.141050268534298
0.425495,-0.107859275787909
0.425995,-0.166242934596367
0.426495,-0.202739402967976
0.426995,-0.0557776260172758
0.427495,-0.0309745945360517
0.427995,-0.114261519025912
0.428495,-0.0874921329836781
0.428995,-0.172692410240712
0.429495,-0.214427349101125
0.429995,-0.16944348052801
0.430495,-0.250749192195791
0.430995,-0.396303180464163
0.431495000000001,-0.466633508814232
0.431995000000001,-0.429990145491564
0.432495000000001,-0.327902766058089
0.432995000000001,-0.157830187056861
0.433495000000001,-0.383883507296423
0.433995,-0.430782955255581
0.434495,-0.421344921328783
0.434995,-0.405865164613215
0.435495,-0.371453775869682
0.435995,-0.378975724682271
0.436495,-0.343509476476608
0.436995,-0.296918625302211
0.437495,-0.312285973578648
0.437995,-0.40837068673858
0.438495,-0.294067272938382
0.438995,-0.210181217916858
0.439495,-0.130819297035903
0.439995,-0.133760046843337
0.440495,-0.177002848246638
0.440995,-0.338130012041593
0.441495,-0.374519275011279
0.441995,-0.342178677481443
0.442495,-0.274208347157888
0.442995,-0.265830801529531
0.443495,-0.212421094960837
0.443995,-0.31471832458302
0.444495,-0.2812197032983
0.444995,-0.108503637717554
0.445495,-0.30396825867117
0.445995,-0.301239217288294
0.446495,-0.304693903431323
0.446995,-0.29656345696344
0.447495,-0.1932054612452
0.447995,-0.107947043605878
0.448495,-0.200553463741018
0.448995,-0.0659611463749949
0.449495,-0.15037586491644
0.449995,-0.115176592708234
0.450495,-0.192033679161292
0.450995,-0.240265029693937
0.451495,-0.183997122826325
0.451995,-0.134029066066429
0.452495,-0.0554263708439185
0.452995,-0.184869554527864
0.453495,-0.0304540688704281
0.453995,-0.072258936161721
0.454495,-0.026643773742121
0.454995,0.0198519229486686
0.455495,-0.0286566707622418
0.455995000000001,-0.213259206514951
0.456495000000001,-0.250873719265446
0.456995,-0.21736309752613
0.457495,-0.325010530631091
0.457995,-0.245892603861777
0.458495,-0.27570057367059
0.458995,-0.228402873301494
0.459495,-0.165702993270228
0.459995,-0.250292737658458
0.460495,-0.102169202615728
0.460995,-0.246487143067773
0.461495,-0.0653458903763195
0.461995,-0.373370082373093
0.462495,-0.235245405193673
0.462995,-0.202541568472405
0.463495,-0.185706604417147
0.463995,-0.240719928181265
0.464495,-0.0981159047865727
0.464995,-0.0571684169279741
0.465495,-0.211004235061305
0.465995,-0.243288171083985
0.466495,-0.114153183425388
0.466995,-0.276719568534396
0.467495,-0.250633581614565
0.467995,-0.0330208160061053
0.468495,-0.106128489611891
0.468995,-0.0975312953499939
0.469495,-0.0964969872106073
0.469995,-0.243016961675983
0.470495,-0.168555922509587
0.470995,-0.153787639210921
0.471495,-0.216309253565569
0.471995,-0.0747495542690204
0.472495,-0.0762770497641367
0.472995,-0.104667583955049
0.473495,-0.226017035168876
0.473995,-0.256250086059301
0.474495,-0.177216170737715
0.474995,-0.283202686794091
0.475495,-0.146755473555008
0.475995,-0.0439120328410359
0.476495,-0.179932163536893
0.476995,-0.0788030018460948
0.477495,0.0162448581466536
0.477995,0.0404703501314166
0.478495,0.0115397407577221
0.478995000000001,-0.0218993182491354
0.479495000000001,-0.140039955089631
0.479995000000001,-0.101884971133976
0.480495000000001,-0.237362531254834
0.480995000000001,-0.246549644273005
0.481495000000001,-0.101614821675854
0.481995000000001,-0.169134656288474
0.482495000000001,-0.19277734948457
0.482995000000001,-0.270312900422127
0.483495,-0.227113619583253
0.483995,-0.272734167134801
0.484495,-0.0992585382597699
0.484995,-0.0180311279868099
0.485495,0.116574114123294
0.485995,0.174751827526851
0.486495,-0.0341486602623372
0.486995,-0.0240189306863469
0.487495,0.00794915579470945
0.487995,-0.00157369649093863
0.488495,-0.0250168373020699
0.488995,-0.123959345883203
0.489495,-0.072493901938492
0.489995,-0.0712254195635552
0.490495,-0.152594128763543
0.490995,-0.159940852991858
0.491495,-0.0195620833598773
0.491995,-0.104297973453395
0.492495,-0.0473979798144288
0.492995,-0.0658754556518867
0.493495,-0.0811532774835248
0.493995,0.122371256514625
0.494495,0.0826687901429503
0.494995,0.033182337100865
0.495495,0.0389350574966696
0.495995,0.0283553121733476
0.496495,0.01765765134609
0.496995,0.125787883707294
0.497495,0.000349585759922689
0.497995,-0.0147935293750019
0.498495,0.00964361850335623
0.498995,0.0365159521756408
0.499495,0.104884108209617
0.499995,-0.0390577698389623