File: DATA&scripts/1.7-data/z/1/1_fracture_stress_data.csv
Strain,Fracture Stress (GPa)
0.0,1.28338284384826
0.000495000000000098,1.33737272127646
0.000994999999999958,-2.21668761207675
0.00149500000000011,0.448191363533595
0.00199499999999997,-1.04684017152853
0.00249500000000012,3.6617421062624
0.00299499999999998,4.70379658510507
0.00349500000000014,4.87348569976161
0.003995,1.70435461183886
0.00449499999999986,1.81058158871521
0.00499500000000001,3.64702818223555
0.00549499999999987,3.78690325224241
0.00599500000000002,4.97457950428881
0.00649499999999988,5.32171773162845
0.00699500000000003,4.95710403088311
0.00749499999999989,5.61623212289425
0.00799500000000004,5.52958800162909
0.0084949999999999,7.30771592508565
0.00899500000000006,6.89785978502103
0.00949499999999992,7.19450400580335
0.00999500000000007,6.56533221562278
0.0104949999999999,7.55571115659014
0.0109950000000001,6.99297567608169
0.0114949999999999,7.22456173762757
0.0119950000000001,7.1026797407941
0.012495,8.55299716730673
0.0129950000000001,9.43221520480589
0.013495,9.17881594191192
0.0139950000000001,9.67806471307585
0.014495,9.67173318145441
0.0149950000000001,10.0962757459562
0.015495,9.79102765303551
0.015995,9.77642467185676
0.016495,10.9456743498435
0.0169949999999999,10.3842056094307
0.017495,11.2052188481962
0.0179949999999999,10.7183903091237
0.018495,11.7522171539411
0.0189949999999999,12.1909634023174
0.019495,12.6235937484237
0.0199949999999999,12.8393604562441
0.0204950000000001,12.4107379300894
0.0209949999999999,12.3850625761902
0.0214950000000001,12.8415601579076
0.0219949999999999,13.457914063403
0.0224950000000001,14.0989836429273
0.0229949999999999,13.2128166717228
0.0234950000000001,13.9955572869013
0.0239949999999999,13.9595037878369
0.0244950000000001,15.4378618115006
0.024995,15.252960983609
0.0254950000000001,15.4893225762623
0.025995,15.3930901278056
0.0264950000000001,15.632257923891
0.026995,15.0717152537678
0.0274950000000001,15.8483476732373
0.027995,16.7947577096694
0.028495,16.6881256531444
0.028995,17.067546607119
0.0294949999999999,17.3910151048171
0.029995,17.4249085527261
0.0304949999999999,17.5920535359156
0.030995,18.2574369892896
0.0314949999999999,18.7156974907919
0.031995,18.1760174764653
0.0324949999999999,18.3134689460748
0.0329950000000001,18.5411339523307
0.0334949999999999,18.9353871546734
0.0339950000000001,19.4048475561599
0.0344949999999999,19.1945717059498
0.0349950000000001,20.3177258397869
0.0354949999999999,20.374270840114
0.0359950000000001,20.8873238093718
0.036495,20.509969343542
0.0369950000000001,21.5765589505312
0.037495,21.1525065182621
0.0379950000000001,21.5106448373213
0.038495,21.3710668882625
0.0389950000000001,21.5406320005322
0.039495,22.5146079906633
0.039995,21.9226539879244
0.040495,23.0297707595663
0.0409949999999999,22.9002888673949
0.041495,23.252665258858
0.0419949999999999,23.5763249491775
0.042495,23.2158376593943
0.0429949999999999,23.8077656388613
0.043495,23.8046892618824
0.0439949999999999,24.4169578440295
0.0444950000000001,24.1830880003536
0.0449949999999999,24.7987076184081
0.0454950000000001,25.1617541507843
0.0459949999999999,25.1170709758223
0.0464950000000001,25.7812123117182
0.0469949999999999,25.8232521711532
0.0474950000000001,26.430250482423
0.0479949999999999,26.1269580476878
0.0484950000000001,26.3494447135911
0.048995,26.2920527316431
0.0494950000000001,26.4640156520967
0.049995,26.8241204323308
0.0504950000000001,26.773164930865
0.050995,27.3825881960992
0.0514950000000001,27.500810088216
0.051995,27.9267829093775
0.052495,28.1505149390321
0.052995,28.7431943422782
0.053495,28.7467774838366
0.053995,28.7282593367489
0.0544949999999999,29.2116546268117
0.054995,28.80754606575
0.0554949999999999,29.665667028189
0.0559950000000001,29.5431668831461
0.0564949999999999,30.634142699295
0.0569950000000001,30.557068481486
0.0574949999999999,30.6007344247762
0.0579950000000001,30.6855820688918
0.0584949999999999,31.1344814363393
0.0589950000000001,31.6432793605771
0.0594949999999999,31.8661892813791
0.0599950000000001,32.0560365305497
0.060495,32.2367131054559
0.0609950000000001,31.8664774616228
0.061495,31.9562832709656
0.0619950000000001,32.3599608426981
0.062495,33.2712599084214
0.0629950000000001,33.1489493792281
0.063495,33.4154013833876
0.063995,33.473407262063
0.064495,33.9537696785717
0.064995,33.9499055209342
0.065495,34.3424590754351
0.0659949999999999,34.3746464934097
0.066495,34.2955439466073
0.0669949999999999,34.6853676125773
0.067495,34.6344616124782
0.0679949999999999,35.2910362467157
0.0684950000000001,35.3405173504857
0.0689949999999999,35.7272696592184
0.0694950000000001,36.1491651443225
0.0699949999999999,36.2633617703178
0.0704950000000001,36.1027643145701
0.0709949999999999,36.1798574455374
0.0714950000000001,36.0739769503423
0.0719949999999999,36.7220352518216
0.0724950000000001,36.3068818412719
0.072995,37.02520171595
0.0734950000000001,36.6392476815568
0.073995,37.0120610349986
0.0744950000000001,37.3154855476533
0.074995,37.871984150708
0.0754950000000001,38.2681421073697
0.075995,38.3553820430022
0.076495,38.4862241046958
0.076995,38.6193574645025
0.0774949999999999,39.0179624985158
0.077995,39.388240721788
0.0784949999999999,39.3639481726839
0.078995,39.5160913726063
0.0794949999999999,40.1261588195523
0.0799950000000001,39.9488109544334
0.0804949999999999,39.7774690249387
0.0809950000000001,40.2618364580241
0.0814949999999999,40.3414676113582
0.0819950000000001,40.8156712665005
0.0824949999999999,41.0345764949223
0.0829950000000001,41.4008658674001
0.0834949999999999,40.8008897056891
0.0839950000000001,41.4974808791905
0.084495,41.4611871544424
0.0849950000000001,41.5334667922599
0.085495,42.0773006758353
0.0859950000000001,41.8604320002258
0.086495,42.7250320533736
0.0869950000000001,42.5131808433337
0.087495,42.9554105182724
0.0879950000000002,43.188766627891
0.088495,43.1555778494413
0.088995,43.1221411069361
0.089495,43.6198202861032
0.089995,43.4804731103036
0.090495,44.0425753350528
0.0909949999999999,43.9168302135318
0.091495,44.1145431488894
0.0919949999999999,44.2136478702337
0.0924950000000001,44.6914050503066
0.0929949999999999,44.4742682211963
0.0934950000000001,44.5551789312566
0.0939949999999999,44.9251316440656
0.0944950000000001,45.3165105478834
0.0949949999999999,45.4673746524342
0.0954950000000001,45.7356691057349
0.095995,45.3701637206773
0.0964950000000001,45.8808437850744
0.096995,45.9384314514231
0.0974950000000001,46.6021198636905
0.097995,46.382021839447
0.0984950000000001,46.4541775210118
0.098995,46.8716903000031
0.0994950000000001,47.1847701293788
0.099995,47.3115474812002
0.100495,47.1530187345229
0.100995,47.6223967722946
0.101495,47.9446379508188
0.101995,47.7410603610983
0.102495,48.0775670179996
0.102995,47.9085410501626
0.103495,48.5883117898306
0.103995,48.735650638059
0.104495,48.8224999072191
0.104995,48.8411794048809
0.105495,48.6464652548015
0.105995,49.1808427585784
0.106495,49.6183327339617
0.106995,49.4390302588504
0.107495,49.9121850980089
0.107995,49.9809202301949
0.108495,50.2732326545163
0.108995,49.9101438336238
0.109495,50.1423512190277
0.109995,50.3210567318832
0.110495,50.7564413853724
0.110995,51.1359058935412
0.111495,51.2252587137511
0.111995,51.2268407818344
0.112495,51.3440616954575
0.112995,51.4140287966623
0.113495,51.6244020929877
0.113995,51.546892585702
0.114495,51.9786212739883
0.114995,52.0239750392749
0.115495,52.4748129325269
0.115995,52.4300238963054
0.116495,52.5368086800167
0.116995,52.538641907599
0.117495,52.7904774424939
0.117995,53.0558156441696
0.118495,52.9065448521292
0.118995,53.3748361306588
0.119495,53.4170338016379
0.119995,54.0650985096488
0.120495,53.5370864973786
0.120995,53.8721502412902
0.121495,53.8242723661523
0.121995,54.1350005904145
0.122495,54.121078003522
0.122995,54.8948054386992
0.123495,54.4290812168264
0.123995,54.7068790478002
0.124495,54.8034370331858
0.124995,55.1681122435418
0.125495,54.7917912866588
0.125995,55.3952279959819
0.126495,55.0963717485474
0.126995,55.9233511743298
0.127495,55.7358807436422
0.127995,55.7477287305342
0.128495,56.0567182931262
0.128995,56.2273913413735
0.129495,56.1894046942795
0.129995,56.2166986371885
0.130495,56.5420235776172
0.130995,56.5233396167651
0.131495,56.9360468012492
0.131995,56.7800392070383
0.132495,57.346234211572
0.132995,57.1997633262694
0.133495,57.4622137859776
0.133995,57.0852083888702
0.134495,57.51062413152
0.134995,57.2954994936715
0.135495,57.9002959273913
0.135995,57.5884393180009
0.136495,58.0493773616137
0.136995,58.1906679538414
0.137495,58.4947285606479
0.137995,58.3210960293374
0.138495,58.1639332807668
0.138995,58.9973500568507
0.139495,58.7018353432167
0.139995,59.155879060185
0.140495,58.7203789131865
0.140995,59.1565816085493
0.141495,59.0962408514387
0.141995,59.7063531592217
0.142495,59.4024603006514
0.142995,59.6034165901575
0.143495,59.5412962269348
0.143995,60.2489525137722
0.144495,59.7130802030115
0.144995,60.2724772083842
0.145495,60.4077485882212
0.145995,60.2882187935758
0.146495,60.7246600680821
0.146995,60.011806525351
0.147495,60.9982406783842
0.147995,60.7988765162054
0.148495,61.037563974219
0.148995,60.80527247152
0.149495,61.3931177369391
0.149995,61.0592263710855
0.150495,61.6847354808527
0.150995,61.3033488297659
0.151495,61.7944748668552
0.151995,61.6026511416992
0.152495,61.8634679606881
0.152995,62.003105600177
0.153495,61.9964820585267
0.153995,62.037684937098
0.154495,61.8229509422743
0.154995,62.4136508417635
0.155495,62.3624503652986
0.155995,62.6198727033877
0.156495,62.7720770730505
0.156995,62.938552783798
0.157495,62.6791925262529
0.157995,62.9603088962911
0.158495,62.9747397971081
0.158995,63.2135764913514
0.159495,63.4254670273287
0.159995,63.0847474508562
0.160495,63.5606761227835
0.160995,63.3675711924635
0.161495,64.0849670768237
0.161995,63.3835393571976
0.162495,63.9024299744707
0.162995,63.7301866246672
0.163495,64.3256560139474
0.163995,64.0661171768446
0.164495,64.1711142838958
0.164995,64.3942805493005
0.165495,64.1978516123183
0.165995,64.6029333953693
0.166495,64.1876550051172
0.166995,65.0582210880324
0.167495,64.4415838571958
0.167995,65.3228057929772
0.168495,64.6980548936009
0.168995,65.5008964914753
0.169495,65.2067613636971
0.169995,65.5898961360909
0.170495,65.3435547144597
0.170995,65.0257135771646
0.171495,65.3993413985196
0.171995,65.6151709409843
0.172495,65.9890295117591
0.172995,65.4219679778702
0.173495,65.9458978317689
0.173995,66.2328669124916
0.174495,66.1373182122334
0.174995,65.9843162520133
0.175495,66.0906660738267
0.175995,66.4004202561522
0.176495,66.2460694182323
0.176995,66.4606899075889
0.177495,66.4323022033392
0.177995,67.0121075187229
0.178495,66.6215464779038
0.178995,66.9320277087675
0.179495,66.7572561923931
0.179995,67.0613071005294
0.180495,66.7978698145736
0.180995,67.1215746790744
0.181495,67.3685447724943
0.181995,67.4927850251682
0.182495,67.5039108016786
0.182995,67.1729688497076
0.183495,67.8242293118612
0.183995,67.5982812961225
0.184495,67.8187872803748
0.184995,67.3808853786302
0.185495,67.8662625815635
0.185995,68.1408568441479
0.186495,68.1093735496073
0.186995,67.9661503905544
0.187495,67.858377660822
0.187995,68.5714949786348
0.188495,68.0007459966542
0.188995,68.6457030509641
0.189495,67.9689376042499
0.189995,69.0332333637164
0.190495,68.4653765227419
0.190995,68.5384753967108
0.191495,68.8258089423439
0.191995,68.6223296732025
0.192495,68.8481547662073
0.192995,68.2877486544339
0.193495,69.3557439384781
0.193995,68.9977419855308
0.194495,69.1644358472042
0.194995,68.8644196588061
0.195495,69.2071678195471
0.195995,69.3685151664505
0.196495,69.6507774454975
0.196995,69.5322334823204
0.197495,69.6313949354161
0.197995,69.9043197151279
0.198495,69.5480020162839
0.198995,70.0814909349001
0.199495,69.7501077961642
0.199995,69.7482311624005
0.200495,69.7491533167517
0.200995,69.9627674859207
0.201495,70.3251423898328
0.201995,70.1682862578615
0.202495,70.38681212961
0.202995,69.7896601761158
0.203495,70.4003320267526
0.203995,70.7079983566944
0.204495,70.5604203689655
0.204995,70.0806931386995
0.205495,70.480618540858
0.205995,70.9265756437764
0.206495,70.9997072905017
0.206995,70.6761467833444
0.207495,70.8418225449151
0.207995,70.9995525219972
0.208495,70.9300155107596
0.208995,71.1822171967412
0.209495,71.2213871456351
0.209995,71.0963482618999
0.210495,71.2461923170627
0.210995,71.1263581436286
0.211495,71.2636393631385
0.211995,71.4890948755999
0.212495,71.6314839282213
0.212995,71.5943206898111
0.213495,71.401235137861
0.213995,71.5946287374951
0.214495,71.7592700109187
0.214995,71.7407968919752
0.215495,71.8819017709871
0.215995,71.9261947509219
0.216495,72.0090877984147
0.216995,72.1801579863027
0.217495,71.884653895227
0.217995,72.0327892145438
0.218495,72.2464188718323
0.218995,72.6773420099108
0.219495,72.3229898876896
0.219995,72.4521555615234
0.220495,72.4626486650739
0.220995,72.2750269171656
0.221495,72.1829208512969
0.221995,73.1162405901801
0.222495,72.7085175152659
0.222995,72.3885846068889
0.223495,72.5099272740723
0.223995,73.0713321629625
0.224495,73.121569883457
0.224995,73.0257697910562
0.225495,73.1922672806521
0.225995,73.3391554277027
0.226495,73.0883036123463
0.226995,72.8203572980627
0.227495,73.3104180184494
0.227995,73.6400160118751
0.228495,73.438169733572
0.228995,73.0681476883547
0.229495,73.3578485400627
0.229995,73.8640812020491
0.230495,73.773826830295
0.230995,73.3492210295119
0.231495,73.6778656447799
0.231995,74.1664819304137
0.232495,74.1935567116964
0.232995,73.7049070361121
0.233495,73.7119405079722
0.233995,74.2310804987087
0.234495,74.2334353136066
0.234995,74.0489151167291
0.235495,73.6964515310003
0.235995,74.5565027807986
0.236495,74.5916129050687
0.236995,73.8840900996438
0.237495,74.257182156024
0.237995,74.7551216563216
0.238495,74.8728968829966
0.238995,74.3487430077443
0.239495,74.134074019524
0.239995,74.5055215616864
0.240495,74.6207235250468
0.240995,74.97960396308
0.241495,75.2841399016176
0.241995,74.9264451395738
0.242495,74.7214250070426
0.242995,75.1390557389737
0.243495,75.6180502500888
0.243995,75.2718994961789
0.244495,75.2652946006445
0.244995,75.3663530383414
0.245495,75.4534787920633
0.245995,75.5202369041093
0.246495,75.6933399998763
0.246995,75.6642764578315
0.247495,75.4425608266609
0.247995,75.6976982714441
0.248495,75.8790102182563
0.248995,75.9462080644565
0.249495,75.7771472000009
0.249995,76.0419839126318
0.250495,76.2046978063179
0.250995,76.1345751925793
0.251495,76.2565361029909
0.251995,76.6470925922483
0.252495,75.6970040002295
0.252995,76.1678188345791
0.253495,76.1198405311389
0.253995,76.5519332011217
0.254495,76.2733955621566
0.254995,76.623247979849
0.255495,76.654756157538
0.255995,76.9763253660832
0.256495,76.9284632168309
0.256995,76.6767699328386
0.257495,76.8585321807668
0.257995,77.1586924074484
0.258495,77.3041385660398
0.258995,76.5161065545569
0.259495,77.082055779639
0.259995,77.5417016582555
0.260495,77.612018561554
0.260995,77.3878208939183
0.261495,76.8437920007292
0.261995,77.5550216659583
0.262495,77.9419565624613
0.262995,77.5628355725975
0.263495,78.0477913387659
0.263995,78.3424951088374
0.264495,78.3138265080552
0.264995,77.9125506872305
0.265495,77.9254910465314
0.265995,78.1520462822833
0.266495,78.2821144594002
0.266995,78.1911615960425
0.267495,78.5417720427751
0.267995,77.8781198074222
0.268495,78.1217562465852
0.268995,78.2975999389553
0.269495,78.7097138551275
0.269995,78.7635064368207
0.270495,78.9417833812687
0.270995,78.4031239890098
0.271495,78.4949370854554
0.271995,79.2228734147023
0.272495,78.5681570807602
0.272995,79.6333791489165
0.273495,79.2432774812059
0.273995,79.2031520702551
0.274495,79.8026069436814
0.274995,79.2489798804119
0.275495,79.2499357453049
0.275995,79.9091385308055
0.276495,79.6488649886859
0.276995,80.511610652325
0.277495,79.92777611094
0.277995,80.3679540874299
0.278495,79.7984431535257
0.278995,79.8616231135874
0.279495,80.083469810689
0.279995,80.1190333099489
0.280495,80.1347995512033
0.280995,80.6693220102527
0.281495,80.6864637343896
0.281995,80.7677371362952
0.282495,80.5292535658514
0.282995,81.2358263886635
0.283495,81.3251398827143
0.283995,80.7371049618637
0.284495,80.7446752887006
0.284995,81.0609186976996
0.285495,81.5831825289187
0.285995,82.1822753606272
0.286495,81.3251230060942
0.286995,81.4825413313524
0.287495,82.0359516792467
0.287995,80.9329292899645
0.288495,82.3355953363825
0.288995,82.3303054273001
0.289495,81.5456967958229
0.289995,82.6689277061822
0.290495,82.1129208015049
0.290995,82.8113972666774
0.291495,83.1199005947853
0.291995,83.0181968769084
0.292495,83.0538817153298
0.292995,82.9568281317912
0.293495,82.84520658556
0.293995,84.1135885363471
0.294495,83.8141167687778
0.294995,84.8921958697202
0.295495,83.6489620715248
0.295995,83.7948233218024
0.296495,84.6457291077913
0.296995,84.7748203697289
0.297495,84.5701577350228
0.297995,84.1938885220959
0.298495,84.9501140639127
0.298995,85.2963495350035
0.299495,85.3920151792797
0.299995,85.2379186510848
0.300495,85.3157934426467
0.300995,85.0090283797018
0.301495,86.2742461858502
0.301995,85.2654636548909
0.302495,85.5175710827022
0.302995,86.3136054433511
0.303495,85.7352061636878
0.303995,86.7374968694311
0.304495,85.9120094555887
0.304995,85.9733796755292
0.305495,87.2443058986879
0.305995,88.3699286156939
0.306495,86.913786785927
0.306995,87.9028473344298
0.307495,87.9795488294694
0.307995,87.8618596285296
0.308495,88.5449437886147
0.308995,88.6327670390294
0.309495,87.9455072100896
0.309995,89.420460414814
0.310495,88.2263016785565
0.310995,89.0671143590899
0.311495,88.4630498829835
0.311995,90.6338811681485
0.312495,90.5172492923888
0.312995,89.4302967777591
0.313495,90.8036514012448
0.313995,90.0225159744809
0.314495,90.2016226763084
0.314995,90.0504972860164
0.315495,90.4790650586767
0.315995,92.4699227500933
0.316495,92.3040060710346
0.316995,92.0410878444274
0.317495,91.4845309739761
0.317995,92.9551423711681
0.318495,91.2939369495437
0.318995,92.0900764531033
0.319495,92.4656049336518
0.319995,92.9441224232715
0.320495,92.9805733625562
0.320995,93.0245765969247
0.321495,94.5234492400531
0.321995,94.5603061306266
0.322495,94.452377638839
0.322995,95.4733321260942
0.323495,95.6832235565969
0.323995,96.0590768945748
0.324495,96.1609335112433
0.324995,96.5458889321112
0.325495,95.8964783379778
0.325995,95.7428298954464
0.326495,96.3924909614411
0.326995,98.0272580984171
0.327495,98.1057938632014
0.327995,98.3946875416422
0.328495,97.9492227862568
0.328995,98.694544726103
0.329495,98.6389116634656
0.329995,98.8190061589011
0.330495,100.603674144145
0.330995,99.1335074996209
0.331495,99.8417430506301
0.331995,99.9847084795091
0.332495,101.446255766837
0.332995,101.512877374874
0.333495,100.361308015823
0.333995,101.613803812349
0.334495,101.390883370683
0.334995,102.174519448673
0.335495,101.915481040459
0.335995,102.927239843384
0.336495,103.701769693737
0.336995,104.469638827702
0.337495,104.148652585774
0.337995,104.641425956482
0.338495,103.45609321429
0.338995,106.170816014499
0.339495,105.236789405286
0.339995,105.464426096417
0.340495,105.962764378785
0.340995,106.148065471885
0.341495,107.528179265776
0.341995,106.464712307194
0.342495,107.346958823084
0.342995,107.333291613636
0.343495,108.628528150147
0.343995,109.367327186886
0.344495,107.56603172466
0.344995,109.955643505162
0.345495,109.561837598011
0.345995,109.711649711623
0.346495,110.035290144348
0.346995,109.888583520068
0.347495,111.870033199008
0.347995,111.744281391622
0.348495,112.21300663108
0.348995,112.624453762974
0.349495,111.859547516877
0.349995,113.803393673279
0.350495,112.474591269969
0.350995,112.759890720592
0.351495,113.635355929329
0.351995,115.182241813343
0.352495,114.517170889763
0.352995,115.77203096909
0.353495,116.23815873128
0.353995,116.322031954611
0.354495,116.816099539087
0.354995,117.080891623856
0.355495,117.212836321261
0.355995,117.790508418619
0.356495,117.260156295503
0.356995,118.849912075805
0.357495,119.495305086723
0.357995,119.480486821906
0.358495,119.367206279423
0.358995,120.543112230833
0.359495,120.436029693288
0.359995,121.206238463173
0.360495,120.478043516539
0.360995,122.52723879595
0.361495,122.942555219843
0.361995,123.324588679457
0.362495,123.662988298187
0.362995,124.115278262915
0.363495,123.440657113725
0.363995,124.976751325249
0.364495,124.780233070447
0.364995,125.909766021584
0.365495,125.95133678632
0.365995,124.873499185069
0.366495,126.267864968245
0.366995,127.512568397386
0.367495,128.676183462166
0.367995,127.844648973392
0.368495,127.799294466896
0.368995,129.511322857924
0.369495,131.149706711036
0.369995,131.272488068072
0.370495,130.19959041079
0.370995,130.661231223911
0.371495,132.290438509254
0.371995,133.432895025438
0.372495,132.871514020332
0.372995,134.417462420099
0.373495,134.191578600862
0.373995,134.437069725441
0.374495,134.705741848236
0.374995,135.313892605496
0.375495,135.810918380398
0.375995,135.896810676576
0.376495,137.384730620984
0.376995,138.406023025999
0.377495,137.770835805059
0.377995,138.556323254668
0.378495,138.58022707461
0.378995,140.527621154052
0.379495,140.600104015344
0.379995,140.078775945936
0.380495,142.128158646493
0.380995,141.389214625625
0.381495,142.626702358059
0.381995,143.428829955339
0.382495,142.743900947276
0.382995,144.560567021913
0.383495,144.674266969311
0.383995,144.470682829181
0.384495,146.223726210032
0.384995,146.266067376745
0.385495,148.236749868811
0.385995,148.162431246798
0.386495,149.431654859412
0.386995,148.558590571319
0.387495,149.623573099966
0.387995,150.500015647102
0.388495,150.001483430945
0.388995,134.084058760127
0.389495,95.2902889865161
0.389995,53.4275545057932
0.390495,15.2744500165777
0.390995,0.751468022987611
0.391495,-6.3808973867458
0.391995,-1.57097124510856
0.392495,4.7635374848014
0.392995,4.09592132124246
0.393495,0.203714933840923
0.393995,-1.74593863530674
0.394495,1.76995477884226
0.394995,4.74239765397693
0.395495,2.54674211991824
0.395995,-0.0565779479840303
0.396495,-0.951013940748453
0.396995,2.21912059433291
0.397495,3.21883322126969
0.397995,1.78987788087294
0.398495,-0.256752309626681
0.398995,0.380584901033213
0.399495,3.01359942977034
0.399995,2.93676846199971
0.400495,1.63156748032784
0.400995,-1.01488017806394
0.401495,0.742099314573771
0.401995,2.91067802493229
0.402495,2.50085225881981
0.402995,1.16260710251415
0.403495,-0.0537431779201187
0.403995,1.26914919299374
0.404495,2.51721986113918
0.404995,1.32095330797385
0.405495,1.70492063888448
0.405995,1.31399561013729
0.406495,1.99453268381394
0.406995,2.05282479929832
0.407495,1.2870459686977
0.407995,0.602263196249472
0.408495,1.29372989649237
0.408995,2.41921060266211
0.409495,2.34510569854035
0.409995,1.12154812716824
0.410495,1.25706921781123
0.410995,1.43599061222266
0.411495,1.53400544386629
0.411995,1.7511654820109
0.412495,1.5124226169269
0.412995,1.54478042679995
0.413495,1.61232732209374
0.413995,2.76933325486807
0.414495,1.80799933344496
0.414995,1.21686178871638
0.415495,1.6025664053903
0.415995,2.05814310267085
0.416495,2.57296295967882
0.416995,1.71841765547062
0.417495,1.75922677335773
0.417995,2.0482041937242
0.418495,2.15257295963014
0.418995,1.89119437538227
0.419495,1.7909521288881
0.419995,1.7751625802887
0.420495,1.88479346416919
0.420995,1.80209530433547
0.421495,1.78329467167104
0.421995,2.08871814011335
0.422495,1.61732939203606
0.422995,1.70142970941811
0.423495,1.91022915305358
0.423995,2.52833527481722
0.424495,2.06959990157111
0.424995,2.76084710893005
0.425495,1.65994660850369
0.425995,2.80553719282165
0.426495,2.30533959071706
0.426995,1.39721855442489
0.427495,1.93987680977225
0.427995,2.39947105871202
0.428495,2.9420738613205
0.428995,1.51995770109791
0.429495,1.87535369041515
0.429995,1.84919891443321
0.430495,3.38639315697243
0.430995,2.41148541042215
0.431495,2.12843112927731
0.431995,2.02099275986354
0.432495,2.34818517375174
0.432995,2.66100999546543
0.433495,2.29065467474754
0.433995,1.76820441499042
0.434495,2.20885044915815
0.434995,2.59750533776912
0.435495,2.66900104667831
0.435995,2.19498212938635
0.436495,1.60708396228155
0.436995,2.10988379667644
0.437495,2.57592899301888
0.437995,2.6700946852916
0.438495,1.74430801106555
0.438995,2.06491213226408
0.439495,2.38061455721437
0.439995,2.65854199325971
0.440495,2.22731929988389
0.440995,2.83044736930681
0.441495,2.12076186609531
0.441995,2.06714446498565
0.442495,3.43430460876972
0.442995,3.00354553540244
0.443495,2.00636204164961
0.443995,2.24378394883681
0.444495,3.20339187786263
0.444995,2.82859491020475
0.445495,2.44568609934642
0.445995,2.53888633136154
0.446495,2.71410293915006
0.446995,3.5132183453875
0.447495,2.71025659594293
0.447995,2.44942767849725
0.448495,2.22194378279241
0.448995,3.05898350443117
0.449495,3.14289790740592
0.449995,3.75000023239799
0.450495,2.60764125480534
0.450995,2.94944992145792
0.451495,3.09713609829218
0.451995,2.93353091276726
0.452495,2.72810337399982
0.452995,2.51601894985835
0.453495,2.40759543451013
0.453995,3.406265256896
0.454495,3.25101059660675
0.454995,2.23413699255855
0.455495,2.12633107461882
0.455995,3.19622639384323
0.456495,3.04081112664444
0.456995,3.53827768318475
0.457495,2.31769424941702
0.457995,2.78555769064996
0.458495,3.42081020139119
0.458995,3.61102251349518
0.459495,3.37840974461013
0.459995,2.12853419156388
0.460495,2.6997467263647
0.460995,2.78637012201252
0.461495,3.6452236660243
0.461995,3.21767797842171
0.462495,2.89036300908328
0.462995,2.66277387361769
0.463495,2.88387851465131
0.463995,3.77835501724464
0.464495,3.0707388621875
0.464995,2.85910691097609
0.465495,2.08950745583798
0.465995,2.82920705580163
0.466495,3.37917751919517
0.466995,3.61057059070519
0.467495,3.17565464592699
0.467995,2.90525215659765
0.468495,2.57395028572274
0.468995,3.11971818772651
0.469495,3.09371048518979
0.469995,3.70055547732547
0.470495,3.30170913133324
0.470995,2.77527871874193
0.471495,3.47323410111101
0.471995,3.62894427003798
0.472495,3.87197412005096
0.472995,2.72633540795083
0.473495,2.86161439621827
0.473995,3.18897199359753
0.474495,3.811519317539
0.474995,3.06005343362804
0.475495,2.41197139803824
0.475995,3.0765173974405
0.476495,4.02918503765395
0.476995,3.40802041379778
0.477495,2.95881106346686
0.477995,3.26651424233426
0.478495,4.29877937995057
0.478995,3.72018648174182
0.479495,2.86422446863709
0.479995,2.9269348392826
0.480495,3.78172913026553
0.480995,3.61359372574577
0.481495,3.56165703677841
0.481995,2.63845883948022
0.482495,3.15122776033657
0.482995,3.87522017287104
0.483495,3.84654085978753
0.483995,3.48632445077267
0.484495,3.01812276601369
0.484995,3.5844662201026
0.485495,3.37688295806797
0.485995,3.83388317563076
0.486495,3.7602298426811
0.486995,3.16879269107885
0.487495,2.94347505668121
0.487995,3.30968723328911
0.488495,3.75624984854574
0.488995,4.01459304177722
0.489495,3.21676915580516
0.489995,3.18298932106945
0.490495,3.37715704628547
0.490995,3.69868033595396
0.491495,3.57493944167944
0.491995,3.72209593350831
0.492495,3.03469024548208
0.492995,3.01562947478702
0.493495,3.54975562185795
0.493995,3.91490914997934
0.494495,3.40596804696808
0.494995,3.22374069300306
0.495495,3.86273055198311
0.495995,3.85431111082656
0.496495,3.57919271104638
0.496995,3.61107041344792
0.497495,3.46727426393803
0.497995,3.51270926936709
0.498495,3.42792182457353
0.498995,3.68830066095052
0.499495,3.97476513643508
0.499995,3.76642059286152
0.500495,3.0388943705929
0.500995,3.3105890789288
0.501495,3.65931569898584
0.501995,3.47299646882864
0.502495,3.62879670375056
0.502995,3.90472204814197
0.503495,2.96962602146404
0.503995,3.41805661255569
0.504495,4.07039387448314
0.504995,4.62269899726166
0.505495,3.16819042243456
0.505995,3.67771504794751
0.506495,3.59871456635716
0.506995,4.30611384513772
0.507495,3.77294102765169
0.507995,3.51166474190314
0.508495,3.9987384879003
0.508995,3.48331742420357
0.509495,3.33098256335009
0.509995,3.83707164890881
0.510495,3.90789770651701
0.510995,3.88519818033105
0.511495,3.57758164945303
0.511995,3.80870289947858
0.512495,3.78446011997546
0.512995,3.31725363796307
0.513495,3.52727956325692
0.513995,4.40217102733407
0.514495,4.30005854293395
0.514995,3.97237623756484
0.515495,3.627735687877
0.515995,3.77730803780741
0.516495,4.06357898308926
0.516995,3.88406152537922
0.517495,3.42273885595216
0.517995,3.52167174735893
0.518495,4.54129123164578
0.518995,3.98641638056962
0.519495,3.09684020511482
0.519995,3.35495229079843
0.520495,4.99838428743643
0.520995,4.46770997318225
0.521495,3.72857291226243
0.521995,3.11299463622372
0.522495,4.25778082099986
0.522995,4.42106075805677
0.523495,4.62142117461861
0.523995,3.42742502092653
0.524495,3.46012558904146
0.524995,4.48866004442703
0.525495,4.98703101392855
0.525995,4.08558116862704
0.526495,3.61876715128678
0.526995,3.71968443742732
0.527495,4.54848251946395
0.527995,4.78754472053098
0.528495,4.08156882092816
0.528995,3.50339262139239
0.529495,3.86232218370727
0.529995,4.72428900882444
0.530495,4.4074965257174
0.530995,4.18898960593635
0.531495,3.0260903754643
0.531995,4.75396337181321
0.532495,5.21793079136358
0.532995,4.54359829853558
0.533495,3.48058405310216
0.533995,3.41503167401275
0.534495,4.98043553895013
0.534995,5.02747853808776
0.535495,4.15490305947691
0.535995,3.99422517681927
0.536495,4.40328796475462
0.536995,5.24161455905866
0.537495,4.39397294416968
0.537995,4.23122285370191
0.538495,4.43417303461562
0.538995,4.51134384027638
0.539495,5.26128904481914
0.539995,4.30678096633396
0.540495,4.24434990207115
0.540995,4.31568037927361
0.541495,5.29983214318744
0.541995,4.59256767984853
0.542495,4.58997956605529
0.542995,4.57744073577314
0.543495,4.43280148455675
0.543995,5.19520636538616
0.544495,4.65068856688645
0.544995,4.78990589338614
0.545495,4.41388800005158
0.545995,5.01554325215571
0.546495,5.08389232479628
0.546995,5.56238022466377
0.547495,4.62691949613533
0.547995,4.82465556255196
0.548495,4.82924642338225
0.548995,5.05714093454047
0.549495,4.66440484069909
0.549995,4.79936537079519
0.550495,4.51551730772045
0.550995,4.9192554272374
0.551495,4.51480815998427
0.551995,4.99801667526134
0.552495,5.15217109681736
0.552995,5.000788063263
0.553495,5.46524106040687
0.553995,4.94923809129134
0.554495,5.16233941272679
0.554995,5.05844949814973
0.555495,5.25797762532115
0.555995,5.53925720347332
0.556495,5.23607475587774
0.556995,5.74489787487184
0.557495,5.09391393388783
0.557995,5.40408097097986
0.558495,5.02019210827865
0.558995,5.46553065952509
0.559495,6.10914503110694
0.559995,6.26638840998924
0.560495,5.68983786597926
0.560995,5.33063550688902
0.561495,5.97888966216671
0.561995,6.86607508544408
0.562495,6.46082467852806
0.562995,5.40469792526842
0.563495,5.57239321548561
0.563995,5.17897907157621
0.564495,5.67313375842657
0.564995,5.64770021085302
0.565495,5.61052867739145
0.565995,5.56520199959494
0.566495,6.23515896419712
0.566995,5.40489537837227
0.567495,6.06218078329572
0.567995,5.77101265413929
0.568495,5.49658502606049
0.568995,5.71476512726989
0.569495,5.50903337215811
0.569995,6.31395865221989
0.570495,6.21680742006699
0.570995,5.46570891576348
0.571495,5.26106948402483
0.571995,5.94151584655802
0.572495,6.59698067387981
0.572995,6.31640028565039
0.573495,5.78151284228775
0.573995,6.31388969856294
0.574495,6.48974703019122
0.574995,5.97943787024313
0.575495,6.16125570485128
0.575995,5.8254222709256
0.576495,6.16428035096295
0.576995,6.23384639230786
0.577495,6.49816410935195
0.577995,6.36891573580234
0.578495,5.84754992072586
0.578995,6.52630353492058
0.579495,6.45906043052734
0.579995,6.6874767720407
0.580495,6.40515127740665
0.580995,6.57758027910841
0.581495,7.49525670678583
0.581995,7.05534654226559
0.582495,6.7639957369471
0.582995,6.43075889211397
0.583495,6.99134186026982
0.583995,6.50693782363756
0.584495,6.88661992211958
0.584995,6.8121644225593
0.585495,6.48832104296428
0.585995,6.77095325741322
0.586495,7.34622575601134
0.586995,6.92752614041888
0.587495,6.89410810862177
0.587995,6.95136453848917
0.588495,7.56708498915994
0.588995,7.04132727793433
0.589495,6.55307155428116
0.589995,7.38657085165944
0.590495,7.17440922474217
0.590995,7.32698336230101
0.591495,7.06920330151549
0.591995,7.02198641456882
0.592495,7.03970004543351
0.592995,7.29785029865165
0.593495,7.62250495375137
0.593995,8.05831979508348
0.594495,7.66154750916417
0.594995,7.29372946671477
0.595495,7.99777351749582
0.595995,7.86207836187676
0.596495,7.35060590878114
0.596995,7.96313103160455
0.597495,7.96573399858643
0.597995,7.90750699552563
0.598495,7.83423524049496
0.598995,7.58906881009398
0.599495,7.77930908444342
0.599995,8.22203856297978
0.600495,7.85629903377711
0.600995,7.79439668651197
0.601495,8.03306973205286
0.601995,7.61317685497675
0.602495,8.22072420115637
0.602995,7.87477157074201
0.603495,7.62551014151397
0.603995,7.8294120654854
0.604495,7.61803720077769
0.604995,6.96096746033788
0.605495,6.35375557184613
0.605995,4.20443606157373
0.606495,3.86060145291326
0.606995,5.30693399955903
0.607495,5.01338309262308
0.607995,3.22164346813198
0.608495,3.5763200526584
0.608995,4.30683313488823
0.609495,5.00085258632982
0.609995,4.23497339234103
0.610495,4.12280136644269
0.610995,3.75254377719266
0.611495,4.67632942153685
0.611995,4.81582992615958
0.612495,3.66763387293145
0.612995,3.855967055801
0.613495,4.01501325586033
0.613995,4.94872092214044
0.614495,4.09173965830166
0.614995,4.13721833970747
0.615495,3.74573020367437
0.615995,4.42045535978863
0.616495,4.50360189150207
0.616995,4.23101472637743
0.617495,4.30841158970371
0.617995,4.26361051967073
0.618495,4.22354898112604
0.618995,4.3019263070387
0.619495,4.41300882781796
0.619995,4.30298671424751
0.620495,4.1883367106582
0.620995,4.76895176853094
0.621495,4.48422923775275
0.621995,4.68048244996047
0.622495,4.04474891233765
0.622995,4.25206464894109
0.623495,4.75728800405324
0.623995,4.56781897672579
0.624495,3.96024888055137
0.624995,4.06815424420344
0.625495,5.43651946038587
0.625995,4.45129769660827
0.626495,4.18236044458583
0.626995,4.26011516100275
0.627495,4.6527702205746
0.627995,4.36643921725008
0.628495,4.70397598105884
0.628995,4.74505845668093
0.629495,5.05417466868737
0.629995,5.41075368945644
0.630495,4.80000044818117
0.630995,4.66998990573137
0.631495,4.59124922413589
0.631995,4.7607261080738
0.632495,4.93625695239208
0.632995,5.25174046565961
0.633495,5.43382133248838
0.633995,4.76794705512781
0.634495,5.60350716803394
0.634995,5.31037397024473
0.635495,5.44729280571219
0.635995,4.7523416724674
0.636495,4.78118022476949
0.636995,4.9158948096318
0.637495,5.64292602345837
0.637995,5.57716835685634
0.638495,5.52224987091418
0.638995,5.6261630135866
0.639495,5.31862500069306
0.639995,5.97700575102123
0.640495,5.30546477916939
0.640995,4.82107710334994
0.641495,5.53302366993778
0.641995,5.59262889053049
0.642495,6.19634204138002
0.642995,5.55611510689904
0.643495,5.59168414518502
0.643995,5.18147254396387
0.644495,5.72895610871411
0.644995,6.14639075676045
0.645495,6.02853551400534
0.645995,5.67692411537748
0.646495,5.69666822138402
0.646995,6.05463617860632
0.647495,6.68762560642662
0.647995,6.40724418454487
0.648495,5.56568906210701
0.648995,5.94568045129007
0.649495,6.33952679624309
0.649995,6.54554995237627
0.650495,6.20549875372572
0.650995,5.70118636787774
0.651495,6.32800853558076
0.651995,7.26729920442961
0.652495,6.41240680616907
0.652995,6.29313949051376
0.653495,5.95184025222493
0.653995,6.93496351863219
0.654495,6.99945663252212
0.654995,6.88545029783967
0.655495,6.58454349115629
0.655995,6.63792360941792
0.656495,7.13266589549171
0.656995,6.92715324933819
0.657495,6.74005040453236
0.657995,6.85732760319487
0.658495,6.94995873241153
0.658995,5.55702944677986
0.659495,4.90039035595289
0.659995,4.52431586480518
0.660495,5.20836562511156
0.660995,5.8389149531941
0.661495,5.24647570095367
0.661995,4.25048847551262
0.662495,5.10933039390129
0.662995,6.23329760268518
0.663495,5.37190372582707
0.663995,4.11160010893453
0.664495,4.68213420763731
0.664995,5.72060433364712
0.665495,5.77014368570759
0.665995,4.59763286444918
0.666495,4.89575885384524
0.666995,5.10241603507106
0.667495,5.92996308779583
0.667995,5.43929311626411
0.668495,5.61639747737178
0.668995,5.04478413338947
0.669495,5.70023904723676
0.669995,5.52835506351322
0.670495,5.44977879919924
0.670995,5.22354107760865
0.671495,5.4657489786635
0.671995,5.78522175813307
0.672495,5.57778662525841
0.672995,5.21514066457883
0.673495,5.91876195930923
0.673995,5.69442152876092
0.674495,5.82191889277239
0.674995,5.19502491171868
0.675495,5.79447096254679
0.675995,6.14604184290805
0.676495,5.94153982836116
0.676995,6.22494897756139
0.677495,5.26314124448417
0.677995,6.0360437370731
0.678495,6.14281227266606
0.678995,5.99939141897644
0.679495,5.67150875170171
0.679995,6.05996226936719
0.680495,6.28080077622253
0.680995,6.26067017094909
0.681495,6.20893811152035
0.681995,6.32386153582406
0.682495,6.12958898490983
0.682995,6.40516864008144
0.683495,6.64913892632078
0.683995,6.37131044995687
0.684495,5.99600576226604
0.684995,6.49342704904676
0.685495,6.96667239849365
0.685995,6.53649079124266
0.686495,6.60327319970627
0.686995,6.64424115399545
0.687495,6.01500703533278
0.687995,6.52348040959207
0.688495,6.79411491338201
0.688995,6.61910017371072
0.689495,7.10620908994257
0.689995,7.30859521839502
0.690495,6.7117867760594
0.690995,6.32161077766955
0.691495,7.03834362162528
0.691995,7.15494151085221
0.692495,6.81248425703432
0.692995,7.23268414571981
0.693495,7.15270098012932
0.693995,7.02820954129465
0.694495,7.07156016416118
0.694995,6.91453883991689
0.695495,7.29543161700227
0.695995,7.70714364757488
0.696495,7.13201122743066
0.696995,7.46148389790624
0.697495,7.78325355533407
0.697995,7.49555158689941
0.698495,7.72795798609941
0.698995,7.38610254551231
0.699495,7.54745838487012
0.699995,7.41209867612292
0.700495,8.03965081941424
0.700995,7.36117951404866
0.701495,7.80590960532181
0.701995,7.4449030347098
0.702495,4.8881352475414
0.702995,4.40282992713472
0.703495,3.96491458757428
0.703995,4.88528174306681
0.704495,5.08775602890591
0.704995,4.48592995192553
0.705495,3.33169643953523
0.705995,3.51898599463671
0.706495,5.01449307668668
0.706995,4.63113040635908
0.707495,3.7740015690514
0.707995,2.83870271195535
0.708495,4.4636940618581
0.708995,4.8732300971561
0.709495,4.61022672196021
0.709995,2.98696634143526
0.710495,3.93831106008833
0.710995,4.12636857672889
0.711495,4.48493122813029
0.711995,4.01478699872405
0.712495,3.65227407551978
0.712995,4.15767816959446
0.713495,4.67120159975328
0.713995,4.63287929644803
0.714495,3.91619788253374
0.714995,3.41919755782678
0.715495,4.84819362502851
0.715995,5.07054891221615
0.716495,4.10976707818522
0.716995,3.76064716772594
0.717495,4.22892325907554
0.717995,4.64777269105331
0.718495,4.7114887508603