File: DATA&scripts/3.4-data/h/9/9_fracture_stress_data.csv
Strain,Fracture Stress (GPa)
0.0,-0.749160838912509
0.000495000000000014,2.28491363287967
0.000995000000000139,-0.257607298351112
0.00149499999999998,2.8093670719116
0.0019950000000001,1.28321898255886
0.00249499999999994,1.70015164482262
0.00299500000000006,3.1126361779812
0.00349500000000004,1.22525023303644
0.00399500000000002,3.91161372979723
0.004495,0.775714600452288
0.00499499999999998,5.00239169055214
0.00549500000000011,1.28374058375078
0.00599499999999995,4.91150769146388
0.00649500000000007,2.69208073534641
0.00699500000000005,4.38721629930148
0.00749500000000003,4.09582653395232
0.00799500000000001,3.97349327595823
0.00849499999999999,5.22765651078454
0.00899500000000012,3.43512337970182
0.00949499999999995,6.47511681098979
0.00999500000000008,3.61285783755767
0.0104950000000001,6.71632700186823
0.010995,4.37691600595399
0.011495,6.93390996830709
0.011995,5.00987954652086
0.0124950000000001,6.5719576056553
0.012995,6.50437603149013
0.0134950000000001,6.29098534812432
0.0139950000000001,7.22130870346257
0.014495,6.26297131561625
0.014995,8.2210218890608
0.015495,6.2742339270065
0.0159950000000001,8.62368827125414
0.016495,6.75442891696061
0.0169950000000001,8.71499237540349
0.0174949999999999,7.46841337340293
0.0179950000000001,8.7352500871068
0.018495,8.45982922031046
0.018995,8.720664921215
0.019495,9.18122977078919
0.019995,8.72057481896132
0.0204950000000001,9.95149716196652
0.0209949999999999,8.86597436561297
0.0214950000000001,10.3145585395104
0.021995,9.22522564261847
0.022495,10.8318834412356
0.022995,9.86405217953503
0.023495,10.78945026366
0.0239950000000001,10.5694748144096
0.024495,10.8240865966449
0.0249950000000001,11.045185689118
0.0254950000000001,10.8731336597104
0.025995,11.8004795409734
0.026495,11.0435004250228
0.026995,12.1742512555494
0.0274950000000001,11.4951128023205
0.027995,12.4771217561837
0.0284950000000001,11.9003160394805
0.0289950000000001,12.6617641189525
0.029495,12.5667003619748
0.029995,12.9354051857883
0.030495,13.0697236923926
0.0309950000000001,13.0515164000038
0.031495,13.5550387114525
0.0319950000000001,13.2785593246587
0.0324950000000001,13.9878466829851
0.0329950000000001,13.5291713242677
0.033495,14.3623158804073
0.033995,13.9619319735586
0.034495,14.7892490699407
0.034995,14.394310281785
0.0354950000000001,14.9509418239431
0.0359949999999999,14.8261415260577
0.0364950000000001,15.1295592022627
0.036995,15.382751445951
0.037495,15.3394415257594
0.037995,15.7590494380074
0.038495,15.6570525925509
0.0389950000000001,16.2153557211242
0.0394949999999999,15.9255075109303
0.0399950000000001,16.5189509670013
0.0404950000000001,16.2299224772727
0.040995,16.7828408082419
0.041495,16.6521771262261
0.041995,17.0730469100658
0.0424950000000001,17.071290369197
0.042995,17.4647585413847
0.0434950000000001,17.5883722105597
0.0439950000000001,17.5898817614553
0.044495,17.9765136132327
0.044995,17.9569466082624
0.045495,18.3434151074314
0.0459950000000001,18.1650030302238
0.046495,18.6450995582291
0.0469950000000001,18.5355788172724
0.0474950000000001,18.8590510761242
0.0479950000000001,18.8969024270987
0.048495,19.2253991930297
0.048995,19.3350908235814
0.0494950000000001,19.4274858432332
0.049995,19.7536636706526
0.0504950000000001,19.764782893963
0.0509949999999999,20.0384135314127
0.0514950000000001,20.0629759061728
0.051995,20.3289711319412
0.052495,20.4203240165059
0.052995,20.6480763579264
0.053495,20.6664587981241
0.0539950000000001,20.8819624426858
0.0544949999999999,21.0952302475182
0.0549950000000001,21.1603360776297
0.0554950000000001,21.4590727357041
0.055995,21.4386091613831
0.056495,21.8439425921239
0.056995,21.7938305854455
0.0574950000000001,22.1559698051017
0.057995,22.1373853168317
0.0584950000000001,22.4666014385916
0.0589950000000001,22.4605576215274
0.059495,22.7511068782238
0.059995,22.8935190957532
0.060495,22.9421777699152
0.0609950000000001,23.2054880993868
0.061495,23.2930677811626
0.0619950000000001,23.6073046355596
0.0624950000000001,23.3964922257421
0.0629950000000001,23.8533515632446
0.063495,23.8480623093222
0.063995,24.1336648594353
0.0644950000000001,24.0271928640955
0.064995,24.2775106097027
0.0654950000000001,24.5036676018186
0.0659949999999999,24.6911274313103
0.0664950000000001,24.8060345371203
0.066995,24.8299078882401
0.067495,25.2008060083036
0.0679950000000002,25.2316432377776
0.068495,25.3738411405713
0.0689950000000001,25.3457411432836
0.0694949999999999,25.7949578873532
0.0699950000000001,25.8777796288891
0.070495,25.9532735175693
0.070995,26.0636258089649
0.071495,26.2407285573623
0.071995,26.5176909871179
0.0724950000000001,26.5123236471131
0.0729949999999999,26.6962161631649
0.0734950000000001,26.8376413887774
0.0739950000000001,27.0612915549483
0.074495,27.0776693870373
0.074995,27.2493552146175
0.075495,27.3800609133637
0.0759950000000001,27.5946517180588
0.076495,27.6188079841527
0.0769950000000001,27.7753130241284
0.0774949999999999,27.9899512404631
0.0779950000000001,28.1382443842123
0.078495,28.1729419219685
0.078995,28.2863476291145
0.0794950000000001,28.5083019861932
0.079995,28.6639582773174
0.0804950000000001,28.8591588008978
0.0809949999999999,28.8492272296553
0.0814950000000001,29.097690735251
0.081995,29.1590096753552
0.082495,29.4404657107884
0.082995,29.4325333251733
0.083495,29.6876754080383
0.0839950000000001,29.6493925919065
0.0844949999999999,29.9057509552051
0.0849950000000001,29.905299616808
0.085495,30.1775661519273
0.085995,30.3154244363075
0.0864950000000002,30.4061009494622
0.086995,30.5811904696725
0.0874950000000001,30.7234746108261
0.0879949999999999,30.8860094395562
0.0884950000000001,30.7943556459044
0.0889950000000001,31.108429021513
0.089495,31.1345284250681
0.089995,31.3861019037806
0.090495,31.3524064830038
0.0909950000000001,31.5928885310213
0.091495,31.7381049527771
0.0919950000000001,31.9270638312179
0.0924949999999999,31.9805435488368
0.092995,32.0777756587103
0.093495,32.3026054286325
0.093995,32.2036462703617
0.0944950000000001,32.4567611087927
0.094995,32.4500062038812
0.0954950000000001,32.7832990872188
0.0959949999999999,32.8103696073899
0.0964950000000001,33.0499965221643
0.096995,32.8969091365496
0.097495,33.19941791918
0.0979950000000001,33.3024740676034
0.098495,33.488597203448
0.0989950000000001,33.5152556767534
0.0994949999999999,33.6119694286962
0.0999950000000001,33.8963124790149
0.100495,33.9094214197009
0.100995,34.0289413699915
0.101495,34.0124860391276
0.101995,34.3976690709769
0.102495,34.3621354551859
0.102995,34.5184215449946
0.103495,34.4946193430571
0.103995,34.8328368007623
0.104495,34.8357665183601
0.104995,34.861197175189
0.105495,35.054651930576
0.105995,35.1652204327815
0.106495,35.375045471991
0.106995,35.2707308595588
0.107495,35.5534776050171
0.107995,35.5912574911245
0.108495,35.864438449094
0.108995,35.781797742738
0.109495,35.97238405409
0.109995,36.0634241183219
0.110495,36.2331440130997
0.110995,36.2358048089694
0.111495,36.4195503368844
0.111995,36.5406986568395
0.112495,36.5622341543286
0.112995,36.7598524639019
0.113495,36.7786184090744
0.113995,37.0264180542783
0.114495,37.0701818754569
0.114995,37.1967577825704
0.115495,37.2338374794845
0.115995,37.4516314638185
0.116495,37.5110229133632
0.116995,37.4985512475741
0.117495,37.7358118236368
0.117995,37.7902675206779
0.118495,37.9907746208214
0.118995,37.9704686776078
0.119495,38.1641692412464
0.119995,38.177425509569
0.120495,38.3595020737715
0.120995,38.3754237763272
0.121495,38.5086811454195
0.121995,38.577612689188
0.122495,38.6144936835977
0.122995,38.7592706738827
0.123495,38.8471797697503
0.123995,39.0753450036385
0.124495,39.0619994217514
0.124995,39.1720984736417
0.125495,39.2684142749469
0.125995,39.4718069505546
0.126495,39.4545602936327
0.126995,39.5384691746392
0.127495,39.570902266576
0.127995,39.8353087448099
0.128495,39.8876608202157
0.128995,39.8929974049741
0.129495,40.0412557753967
0.129995,40.1793474512649
0.130495,40.2170502591142
0.130995,40.205885429867
0.131495,40.4386075634969
0.131995,40.5820338888721
0.132495,40.5580508442996
0.132995,40.5918913912876
0.133495,40.8092296649004
0.133995,40.893866490716
0.134495,40.9341832293801
0.134995,40.9979647907714
0.135495,41.123705457345
0.135995,41.3027934459358
0.136495,41.3063580930315
0.136995,41.3216800186946
0.137495,41.4091597353494
0.137995,41.5924653190907
0.138495,41.6940685213819
0.138995,41.7639275624118
0.139495,41.7740713335816
0.139995,41.8822485283466
0.140495,42.0800942213606
0.140995,42.0848976559277
0.141495,42.1348340633083
0.141995,42.2210057585039
0.142495,42.361389675657
0.142995,42.3935476162904
0.143495,42.4583892080084
0.143995,42.5679517080552
0.144495,42.7226158521896
0.144995,42.8399439372112
0.145495,42.8717210603689
0.145995,42.8621491527932
0.146495,42.9279854644926
0.146995,43.1139343585392
0.147495,43.19163227382
0.147995,43.1880861921448
0.148495,43.2798918754681
0.148995,43.3648213718842
0.149495,43.483339478977
0.149995,43.5559355755587
0.150495,43.6144115632524
0.150995,43.6622306853699
0.151495,43.8159453029629
0.151995,43.8910891042479
0.152495,43.8732540065093
0.152995,43.9530660480339
0.153495,44.0539335259521
0.153995,44.2250944713461
0.154495,44.2120368155951
0.154995,44.3105358997993
0.155495,44.3295577896149
0.155995,44.4685079635067
0.156495,44.4866263574652
0.156995,44.5098609629535
0.157495,44.5780618682397
0.157995,44.7554574987499
0.158495,44.8541149168837
0.158995,44.7583255328399
0.159495,44.8571036714948
0.159995,44.9318023909781
0.160495,45.0835849132375
0.160995,45.038896200887
0.161495,45.230657309113
0.161995,45.2311939457271
0.162495,45.3400220043533
0.162995,45.3223436075914
0.163495,45.4241667885411
0.163995,45.5038497530863
0.164495,45.6055253363338
0.164995,45.6460406653892
0.165495,45.6479856765903
0.165995,45.7850582783745
0.166495,45.7880932315643
0.166995,45.9818363469984
0.167495,45.9229843143676
0.167995,46.0462089789733
0.168495,46.0604482369806
0.168995,46.1193348720042
0.169495,46.1600520104265
0.169995,46.2517436014705
0.170495,46.3878349701897
0.170995,46.4405057627241
0.171495,46.4743862175494
0.171995,46.4493427093538
0.172495,46.6120211487249
0.172995,46.6269156372634
0.173495,46.7242073856227
0.173995,46.7708573309867
0.174495,46.8475874957449
0.174995,46.7664383728645
0.175495,46.9112158420945
0.175995,47.0687613461481
0.176495,47.1260539970947
0.176995,47.118222413127
0.177495,47.1257948812043
0.177995,47.2201787961853
0.178495,47.1928261553717
0.178995,47.3326054054792
0.179495,47.2680066641021
0.179995,47.4503004571007
0.180495,47.4364806568122
0.180995,47.631665532214
0.181495,47.5166105322576
0.181995,47.6974485253821
0.182495,47.7099486188066
0.182995,47.8227282280002
0.183495,47.8473589910626
0.183995,47.8178863006658
0.184495,47.971800528446
0.184995,47.972493956642
0.185495,48.1138456552107
0.185995,48.010782120764
0.186495,48.2396496582093
0.186995,48.159407683151
0.187495,48.2265761359038
0.187995,48.3249490807773
0.188495,48.368786273665
0.188995,48.3532997365311
0.189495,48.4853085909456
0.189995,48.5635000052119
0.190495,48.5794398619345
0.190995,48.6167656737332
0.191495,48.5886091630387
0.191995,48.7742699961285
0.192495,48.6793363952135
0.192995,48.8375241052232
0.193495,48.8482134963908
0.193995,48.8915860241506
0.194495,48.903419810477
0.194995,48.9770107594709
0.195495,49.0232868368418
0.195995,49.0944838569575
0.196495,49.1787753050069
0.196995,49.1059366199274
0.197495,49.2736877276986
0.197995,49.2055527805754
0.198495,49.3793345207182
0.198995,49.3565977989466
0.199495,49.4178177441838
0.199995,49.4207196616476
0.200495,49.5726625798428
0.200995,49.5066736348649
0.201495,49.6405656391761
0.201995,49.6380451299262
0.202495,49.6293717661702
0.202995,49.7499272733842
0.203495,49.7557529901723
0.203995,49.8684303428617
0.204495,49.8802039767307
0.204995,49.9538948825547
0.205495,49.9491499409882
0.205995,50.0901614452495
0.206495,50.0405787113168
0.206995,50.1021761009148
0.207495,50.150526074048
0.207995,50.2474169328273
0.208495,50.2186484730132
0.208995,50.2803767884119
0.209495,50.3292222614447
0.209995,50.3715763879403
0.210495,50.4864955944235
0.210995,50.3458909307257
0.211495,50.467638145383
0.211995,50.5383837763416
0.212495,50.6441313830556
0.212995,50.5473810952512
0.213495,50.5621428821798
0.213995,50.6851185068286
0.214495,50.8363829941893
0.214995,50.7267368469802
0.215495,50.724970165677
0.215995,50.8824573500013
0.216495,50.9274560873614
0.216995,50.8919489605142
0.217495,50.9201528382881
0.217995,51.0345549411668
0.218495,50.9969962071141
0.218995,51.1093365338895
0.219495,51.0774861121754
0.219995,51.16593038492
0.220495,51.1973940722176
0.220995,51.2485250911661
0.221495,51.2259786757544
0.221995,51.4187142582089
0.222495,51.4190851675711
0.222995,51.3398041285496
0.223495,51.3972241699705
0.223995,51.4439528934428
0.224495,51.5566615178105
0.224995,51.4930109126265
0.225495,51.7121770709163
0.225995,51.6162984677752
0.226495,51.7383155089871
0.226995,51.7138196545778
0.227495,51.8368151124661
0.227995,51.7730931013649
0.228495,51.8669649895341
0.228995,51.904113005512
0.229495,51.9348193726809
0.229995,52.0057479327536
0.230495,52.0260156433777
0.230995,52.1018912651612
0.231495,52.1203583105233
0.231995,52.2091600582505
0.232495,52.17202345277
0.232995,52.3802772994634
0.233495,52.2412101892366
0.233995,52.4069711028211
0.234495,52.3059599610205
0.234995,52.4335880352556
0.235495,52.462743817808
0.235995,52.5692619342953
0.236495,52.5218364944862
0.236995,52.5643398943244
0.237495,52.6152139306016
0.237995,52.5610739671614
0.238495,52.7265736944994
0.238995,52.6566853439599
0.239495,52.8477687358037
0.239995,52.7801343582304
0.240495,52.9089305569536
0.240995,52.957314992723
0.241495,52.8662157412027
0.241995,52.9522011092077
0.242495,52.9749610062036
0.242995,53.0768405110603
0.243495,53.092475926977
0.243995,53.0650578874218
0.244495,53.1235042948456
0.244995,53.3048080825312
0.245495,53.3595128391295
0.245995,53.2808439151511
0.246495,53.2886753125197
0.246995,53.4552580806938
0.247495,53.5816337467191
0.247995,53.468737121508
0.248495,53.5023325653264
0.248995,53.5608791154652
0.249495,53.7479671298764
0.249995,53.6870025741525
0.250495,53.5639257940459
0.250995,53.7938613125131
0.251495,53.9248881176392
0.251995,53.8594049968049
0.252495,53.9613947344761
0.252995,53.8983153744434
0.253495,54.0093435075985
0.253995,54.0961912082192
0.254495,54.0088745248232
0.254995,54.057353666559
0.255495,54.0987533683766
0.255995,54.4044641479856
0.256495,54.1668210155955
0.256995,54.2646041079627
0.257495,54.3611071643335
0.257995,54.4735066207919
0.258495,54.4741481385631
0.258995,54.4460771923999
0.259495,54.4448787552306
0.259995,54.5951186164561
0.260495,54.537412572057
0.260995,54.6169825630227
0.261495,54.6478228564072
0.261995,54.6228002329759
0.262495,54.8119834671214
0.262995,54.8296974821282
0.263495,54.9022266959699
0.263995,54.8506953016561
0.264495,54.9670765536009
0.264995,55.0278055329091
0.265495,55.071663822725
0.265995,55.1334582473459
0.266495,55.260689806713
0.266995,55.243345353421
0.267495,55.3237340259071
0.267995,55.3911966738365
0.268495,55.4080956508011
0.268995,55.4973871806362
0.269495,55.4954829262478
0.269995,55.6000037853973
0.270495,55.5994953541102
0.270995,55.7067754652878
0.271495,55.7791060024663
0.271995,55.9254541320795
0.272495,55.883850026227
0.272995,55.89882467162
0.273495,56.0942776347062
0.273995,55.9780124930801
0.274495,56.2042943327616
0.274995,56.1530292978613
0.275495,56.2125912915806
0.275995,56.3562138211695
0.276495,56.3948741859625
0.276995,56.4457696117036
0.277495,56.4523178099476
0.277995,56.7514979088888
0.278495,56.5534356130351
0.278995,56.680833640563
0.279495,56.835086550374
0.279995,56.949878383094
0.280495,56.9917519941916
0.280995,56.8738583325587
0.281495,56.9500038975464
0.281995,57.1030516453974
0.282495,57.1695455894312
0.282995,57.2317262699525
0.283495,57.3349221870416
0.283995,57.3304181456889
0.284495,57.4323283258795
0.284995,57.5833562457665
0.285495,57.4848933217071
0.285995,57.6841168207195
0.286495,57.8010154405214
0.286995,57.7513609770386
0.287495,57.7724409602662
0.287995,57.9680649916671
0.288495,58.2305747546924
0.288995,58.0877586380564
0.289495,58.0010705893871
0.289995,58.1208248440799
0.290495,58.4617064131796
0.290995,58.6036434020044
0.291495,58.762597607354
0.291995,58.6932129388232
0.292495,58.8383541860119
0.292995,58.8679807939917
0.293495,58.9571739242526
0.293995,59.0911588222337
0.294495,59.1597452295882
0.294995,59.3788700952859
0.295495,59.5104578845517
0.295995,59.5178427702347
0.296495,59.4889075985824
0.296995,59.7078531480852
0.297495,59.5549296700425
0.297995,59.8757558047821
0.298495,60.0114579823464
0.298995,59.9637257602684
0.299495,60.1051997030217
0.299995,60.3116607110718
0.300495,60.3699641514479
0.300995,60.2896314978044
0.301495,60.7684858894063
0.301995,60.7046579363227
0.302495,60.9394793663765
0.302995,61.0013034105644
0.303495,61.010013070475
0.303995,61.0071321868938
0.304495,61.4596720774707
0.304995,61.3966066028824
0.305495,61.6084896459349
0.305995,61.7797033054937
0.306495,62.0145206811824
0.306995,62.0844364704981
0.307495,62.0503487191449
0.307995,62.2541361823138
0.308495,62.4881672750356
0.308995,62.5308548456641
0.309495,62.4507183581021
0.309995,62.8571348788742
0.310495,63.0108181483427
0.310995,63.1863595226974
0.311495,63.3212410114719
0.311995,63.497556924789
0.312495,63.4942180449737
0.312995,63.619658517388
0.313495,64.1180034435801
0.313995,64.0387717035419
0.314495,64.0787728252345
0.314995,64.443034158771
0.315495,64.7020835581276
0.315995,64.6642463931723
0.316495,64.9382630558552
0.316995,64.9375286648121
0.317495,65.3437725886907
0.317995,65.419778549548
0.318495,65.4846875498217
0.318995,65.9222904370829
0.319495,65.9845075021711
0.319995,66.1130002493628
0.320495,66.2314323677423
0.320995,66.6195531888478
0.321495,66.5507649978612
0.321995,66.9989143679172
0.322495,67.0785451376669
0.322995,67.2750265367981
0.323495,67.414191698255
0.323995,67.8206430062895
0.324495,67.9654631698103
0.324995,67.8734430338213
0.325495,68.2431906904783
0.325995,68.5853286983586
0.326495,68.7119656409665
0.326995,68.8727387253925
0.327495,68.964268746608
0.327995,69.2190598661296
0.328495,69.6053731739804
0.328995,69.6047139805949
0.329495,70.1936235426316
0.329995,70.0983532992381
0.330495,70.3748905658246
0.330995,70.8055005100865
0.331495,70.8999177220494
0.331995,71.1556002748347
0.332495,71.4618959260262
0.332995,71.5862103048493
0.333495,71.8296442988698
0.333995,72.0821239249048
0.334495,72.3836902060051
0.334995,72.4070943214541
0.335495,72.8639926896856
0.335995,73.0488348124839
0.336495,73.2625984948895
0.336995,73.2682713210027
0.337495,73.7775126127152
0.337995,73.7838650092925
0.338495,74.1076320244365
0.338995,74.6192123857049
0.339495,74.7866337530194
0.339995,75.0134360108367
0.340495,75.4003516789638
0.340995,75.3510654086983
0.341495,75.9597673770888
0.341995,76.0008451903139
0.342495,76.2159801245153
0.342995,76.6331157335463
0.343495,76.699595071134
0.343995,77.1148357093888
0.344495,77.2035313782375
0.344995,77.6523240909367
0.345495,77.8536842653275
0.345995,78.1390687672335
0.346495,78.2485217252241
0.346995,78.5042590269478
0.347495,78.9797093035366
0.347995,79.191987051786
0.348495,79.4143137111244
0.348995,79.8514782031715
0.349495,80.1043074167664
0.349995,80.360396466562
0.350495,80.3858846973877
0.350995,80.7995311511042
0.351495,81.1201277488831
0.351995,81.4224062923308
0.352495,81.7530682264363
0.352995,81.9786301886488
0.353495,82.3699156356604
0.353995,82.5937709765462
0.354495,82.8539458538413
0.354995,82.7614789880966
0.355495,83.6466823025464
0.355995,83.9161969135686
0.356495,83.6112282034982
0.356995,84.0986947581091
0.357495,84.7077808224374
0.357995,84.9147598433598
0.358495,85.2498803481014
0.358995,85.6639067406074
0.359495,85.843056537558
0.359995,86.1135198168888
0.360495,86.6022050956468
0.360995,86.7292552375005
0.361495,87.2793939298795
0.361995,87.4338108280106
0.362495,87.7523752036283
0.362995,88.0068720050148
0.363495,88.2057233531214
0.363995,88.6574243763683
0.364495,89.0461987916347
0.364995,89.4479675597357
0.365495,89.777869022623
0.365995,90.2092045723138
0.366495,90.5120571196886
0.366995,90.6000968011678
0.367495,91.1796470124074
0.367995,91.4490747952725
0.368495,91.3581886846864
0.368995,91.9591531286034
0.369495,92.5769461850196
0.369995,92.9204425394074
0.370495,93.1474198775539
0.370995,93.3321693351799
0.371495,93.7037582122465
0.371995,94.2638055135885
0.372495,94.7573839427169
0.372995,95.0185213818257
0.373495,95.4400142042553
0.373995,96.0220409617152
0.374495,96.2409765216219
0.374995,96.3776949438762
0.375495,97.0219171246109
0.375995,97.2814164610943
0.376495,97.5444400483239
0.376995,97.9953958424478
0.377495,98.4348860495783
0.377995,98.7042157032434
0.378495,98.8023209150316
0.378995,98.2974616966344
0.379495,95.9154016458675
0.379995,91.1444521045375
0.380495,84.3172744439208
0.380995,75.714732704941
0.381495,69.0876425591538
0.381995,63.8570204791977
0.382495,58.5521261530727
0.382995,53.6644311044522
0.383495,49.5553066724096
0.383995,45.7951555588961
0.384495,42.3860764584355
0.384995,39.2542694686098
0.385495,36.8026986160906
0.385995,34.7796509419072
0.386495,33.3313632391297
0.386995,32.0613448999309
0.387495,30.8138906218875
0.387995,29.5807883072892
0.388495,28.352542082169
0.388995,27.161163118144
0.389495,26.000445221187
0.389995,24.9006571063867
0.390495,23.8536575343014
0.390995,22.8632272906627
0.391495,21.883118510452
0.391995,20.977685064815
0.392495,20.1183852602144
0.392995,19.1816875669011
0.393495,18.0475082591062
0.393995,16.7940075438322
0.394495,15.414194252241
0.394995,13.9162279171903
0.395495,12.3384413989188
0.395995,10.6407428510383
0.396495,8.80990708335639
0.396995,6.85383650165588
0.397495,4.7845402584703
0.397995,2.55442231960937
0.398495,0.252925600445002
0.398995,-1.79533664544066
0.399495,-3.65949008606961
0.399995,-5.69305297618313
0.400495,-7.95560623647097
0.400995,-10.1544169262866
0.401495,-11.3564151523875
0.401995,-10.8767174178503
0.402495,-7.82465290842659
0.402995,-6.69018294284988
0.403495,-5.82113578549017
0.403995,-4.71705248059395
0.404495,-3.98571330794688
0.404995,-3.23632172965822
0.405495,-3.35312647558375
0.405995,-3.53670763262264
0.406495,-3.56436821153058
0.406995,-3.67874487205486
0.407495,-3.28350262084018
0.407995,-2.61712582530862
0.408495,-2.29987251622923
0.408995,-1.9766524601088
0.409495,-1.55069616477184
0.409995,-1.56871871710192
0.410495,-1.52074523767114
0.410995,-1.2045100607156
0.411495,-0.618544750252514
0.411995,-0.54218010842186
0.412495,-0.216019770466033
0.412995,-0.284686830542785
0.413495,-0.372371923062899
0.413995,-0.324664124892981
0.414495,-0.248268048945431
0.414995,-0.183761203625275
0.415495,-0.194368453484437
0.415995,-0.772148782360985
0.416495,-1.02897835370234
0.416995,-1.25440864836045
0.417495,-1.16444829453481
0.417995,-1.08460137229268
0.418495,-1.12175618405755
0.418995,-0.76529271818081
0.419495,-0.686550412806193
0.419995,-0.474004800699293
0.420495,-0.296078782396048
0.420995,-0.247641724696316
0.421495,-0.372723829328749
0.421995,-0.124193999964767
0.422495,-0.548739756704502
0.422995,-0.688456738419816
0.423495,-0.716280243294954
0.423995,-0.542880736242476
0.424495,-0.786690960554662
0.424995,-0.489984263747251
0.425495,-0.439597924246216
0.425995,-0.368080549462772
0.426495,-0.406127916875908
0.426995,-0.140696192979836
0.427495,-0.236634867880366
0.427995,-0.163251938956871
0.428495,-0.381638015185003
0.428995,-0.541434261954785
0.429495,-0.750371684273058
0.429995,-0.58043071719705
0.430495,-0.780891097267316
0.430995,-0.486671902741339
0.431495,-0.574968762266046
0.431995,-0.447192165738667
0.432495,-0.375482858634775
0.432995,-0.0519178472978613
0.433495,0.0303715774603346
0.433995,-0.129405105381372
0.434495,-0.0101262183206852
0.434995,0.028409215612824
0.435495,0.0597368276224263
0.435995,0.0241920491668654
0.436495,0.0207504052313275
0.436995,-0.0684980845400895
0.437495,0.0601481443046901
0.437995,-0.00241932223493693
0.438495,0.028303815369894
0.438995,0.152402106168932
0.439495,0.0642576298910424
0.439995,-0.133045108949381
0.440495,-0.116243843326209
0.440995,-0.00770548992019179
0.441495,-0.113806444247435
0.441995,0.201442868035467
0.442495,0.110856674392313
0.442995,0.0397290706846593
0.443495,-0.0350342951816697
0.443995,-0.00756292832300084
0.444495,0.0291829347442061
0.444995,-0.315664787645943
0.445495,-0.220569026673781
0.445995,-0.149273465472362
0.446495,-0.321700977205422
0.446995,-0.266522570067436
0.447495,-0.154028796365946
0.447995,-0.340832310145544
0.448495,-0.17798854723124
0.448995,-0.261335501502025
0.449495,-0.294917204346672
0.449995,-0.327099364604762
0.450495,-0.498873214590997
0.450995,-0.502261396762522
0.451495,-0.365008052547936
0.451995,-0.185808022307597
0.452495,-0.181023674102555
0.452995,-0.122663741256222
0.453495,-0.0364801302815403
0.453995,-0.08623357561339
0.454495,-0.0891777034890912
0.454995,0.0393605722525968
0.455495,-0.0230426038442198
0.455995,-0.054140166326207
0.456495,-0.0182738472903217
0.456995,0.0733243236535023
0.457495,0.183773141601048
0.457995,0.0894825447130833
0.458495,0.00451142017877164
0.458995,0.0160767780603709
0.459495,0.0308020146517114
0.459995,-0.0583177574401249
0.460495,0.187115635024764
0.460995,0.169260138554869
0.461495,0.347505827903474
0.461995,0.310504889623588
0.462495,0.332041676506092
0.462995,0.298677495725314
0.463495,0.229596322825419
0.463995,0.157831907731973
0.464495,0.0770226325813993
0.464995,0.300933531088472
0.465495,0.0902986879190397
0.465995,-0.0999921397809648
0.466495,-0.0856791168278146
0.466995,-0.0726856328514389
0.467495,-0.206835537201186
0.467995,-0.116920450931356
0.468495,-0.282977070752444
0.468995,-0.329619418176037
0.469495,-0.209132154070669
0.469995,-0.301343636077819
0.470495,-0.321559767705391
0.470995,-0.258670280284521
0.471495,-0.242789035276786
0.471995,-0.287078167527926
0.472495,-0.157442826658689
0.472995,-0.337651742731248
0.473495,-0.0899233974190766
0.473995,-0.115279059836937
0.474495,0.0344997743484559
0.474995,0.0117660047576807
0.475495,0.0402456746541875
0.475995,0.136986489566801
0.476495,0.162912298509566
0.476995,0.213266413211183
0.477495,0.133712972381337
0.477995,0.235468679488487
0.478495,0.163462707456295
0.478995,0.240020030844986
0.479495,0.208135423545027
0.479995,0.316356369033945
0.480495,0.390559410707746
0.480995,0.324507699384
0.481495,0.226997440889737
0.481995,0.189375402318575
0.482495,0.121862630932046
0.482995,0.115392180439638
0.483495,0.184561522689802
0.483995,0.152712569655722
0.484495,0.104377818219506
0.484995,-0.078391828678748
0.485495,-0.0771752300385973
0.485995,-0.212880178345189
0.486495,-0.103373625739739
0.486995,-0.357880478125863
0.487495,-0.485069614815952
0.487995,-0.4628846505072
0.488495,-0.4031094222523
0.488995,-0.559160171639215
0.489495,-0.561016188650227
0.489995,-0.544783545109454
0.490495,-0.56121907869279
0.490995,-0.458189045983641
0.491495,-0.291678588411875
0.491995,-0.350624793290158
0.492495,-0.233534946512754
0.492995,-0.133606795466672
0.493495,-0.163504269397666
0.493995,-0.171399608925389
0.494495,-0.102737349183111
0.494995,-0.185462835777118
0.495495,-0.0747153945160513
0.495995,-0.090348799655148
0.496495,-0.0396719427100318
0.496995,0.173330750861978
0.497495,0.22882149351972
0.497995,0.271921472379359
0.498495,0.276654727796579
0.498995,0.415621201360911
0.499495,0.158388135531932
0.499995,0.157195781355349