File: DATA&scripts/1.7-data/h0/5/5_fracture_stress_data.csv
Strain,Fracture Stress (GPa)
-1.37893123345398e-16,0.640721300270425
0.000494999999999992,0.85281351860244
0.000994999999999836,1.11806379054168
0.00149499999999996,1.51823597400824
0.0019949999999998,1.65218261048636
0.00249499999999992,1.70985495675756
0.00299499999999976,2.30828689410813
0.00349499999999988,2.36280428051253
0.00399499999999973,2.45451203968663
0.00449499999999985,2.9889423868512
0.00499499999999997,3.07647976766861
0.00549499999999981,3.14362587968264
0.00599499999999993,3.73670276362328
0.00649499999999977,3.70480710046312
0.00699499999999989,3.86912325833072
0.00749499999999974,4.44315306586798
0.00799499999999986,4.43817806901658
0.00849499999999998,4.54365880266613
0.00899499999999982,5.18095498368771
0.00949499999999994,5.15801563029596
0.00999499999999979,5.3303171807746
0.0104949999999999,5.81370441866082
0.0109949999999997,5.82677905284709
0.0114949999999999,6.03405468545953
0.011995,6.45252801533135
0.0124949999999998,6.4522466073274
0.012995,6.68665579520691
0.0134949999999998,7.18166218326447
0.0139949999999999,7.23703725405429
0.0144949999999998,7.29538766498478
0.0149949999999999,7.68645369644576
0.0154949999999997,7.93343036540146
0.0159949999999998,8.07770320661059
0.016495,8.30599494823721
0.0169949999999998,8.46124754630086
0.0174949999999999,8.75889824226286
0.0179949999999998,9.07505305802281
0.0184949999999999,9.18201531213754
0.0189949999999997,9.31337138591405
0.0194949999999999,9.61262444292233
0.019995,9.80887008235937
0.0204949999999998,10.1419009037605
0.0209949999999999,10.3123632452081
0.0214949999999998,10.4033729508347
0.0219949999999999,10.6377342626491
0.0224949999999997,10.9286710402141
0.0229949999999999,11.1146234875461
0.023495,11.2275938394045
0.0239949999999998,11.468040755546
0.0244949999999999,11.7623401813375
0.0249949999999998,11.9750677284854
0.0254949999999999,12.1529127319742
0.0259949999999998,12.2557013847247
0.0264949999999999,12.4632354412404
0.0269949999999997,12.7386771581806
0.0274949999999998,12.9783695337198
0.027995,13.1629306422909
0.0284949999999998,13.2972708071137
0.0289949999999999,13.5447632134191
0.0294949999999998,13.7541040731954
0.0299949999999999,13.8881387774893
0.0304949999999997,14.1597793946716
0.0309949999999999,14.3143525499458
0.031495,14.5330228120812
0.0319949999999998,14.8202339019532
0.0324949999999999,14.9949880778589
0.0329949999999998,15.1253680846188
0.0334949999999999,15.3501350521944
0.0339949999999997,15.5245185432111
0.0344949999999999,15.7043723549856
0.034995,15.9121634646191
0.0354949999999998,16.0950917802007
0.0359949999999999,16.2460518383254
0.0364949999999998,16.5596096513395
0.0369949999999999,16.7704992682451
0.0374949999999998,16.743182675346
0.0379949999999999,16.9891872607936
0.0384949999999999,17.2985967980877
0.0389949999999998,17.4288874575403
0.039495,17.6680612973539
0.0399949999999998,17.8783135840579
0.0404949999999999,18.0860288097504
0.0409949999999998,18.2592618367813
0.0414949999999999,18.4774494268506
0.0419949999999997,18.6176022318405
0.0424949999999998,18.8115290459397
0.042995,18.9817096039658
0.0434949999999998,19.1609902331724
0.0439949999999999,19.3024358449874
0.0444949999999998,19.4908241767135
0.0449949999999999,19.7215894518024
0.0454949999999997,19.9309418095309
0.0459949999999999,20.1279524394724
0.0464949999999998,20.3352882724796
0.0469949999999998,20.4516809474798
0.0474949999999999,20.6233281269851
0.0479949999999998,20.8607256425219
0.0484949999999999,21.0970907180831
0.0489949999999997,21.225560215245
0.0494949999999999,21.4771672672506
0.0499949999999997,21.5751490740671
0.0504949999999998,21.7672300523897
0.050995,21.9463111673342
0.0514949999999998,22.1144900999379
0.0519949999999999,22.2820809954985
0.0524949999999998,22.4777333675384
0.0529949999999999,22.6120104876169
0.0534949999999997,22.7797666030877
0.0539949999999998,23.012087277692
0.054495,23.147121541416
0.0549949999999998,23.3252578314536
0.0554949999999999,23.5473666520441
0.0559949999999998,23.7219509936663
0.0564949999999999,23.881881200201
0.0569949999999997,24.1482156685389
0.0574949999999999,24.2804811407844
0.0579949999999998,24.3426631859089
0.0584949999999998,24.6316247229079
0.0589949999999999,24.7848710240169
0.0594949999999998,24.8629288332572
0.0599949999999999,25.1517600523738
0.0604949999999997,25.3326937106663
0.0609949999999999,25.4716814611973
0.0614949999999998,25.6613941089832
0.0619949999999998,25.8847495093061
0.0624949999999999,25.9790599330455
0.0629949999999998,26.1918588754341
0.0634949999999999,26.3819355825257
0.0639949999999998,26.4581551038384
0.0644949999999999,26.682041634499
0.0649949999999997,26.8896418290966
0.0654949999999998,27.0091183601658
0.065995,27.1721113833445
0.0664949999999998,27.3644984076959
0.0669949999999999,27.4552827725341
0.0674949999999998,27.6283523212236
0.0679949999999999,27.8361555688551
0.0684949999999997,27.9345932664255
0.0689949999999998,28.105011152103
0.0694949999999998,28.2877679310662
0.0699949999999998,28.4522281744466
0.0704949999999999,28.5845024518307
0.0709949999999998,28.7957036355473
0.0714949999999999,28.907643693839
0.0719949999999997,29.0876177075556
0.0724949999999999,29.3293652680876
0.0729949999999998,29.3664577254216
0.0734949999999998,29.5485084246525
0.0739949999999999,29.7526058644721
0.0744949999999998,29.8416287900069
0.0749949999999999,29.9411510752314
0.0754949999999998,30.1601983049803
0.0759949999999999,30.2895544012736
0.0764949999999997,30.380167677737
0.0769949999999998,30.6584493597866
0.077495,30.7534511209026
0.0779949999999998,30.8163837286053
0.0784949999999999,31.1243609729253
0.0789949999999998,31.2448517578777
0.0794949999999999,31.312081760292
0.0799949999999997,31.5437340055065
0.0804949999999998,31.7433591479757
0.0809949999999998,31.7858329926136
0.0814949999999998,31.9753218873213
0.0819949999999999,32.1421075112175
0.0824949999999998,32.2385016404231
0.0829949999999999,32.3941317891961
0.0834949999999997,32.5680922543304
0.0839949999999999,32.6672927977488
0.0844949999999998,32.847765808169
0.0849949999999998,33.0502829863427
0.0854949999999999,33.158693341237
0.0859949999999998,33.3276842334997
0.0864949999999999,33.5231078174205
0.0869949999999998,33.5560385232562
0.0874949999999999,33.6701826480773
0.0879949999999997,33.8812334887293
0.0884949999999998,34.0270294422585
0.0889949999999999,34.1630125099455
0.0894949999999998,34.3428269287504
0.0899949999999999,34.5096921736978
0.0904949999999998,34.6165332900197
0.0909949999999999,34.7571373118889
0.0914949999999997,34.8641906745424
0.0919949999999998,34.9546631510917
0.0924949999999998,35.136939924981
0.0929949999999998,35.3279949154335
0.0934949999999999,35.4782133648371
0.0939949999999998,35.615014548756
0.0944949999999999,35.7733126120553
0.0949949999999997,35.8204470599895
0.0954949999999999,35.9588959060739
0.0959949999999997,36.0621514240793
0.0964949999999998,36.2333141650217
0.0969949999999999,36.4461750505277
0.0974949999999998,36.5618363729171
0.0979949999999999,36.6665247365708
0.0984949999999997,36.745745453865
0.0989949999999999,36.9041960949062
0.0994949999999997,37.0861766627014
0.0999949999999998,37.2399047414345
0.100495,37.35148411459
0.100995,37.469554233298
0.101495,37.5189769809732
0.101995,37.6981517321784
0.102495,37.8767353089664
0.102995,37.9953410449348
0.103495,38.1323712819538
0.103995,38.228110957213
0.104495,38.3542750018577
0.104995,38.5182605822222
0.105495,38.5963984258543
0.105995,38.7497934219079
0.106495,38.8612628512194
0.106995,38.9807412318625
0.107495,39.172690849843
0.107995,39.257120317477
0.108495,39.3517403030135
0.108995,39.5171601585224
0.109495,39.6240191688221
0.109995,39.7005416679309
0.110495,39.8680183240805
0.110995,40.0049001953696
0.111495,40.0829025454623
0.111995,40.2050935674023
0.112495,40.3864602081505
0.112995,40.4333341312464
0.113495,40.5424129190051
0.113995,40.7150226523474
0.114495,40.8165614765312
0.114995,40.875543104959
0.115495,41.052386985148
0.115995,41.2234598017501
0.116495,41.3100486921675
0.116995,41.3702054987076
0.117495,41.5159509845059
0.117995,41.6268010004039
0.118495,41.7488955825918
0.118995,41.8336004429055
0.119495,41.9559315651585
0.119995,42.0998296967487
0.120495,42.162569918793
0.120995,42.2345616829362
0.121495,42.4589856181569
0.121995,42.541367485062
0.122495,42.5849036689486
0.122995,42.7876732012395
0.123495,42.8855413794238
0.123995,42.9053517470105
0.124495,43.1179815595856
0.124995,43.1906783947433
0.125495,43.222314236499
0.125995,43.3992583123331
0.126495,43.5517533775727
0.126995,43.5953190046764
0.127495,43.6804943432579
0.127995,43.8163227474436
0.128495,43.8908821953308
0.128995,43.9912023966812
0.129495,44.119439039679
0.129995,44.2460589542634
0.130495,44.3208159769387
0.130995,44.3952810180462
0.131495,44.5364685576876
0.131995,44.6514114664315
0.132495,44.7519862397951
0.132995,44.8275500186706
0.133495,44.9490054151755
0.133995,45.0102858335174
0.134495,45.1616191486876
0.134995,45.2176404863075
0.135495,45.304315476348
0.135995,45.4621346937078
0.136495,45.5384899464997
0.136995,45.5661746303673
0.137495,45.7179987349426
0.137995,45.8164368607628
0.138495,45.8729513625408
0.138995,46.0107036906459
0.139495,46.0587890886323
0.139995,46.1593124799653
0.140495,46.2814572811551
0.140995,46.38212002449
0.141495,46.4379537829462
0.141995,46.542042784012
0.142495,46.6279256069013
0.142995,46.7602264414982
0.143495,46.7941775264876
0.143995,46.9487366496394
0.144495,47.0534474757045
0.144995,47.0904057671081
0.145495,47.2039433989061
0.145995,47.2421548896734
0.146495,47.3896556345323
0.146995,47.4782644886631
0.147495,47.5725955667268
0.147995,47.6447219735732
0.148495,47.7520339422045
0.148995,47.7987319578073
0.149495,47.8806507925622
0.149995,47.956820834032
0.150495,48.0654733000895
0.150995,48.1668099814048
0.151495,48.2008223456828
0.151995,48.3629028223727
0.152495,48.3663314758013
0.152995,48.47257873564
0.153495,48.522563045323
0.153995,48.6369226099997
0.154495,48.6946966994301
0.154995,48.7572704750099
0.155495,48.8880176842533
0.155995,48.9450007330425
0.156495,49.0361863058406
0.156995,49.0853137867917
0.157495,49.1554861940805
0.157995,49.2551753364484
0.158495,49.3193619983274
0.158995,49.4160239087278
0.159495,49.4697641339677
0.159995,49.571553983835
0.160495,49.6114046013668
0.160995,49.7649367740662
0.161495,49.7560594932033
0.161995,49.8787731824335
0.162495,49.8786377363755
0.162995,50.0433033779498
0.163495,50.094044179849
0.163995,50.1926697300713
0.164495,50.2354359957685
0.164995,50.3083445042409
0.165495,50.3623698396145
0.165995,50.4603097457055
0.166495,50.5477146662744
0.166995,50.5924131897727
0.167495,50.6669978766532
0.167995,50.7243534418646
0.168495,50.7742921119216
0.168995,50.8662080709813
0.169495,50.9724772633694
0.169995,51.0252796597802
0.170495,51.0737751968611
0.170995,51.1379826842196
0.171495,51.2011150521978
0.171995,51.2657402176161
0.172495,51.3787196135896
0.172995,51.3997435058286
0.173495,51.467540009114
0.173995,51.564173819974
0.174495,51.5895226024862
0.174995,51.6615363418629
0.175495,51.7453591222235
0.175995,51.8180119600978
0.176495,51.8678086551289
0.176995,51.9477129867169
0.177495,51.9396528864316
0.177995,52.1037778797543
0.178495,52.1282795948285
0.178995,52.2187100947869
0.179495,52.278318818471
0.179995,52.3074428162605
0.180495,52.3392801345074
0.180995,52.4021962450124
0.181495,52.5053113357504
0.181995,52.5554091190949
0.182495,52.6323388785642
0.182995,52.6586866270338
0.183495,52.6731926357552
0.183995,52.7704001947552
0.184495,52.8803459999932
0.184995,52.9084665292509
0.185495,52.987974836873
0.185995,52.9985564445073
0.186495,53.071027724037
0.186995,53.1438747249972
0.187495,53.2159681386428
0.187995,53.2440706420233
0.188495,53.2660856947893
0.188995,53.3161201245296
0.189495,53.4363622082307
0.189995,53.4404877969938
0.190495,53.5200114727667
0.190995,53.6250874356043
0.191495,53.5682370620721
0.191995,53.6719131769944
0.192495,53.7559751955691
0.192995,53.6962913787784
0.193495,53.8956758919177
0.193995,53.8972490802447
0.194495,53.8693199980691
0.194995,53.9949195889606
0.195495,54.0639178718841
0.195995,54.150422270792
0.196495,54.1702591467108
0.196995,54.2398650497934
0.197495,54.2761792589419
0.197995,54.321287792655
0.198495,54.3777460928453
0.198995,54.4170991932033
0.199495,54.4657580611539
0.199995,54.5349175169055
0.200495,54.5471702858798
0.200995,54.6214320411318
0.201495,54.7056731842742
0.201995,54.7121006369201
0.202495,54.8289290109129
0.202995,54.8331774391054
0.203495,54.8895698541774
0.203995,54.9273113691474
0.204495,54.9753249925289
0.204995,54.942826503704
0.205495,55.0970458522467
0.205995,55.1581268387129
0.206495,55.1658306591465
0.206995,55.2750656794052
0.207495,55.2796012524596
0.207995,55.3563107435632
0.208495,55.3954107489454
0.208995,55.4189437952073
0.209495,55.534604513116
0.209995,55.5304492884421
0.210495,55.6351085979853
0.210995,55.7056455722965
0.211495,55.6461336809916
0.211995,55.7524680677424
0.212495,55.8438242158636
0.212995,55.8997462308838
0.213495,55.8135712216002
0.213995,55.9250652412036
0.214495,56.0268634085078
0.214995,56.0009984185307
0.215495,56.122620179119
0.215995,56.1269237288239
0.216495,56.1227044851971
0.216995,56.2466048916095
0.217495,56.2430918231704
0.217995,56.236435580648
0.218495,56.3691403876722
0.218995,56.4122630221913
0.219495,56.5027234054577
0.219995,56.487687109805
0.220495,56.5512792093277
0.220995,56.5597368596732
0.221495,56.6467119305139
0.221995,56.6904661979886
0.222495,56.7265076494198
0.222995,56.7432768292391
0.223495,56.8230724477298
0.223995,56.8318726271006
0.224495,56.9116682549771
0.224995,56.9473093776833
0.225495,57.0437838978776
0.225995,57.0815672676069
0.226495,57.1294204949669
0.226995,57.1688804873408
0.227495,57.2538112298442
0.227995,57.3142943681291
0.228495,57.3482743381056
0.228995,57.3309477325697
0.229495,57.4057928887236
0.229995,57.4761182779072
0.230495,57.4476858631864
0.230995,57.5458084002467
0.231495,57.5390691373265
0.231995,57.5753596766696
0.232495,57.7541495562932
0.232995,57.7842719297654
0.233495,57.7141949286912
0.233995,57.6773405647139
0.234495,57.7944495149635
0.234995,57.926915807535
0.235495,57.943817085977
0.235995,57.9609370560603
0.236495,58.0440665453849
0.236995,58.0290277252852
0.237495,58.1554801526681
0.237995,58.1795189311515
0.238495,58.1826936401153
0.238995,58.2415692367046
0.239495,58.3965509728504
0.239995,58.3958084988141
0.240495,58.3384462439418
0.240995,58.3809913821905
0.241495,58.5691918612988
0.241995,58.5246697263685
0.242495,58.6097333404324
0.242995,58.6583531453577
0.243495,58.7188352730244
0.243995,58.6241551016929
0.244495,58.8766492279583
0.244995,58.8151726392859
0.245495,58.8724410910074
0.245995,58.9302818599415
0.246495,59.0286027332462
0.246995,59.1461439565404
0.247495,59.0747574621059
0.247995,59.1803609365843
0.248495,59.3547226400693
0.248995,59.2571048120125
0.249495,59.2647516355332
0.249995,59.3191999944611
0.250495,59.3100360857201
0.250995,59.4333052281646
0.251495,59.3761165884256
0.251995,59.5606088526803
0.252495,59.5450880344432
0.252995,59.6100524597488
0.253495,59.6716024606519
0.253995,59.7318896900777
0.254495,59.8351206437352
0.254995,59.8181040731539
0.255495,59.9098366773942
0.255995,59.89148221122
0.256495,60.0055319910475
0.256995,60.1477781205038
0.257495,60.1640014298776
0.257995,60.2868273193605
0.258495,60.3007271088022
0.258995,60.3323329504564
0.259495,60.3186370380679
0.259995,60.4091744490507
0.260495,60.5342883489766
0.260995,60.6711649537281
0.261495,60.541857307035
0.261995,60.7403036886198
0.262495,60.6222346275064
0.262995,60.7308054329641
0.263495,60.7714489992693
0.263995,60.9568189711014
0.264495,60.6745643354931
0.264995,60.7868228674684
0.265495,60.9990502278477
0.265995,61.1558582141393
0.266495,60.9516829586071
0.266995,61.2539135801418
0.267495,61.3996241152808
0.267995,61.2186344265989
0.268495,61.5032252039878
0.268995,61.3382284733488
0.269495,61.4246241412218
0.269995,61.3028440420761
0.270495,61.7478504102871
0.270995,61.7038822542725
0.271495,61.9156739734978
0.271995,61.5990072608167
0.272495,61.7192387048766
0.272995,61.8301252872077
0.273495,62.1492949608438
0.273995,62.1709033935616
0.274495,62.0787396867504
0.274995,62.3649351758219
0.275495,62.0793911555099
0.275995,62.3772274541315
0.276495,62.2858944632477
0.276995,62.4496329595891
0.277495,62.5709202866313
0.277995,62.4273037517622
0.278495,62.4947646488988
0.278995,62.8423029127585
0.279495,62.9281557262886
0.279995,62.9142920860581
0.280495,63.0188165155169
0.280995,63.1178029654936
0.281495,63.0171345792846
0.281995,63.2329144038911
0.282495,63.0024785871525
0.282995,63.3675164082702
0.283495,63.3168994593987
0.283995,63.2216954049233
0.284495,63.532661217875
0.284995,63.7228564203353
0.285495,63.5661427735553
0.285995,63.8515809716395
0.286495,63.6376556020659
0.286995,63.9299670633044
0.287495,63.9746296689165
0.287995,63.9799188256514
0.288495,63.9083310217854
0.288995,64.0404613946121
0.289495,64.1701562145906
0.289995,64.2777385799673
0.290495,64.3757219823245
0.290995,64.6434662710933
0.291495,64.5811848324871
0.291995,64.6593241966162
0.292495,64.8375816757409
0.292995,65.0003437051749
0.293495,65.0715183218748
0.293995,65.2030614720463
0.294495,65.4753893627112
0.294995,65.3910964848675
0.295495,65.6989718153024
0.295995,65.7621687468986
0.296495,65.6496005064941
0.296995,65.7956551176028
0.297495,66.0911604237012
0.297995,65.9998675017053
0.298495,66.2566266899371
0.298995,66.2058215864724
0.299495,66.2643194762249
0.299995,66.6991248615764
0.300495,66.7421744226336
0.300995,66.8032869688854
0.301495,67.1811118712636
0.301995,66.844581421141
0.302495,67.2260122613764
0.302995,67.4952859767359
0.303495,67.3472205570057
0.303995,67.266947852305
0.304495,67.6185730876264
0.304995,67.8983828882835
0.305495,67.7640233941762
0.305995,67.9808478727676
0.306495,68.2725069626533
0.306995,68.3340934952692
0.307495,68.7510179335381
0.307995,68.4288232354436
0.308495,68.762324436771
0.308995,68.8699583993091
0.309495,69.0956246965252
0.309995,69.5609683089891
0.310495,69.1645879361225
0.310995,69.7084621949889
0.311495,69.6559962578457
0.311995,69.8991748148448
0.312495,70.1578975250006
0.312995,70.5987327548739
0.313495,70.638257705931
0.313995,70.568823113423
0.314495,70.800889717542
0.314995,70.838064239599
0.315495,71.2244633428529
0.315995,71.3299140519946
0.316495,71.6412733008527
0.316995,71.6094141120304
0.317495,71.8617416932981
0.317995,72.0647546266386
0.318495,72.5166589212866
0.318995,72.4587544081514
0.319495,72.5967162184702
0.319995,72.9714197121707
0.320495,73.2351306783335
0.320995,73.0819904642167
0.321495,73.5130482240354
0.321995,73.7666060113208
0.322495,73.8959050433736
0.322995,74.2668563714
0.323495,74.3927110771698
0.323995,74.4818264769851
0.324495,74.8250451990582
0.324995,75.2788043094293
0.325495,75.122315493407
0.325995,75.2909240112079
0.326495,75.5311345464098
0.326995,76.1828933202264
0.327495,75.9763873530581
0.327995,76.2957427871188
0.328495,76.5598289901805
0.328995,76.8960948072512
0.329495,77.2686147741452
0.329995,77.4428066595093
0.330495,77.9927347197401
0.330995,77.8407301291439
0.331495,78.2611324833406
0.331995,77.9116197134474
0.332495,78.7473822726979
0.332995,78.6622727913781
0.333495,79.4406251376098
0.333995,79.2920579248956
0.334495,80.0660412261801
0.334995,80.1058979012061
0.335495,79.9851871424233
0.335995,80.8667998677849
0.336495,80.6826919231874
0.336995,80.9585812123078
0.337495,81.5329360618595
0.337995,81.6541079487061
0.338495,81.8631309357576
0.338995,82.2124626584581
0.339495,82.7294421783377
0.339995,82.404824243579
0.340495,82.8144996383146
0.340995,83.8472633444228
0.341495,83.2513475141036
0.341995,83.6391083229891
0.342495,84.1470649818149
0.342995,84.1148766716539
0.343495,84.7445107891568
0.343995,85.0440358737437
0.344495,85.2511345884888
0.344995,85.5968659274166
0.345495,85.8003097023258
0.345995,85.8703428035152
0.346495,86.5443071331935
0.346995,86.8930048439609
0.347495,86.9965645711943
0.347995,87.2421582109999
0.348495,88.0525935525856
0.348995,88.0919660021577
0.349495,87.9245886224794
0.349995,89.0264994859168
0.350495,88.7850534827562
0.350995,88.9685695808571
0.351495,89.3703366537639
0.351995,90.0290025345247
0.352495,90.2074293537838
0.352995,90.303346620671
0.353495,90.9238333532794
0.353995,91.1361839078008
0.354495,91.4472928733675
0.354995,91.357566454815
0.355495,91.8947773028031
0.355995,92.7586485626852
0.356495,92.5563820662755
0.356995,92.8583707537678
0.357495,93.2479959957415
0.357995,93.2927509411472
0.358495,94.1853231756618
0.358995,94.6153212129911
0.359495,94.9259670323132
0.359995,94.6979814031981
0.360495,95.600986380671
0.360995,95.847509639658
0.361495,95.8830877155294
0.361995,96.7370406151424
0.362495,97.0062334658128
0.362995,96.9568598320632
0.363495,97.6029671173759
0.363995,97.801612239157
0.364495,98.196128943836
0.364995,98.6453046870091
0.365495,98.950458669458
0.365995,99.025667707912
0.366495,99.3855549968087
0.366995,100.022446236813
0.367495,100.608710328261
0.367995,101.03442342018
0.368495,101.143944029757
0.368995,101.457435452516
0.369495,101.644817986711
0.369995,102.557833109434
0.370495,102.698811321141
0.370995,102.958706604369
0.371495,103.450644632639
0.371995,103.76299498433
0.372495,104.01999191652
0.372995,104.78414957771
0.373495,105.00895565546
0.373995,105.625418601738
0.374495,105.839431649311
0.374995,106.344623900806
0.375495,106.883160741241
0.375995,107.102751803655
0.376495,107.668997099935
0.376995,108.035396578313
0.377495,108.557493432684
0.377995,108.872381822848
0.378495,109.496869979942
0.378995,110.082281559229
0.379495,110.478466815477
0.379995,110.771456036526
0.380495,111.421822099227
0.380995,111.735037696579
0.381495,111.704903884842
0.381995,112.226195813979
0.382495,112.890497837055
0.382995,113.281966935139
0.383495,113.677696404335
0.383995,114.186461241921
0.384495,114.88476202201
0.384995,115.320895594748
0.385495,115.917920981226
0.385995,116.318820425036
0.386495,116.693777488444
0.386995,117.209546910944
0.387495,117.84211599585
0.387995,118.44871810502
0.388495,118.636844011763
0.388995,119.321902653209
0.389495,119.529854797201
0.389995,119.890734098164
0.390495,120.088775889141
0.390995,118.193348873289
0.391495,110.111928604512
0.391995,95.4776546171648
0.392495,76.8734987972146
0.392995,62.6395578741471
0.393495,53.8267476319266
0.393995,45.62863617802
0.394495,39.5244314139849
0.394995,35.9627727904615
0.395495,33.23852924313
0.395995,30.5306589658722
0.396495,28.047754921124
0.396995,25.8499244123728
0.397495,23.6724982623145
0.397995,21.7015812109921
0.398495,19.4650619682402
0.398995,16.6459759084648
0.399495,13.5039395717254
0.399995,10.0313149816624
0.400495,6.21827670244018
0.400995,2.3257475540246
0.401495,-0.899756531669122
0.401995,-4.04896304860932
0.402495,-7.52720437082626
0.402995,-11.6693267420447
0.403495,-15.4968574392733
0.403995,-17.375392128582
0.404495,-12.0077358842853
0.404995,-6.08923767930535
0.405495,-1.29745034098195
0.405995,-0.292220031330922
0.406495,-0.958738514151152
0.406995,-1.85690274889988
0.407495,-2.3238529434298
0.407995,-1.53500989304712
0.408495,-0.403715625218655
0.408995,1.16448877760828
0.409495,1.8790666768745
0.409995,2.45935730452689
0.410495,2.19390073454931
0.410995,2.42129986299468
0.411495,2.32029174086535
0.411995,2.50148764912589
0.412495,2.39551483477236
0.412995,1.65421975156303
0.413495,1.24607889225322
0.413995,0.596525849846147
0.414495,-0.327477989126286
0.414995,-0.692837343288157
0.415495,-1.25668443291267
0.415995,-1.07660188538533
0.416495,-0.844566622934613
0.416995,-1.28162933299646
0.417495,-1.27124379550506
0.417995,-1.21549452145931
0.418495,-1.20985477078863
0.418995,-0.93822098263704
0.419495,-0.848467432263039
0.419995,-0.216608483464247
0.420495,-0.0698635073379661
0.420995,0.128921570755454
0.421495,0.308001620408474
0.421995,0.386537718022592
0.422495,0.742489261338072
0.422995,1.17272913875695
0.423495,1.26516031149878
0.423995,1.25788570288159
0.424495,1.26559753106765
0.424995,0.918228502511454
0.425495,0.536303334853761
0.425995,0.306400494581842
0.426495,-0.0863978599865447
0.426995,-0.160159964784818
0.427495,-0.539307871893362
0.427995,-1.04919833413443
0.428495,-1.10026944250494
0.428995,-1.24252470462726
0.429495,-1.47734993517405
0.429995,-0.887352131897959
0.430495,-0.990903218794365
0.430995,-0.576085890299118
0.431495,-0.225953512283516
0.431995,-0.123449066063885
0.432495,0.432563958153176
0.432995,0.802680487936616
0.433495,1.11964164689043
0.433995,1.32383073887658
0.434495,1.54428552236719
0.434995,1.27684044442838
0.435495,1.17194340253737
0.435995,0.940953562629293
0.436495,0.388196955815379
0.436995,0.0952348508555575
0.437495,-0.35994723714476
0.437995,-0.674500645081346
0.438495,-0.949149416843855
0.438995,-1.18687192298613
0.439495,-1.33914293947617
0.439995,-1.35083095907336
0.440495,-1.21877446234436
0.440995,-0.938656136981173
0.441495,-0.547286924375993
0.441995,-0.0141704349146161
0.442495,0.258199014552425
0.442995,0.563738773457816
0.443495,0.904736883018578
0.443994999999999,1.26748862526516
0.444495,1.27133427216923
0.444995,1.38859429757991
0.445495,1.20150848730246
0.445995,0.837388084947192
0.446495,0.630006946401157
0.446995,0.197293565107382
0.447495,-0.060046602191578
0.447995,-0.265526214532682
0.448495,-0.813675536378956
0.448995,-1.13494508167848
0.449495,-1.3202124829514
0.449995,-1.36118418869773
0.450495,-1.19460949489929
0.450995,-0.969882489316084
0.451495,-0.668602567853611
0.451995,-0.29102795922451
0.452495,0.0639102524576237
0.452995,0.337688174493152
0.453495,0.707043470535413
0.453995,1.10093795897517
0.454495,1.21954450781452
0.454995,1.45560150899656
0.455494999999999,1.36716807129728
0.455995,1.04884274810412
0.456495,0.710703245275794
0.456995,0.273830036647366
0.457495,0.0356936768851011
0.457995,-0.235264637414356
0.458495,-0.72156321319821
0.458995,-1.00302549001606
0.459495,-1.20500599321702
0.459995,-1.45973912542557
0.460495,-1.31210933226013
0.460995,-0.898535737144408
0.461495,-0.858874685670337
0.461995,-0.401365564847209
0.462494999999999,-0.147568008365213
0.462995,0.240901392660589
0.463495,0.512445388637061
0.463995,0.811327697092586
0.464495,1.09904316079583
0.464995,1.27425976810736
0.465495,1.16621603027668
0.465995,0.97806893877868
0.466495,0.776591741028939
0.466995,0.494218274276044
0.467495,0.180600144353542
0.467995,-0.0590510124478784
0.468495,-0.515660246552231
0.468995,-0.862192988199069
0.469495,-1.06537332759114
0.469995,-1.19435253191034
0.470495,-1.1683548710232
0.470995,-0.930136078331234
0.471495,-0.758527013158917
0.471995,-0.374196340261934
0.472495,-0.163448804788211
0.472995,0.048794157969569
0.473495,0.502283729112363
0.473995,0.827349009010604
0.474495,0.929503937472236
0.474995,1.28755182254519
0.475495,1.10383994871255
0.475995,0.909663531180446
0.476495,0.836448865417081
0.476995,0.411870073406868
0.477495,0.307924203803376
0.477995,-0.0327568157338805
0.478495,-0.308561854288335
0.478995,-0.845356002144899
0.479495,-0.947502406580119
0.479995,-1.13916443056049
0.480495,-1.02306817608562
0.480995,-0.904789554483974
0.481495,-0.729885139884273
0.481995,-0.696522374053257
0.482495,-0.330823780696646
0.482995,0.0748295909692171
0.483495,0.381904956257792
0.483995,0.739986084954394
0.484495,0.949080812636982
0.484995,0.987588565720736
0.485495,0.894611006058239
0.485995,0.953146346333532
0.486495,0.84779492772448
0.486995,0.589694795494374
0.487495,0.462780628074981
0.487995,-0.0850521198523204
0.488495,-0.321268487578359
0.488995,-0.657527981282653
0.489495,-0.97520893527874
0.489995,-0.941521650216279
0.490495,-0.946962475986919
0.490995,-0.796712701377225
0.491495,-0.941476933772958
0.491995,-0.629030894525948
0.492495,-0.317329951865355
0.492995,0.0423289186917403
0.493495,0.28020832722674
0.493995,0.677801806877527
0.494495,0.962565080924742
0.494995,0.843530850627115
0.495495,0.88699862119206
0.495995,0.94775829799546
0.496495,0.836678265145452
0.496995,0.622301527347454
0.497495,0.356460252447674
0.497995,0.0614217614493512
0.498495,-0.21903913228971
0.498995,-0.585361854246678
0.499495,-0.839717641838153
0.499995,-0.909902435322991