File: DATA&scripts/1.7-data/z0/17/17_fracture_stress_data.csv
Strain,Fracture Stress (GPa)
0.0,0.382550484767643
0.000995000000000079,1.22441657391173
0.0019949999999999,1.76153803631378
0.002995,2.31883154076284
0.0039950000000001,2.94214977106541
0.00499499999999992,3.66000909409131
0.00599500000000002,4.29362850346757
0.00699500000000012,4.87173846465589
0.00799499999999994,5.39825094461012
0.00899500000000004,6.03569827167844
0.009995,6.72227035461433
0.010995,7.29485022828689
0.0119950000000001,7.88035072943858
0.0129949999999999,8.46093926567682
0.013995,8.95332325240751
0.0149950000000001,9.52813991572198
0.0159949999999999,10.1291543017642
0.016995,10.6959983159343
0.0179950000000001,11.2922987628352
0.0189949999999999,11.806558801679
0.019995,12.3236037364888
0.0209950000000001,12.8288479067696
0.0219949999999999,13.4850636478406
0.022995,13.9898844861769
0.023995,14.4914755398757
0.024995,14.9980758619082
0.0259950000000001,15.6402675699666
0.0269949999999999,16.0963460919765
0.027995,16.5176754973499
0.0289950000000001,17.1143074724092
0.0299949999999999,17.6213531800613
0.030995,18.0930206137982
0.0319950000000001,18.6361887507931
0.0329949999999999,19.1519289703224
0.033995,19.7148246454375
0.0349950000000001,20.1426533775562
0.0359949999999999,20.5470236149253
0.036995,21.1140374719584
0.037995,21.6827507290278
0.038995,22.2103219428711
0.0399950000000001,22.6352058349365
0.0409949999999999,23.1205274166675
0.041995,23.6173391936636
0.0429950000000001,24.0523240940647
0.0439949999999999,24.5092660973002
0.044995,24.9793946940719
0.0459950000000001,25.4964378478642
0.0469949999999999,26.0283901283276
0.047995,26.5451766702976
0.0489950000000001,26.9966810418102
0.0499949999999999,27.3821625948212
0.050995,27.7821217701028
0.051995,28.2578446712704
0.052995,28.6856115902399
0.0539950000000001,29.155200038827
0.0549949999999999,29.6067130415152
0.055995,30.0460895428254
0.0569950000000001,30.5026369409309
0.0579949999999999,30.9603955608056
0.058995,31.4030875601702
0.0599950000000001,31.8190639951328
0.0609949999999999,32.2823409722656
0.061995,32.7139813470567
0.0629950000000001,33.1721337204109
0.0639949999999999,33.5936825041746
0.064995,34.0550286152544
0.065995,34.4790400155702
0.066995,34.8727457845702
0.0679950000000001,35.3049064055663
0.068995,35.7197475682892
0.069995,36.1368385329102
0.0709950000000001,36.5948420953746
0.0719949999999999,36.9895576972526
0.072995,37.3963511021145
0.0739950000000001,37.7731388912843
0.0749949999999999,38.1794259327533
0.075995,38.5643674025404
0.0769950000000001,38.9362048294352
0.0779949999999999,39.3628906000135
0.078995,39.7324298641554
0.079995,40.1674043412041
0.080995,40.5691836954075
0.0819950000000001,40.956196837869
0.0829949999999999,41.2978989930841
0.083995,41.6308935982171
0.0849950000000001,42.0953916224479
0.0859949999999999,42.4629710191139
0.086995,42.7875527523015
0.0879950000000001,43.1610276408244
0.0889949999999999,43.5445346923992
0.089995,43.931339593342
0.0909950000000001,44.2172900019838
0.0919949999999999,44.6274923991869
0.092995,45.0012001582093
0.093995,45.3161389264783
0.094995,45.677781036489
0.0959950000000001,46.0665937474875
0.096995,46.3477995658969
0.097995,46.7146117867817
0.0989950000000001,47.090444990231
0.0999949999999999,47.3573685890053
0.100995,47.7751089150569
0.101995,48.0846095237031
0.102995,48.3714621448416
0.103995,48.7940689034964
0.104995,48.9911376225208
0.105995,49.3859242486522
0.106995,49.6634357845483
0.107995,50.0427367095703
0.108995,50.3611699566048
0.109995,50.5940430249929
0.110995,50.972757351284
0.111995,51.2461628815244
0.112995,51.5931981272322
0.113995,51.8568175942078
0.114995,52.1612149837303
0.115995,52.4818468073458
0.116995,52.7218092399202
0.117995,53.1163344159019
0.118995,53.3267561471413
0.119995,53.6635541538053
0.120995,53.921840232901
0.121995,54.2150371659535
0.122995,54.5058508328794
0.123995,54.795651529507
0.124995,55.0062317111106
0.125995,55.3209449946514
0.126995,55.5528563494506
0.127995,55.8523616765838
0.128995,56.1027795014266
0.129995,56.3614900816383
0.130995,56.6600038952871
0.131995,56.9260191209931
0.132995,57.1497045398372
0.133995,57.3985578798638
0.134995,57.7132913739026
0.135995,57.9103028115426
0.136995,58.1208913235721
0.137995,58.4049104476357
0.138995,58.6812494567042
0.139995,58.8918223596427
0.140995,59.1573961612787
0.141995,59.3754940895103
0.142995,59.6014679991952
0.143995,59.8206634837941
0.144995,60.091055490269
0.145995,60.2922132890386
0.146995,60.5372271248041
0.147995,60.7351611822122
0.148995,60.962936135343
0.149995,61.1463519363886
0.150995,61.3844078662748
0.151995,61.5966096818342
0.152995,61.8171655892509
0.153995,62.0345135497681
0.154995,62.2145805368728
0.155995,62.4150436928148
0.156995,62.6164485457263
0.157995,62.8061018184561
0.158995,63.0125071421533
0.159995,63.2238165445664
0.160995,63.3852058495081
0.161995,63.5964094589456
0.162995,63.8187633558713
0.163995,63.9874038896694
0.164995,64.1712487071453
0.165995,64.3622013271968
0.166995,64.5151442604143
0.167995,64.7457700469207
0.168995,64.9028066428174
0.169995,65.0953796374721
0.170995,65.2622374385267
0.171995,65.4248646631059
0.172995,65.5758464115294
0.173995,65.7568791828655
0.174995,65.9411358569637
0.175995,66.1143355750072
0.176995,66.2759838474668
0.177995,66.4492611164467
0.178995,66.592655166267
0.179995,66.7062972931981
0.180995,66.9021909833807
0.181995,67.0571069860966
0.182995,67.1523315211576
0.183995,67.3276455963505
0.184995,67.5268008434058
0.185995,67.669208628084
0.186995,67.770365082203
0.187995,67.9230272417831
0.188995,68.1412613190029
0.189995,68.2572647784808
0.190995,68.3636477232698
0.191995,68.5185875863127
0.192995,68.6632862845082
0.193995,68.7982109824096
0.194995,68.9280439555776
0.195995,69.0785164701659
0.196995,69.2424815902137
0.197995,69.3295716208433
0.198995,69.4756132970712
0.199995,69.611196709899
0.200995,69.762057093089
0.201995,69.8768292551832
0.202995,70.0063111373216
0.203995,70.1055301211859
0.204995,70.2327075021274
0.205995,70.3801414134715
0.206995,70.5001032194352
0.207995,70.6433022204974
0.208995,70.7410900881635
0.209995,70.8842886185645
0.210995,70.9531900696834
0.211995,71.1634797245845
0.212995,71.207265715736
0.213995,71.351556732486
0.214995,71.5600314934968
0.215995,71.5883242567413
0.216995,71.7739377003466
0.217995,71.8902001874022
0.218995,71.9868526891236
0.219995,72.0876690564712
0.220995,72.2404612913135
0.221995,72.3210779047031
0.222995,72.5101770485334
0.223995,72.5824866663147
0.224995,72.6750249329458
0.225995,72.8402714324035
0.226995,72.97326925394
0.227995,73.1130783335305
0.228995,73.2301359125557
0.229995,73.3199603781945
0.230995,73.4222355214279
0.231995,73.5272709668025
0.232995,73.7175442858384
0.233995,73.7822415582841
0.234995,73.8736571561731
0.235995,74.0645223043925
0.236995,74.1019077459348
0.237995,74.3190919823402
0.238995,74.4197935970642
0.239995,74.5026004421698
0.240995,74.7028763004007
0.241995,74.7502003392266
0.242995,74.9256108190233
0.243995,74.9968514450172
0.244995,75.109197604508
0.245995,75.2211654889713
0.246995,75.3529974872878
0.247995,75.6021690057239
0.248995,75.6563006555635
0.249995,75.7948652817739
0.250995,75.8986039400608
0.251995,76.1486137823644
0.252995,76.1964305025646
0.253995,76.3152457708791
0.254995,76.4236834055382
0.255995,76.5371190234566
0.256995,76.7729904129901
0.257995,76.8588921651016
0.258995,76.8733130011723
0.259995,77.1044221469793
0.260995,77.2162839336995
0.261995,77.4757681997513
0.262995,77.5266035233598
0.263995,77.561943980255
0.264995,77.7729381242579
0.265995,77.8880856025836
0.266995,78.1538440360228
0.267995,78.2444009394606
0.268995,78.5103404847483
0.269995,78.610449197105
0.270995,78.6710963932479
0.271995,78.9270794659755
0.272995,79.0149659645283
0.273995,79.1441770493148
0.274995,79.507520558831
0.275995,79.5364765225914
0.276995,79.7240490639428
0.277995,80.0318288016021
0.278995,80.1673436287437
0.279995,80.4289307402349
0.280995,80.5427860712626
0.281995,80.7902641314377
0.282995,80.7051151531952
0.283995,81.0395946972606
0.284995,81.0592509030694
0.285995,81.3527777614911
0.286995,81.4566737026073
0.287995,81.9658302177155
0.288995,82.010481056092
0.289995,82.4055646634623
0.290995,82.4467119531316
0.291995,82.8298269801199
0.292995,83.0090386895913
0.293995,83.3601491636842
0.294995,83.5317148425664
0.295995,83.9207348238174
0.296995,84.2341811186739
0.297995,84.3242306050197
0.298995,84.6273139934443
0.299995,85.1097005499268
0.300995,85.4103603238497
0.301995,85.5134785221685
0.302995,85.9218174490917
0.303995,86.3914431617466
0.304995,86.5161967058071
0.305995,86.8251824118648
0.306995,87.2714202721275
0.307995,87.690359945726
0.308995,88.2765849187226
0.309995,88.5252631643605
0.310995,88.7752219628644
0.311995,89.421646958382
0.312995,89.7913143273563
0.313995,90.1984318210791
0.314995,90.649373158541
0.315995,91.0825389811309
0.316995,91.5347855548622
0.317995,92.0450363704767
0.318995,92.72391925988
0.319995,93.00717109487
0.320995,93.6783222713276
0.321995,94.1283787607951
0.322995,94.7222004888286
0.323995,95.1080726316367
0.324995,95.8400119704574
0.325995,96.629968319982
0.326995,97.1190447750963
0.327995,97.5812131276565
0.328995,98.0399839185367
0.329995,98.8377463949604
0.330995,99.4748920526626
0.331995,100.202648220597
0.332995,100.625067532733
0.333995,101.398538770002
0.334995,101.978911447266
0.335995,102.613512660371
0.336995,103.600804169904
0.337995,104.013029612762
0.338995,104.584255301907
0.339995,105.397485639484
0.340995,105.985934840249
0.341995,106.956448730662
0.342995,107.686809063546
0.343995,108.492227455914
0.344995,109.305429539454
0.345995,109.883801025133
0.346995,110.701600376118
0.347995,111.50984696268
0.348995,112.232169559146
0.349995,113.113006303964
0.350995,114.018942315728
0.351995,114.957540517685
0.352995,115.520583703187
0.353995,116.213193284173
0.354995,117.209649101164
0.355995,118.045615767403
0.356995,118.894646616259
0.357995,119.814786401027
0.358995,120.611226994456
0.359995,121.061381371495
0.360995,122.524624343027
0.361995,123.100479952182
0.362995,123.862208721453
0.363995,124.803974781591
0.364995,125.685882886232
0.365995,126.736010184406
0.366995,127.877798790305
0.367995,128.531975329806
0.368995,129.649124938655
0.369995,130.679332610667
0.370995,131.741927513378
0.371995,132.650531253004
0.372995,133.786276086276
0.373995,134.756004862852
0.374995,135.956888507281
0.375995,137.092503127669
0.376995,138.13737286896
0.377995,139.35619317774
0.378995,140.385748168053
0.379995,141.309301899439
0.380995,142.417251125446
0.381995,143.856007032353
0.382995,145.108071303568
0.383995,146.147813228071
0.384995,147.467373873264
0.385995,148.645829198374
0.386995,149.627820863791
0.387995,150.621016650254
0.388995,144.588517231208
0.389995,133.41116272734
0.390995,124.832286341109
0.391995,118.006614050268
0.392995,111.807797328571
0.393995,105.940016513567
0.394995,100.024016369161
0.395995,94.3776623557562
0.396995,89.3650529207014
0.397995,84.8026393864626
0.398995,80.4163946163615
0.399995,76.4398085568968
0.400995,72.5822567044435
0.401995,69.029045756358
0.402995,65.7317701020213
0.403995,62.6900311876022
0.404995,59.8334754837583
0.405995,57.2450457985886
0.406995,54.9804774737272
0.407995,52.9422934265068
0.408995,51.1633998505919
0.409995,49.587108151449
0.410995,48.2065258133073
0.411995,46.9559786745243
0.412995,45.819498073988
0.413995,44.7594930187357
0.414995,43.7450855304434
0.415995,42.7863584374993
0.416995,41.8706782248503
0.417995,40.9712218431881
0.418995,40.0741905650983
0.419995,39.168292185312
0.420995,38.2697969656088
0.421995,37.4017561292365
0.422995,36.579703960798
0.423995,35.7855314034832
0.424995,35.0198535367599
0.425995,34.2540756375511
0.426995,33.4844145269329
0.427995,32.7389934935226
0.428995,31.9955123951844
0.429995,31.2105023140399
0.430995,30.3204363970165
0.431995,29.3344241930201
0.432995,28.2667428144463
0.433995,27.1139844342584
0.434995,25.8896075668385
0.435995,24.5675138820429
0.436995,23.1584887667591
0.437995,21.6581765970877
0.438995,20.0562183374331
0.439995,18.3479978194837
0.440995,16.5305913485698
0.441995,14.5978984020635
0.442995,12.5725021174857
0.443995,10.6617553311027
0.444995,8.79610847939763
0.445995,6.93161204304197
0.446995,5.06108215150517
0.447995,3.18618271149707
0.448995,1.32493394722679
0.449995,-0.535796543751182
0.450995,-2.4979640198568
0.451995,-4.73127410120481
0.452995,-7.20551537477658
0.453995,-9.90016536737595
0.454995,-12.8123905870296
0.455995,-15.9346931140298
0.456995,-19.246913934111
0.457995,-22.7033242241676
0.458995,-26.2085548727046
0.459995,-27.3420135798676
0.460995,-18.6078592809425
0.461995,-10.739545913298
0.462995,-6.07754925465416
0.463995,-4.40585801369629
0.464995,-4.32710424005896
0.465995,-2.77636045531182
0.466995,-1.77962323866785
0.467995,-0.982483571043589
0.468995,-0.750989371761638
0.469995,-0.161502831859432
0.470995,0.242848392503991
0.471995,-0.19774682304467
0.472995,-0.242198691049931
0.473995,-0.103543092112009
0.474995,-0.423017418730395
0.475995,-1.12712002681315
0.476995,-1.94590262493225
0.477995,-2.35694748900196
0.478995,-1.97753175120386
0.479995,-1.67556514096234
0.480995,-1.23218336513113
0.481995,-1.03943270704014
0.482995,-0.660466551913032
0.483995,-0.0770363339743879
0.484995,0.48029032472162
0.485995,0.56355784432301
0.486995,0.116064418937037
0.487995,-0.46550677235771
0.488995,-0.593681227896836
0.489995,-0.732766529308093
0.490995,-0.778226938324787
0.491995,-0.994730012346631
0.492995,-1.00911463294104
0.493995,-0.958832095898923
0.494995,-0.957418471923519
0.495995,-1.02407607851791
0.496995,-0.878254218510371
0.497995,-0.82452778989536
0.498995,-0.79751629758707
0.499995,-0.814578772356241
0.500995,-0.579147954824394
0.501995,-0.284059646787277
0.502995,-0.2020933019294
0.503995,-0.187413376906052
0.504995,-0.112562987561755
0.505995,-0.272403048710893
0.506995,-0.249997598886142
0.507995,-0.319029794660332
0.508995,-0.341036766590539
0.509995,-0.384494159938319
0.510995,-0.582044229671107
0.511995,-0.621159237019731
0.512995,-0.669947873150119
0.513995,-0.74887444672123
0.514995,-0.753585174574354
0.515995,-0.558938693754629
0.516995,-0.206828137872647
0.517995,0.110769807862593
0.518995,0.353563899600149
0.519995,0.537730199806006
0.520995,0.682200788307699
0.521995,0.918877105484044
0.522995,1.01723951772537
0.523995,1.03145617209811
0.524995,0.935346190810807
0.525995,0.931084634349037
0.526995,0.794455631704382
0.527995,0.691313797802652
0.528995,0.745780828061005
0.529995,0.738799685155285
0.530995,0.794178924948375
0.531995,0.882566475358964
0.532995,1.07978671030537
0.533995,1.39883002158215
0.534995,1.52943454558007
0.535995,1.54296759999122
0.536995,1.51397157265391
0.537995,1.41778240274626
0.538995,1.53049886051265
0.539995,1.24407132518218
0.540995,1.28574659945424
0.541995,1.07823588883427
0.542995,0.890173252923505
0.543995,0.872572546128092
0.544995,0.923535928610398
0.545995,0.68885936797299
0.546995,0.547323265382087
0.547995,0.400978785733937
0.548995,0.274807486967169
0.549995,0.207090213410201
0.550995,0.00290019568855582
0.551995,-0.215756418267017
0.552995,-0.243320857002245
0.553995,-0.456332875338449
0.554995,-1.04338877602125
0.555995,-1.25755668202627
0.556995,-1.29848864362013
0.557995,-1.21527318587945
0.558995,-1.32685913947688
0.559995,-1.43198943608572
0.560995,-1.4483616632869
0.561995,-1.50613697170033
0.562995,-1.35923469220593
0.563995,-1.28518181082042
0.564995,-0.968451588822148
0.565995,-0.814778079390994
0.566995,-0.813750185043873
0.567995,-0.725615717587007
0.568995,-0.221893685289463
0.569995,0.108434484714631
0.570995,0.398035426888327
0.571995,0.582323560068384
0.572995,0.99535497247612
0.573995,1.32450676465945
0.574995,1.51615002747391
0.575995,1.63155279907791
0.576995,1.74634219461091
0.577995,1.74242849657645
0.578995,1.65064013452656
0.579995,1.45288071451593
0.580995,1.56557075248033
0.581995,1.58722543528209
0.582995,1.45419256483107
0.583995,1.30745548094181
0.584995,1.13959091952238
0.585995,0.919981235812121
0.586995,0.621452301279085
0.587995,0.350136525168775
0.588995,-0.110467308754433
0.589995,-0.569407184079425
0.590995,-0.879271997179518
0.591995,-1.26478352293354
0.592995,-1.54133148465089
0.593995,-1.83563747790702
0.594995,-2.03138210890889
0.595995,-2.03875730367712
0.596995,-2.00514278779011
0.597995,-1.89662081704116
0.598995,-1.91126186447868
0.599995,-1.88460668027149
0.600995,-1.63662513175946
0.601995,-1.41343955159237
0.602995,-1.08872976307308
0.603995,-0.860124321513392
0.604995,-0.577616412067857
0.605995,-0.210150062389893
0.606995,0.267124020911426
0.607995,0.700735028415472
0.608995,1.1304106451778
0.609995,1.55813359427737
0.610995,1.951418646795
0.611995,1.9908681426632
0.612995,2.08126828450166
0.613995,2.27816192605343
0.614995,2.41589743081338
0.615995,2.4347220596459
0.616995,2.4100224654942
0.617995,2.17796964088054
0.618995,1.88372575270921
0.619995,1.61071884289931
0.620995,1.2956252568262
0.621995,0.957700401661662
0.622995,0.546351934907062
0.623995,0.17152979908747
0.624995,-0.214863076151085
0.625995,-0.621521886024545
0.626995,-0.968953415310586
0.627995,-1.44020678808996
0.628995,-1.8927827111499
0.629995,-2.28321310890657
0.630995,-2.53972083547898
0.631995,-2.65410517341604
0.632995,-2.70342157502216
0.633995,-2.62144174960797
0.634995,-2.3995445254024
0.635995,-2.13039370770338
0.636995,-1.95896617931696
0.637995,-1.67146670324814
0.638995,-1.36698558154865
0.639995,-1.13411580488525
0.640995,-0.953972693027427
0.641995,-0.68604366473841
0.642995,-0.381057674790251
0.643995,0.0202137415765381
0.644995,0.278438717572306
0.645995,0.603862453468125
0.646995,0.962383538344375
0.647995,1.36231561964012
0.648995,1.58828126975049
0.649995,1.67827387396244
0.650995,1.82219505760525
0.651995,1.89369075772477
0.652995,1.8726815483837
0.653995,1.91333698723109
0.654995,1.98807578431677
0.655995,1.92403960880118
0.656995,1.89821585670394
0.657995,1.82503489368575
0.658995,1.77367957732124
0.659995,1.77735461456152
0.660995,1.7322201740654
0.661995,1.47934737862513
0.662995,1.23334732037919
0.663995,0.860822077423077
0.664995,0.418654288501107
0.665995,0.00266693310200221
0.666995,-0.400558709251572
0.667995,-0.93300698707311
0.668995,-1.40401013213425
0.669995,-1.72990406713382
0.670995,-1.87204814393304
0.671995,-1.99008906746931
0.672995,-2.07074669216827
0.673995,-2.10776926237518
0.674995,-2.0877361941166
0.675995,-2.04799735519697
0.676995,-1.93869852712973
0.677995,-1.84085631876105
0.678995,-1.69582343016538
0.679995,-1.63157266482934
0.680995,-1.58523519933016
0.681995,-1.43773597840974
0.682995,-1.25007913534907
0.683995,-0.938017703111614
0.684995,-0.358482453503936
0.685995,0.0551077006482242
0.686995,0.511242282203555
0.687995,1.02309252632096
0.688995,1.42371657169588
0.689995,1.73543063717159
0.690995,1.98111902652658
0.691995,2.16532938711578
0.692995,2.24734354522947
0.693995,2.25690846955183
0.694995,2.15094820249217
0.695995,2.05132363374713
0.696995,1.86854153945998
0.697995,1.80545202610633
0.698995,1.64296542378667
0.699995,1.50551124695951
0.700995,1.32301418979815
0.701995,1.05002256422418
0.702995,0.755775217305063
0.703995,0.377168278340641
0.704995,-0.04965882907587
0.705995,-0.570906407779744
0.706995,-0.93726686034668
0.707995,-1.4550225281872
0.708995,-1.96411670318003
0.709995,-2.26646351482625
0.710995,-2.42245070728336
0.711995,-2.50855252378533
0.712995,-2.52482448244277
0.713995,-2.50920803420053
0.714995,-2.35768570972035
0.715995,-2.21331334589461
0.716995,-1.90223632170243
0.717995,-1.64456046615625
0.718995,-1.37452522612187
0.719995,-1.13530816575337
0.720995,-0.878790973902274
0.721995,-0.518338407551202
0.722995,-0.194286893605818
0.723995,0.178810394853279
0.724995,0.564832219263146
0.725995,0.937122364026009
0.726995,1.08388641565098
0.727995,1.38340837583533
0.728995,1.53153844587119
0.729995,1.64187800910775
0.730995,1.77824606075971
0.731995,1.74191650986069
0.732995,1.78340014080471
0.733995,1.68361160682015
0.734995,1.73545976509259
0.735995,1.67555206928163
0.736995,1.67969360673924
0.737995,1.64177900674729
0.738995,1.66679228723948
0.739995,1.4986391138355
0.740995,1.37287170768309
0.741995,1.01751731908701
0.742995,0.692137356068898
0.743995,0.421148588153525
0.744995,0.010606619073307
0.745995,-0.361978073632424
0.746995,-0.750924893056459
0.747995,-1.03303001968254
0.748995,-1.30094640946349
0.749995,-1.48031817164369
0.750995,-1.65515476570927
0.751995,-1.63792553135234
0.752995,-1.60651215392494
0.753995,-1.58125672497211
0.754995,-1.65202616448224
0.755495,-1.6544959145675