File: DATA&scripts/1.7-data/z0/15/15_fracture_stress_data.csv
Strain,Fracture Stress (GPa)
-1.56278871039692e-16,0.383004693726992
0.000494999999999708,0.815339555464977
0.000994999999999977,1.21834781079309
0.00149499999999993,1.5982747606959
0.00199499999999989,1.739962651144
0.00249499999999985,2.31856107074511
0.00299499999999981,2.31539579786751
0.00349499999999976,2.84105721338454
0.00399499999999972,2.99213552729144
0.00449499999999983,3.32336764470921
0.00499499999999995,3.7130216388914
0.00549499999999991,3.90893245387457
0.00599499999999986,4.24298392107493
0.00649499999999982,4.60426693867266
0.00699499999999978,4.86302416812198
0.00749499999999973,5.1811379527988
0.00799499999999969,5.47908240083887
0.00849499999999996,5.83926884386279
0.00899499999999992,6.00813332773527
0.00949499999999988,6.44692440478704
0.00999499999999983,6.72628934076204
0.0104949999999998,6.91565738594764
0.0109949999999997,7.3423841761544
0.0114949999999997,7.55284822397112
0.011995,7.85322794834498
0.0124949999999999,8.11571230469498
0.0129949999999999,8.49421449870496
0.0134949999999998,8.7140461791355
0.0139949999999998,8.94714975573926
0.0144949999999998,9.28663795439185
0.0149949999999997,9.59391711232417
0.0154949999999998,9.8499187168962
0.0159949999999999,10.1198902316774
0.0164949999999999,10.3976152450064
0.0169949999999999,10.7887533440571
0.0174949999999998,10.9658679817088
0.0179949999999998,11.2484118805262
0.0184949999999997,11.5247823002384
0.0189949999999997,11.8336138233865
0.019495,12.1698548079696
0.0199949999999999,12.2455937965138
0.0204949999999999,12.5736148675207
0.0209949999999998,12.9131389752754
0.0214949999999998,13.208935335736
0.0219949999999997,13.4995597559595
0.0224949999999997,13.6355526078301
0.022995,13.9269437764394
0.0234949999999999,14.2202463634893
0.0239949999999999,14.5226825706089
0.0244949999999998,14.8219746241957
0.0249949999999998,15.0429077999596
0.0254949999999998,15.3775001216813
0.0259949999999997,15.5447933085526
0.0264949999999998,15.8165776424135
0.0269949999999999,16.0992877389079
0.0274949999999999,16.2520789627415
0.0279949999999999,16.6945998628928
0.0284949999999998,16.8492618076097
0.0289949999999998,17.1819348211195
0.0294949999999997,17.3890679914447
0.0299949999999997,17.549587603128
0.030495,17.8786845348799
0.0309949999999999,18.0979733513096
0.0314949999999999,18.3985342115633
0.0319949999999998,18.6922186669685
0.0324949999999998,18.921441916698
0.0329949999999997,19.1939961623067
0.0334949999999997,19.3155400150026
0.033995,19.6296546903469
0.0344949999999999,19.861020083348
0.0349949999999999,20.1701565983654
0.0354949999999998,20.4681673929396
0.0359949999999998,20.6802526542797
0.0364949999999998,20.979460982771
0.0369949999999997,21.14911765801
0.0374949999999997,21.3987873935632
0.0379949999999999,21.6518487783051
0.0384949999999999,21.8406572102401
0.0389949999999999,22.140668235388
0.0394949999999998,22.3352732711265
0.0399949999999998,22.65295420562
0.0404949999999997,22.9374455485853
0.0409949999999997,23.1317056709601
0.041495,23.4687180101732
0.0419949999999999,23.6592638821407
0.0424949999999999,23.9059666534121
0.0429949999999998,24.0951950172769
0.0434949999999998,24.2484161462294
0.0439949999999997,24.4654192091197
0.0444949999999997,24.7198280672146
0.044995,25.006579159931
0.0454949999999999,25.2286899524337
0.0459949999999999,25.4938524129052
0.0464949999999998,25.776624583825
0.0469949999999998,25.9624160163261
0.0474949999999998,26.2356072901877
0.0479949999999997,26.5058301117758
0.048495,26.6962812893274
0.0489949999999999,26.9743392900433
0.0494949999999999,27.1709062005737
0.0499949999999999,27.436565600808
0.0504949999999998,27.6864917456535
0.0509949999999998,27.8600640955718
0.0514949999999997,28.1290459604812
0.0519949999999997,28.3450319469424
0.052495,28.5697978563723
0.0529949999999999,28.7752952539329
0.0534949999999999,28.9789393461321
0.0539949999999998,29.254269581899
0.0544949999999998,29.48941038549
0.0549949999999997,29.6471371150021
0.0554949999999997,29.8690026121672
0.055995,30.0569367625048
0.0564949999999999,30.2932518993029
0.0569949999999999,30.4827329517624
0.0574949999999998,30.7235498773024
0.0579949999999998,30.9327428137602
0.0584949999999997,31.1780316407036
0.0589949999999997,31.4335729563585
0.0594949999999997,31.6260639465468
0.0599949999999999,31.8496732346583
0.0604949999999999,32.0766682002481
0.0609949999999998,32.2818978938967
0.0614949999999998,32.5203027644597
0.0619949999999998,32.7302948284604
0.0624949999999997,32.9739196399242
0.0629949999999997,33.1258317990674
0.063495,33.3806643441687
0.0639949999999999,33.5606782011057
0.0644949999999999,33.7854170697213
0.0649949999999998,33.9733930729227
0.0654949999999998,34.1997973482067
0.0659949999999997,34.4313156113097
0.0664949999999997,34.6371925041227
0.066995,34.8978449749894
0.0674949999999999,35.0948454664446
0.0679949999999999,35.2870216907349
0.0684949999999998,35.5285450202049
0.0689949999999998,35.7542529571516
0.0694949999999998,35.9720663194524
0.0699949999999997,36.1929821170994
0.0704949999999997,36.3897435495385
0.0709949999999999,36.5853783748544
0.0714949999999999,36.7978794506035
0.0719949999999999,36.9784359473089
0.0724949999999998,37.2282248887793
0.0729949999999998,37.3594314518989
0.0734949999999997,37.6066575551937
0.0739949999999997,37.7536742235058
0.074495,37.9701483299441
0.0749949999999999,38.1649532886223
0.0754949999999999,38.3614231623506
0.0759949999999998,38.5974390540864
0.0764949999999998,38.7930187326437
0.0769949999999997,39.0068745290585
0.0774949999999997,39.2629257818018
0.077995,39.4107930437767
0.0784949999999999,39.6231839742243
0.0789949999999999,39.7834403827287
0.0794949999999998,39.9541470929181
0.0799949999999998,40.1363819817176
0.0804949999999997,40.3037387706336
0.0809949999999997,40.5351322483134
0.0814949999999997,40.6987088221449
0.0819949999999999,40.9244034897785
0.0824949999999999,41.188275409589
0.0829949999999998,41.3385334965473
0.0834949999999998,41.5627962713897
0.0839949999999998,41.6939414744857
0.0844949999999997,41.87923223419
0.0849949999999997,42.0442721930518
0.0854949999999999,42.2257359993354
0.0859949999999999,42.4425187384018
0.0864949999999999,42.6193182076223
0.0869949999999998,42.8320313211915
0.0874949999999998,43.0328549755762
0.0879949999999997,43.1765793341972
0.0884949999999997,43.3610636985658
0.0889949999999998,43.4947777896786
0.0894949999999999,43.7321361862001
0.0899949999999999,43.9265906571848
0.0904949999999998,44.0843203712374
0.0909949999999998,44.3114182862593
0.0914949999999997,44.4548066154313
0.0919949999999997,44.6070550670676
0.0924949999999997,44.8337478551547
0.0929949999999999,44.957536046075
0.0934949999999999,45.160155596499
0.0939949999999998,45.3185329246214
0.0944949999999998,45.531727640949
0.0949949999999998,45.7098316700138
0.0954949999999997,45.8569992016307
0.0959949999999997,46.0207216835074
0.0964949999999999,46.2209681591645
0.0969949999999999,46.4299033680752
0.0974949999999999,46.5782003368726
0.0979949999999998,46.6771859454203
0.0984949999999998,46.8725934732055
0.0989949999999997,47.0751469608686
0.0994949999999997,47.2927441915696
0.099995,47.4494990067522
0.100495,47.5393288411136
0.100995,47.7533774989351
0.101495,47.8953254666602
0.101995,48.0899349743584
0.102495,48.303115127403
0.102995,48.3853046423311
0.103495,48.570530839795
0.103995,48.7124209741175
0.104495,48.8878669207092
0.104995,49.0907234184466
0.105495,49.2104996466156
0.105995,49.3638314029372
0.106495,49.5118064579214
0.106995,49.703055416136
0.107495,49.8922227405696
0.107995,49.9962280012098
0.108495,50.1423432293435
0.108995,50.3346529334227
0.109495,50.4978939911126
0.109995,50.6185996231536
0.110495,50.7479790024969
0.110995,50.9700105523529
0.111495,51.1306813020544
0.111995,51.2310151871572
0.112495,51.371956132469
0.112995,51.5691403140846
0.113495,51.7494950887937
0.113995,51.8187863016897
0.114495,52.0166780671988
0.114995,52.2522588074437
0.115495,52.3110610672108
0.115995,52.4266800781273
0.116495,52.6421978909261
0.116995,52.8142051431492
0.117495,52.9133788700296
0.117995,53.0163925177904
0.118495,53.2433910450124
0.118995,53.3818911316264
0.119495,53.4401572462378
0.119995,53.6425490655978
0.120495,53.8321187256306
0.120995,53.8977251125041
0.121495,54.0473563369535
0.121995,54.2522581380566
0.122495,54.3632856189768
0.122995,54.4285975988675
0.123495,54.6524551822826
0.123995,54.8067643328626
0.124495,54.8236094269506
0.124995,55.0329533047976
0.125495,55.2371956109398
0.125995,55.273686633125
0.126495,55.4479746025395
0.126995,55.6090134808567
0.127495,55.6995083696172
0.127995,55.8515368239472
0.128495,56.0367936807234
0.128995,56.0974548878644
0.129495,56.2411477486228
0.129995,56.3820068084317
0.130495,56.5073850485774
0.130995,56.6553813834211
0.131495,56.8075593707498
0.131995,56.9123157466678
0.132495,57.0287583377424
0.132995,57.1806287784656
0.133495,57.2867617756936
0.133995,57.4234279948654
0.134495,57.5537209783613
0.134995,57.6984967566072
0.135495,57.7839480342356
0.135995,57.8927354820137
0.136495,58.0536162802337
0.136995,58.1849356534638
0.137495,58.2748565193885
0.137995,58.4583046544316
0.138495,58.5317148235083
0.138995,58.6248389568383
0.139495,58.7908095480498
0.139995,58.8753150930568
0.140495,59.0288049094637
0.140995,59.1387781488725
0.141495,59.2449753861875
0.141995,59.3844736616514
0.142495,59.4855437411244
0.142995,59.5904344555872
0.143495,59.7405222872947
0.143995,59.8202186170954
0.144495,59.9711338005513
0.144995,60.0533815194388
0.145495,60.1773299534429
0.145995,60.3080320459166
0.146495,60.3904768644193
0.146995,60.5243117555607
0.147495,60.5999589048622
0.147995,60.7585125909806
0.148495,60.867151975446
0.148995,60.9381349360909
0.149495,61.0822426982541
0.149995,61.1343610323691
0.150495,61.3032457762189
0.150995,61.3750939002768
0.151495,61.4972948933441
0.151995,61.5964136050503
0.152495,61.7341301985665
0.152995,61.8097681911947
0.153495,61.9103520177028
0.153995,62.0097976448545
0.154495,62.0918024007597
0.154995,62.210457759497
0.155495,62.3425642656635
0.155995,62.4269437779531
0.156495,62.526747558536
0.156995,62.6335133721001
0.157495,62.7123741082075
0.157995,62.841173951532
0.158495,62.9398295124663
0.158995,63.0225807671064
0.159495,63.1064707008362
0.159995,63.2169412832353
0.160495,63.3229737960084
0.160995,63.4429601106807
0.161495,63.4923706361686
0.161995,63.5927771319434
0.162495,63.7058119744087
0.162995,63.7985879276994
0.163495,63.9184936809631
0.163995,63.9814100557875
0.164495,64.0879107214974
0.164995,64.1531369797159
0.165495,64.2776798136996
0.165995,64.3913349837439
0.166495,64.4658022280641
0.166995,64.5653362581722
0.167495,64.6432846105029
0.167995,64.7339466811484
0.168495,64.8449612416683
0.168995,64.8958277485315
0.169495,64.9937957742688
0.169995,65.1114185143986
0.170495,65.1379668538315
0.170995,65.2603836248945
0.171495,65.3283829361308
0.171995,65.4450332894802
0.172495,65.529208610318
0.172995,65.5876175009117
0.173495,65.7015868728621
0.173995,65.7433842555698
0.174495,65.8477171538225
0.174995,65.941119484349
0.175495,66.019172830422
0.175995,66.0815052934968
0.176495,66.1680375839083
0.176995,66.2513922848555
0.177495,66.3176754553267
0.177995,66.4140066373333
0.178495,66.4986571312603
0.178995,66.58382828739
0.179495,66.6607165626438
0.179995,66.7155121874406
0.180495,66.8046348329373
0.180995,66.8992044355274
0.181495,66.9491955127324
0.181995,67.038238814791
0.182495,67.1327256315905
0.182995,67.2180032745801
0.183495,67.252744686807
0.183995,67.3833459249445
0.184495,67.4471913594442
0.184995,67.4812166622076
0.185495,67.5762324822175
0.185995,67.63664736587
0.186495,67.7192070663304
0.186995,67.8286167562406
0.187495,67.8929344089454
0.187995,67.9047398411714
0.188495,68.0192845298569
0.188995,68.0878065862251
0.189495,68.1849685889083
0.189995,68.2226490523396
0.190495,68.3402792380749
0.190995,68.3976303413221
0.191495,68.4514880021275
0.191995,68.5533941274829
0.192495,68.6183566758554
0.192995,68.637546013556
0.193495,68.7085223184212
0.193995,68.8122100742639
0.194495,68.8877830020109
0.194995,68.9757064388071
0.195495,68.9957699380322
0.195995,69.0688418694977
0.196495,69.1393828591351
0.196995,69.1993480085149
0.197495,69.2714493332079
0.197995,69.3293257941684
0.198495,69.3944112317096
0.198995,69.4455854574376
0.199495,69.4902576391374
0.199995,69.5937288725071
0.200495,69.6742896759238
0.200995,69.7243199488523
0.201495,69.8259376377063
0.201995,69.8583308390922
0.202495,69.9559731602897
0.202995,69.9668338135219
0.203495,70.0472656277918
0.203995,70.172842917065
0.204495,70.184357681076
0.204995,70.2397540152696
0.205495,70.3378564257686
0.205995,70.3620471572442
0.206495,70.4435441675132
0.206995,70.5074577891669
0.207495,70.5784366085013
0.207995,70.6041384257576
0.208495,70.6967051727518
0.208995,70.7429302356245
0.209495,70.8118271312857
0.209995,70.9477502624661
0.210495,71.0116091123043
0.210995,71.0453493496893
0.211495,71.1088219292254
0.211995,71.106116656537
0.212495,71.2243669443444
0.212995,71.2846192883206
0.213495,71.3184550644868
0.213995,71.3836294608834
0.214495,71.4464940450698
0.214995,71.4613615719488
0.215495,71.5849883158525
0.215995,71.6396906151273
0.216495,71.7137832447834
0.216995,71.768789495041
0.217495,71.8277688395518
0.217995,71.8956932702897
0.218495,71.9204787589026
0.218995,71.9788483141701
0.219495,72.0463865708797
0.219995,72.0881370662905
0.220495,72.181123451157
0.220995,72.2532894331967
0.221495,72.2388396853318
0.221995,72.3055524282508
0.222495,72.4197377073879
0.222995,72.4744729979139
0.223495,72.5337972244254
0.223995,72.5769799065065
0.224495,72.6764664906784
0.224995,72.748654069321
0.225495,72.7883497905601
0.225995,72.8743233615733
0.226495,72.9186251198392
0.226995,72.9649997639805
0.227495,73.0259088767968
0.227995,73.0274293156467
0.228495,73.1864562301009
0.228995,73.2091682141911
0.229495,73.2552547768135
0.229995,73.2848447275148
0.230495,73.3149538428573
0.230995,73.3874923319289
0.231495,73.4566972107284
0.231995,73.6514277849448
0.232495,73.5287365938682
0.232995,73.6355251422236
0.233495,73.63809915447
0.233995,73.7787950656074
0.234495,73.9470632348288
0.234995,73.9449888532585
0.235495,73.9566524082203
0.235995,74.062509152788
0.236495,74.1268403369635
0.236995,74.2076457959109
0.237495,74.2022077261136
0.237995,74.2988654203587
0.238495,74.2863549072784
0.238995,74.3848929823423
0.239495,74.4546483137872
0.239995,74.5692101525754
0.240495,74.5856213133287
0.240995,74.5581118891685
0.241495,74.6777891452693
0.241995,74.7027371376318
0.242495,74.9011052914813
0.242995,74.9480197236207
0.243495,75.0053872391688
0.243995,75.0157703887882
0.244495,75.0161253817724
0.244995,75.1280827288673
0.245495,75.1388070549984
0.245995,75.2801986389696
0.246495,75.4240943099917
0.246995,75.4459562855922
0.247495,75.4685155265172
0.247995,75.5252457049942
0.248495,75.6119162934236
0.248995,75.6432793296266
0.249495,75.8294989810072
0.249995,75.8288996328047
0.250495,75.8293677648228
0.250995,75.9362031807641
0.251495,75.9879951555329
0.251995,76.0090196928114
0.252495,76.2125127414919
0.252995,76.2453375928961
0.253495,76.3428223010917
0.253995,76.2566151099224
0.254495,76.3519185828711
0.254995,76.4553861851407
0.255495,76.4263780166685
0.255995,76.5362829566208
0.256495,76.6117791896562
0.256995,76.697191007893
0.257495,76.7871565020271
0.257995,76.8082773543167
0.258495,76.8330266719712
0.258995,77.0204076855544
0.259495,77.0957372479126
0.259995,77.2609765878457
0.260495,77.1930280337391
0.260995,77.1570929733102
0.261495,77.3168577534409
0.261995,77.3627701128851
0.262495,77.4619253453309
0.262995,77.5538698085846
0.263495,77.6327862942952
0.263995,77.6768272629584
0.264495,77.7803530666441
0.264995,77.9054854635275
0.265495,77.8594889015547
0.265995,77.9416845592033
0.266495,78.0439329405828
0.266995,78.0658081425548
0.267495,78.218227285978
0.267995,78.1988174258768
0.268495,78.2428734992483
0.268995,78.3912622479701
0.269495,78.4709981944339
0.269995,78.5466350071709
0.270495,78.7251667723147
0.270995,78.7075124620532
0.271495,78.7274604008505
0.271995,78.8749594793497
0.272495,78.9236421174805
0.272995,78.9635900796171
0.273495,79.0879561959912
0.273995,79.2095055493588
0.274495,79.3523140017917
0.274995,79.3191125492418
0.275495,79.4885643114053
0.275995,79.4199025063071
0.276495,79.6208465601131
0.276995,79.7389601620919
0.277495,79.7430844588957
0.277995,79.9883658748193
0.278495,79.9830510913206
0.278995,80.0828306557486
0.279495,80.1764342359108
0.279995,80.3506770295578
0.280495,80.3363634433956
0.280995,80.5165600316247
0.281495,80.4775261472984
0.281995,80.6969124839371
0.282495,80.7308764563781
0.282995,80.6992817650782
0.283495,80.9682624934417
0.283995,80.9061515486842
0.284495,81.1589729130629
0.284995,81.2138198296507
0.285495,81.4005286693274
0.285995,81.4477826981618
0.286495,81.672965193874
0.286995,81.7335078972956
0.287495,81.9818808774024
0.287995,81.7491302398934
0.288495,82.0193772148648
0.288995,82.1076724130217
0.289495,82.2029041905758
0.289995,82.42012890588
0.290495,82.4230213253885
0.290995,82.6204413982621
0.291495,82.6982612475012
0.291995,82.7741867055697
0.292495,83.0138275571621
0.292995,82.932643401544
0.293495,83.1700849158059
0.293995,83.0524782422061
0.294495,83.5346271972284
0.294995,83.423018731429
0.295495,83.8038166730574
0.295995,83.9516836927942
0.296495,84.030731395267
0.296995,83.9919438050317
0.297495,84.2038547618529
0.297995,84.3729665029276
0.298495,84.5899785583996
0.298995,84.7181822778622
0.299495,84.7356367787609
0.299995,85.2743479884453
0.300495,84.9468840215328
0.300995,85.2322733616561
0.301495,85.4131203051707
0.301995,85.5397904409933
0.302495,85.8911957967343
0.302995,85.859164075923
0.303495,86.0245960369073
0.303995,86.1954900785401
0.304495,86.3759315687324
0.304995,86.6969286282603
0.305495,86.7692804430387
0.305995,87.0746756089612
0.306495,87.2561418741928
0.306995,87.2014733782762
0.307495,87.4920937969435
0.307995,87.7129591636781
0.308495,87.7288847596061
0.308995,88.543318851427
0.309495,88.2983565276999
0.309995,88.5573283693083
0.310495,88.5939000420679
0.310995,89.025738871143
0.311495,89.13419979802
0.311995,89.0608746311195
0.312495,89.6615431153563
0.312995,89.9159575986823
0.313495,90.000625449376
0.313995,90.0991660126839
0.314495,90.2646651744219
0.314995,90.894773082539
0.315495,90.7373305876053
0.315995,91.0756767534551
0.316495,91.4883267392108
0.316995,91.7002536731717
0.317495,91.6206415709289
0.317995,92.1744923354806
0.318495,92.4251123671033
0.318995,92.9160180745244
0.319495,92.7912134567189
0.319995,93.0534815231188
0.320495,93.5585496745997
0.320995,93.4990466470484
0.321495,94.0307285319989
0.321995,94.1560427628348
0.322495,94.5174149862874
0.322995,94.5357374990899
0.323495,94.9066629791995
0.323995,95.272791049154
0.324495,95.4146992568803
0.324995,96.1314552154204
0.325495,96.1782531733711
0.325995,96.3254579623822
0.326495,96.8599341074954
0.326995,97.012730258893
0.327495,97.3288678910429
0.327995,97.6065045023815
0.328495,97.9523049125481
0.328995,98.315576875504
0.329495,98.5619629342992
0.329995,98.7981482678744
0.330495,99.300386076967
0.330995,99.3475504538138
0.331495,99.7953077379748
0.331995,100.165431930841
0.332495,100.401733243452
0.332995,100.833381107547
0.333495,101.040547560369
0.333995,101.583453414107
0.334495,101.764391645607
0.334995,102.261084117164
0.335495,102.40186823804
0.335995,103.095180999907
0.336495,102.781492548649
0.336995,103.73124979134
0.337495,103.797132772242
0.337995,104.212052362262
0.338495,104.686488649402
0.338995,104.633344131848
0.339495,105.346464603932
0.339995,105.651451899383
0.340495,105.67741874418
0.340995,106.550298276413
0.341495,106.508979980701
0.341995,107.277824490358
0.342495,107.181390919892
0.342995,107.82100313246
0.343495,108.109628706282
0.343995,108.582275003637
0.344495,108.784546673386
0.344995,109.313380389308
0.345495,109.841316374761
0.345995,110.082357298425
0.346495,110.276997019762
0.346995,110.678440337933
0.347495,111.30093553677
0.347995,111.60137399942
0.348495,111.973555303176
0.348995,112.528068116601
0.349495,112.532129280769
0.349995,113.195443639225
0.350495,113.700580543723
0.350995,113.952961605183
0.351495,114.429705759014
0.351995,114.739788897596
0.352495,115.415947864443
0.352995,115.458229310305
0.353495,116.013851368957
0.353995,116.197716649975
0.354495,116.399800664253
0.354995,117.398885462616
0.355495,117.420441144362
0.355995,118.006805327877
0.356495,118.385676078019
0.356995,118.562112773922
0.357495,119.494074749135
0.357995,119.669064054832
0.358495,119.942578141414
0.358995,120.616952379479
0.359495,121.028847985969
0.359995,121.236868849093
0.360495,121.712836255181
0.360995,122.242469023511
0.361495,122.727497275238
0.361995,122.882724599115
0.362495,123.492345301968
0.362995,124.093874032804
0.363495,124.30806860595
0.363995,124.982051129367
0.364495,125.431035228324
0.364995,126.027336303872
0.365495,126.44591738387
0.365995,126.466061719149
0.366495,127.095675187852
0.366995,127.813598316779
0.367495,128.119133245082
0.367995,128.937413508684
0.368495,129.144735227803
0.368995,129.823386919098
0.369495,129.970095296959
0.369995,130.258147024274
0.370495,130.738635164641
0.370995,131.394018676932
0.371495,132.433088683083
0.371995,133.087659675331
0.372495,133.090262235491
0.372995,133.633896639223
0.373495,133.953928519197
0.373995,134.887020302844
0.374495,135.521687664784
0.374995,136.011784007864
0.375495,136.586704282389
0.375995,136.739302185247
0.376495,137.632645209239
0.376995,138.487226833525
0.377495,138.756242048399
0.377995,139.47247130239
0.378495,139.994912413252
0.378995,140.263133237659
0.379495,141.051520289147
0.379995,141.334386080743
0.380495,142.086060115256
0.380995,142.767288217798
0.381495,143.39555813602
0.381995,143.977522753808
0.382495,144.581426254747
0.382995,145.33350553664
0.383495,145.494576460477
0.383995,145.851479141106
0.384495,146.341325287517
0.384995,147.16805438473
0.385495,147.704871624623
0.385995,148.245734463629
0.386495,148.850520079429
0.386995,149.619133853368
0.387495,149.96755768026
0.387995,150.558893525958
0.388495,151.426693730986
0.388995,151.861982224224
0.389495,152.497605950687
0.389995,153.120204066487
0.390495,151.582557681822
0.390995,146.522201581284
0.391495,137.190668024988
0.391995,126.92812435405
0.392495,114.89907574116
0.392995,104.48234919701
0.393495,95.401540388613
0.393995,87.6412011698346
0.394495,80.6686023748389
0.394995,74.5182435736462
0.395495,69.2036788585752
0.395995,65.0320286955511
0.396495,61.1889991924841
0.396995,57.61794125234
0.397495,54.2950467212336
0.397995,51.1738715771504
0.398495,48.396004392305
0.398995,45.8955953107488
0.399495,43.7599396941872
0.399995,41.9298366151449
0.400495,40.3525331369314
0.400995,38.8665207041989
0.401495,37.2325037761615
0.401995,35.5350633364806
0.402495,33.7596980006844
0.402995,31.9244163688756
0.403495,30.0645476568469
0.403995,28.1486641954792
0.404495,26.2304246469196
0.404995,24.4390324263325
0.405495,22.8548767204482
0.405995,21.5236358310429
0.406495,20.3082441872653
0.406995,19.196912203146
0.407495,18.1604873383497
0.407995,17.2100228525158
0.408495,16.3857356145225
0.408995,15.6196517183636
0.409495,14.7976483257411
0.409995,13.9677454080616
0.410495,13.1437926877468
0.410995,12.3008524134676
0.411495,11.4175464604565
0.411995,10.4644099104708
0.412495,9.40902886980837
0.412995,8.23680915816456
0.413495,6.95717838417872
0.413995,5.56337299379758
0.414495,4.04564377422128
0.414995,2.38325655961094
0.415495,0.667445606599748
0.415995,-0.918290187108723
0.416495,-2.39632480177945
0.416995,-4.13170417048791
0.417495,-6.03975627956062
0.417995,-8.11029705049799
0.418495,-10.4165581222394
0.418995,-12.9132436645899
0.419495,-15.5470909576122
0.419995,-15.7964957210757
0.420495,-15.0963248803181
0.420995,-13.0434748339399
0.421495,-11.0902368455905
0.421995,-9.45007088487025
0.422495,-6.42465251396263
0.422995,-3.65449240832641
0.423495,-1.91576286901332
0.423995,-0.54802431455552
0.424495,0.533406107789482
0.424995,1.26089563462905
0.425495,1.426074370906
0.425995,1.48778404208855
0.426495,1.01298671525511
0.426995,0.55894244215194
0.427495,-0.243129338340547
0.427995,-0.886810094710152
0.428495,-1.18796162974757
0.428995,-1.61654982902617
0.429495,-1.66281725790974
0.429995,-0.830918925426165
0.430495,-0.353950196448871
0.430995,0.191090901480364
0.431495,0.802800643228019
0.431995,0.864301082991349
0.432495,0.853505554044409
0.432995,0.331007039827364
0.433495,0.0443132125288678
0.433995,-0.66243768345715
0.434495,-0.943390097062091
0.434995,-1.27164747029948
0.435495,-1.36480419804471
0.435995,-1.41385747902581
0.436495,-1.26941369374478
0.436995,-1.323639092726
0.437495,-1.47467202996291
0.437995,-1.29145248965626
0.438495,-1.41655577264624
0.438995,-1.1368043479054
0.439495,-1.37482568567273
0.439995,-1.21883778070247
0.440495,-1.22196535507558
0.440995,-1.20169651230201
0.441495,-1.11197864801474
0.441995,-0.951811434503738
0.442495,-0.481216083241093
0.442995,-0.210144195022071
0.443495,-0.17050082357566
0.443995,-0.0430498191937714
0.444495,0.194972658883976
0.444995,0.404615886617258
0.445495,0.395069287191972
0.445995,0.504047534220652
0.446495,0.400060159578898
0.446995,0.724161165023975
0.447495,0.713821351031607
0.447995,0.781937536464092
0.448495,0.406853574189595
0.448994999999999,0.423326557275611
0.449495,-0.0532063245242673
0.449995,-0.20815628107033
0.450495,-0.549133036894429
0.450995,-1.10845960246309
0.451495,-1.20583427887664
0.451995,-1.36561229500049
0.452495,-1.25410427538829
0.452995,-1.64827501424899
0.453495,-1.66138831021014
0.453995,-1.75611287610617
0.454495,-1.46634975659829
0.454995,-1.25284189436355
0.455495,-0.851182445038488
0.455995,-0.474846717329599
0.456494999999999,-0.475937480624416
0.456995,-0.308399705996715
0.457495,-0.268634923151927
0.457995,-0.00596158550318575
0.458495,0.321335079401364
0.458995,0.508553253295959
0.459495,0.647862990653522
0.459995,0.786426924832027
0.460495,0.840472086621381
0.460995,0.826863578601619
0.461495,0.770607909652499
0.461995,0.760730551950851
0.462495,0.594380699596323
0.462995,0.532458085744093
0.463494999999999,0.291172101877688
0.463995,0.173023751007501
0.464495,0.10988941556929
0.464995,-0.113872183229096
0.465495,-0.149814171455185
0.465995,-0.416649503728977
0.466495,-0.544245806254387
0.466995,-0.664678413061427
0.467495,-0.806726543730607
0.467995,-0.954038578320262
0.468495,-1.19697307221029
0.468995,-1.08786708337781
0.469495,-1.21689347024226
0.469995,-1.16448411826423
0.470495,-0.883418888213884
0.470994999999999,-0.698019323561452
0.471495,-0.34909936982294
0.471995,-0.181735713247089
0.472495,0.238303514856973
0.472995,0.4050734547226
0.473495,0.609576900256816
0.473995,0.670752578355067
0.474495,0.701441237886798
0.474995,0.807356865639976
0.475495,0.801123830452125
0.475995,1.074026538821
0.476495,0.843323718421353
0.476995,0.994165270284122
0.477495,0.832479278527015
0.477995,0.827475141239349
0.478495,0.799585053123033
0.478995,0.761657720098511
0.479495,0.668836101121793
0.479995,0.557261062309622
0.480495,0.542744957486234
0.480995,0.439829301076094
0.481495,0.321034829612205
0.481995,0.32782708121213
0.482495,0.336301556034218
0.482995,0.512971882006833
0.483495,0.603015462942039
0.483995,0.61265175702586
0.484495,0.690390211452957
0.484995,0.743782372982677
0.485495,0.788122536477795
0.485995,0.688689395683926
0.486495,0.843944790542769
0.486995,0.744996437275526
0.487495,0.638888251512415
0.487995,0.689082003377549
0.488495,0.698961995246042
0.488995,0.837801032954886
0.489495,0.829919986883363
0.489995,0.671727333650895
0.490495,0.424644541536586
0.490995,0.243880612656136
0.491495,0.0950950325099461
0.491995,-0.0603102136837717
0.492495,-0.494151721557967
0.492995,-0.534470107619854
0.493495,-0.535352007359191
0.493995,-0.708687251272725
0.494495,-0.873583702433799
0.494995,-0.7780787194218
0.495495,-0.805359204330419
0.495995,-0.9517474935679
0.496495,-1.02270721885153
0.496995,-0.90738830250587
0.497495,-0.751674565627833
0.497995,-0.653866740856591
0.498495,-0.492603582344928
0.498995,-0.539317895557193
0.499495,-0.46269017806211
0.499995,-0.215258168452198
0.500495,0.0122812255899536
0.500995,0.325042597493868
0.501495,0.442597013231887
0.501995,0.63010894111707
0.502495,0.9126062395932
0.502995,1.20130348998814
0.503495,1.25186106698554
0.503995,1.44351934359439
0.504495,1.50946799931843
0.504995,1.6190297542696
0.505495,1.53834830534937
0.505995,1.31044567445559
0.506495,1.29461399750775
0.506995,1.01473807908604
0.507495,0.725366524238474
0.507995,0.54373570770169
0.508495,0.171196390318347
0.508995,0.00407296530572949
0.509495,-0.270814107789408
0.509995,-0.414548069921377
0.510495,-0.658557842937154
0.510995,-0.875521033435168
0.511495,-1.11442164353506
0.511995,-1.32544801379143
0.512495,-1.34160338110455
0.512995,-1.52199926927009
0.513495,-1.4235003732445
0.513995,-1.59156656907533
0.514494999999999,-1.38790509394
0.514995,-1.24900293183983
0.515495,-1.10815751436372
0.515995,-0.80506666164255
0.516495,-0.704544259275162
0.516995,-0.443852187172083
0.517495,-0.310814893525996
0.517995,-0.0831570279443362
0.518495,0.0688398738030898
0.518995,0.161264021419244
0.519495,0.345395320241298
0.519995,0.487014083469345
0.520495,0.629914958453525
0.520995,0.603020995598389
0.521495,0.64426658309698
0.521995,0.605974875331605
0.522495,0.610962614479864
0.522995,0.564858626196895
0.523495,0.505138054320445
0.523995,0.556546647455187
0.524495,0.484541625155876
0.524995,0.594012669604527
0.525495,0.521533850586077
0.525994999999999,0.548550300814966
0.526495,0.453573772713839
0.526995,0.308730570165107
0.527495,0.320982668183167
0.527995,0.183416264361269
0.528495,0.11437556454453
0.528995,0.162590764199522
0.529495,0.175257498016021
0.529995,0.346185904015305
0.530495,0.262737132474499
0.530995,0.335149881182875
0.531495,0.315328754933296
0.531995,0.354399952491125
0.532494999999999,0.461000777913387
0.532995,0.319065342327473
0.533495,0.413047013955769
0.533995,0.239004611141299
0.534495,0.186435518552123
0.534995,-0.0373495530597789
0.535495,-0.188604713125839
0.535995,-0.398426546832096
0.536495,-0.609350274746875
0.536995,-0.836716009959495
0.537494999999999,-0.894533488191831
0.537995,-1.01138487142609
0.538495,-1.08801671441849
0.538995,-1.11443810143617
0.539495,-1.12379072694737
0.539995,-1.14511062612811
0.540495,-1.24913618047849
0.540995,-1.15638795907405
0.541495,-1.12679927378455
0.541995,-1.01594382223828
0.542495,-0.912720911381044
0.542995,-0.747619466853182
0.543495,-0.517845359171487
0.543994999999999,-0.396082758980985
0.544495,-0.168063354133402
0.544995,0.129587783946999
0.545495,0.516943252585776
0.545995,0.741649817860158
0.546495,1.11691346885609
0.546995,1.37546343367522
0.547495,1.54794450709418
0.547995,1.77873628844988
0.548494999999999,1.76548283741992
0.548995,1.83539746852339
0.549495,1.8698843594301
0.549995,1.86745106428763
0.550495,1.71270174769932
0.550995,1.58653533312077
0.551495,1.49411824039341
0.551995,1.11751760355126
0.552495,0.943446086065556
0.552995,0.681532324774218
0.553495,0.325900697289457
0.553995,0.131225689002123
0.554495,-0.304000068226123
0.554994999999999,-0.405656705915769
0.555494999999999,-0.792135506808936
0.555995,-1.13169673244833
0.556495,-1.41591934749888
0.556995,-1.67156380917332
0.557495,-1.81276269697874
0.557995,-1.93366878154372
0.558495,-2.0065496806466
0.558995,-1.89383577130658
0.559495,-1.76793924865864
0.559995,-1.60417764799631
0.560495,-1.49446884957462
0.560995,-1.2747306696188
0.561495,-0.938445298525954
0.561995,-0.71395533571597
0.562495,-0.485498206111411
0.562995,-0.166359544859425
0.563495,0.0628226963540141
0.563995,0.261648176063726
0.564495,0.482774854923455
0.564995,0.617354929811782
0.565495,0.776542613794951
0.565995,0.965705180293018
0.566494999999999,0.965684291842742
0.566995,1.19780345779449
0.567495,1.20209479859345
0.567995,1.27685873132542
0.568495,1.23704237306267
0.568995,1.18468659163635
0.569495,1.0769571769515
0.569995,0.889181667331689
0.570495,0.80178773372168
0.570995,0.660074405636825
0.571495,0.418501904311986
0.571995,0.317193004058902
0.572495,0.108926756802111
0.572994999999999,0.0856335169927803
0.573495,-0.0251976720932667
0.573995,-0.12496571551301
0.574495,-0.137309581544114
0.574995,-0.187946846659825
0.575495,-0.137080508162735
0.575995,-0.178675833862106
0.576495,-0.159661516317267
0.576994999999999,-0.161753514074078
0.577494999999999,-0.228104976063252
0.577995,-0.337468746145349
0.578495,-0.310487828198206
0.578995,-0.390264075156203
0.579495,-0.371510789168145
0.579995,-0.456664160129114
0.580495,-0.362210445504576
0.580995,-0.422218182587625
0.581495,-0.395984321313942
0.581995,-0.473018583678676
0.582495,-0.42254855583871
0.582995,-0.429850210336323
0.583495,-0.492408564152042
0.583994999999999,-0.408125257954894
0.584494999999999,-0.566620260181848
0.584995,-0.529140801051393
0.585495,-0.509530863361987
0.585995,-0.589992565471805
0.586495,-0.478990653320236
0.586995,-0.432182455951838
0.587495,-0.283311915445516
0.587995,-0.193333599532774
0.588495,-0.00120558151516451
0.588995,0.15635486708419
0.589495,0.242183168984848
0.589995,0.456196408771661
0.590495,0.452662267396834
0.590995,0.619401177164464
0.591495,0.7345141005275
0.591995,0.748417602605998
0.592495,0.857538362123153
0.592995,0.919602537468465
0.593495,0.887217750743014
0.593995,0.998004420452577
0.594495,0.897850413327686
0.594995,0.873352258859027
0.595494999999999,0.792300566737746
0.595995,0.742827340262836
0.596495,0.690367200519007
0.596995,0.514052262815827
0.597495,0.434864731480706
0.597995,0.223497835952097
0.598495,0.121827173836856
0.598995,-0.143572054506264
0.599494999999999,-0.355987802283163
0.599994999999999,-0.495278599389979
0.600495,-0.783175442884873
0.600995,-0.791148607922263
0.601495,-1.03139592919051
0.601995,-1.0016722863418
0.602495,-1.07977372089334
0.602995,-1.13762252234903
0.603495,-1.08829779267978
0.603995,-1.02059892146687
0.604495,-0.932744800641923
0.604995,-0.909931089006447
0.605495,-0.661550385205743
0.605995,-0.622718300977709
0.606494999999999,-0.422239324912743
0.606994999999999,-0.294888371023507
0.607495,-0.0923869888237159
0.607995,0.060003923878683
0.608495,0.208422638897855
0.608995,0.363507513473118
0.609495,0.631951582636113
0.609995,0.743055571673133
0.610495,0.935013516480151
0.610995,0.847675126068537
0.611495,0.975691822832469
0.611995,0.953884759370739
0.612495,0.924650464153678
0.612995,0.904424396196235
0.613494999999999,0.80816539769122
0.613995,0.624850613578324
0.614495,0.510761465166431
0.614995,0.384679773673221
0.615495,0.250346551852923
0.615995,0.0374298638486216
0.616495,-0.0534694386442172
0.616995,-0.114161491065441
0.617495,-0.277100704554912
0.617995,-0.271864043991931
0.618495,-0.38583895549687
0.618995,-0.457675738835263
0.619495,-0.499275445741407
0.619995,-0.570540446848396
0.620495,-0.631627829849964
0.620995,-0.673300519913867
0.621495,-0.590026241079519
0.621994999999999,-0.551899408724794
0.622495,-0.431619611948501
0.622995,-0.381937351354619
0.623495,-0.288434623972328
0.623995,-0.139447926459258
0.624494999999999,-0.000185847410831753
0.624994999999999,0.104541422604813
0.625495,0.216753650505737
0.625995,0.247039327115995
0.626495,0.406903762162066
0.626995,0.482426875443793
0.627495,0.39081535678732
0.627995,0.45426234374818
0.628494999999999,0.400597591843249
0.628994999999999,0.382888025510403
0.629495,0.283477375599791
0.629995,0.237063187752986
0.630495,0.286370737096911
0.630995,0.197826359480598
0.631494999999999,0.157299713214093
0.631995,0.0933264037950656
0.632495,0.0210973323610294
0.632995,-0.0988621011992788
0.633495,-0.166587711179646
0.633995,-0.256266729694085
0.634495,-0.225863531687893
0.634995,-0.401416077414335
0.635494999999999,-0.372289181033755
0.635994999999999,-0.405867345714538
0.636495,-0.448764119900146
0.636995,-0.34801965096929
0.637495,-0.388254360089492
0.637995,-0.312351350397524
0.638495,-0.141666716337307
0.638995,-0.176859228819902
0.639495,-0.00338628933997715
0.639995,0.0318814216640981
0.640495,0.09263115060917
0.640995,0.0916185403927238
0.641495,0.129313282672404
0.641995,0.0925379771614155
0.642494999999999,0.0797430377230349
0.642994999999999,0.0967872687848732
0.643495,0.0875624475353215
0.643995,0.135681233011023
0.644495,0.0624664153402537
0.644995,0.0171419163286115
0.645495,0.0823141157890337
0.645995,0.0854195417183724
0.646495,-0.013186990656373
0.646995,0.0819811986154681
0.647495,0.0774138472602769
0.647995,0.124429394228662
0.648495,0.0301082925532905
0.648995,0.029579771352111
0.649495,0.0742579178116199
0.649995,0.0781784003713976
0.650495,0.0799323024260876
0.650994999999999,0.0667536089191095
0.651495,0.0908525525656051
0.651995,0.250343523815471
0.652495,0.235070280966283
0.652995,0.373041340304579
0.653494999999999,0.386810069565345
0.653994999999999,0.342017812787283
0.654495,0.293847506388609
0.654995,0.331694060170316
0.655495,0.334203310608688
0.655995,0.211514634792006
0.656495,0.138763186259714
0.656995,0.0716710699375781
0.657494999999999,-0.0826764063188427
0.657994999999999,-0.138874564171288
0.658495,-0.332295207012009
0.658995,-0.340249727753619
0.659495,-0.446686938545183
0.659995,-0.439269239553175
0.660494999999999,-0.602531148290212
0.660995,-0.608149826793953
0.661495,-0.694636062831134
0.661995,-0.688025124293285
0.662495,-0.824092540918334
0.662995,-0.753438936088188
0.663495,-0.811193314410451
0.663995,-0.619081958637617
0.664495,-0.556831414778748
0.664994999999999,-0.361971433061857
0.665494999999999,-0.289952216678671
0.665995,-0.129422583725102
0.666495,-0.0432182309028475
0.666995,0.185669860737064
0.667495,0.309023516414699
0.667995,0.460292027691166
0.668495,0.762055610574401
0.668995,0.814572909658195
0.669495,0.958950598416425
0.669995,0.951187181687156
0.670495,1.02868910681167
0.670995,1.02383685280943
0.671495,1.05522092428488
0.671994999999999,0.971823374838947
0.672495,0.888592112491417
0.672995,0.843205832862094
0.673494999999999,0.766554570231208
0.673995,0.683992308350142
0.674495,0.551616509759565
0.674995,0.326028488314402
0.675495,0.130518631298165
0.675995,-0.119040907562423
0.676494999999999,-0.295671082831469
0.676995,-0.46273499503874
0.677495,-0.562002441279171
0.677995,-0.785414886794425
0.678495,-0.880449869328541
0.678995,-0.968792849218172
0.679495,-1.11852142140166
0.679994999999999,-1.07123604213984
0.680494999999999,-1.16950855024786
0.680995,-1.05582157926343
0.681495,-1.03516195611582
0.681995,-0.980374420006023
0.682495,-0.817738824387822
0.682994999999999,-0.7173046629
0.683494999999999,-0.539619783676633
0.683995,-0.488644118818459
0.684495,-0.342441986122292
0.684995,-0.192196113092923
0.685495,0.00500637670487453
0.685995,0.138956189344909
0.686495,0.338034531574444
0.686994999999999,0.468927734258229
0.687494999999999,0.497071254307153
0.687995,0.635731226167582
0.688495,0.72653627873931
0.688995,0.733383661823867
0.689495,0.80864151533234
0.689995,0.766866326644365
0.690495,0.811446988919121
0.690995,0.733622414575911
0.691495,0.676775379543078
0.691995,0.646945637097469
0.692495,0.603336048034963
0.692995,0.47623566180127
0.693495,0.442481541415097
0.693994999999999,0.38181844645581
0.694494999999999,0.315335797008719
0.694995,0.325197327903164
0.695495,0.270578890641688
0.695995,0.149234668683951