File: DATA&scripts/1.7-data/z/13/13_fracture_stress_data.csv
Strain,Fracture Stress (GPa)
0.0,1.27808948803854
0.000495000000000008,1.46669448731703
0.000994999999999845,-2.73913261967175
0.00149500000000004,0.573260712540476
0.00199499999999988,-1.09288729086584
0.00249500000000008,4.14576722944568
0.00299499999999991,4.48230187469825
0.00349500000000011,5.47913883402226
0.00399499999999995,1.34880104860083
0.00449500000000015,1.90120420635764
0.00499499999999998,2.09414946765295
0.00549499999999982,3.03687789336161
0.00599500000000002,5.94943689081196
0.00649499999999986,5.49010856935874
0.00699500000000005,4.67410979240037
0.00749499999999989,4.80657775237052
0.00799500000000009,6.2551082348407
0.00849499999999993,6.83890128828716
0.00899500000000012,7.07932584434178
0.00949499999999996,7.20684603525571
0.00999499999999998,6.36335079293243
0.010495,7.10830166626037
0.0109949999999998,6.97955007959975
0.011495,7.06821194132023
0.0119949999999999,8.20934313391514
0.0124950000000001,8.34396486484481
0.0129949999999999,9.05913971088819
0.0134950000000001,9.4805713490137
0.0139949999999999,9.93747505489628
0.0144950000000001,9.38896868309112
0.014995,9.73998062490948
0.015495,9.93576412206442
0.015995,10.123186367697
0.0164949999999998,10.4577596810132
0.016995,10.2477895303747
0.0174949999999999,11.1129677800477
0.0179950000000001,11.3076771636233
0.0184949999999999,11.8458745556276
0.0189950000000001,12.2856681026269
0.0194949999999999,12.4625267932766
0.0199950000000001,12.8075187926816
0.020495,12.5004800837522
0.0209949999999998,12.8596078519034
0.021495,12.8348268995153
0.0219949999999999,13.5081664385216
0.0224950000000001,13.6275658591638
0.0229949999999999,13.8491161241516
0.0234950000000001,14.411414773553
0.0239949999999999,14.3979764664063
0.0244950000000001,14.8604961286037
0.024995,15.1986581806117
0.025495,15.5794651766291
0.025995,15.4075159492253
0.0264949999999998,15.4222665263259
0.026995,15.7949886750451
0.0274949999999999,16.1311008032724
0.0279950000000001,16.5488885037736
0.0284949999999999,16.816778744567
0.0289950000000001,17.0675849226077
0.0294949999999999,17.2416367437898
0.0299950000000001,17.4701633934403
0.030495,17.8990420795844
0.030995,18.166608421513
0.031495,18.3715251854843
0.0319949999999998,18.4039098345956
0.032495,18.6697137124181
0.0329949999999999,18.8015253364338
0.0334950000000001,19.2040466364305
0.0339949999999999,19.5318699787821
0.0344950000000001,19.8527211610926
0.0349949999999999,20.1561947619427
0.0354950000000001,20.3637477374532
0.035995,20.5830100786123
0.0364949999999998,20.7395826536782
0.036995,20.7935210351687
0.0374949999999999,21.1537334373649
0.037995,21.3116825028064
0.0384949999999999,21.713743398209
0.0389950000000001,21.7405783172442
0.0394949999999999,22.188432370445
0.0399950000000001,22.569573866626
0.040495,22.7943289278929
0.040995,23.0310551597141
0.041495,23.1490491131202
0.0419949999999998,23.353266120691
0.042495,23.3219889365361
0.0429949999999999,23.7548453418981
0.0434950000000001,24.1044461125865
0.0439949999999999,24.290809773714
0.0444950000000001,24.501985825412
0.0449949999999999,24.5369219710114
0.0454950000000001,25.0657406788244
0.045995,25.222546639069
0.046495,25.6681954074152
0.046995,25.7407147850327
0.0474949999999998,26.0188498014675
0.047995,26.1416544875591
0.0484949999999999,26.3653477356031
0.0489950000000001,26.7151547592795
0.0494949999999999,27.0350900284326
0.0499950000000001,27.2220362937621
0.0504949999999999,27.3780301441033
0.0509950000000001,27.5552796787596
0.051495,27.685640961612
0.0519949999999998,27.8512925607427
0.052495,28.4293811171117
0.0529949999999999,28.5954256676834
0.053495,28.7943699704516
0.0539949999999999,28.8065680467415
0.0544950000000001,29.0638053037961
0.0549949999999999,29.2025443578142
0.0554950000000001,29.5838047482386
0.055995,29.9555895423867
0.056495,30.3064240346143
0.056995,30.3707670272649
0.0574949999999998,30.4052032203707
0.057995,30.5143253938047
0.0584949999999999,30.9081668781613
0.0589950000000001,31.1441708522295
0.0594949999999999,31.4863709664325
0.0599950000000001,31.6197770665438
0.0604949999999999,31.8638773717151
0.0609950000000001,31.8736402924531
0.061495,32.1445889139904
0.061995,32.4092284933263
0.062495,32.89456878141
0.0629949999999998,33.0388012498864
0.063495,33.087495644201
0.0639949999999999,33.2386118933839
0.0644950000000001,33.5518491894124
0.0649949999999999,33.7020087782606
0.0654950000000001,33.9801768448315
0.0659949999999999,34.3213879001441
0.0664950000000001,34.5213365399415
0.066995,34.5728208675585
0.0674949999999998,34.788935936466
0.067995,34.9661505384619
0.0684949999999998,35.255859584187
0.068995,35.5151351342605
0.0694949999999999,35.6556789031644
0.0699950000000001,35.797078374876
0.0704949999999999,36.0615015288226
0.0709950000000001,36.1569716653176
0.071495,36.4228690937905
0.0719950000000002,36.7168693703296
0.072495,36.8719561878705
0.0729949999999998,37.0938193361796
0.073495,37.2800393546594
0.0739949999999999,37.5406544822563
0.0744950000000001,37.7948277324617
0.0749949999999999,37.8930545204408
0.0754950000000001,38.1259496946855
0.0759949999999999,38.2522777529224
0.0764950000000001,38.5367000870793
0.076995,38.6085143987937
0.0774949999999998,38.9588720694629
0.077995,39.0909906170083
0.0784949999999998,39.2743337969182
0.078995,39.5187299058569
0.0794949999999999,39.6472236134815
0.0799950000000001,39.901510816958
0.0804949999999999,40.0618528095896
0.0809950000000001,40.2730137099424
0.0814949999999999,40.3972214910144
0.0819950000000001,40.5513334514947
0.082495,40.8350708143946
0.0829949999999998,41.0196754986516
0.083495,41.229546528925
0.0839949999999998,41.3748307614745
0.084495,41.5766147795775
0.0849949999999999,41.7944726279517
0.0854950000000001,41.9190733750838
0.0859949999999999,42.1277905272756
0.0864950000000001,42.3468458097748
0.0869949999999999,42.5849147245041
0.0874950000000002,42.8333314244792
0.087995,42.9408157299347
0.0884949999999998,43.1814109047684
0.088995,43.2539895218699
0.0894949999999999,43.5297988528275
0.0899950000000001,43.5890201878855
0.0904949999999999,43.8011742816281
0.0909950000000001,44.0140546855148
0.0914949999999999,44.4653614226495
0.0919950000000001,44.4496106912689
0.092495,44.6834106498002
0.092995,44.6560187166001
0.093495,44.9574968282076
0.0939949999999998,45.0773114681677
0.094495,45.430247665926
0.0949949999999999,45.4853303851447
0.0954950000000001,45.7510733078093
0.0959949999999999,45.7797837927892
0.0964950000000001,45.9396188946153
0.0969949999999999,46.0600330264571
0.0974950000000001,46.4935195416341
0.097995,46.4496595732336
0.0984949999999998,46.7533188624664
0.098995,46.8335702975081
0.0994949999999998,47.1502884565492
0.099995,47.1342370972669
0.100495,47.4180776662273
0.100995,47.5836274518794
0.101495,47.7542863649581
0.101995,47.8475310696392
0.102495,48.0524574275437
0.102995,48.2050891951401
0.103495,48.4223059863271
0.103995,48.5460023819942
0.104495,48.8164765437211
0.104995,48.7778782363793
0.105495,48.9753672177262
0.105995,49.1484792714737
0.106495,49.3706327665311
0.106995,49.4696379283831
0.107495,49.7202998897
0.107995,49.8398887139551
0.108495,50.0737747110842
0.108995,50.157518258695
0.109495,50.294164933249
0.109995,50.5476249773445
0.110495,50.6938545856385
0.110995,50.8022157658058
0.111495,50.8999382435525
0.111995,51.1649722001702
0.112495,51.3705637562882
0.112995,51.5011722059504
0.113495,51.5626021005626
0.113995,51.7863375656308
0.114495,51.9681334928713
0.114995,52.0191847435951
0.115495,52.1233046523954
0.115995,52.3799383389657
0.116495,52.6021568633863
0.116995,52.6531534577351
0.117495,52.7403630029005
0.117995,52.9514354118127
0.118495,53.1352251368193
0.118995,53.2747411429292
0.119495,53.3673537494266
0.119995,53.6277244458342
0.120495,53.7515679101479
0.120995,53.8530993317591
0.121495,53.9606896958126
0.121995,54.198587557956
0.122495,54.3085772500265
0.122995,54.4434132589865
0.123495,54.614616239732
0.123995,54.8141744931841
0.124495,54.8545021380774
0.124995,54.9281855944518
0.125495,55.1321618049313
0.125995,55.3026458238395
0.126495,55.3923159242345
0.126995,55.5334749929971
0.127495,55.7357093855981
0.127995,55.7479860481726
0.128495,56.0106563349582
0.128995,56.0336502320668
0.129495,56.2840168511753
0.129995,56.3361140256702
0.130495,56.5677276085998
0.130995,56.5917486973096
0.131495,56.788987687201
0.131995,56.9187600151109
0.132495,56.9507140296457
0.132995,57.1380223455554
0.133495,57.2861768856245
0.133995,57.4132695169626
0.134495,57.4610419072664
0.134995,57.7151512384738
0.135495,57.8312505989443
0.135995,58.010352290693
0.136495,58.0651012018645
0.136995,58.1987845407487
0.137495,58.2417839298683
0.137995,58.5061340702813
0.138495,58.5984162768755
0.138995,58.7076191624252
0.139495,58.8147395226942
0.139995,58.9197721066784
0.140495,59.1280731973936
0.140995,59.2036541658951
0.141495,59.2287323178165
0.141995,59.4431979780664
0.142495,59.5814833034666
0.142995,59.6494145332073
0.143495,59.8172337342551
0.143995,59.8751623291722
0.144495,60.087920654354
0.144995,60.1981167855962
0.145495,60.2238379438609
0.145995,60.3469635267168
0.146495,60.340293870444
0.146995,60.6453935720458
0.147495,60.73613719728
0.147995,60.8674395703279
0.148495,60.8492093369675
0.148995,61.0406039039764
0.149495,61.251327661669
0.149995,61.3220920126293
0.150495,61.3181774647571
0.150995,61.4834044684475
0.151495,61.6558161850107
0.151995,61.6870336738119
0.152495,61.696718963049
0.152995,61.8672093272755
0.153495,62.1299562878991
0.153995,62.1267223691695
0.154495,62.2509353592595
0.154995,62.3379911034664
0.155495,62.5630990400051
0.155995,62.5106497261409
0.156495,62.6522321104197
0.156995,62.7836071482164
0.157495,62.8812997020176
0.157995,62.8974709333694
0.158495,63.0405846863027
0.158995,63.1267467079153
0.159495,63.3529677784377
0.159995,63.3613635045529
0.160495,63.4310822833226
0.160995,63.6410178575108
0.161495,63.6538286365227
0.161995,63.7699972920312
0.162495,63.7803745379403
0.162995,64.0400139452499
0.163495,64.1146255073807
0.163995,64.1334877573764
0.164495,64.2580013809785
0.164995,64.3379822225138
0.165495,64.503701477057
0.165995,64.3841761999223
0.166495,64.6751603661823
0.166995,64.7344529033792
0.167495,64.9481864422529
0.167995,64.8241402050778
0.168495,64.9911628178098
0.168995,65.0058971396592
0.169495,65.3203068406788
0.169995,65.2106222650134
0.170495,65.320508159359
0.170995,65.4324338147394
0.171495,65.5583591197402
0.171995,65.6250793215102
0.172495,65.6560828558985
0.172995,65.8771844033948
0.173495,65.8099380828654
0.173995,65.9134071034489
0.174495,66.008573628062
0.174995,66.2181932398951
0.175495,66.2948875875393
0.175995,66.3169420141125
0.176495,66.4507348343284
0.176995,66.4278614018763
0.177495,66.611149637481
0.177995,66.5849426299113
0.178495,66.8414695966518
0.178995,66.7951161742852
0.179495,66.9304849202531
0.179995,66.8620855348705
0.180495,67.0555651854712
0.180995,67.1696918237204
0.181495,67.1914230285813
0.181995,67.3443906547704
0.182495,67.3576610937438
0.182995,67.4824681177139
0.183495,67.532459296441
0.183995,67.6327583614263
0.184495,67.6578525583924
0.184995,67.7162728187263
0.185495,67.8067635612882
0.185995,67.9754159059822
0.186495,67.9898643008164
0.186995,67.9944107096017
0.187495,68.18215909397
0.187995,68.2241785065712
0.188495,68.330536911711
0.188995,68.258273702079
0.189495,68.4535087409241
0.189995,68.4772663249324
0.190495,68.6554813577465
0.190995,68.6290321811239
0.191495,68.727643508579
0.191995,68.8544302496817
0.192495,68.8983054562441
0.192995,68.9962916100915
0.193495,68.9386911571166
0.193995,69.0827044675651
0.194495,69.1888542788164
0.194995,69.2743718252609
0.195495,69.1781948993127
0.195995,69.3335123580285
0.196495,69.463068462825
0.196995,69.5384497294969
0.197495,69.5579661176756
0.197995,69.556482881541
0.198495,69.7262450435706
0.198995,69.7558219259704
0.199495,69.8500927409094
0.199995,69.8652949096537
0.200495,69.921746078698
0.200995,70.0915429753081
0.201495,70.1526162528743
0.201995,70.0787895826203
0.202495,70.1659630728155
0.202995,70.3308240087783
0.203495,70.3709594519905
0.203995,70.3971504090473
0.204495,70.521396778254
0.204995,70.5248958764583
0.205495,70.680554284814
0.205995,70.7068613878627
0.206495,70.7865127533332
0.206995,70.7088442210155
0.207495,70.8225233669693
0.207995,70.9731363838256
0.208495,71.0206508940912
0.208995,71.0065615412001
0.209495,71.0888374681747
0.209995,71.1408520653341
0.210495,71.3071088083063
0.210995,71.3139815740709
0.211495,71.4287916818741
0.211995,71.3749621498771
0.212495,71.4693676746
0.212995,71.5566128937459
0.213495,71.5991992583953
0.213995,71.6917769569474
0.214495,71.6971175104637
0.214995,71.8468763252792
0.215495,71.9354978022238
0.215995,71.8586160861189
0.216495,71.9678902360178
0.216995,71.9623145144974
0.217495,72.0314657585017
0.217995,72.0696640060574
0.218495,72.2393139377572
0.218995,72.2285630063351
0.219495,72.3224443736472
0.219995,72.3021259024117
0.220495,72.46065354404
0.220995,72.6432754635399
0.221495,72.5376149174995
0.221995,72.5846938472982
0.222495,72.5887581779017
0.222995,72.7357452772537
0.223495,72.8076515246801
0.223995,72.8639036151194
0.224495,72.796394559817
0.224995,72.9726374925424
0.225495,73.0313174453863
0.225995,73.0214063442305
0.226495,73.1589684333072
0.226995,73.0760703938459
0.227495,73.3347103372012
0.227995,73.3578598801975
0.228495,73.4258666401675
0.228995,73.3818784539593
0.229495,73.5259798099004
0.229995,73.599672671533
0.230495,73.5830937789038
0.230995,73.6762365716536
0.231495,73.6130066976334
0.231995,73.7146008121534
0.232495,73.860697951286
0.232995,73.8975384806158
0.233495,73.8398620794098
0.233995,74.0965002876021
0.234495,74.1547931024178
0.234995,74.0042017035852
0.235495,74.2506282579845
0.235995,74.2027697303678
0.236495,74.3812079905503
0.236995,74.3748778548781
0.237495,74.3331518122348
0.237995,74.362483350708
0.238495,74.7339978857107
0.238995,74.685314153425
0.239495,74.6216630246137
0.239995,74.618905097184
0.240495,74.8319219628988
0.240995,74.9325380870498
0.241495,74.866305767569
0.241995,74.9891219260928
0.242495,75.0529301328801
0.242995,75.1610664630778
0.243495,74.9785561734958
0.243995,75.1587770864618
0.244495,75.1433259484274
0.244995,75.2173974737183
0.245495,75.4582093656348
0.245995,75.3482864218455
0.246495,75.5418592199647
0.246995,75.4665101069579
0.247495,75.6902937756251
0.247995,75.650123776634
0.248495,75.8553519407965
0.248995,75.5979299485023
0.249495,75.8980755988486
0.249995,75.8752642981179
0.250495,75.9086183416592
0.250995,76.041118929976
0.251495,76.0062036700556
0.251995,76.1837662370826
0.252495,76.1396494060941
0.252995,76.2460296135419
0.253495,76.266964774381
0.253995,76.3942733628027
0.254495,76.3979632876297
0.254995,76.5132108718938
0.255495,76.5878146197078
0.255995,76.596642568822
0.256495,76.8068280767575
0.256995,76.8883232373866
0.257495,77.043492895221
0.257995,76.9482690491741
0.258495,77.0771216977929
0.258995,77.004496774945
0.259495,77.1506182643173
0.259995,77.2590803436933
0.260495,77.2768321053904
0.260995,77.321039326491
0.261495,77.4343053935577
0.261995,77.5150495718701
0.262495,77.537559068606
0.262995,77.433990228213
0.263495,77.5502853033182
0.263995,77.7902451041701
0.264495,77.851817322063
0.264995,77.8281014525271
0.265495,77.7956511712165
0.265995,78.2496716634527
0.266495,78.2313749150504
0.266995,78.2488991197468
0.267495,78.2895222603379
0.267995,78.3391671986181
0.268495,78.532108058395
0.268995,78.4212344088782
0.269495,78.4734796886678
0.269995,78.5628384268109
0.270495,78.7733512468689
0.270995,78.8550343896542
0.271495,78.8300076648533
0.271995,79.0217440745144
0.272495,79.078529654192
0.272995,79.0420285945621
0.273495,78.9128791305147
0.273995,79.3082813546723
0.274495,79.4038231238802
0.274995,79.3363264253732
0.275495,79.5851126308715
0.275995,79.6858115561681
0.276495,79.7553803500973
0.276995,80.0454211906663
0.277495,79.7744028555166
0.277995,79.927543942843
0.278495,80.0111139852393
0.278995,80.1680427828154
0.279495,80.1335565338813
0.279995,80.4213784325624
0.280495,80.5829875929755
0.280995,80.4795255391276
0.281495,80.6169027380418
0.281995,80.8274531390529
0.282495,80.8048300159072
0.282995,81.143410023334
0.283495,81.0125590812204
0.283995,81.089869262911
0.284495,81.3172475539457
0.284995,81.284252200454
0.285495,81.2678452677358
0.285995,81.5180457634341
0.286495,81.7269589068219
0.286995,81.8556572718159
0.287495,81.8491227762487
0.287995,82.0862719812516
0.288495,82.2190506287391
0.288995,82.277773663513
0.289495,82.5010528023369
0.289995,82.4489121340278
0.290495,82.656497526712
0.290995,82.8384792855891
0.291495,82.8456108656883
0.291995,82.8696635106845
0.292495,83.1656829155658
0.292995,83.3464520448223
0.293495,83.2889789106162
0.293995,83.538609697176
0.294495,83.624801237801
0.294995,83.550484761251
0.295495,83.8565933269717
0.295995,83.884760752075
0.296495,84.1330073927695
0.296995,84.3693837762076
0.297495,84.1615284245626
0.297995,84.7248352518411
0.298495,84.6762981381555
0.298995,84.9944715183934
0.299495,85.2245542786297
0.299995,85.1788788172695
0.300495,85.3458421869552
0.300995,85.4551482519387
0.301495,85.6016801428287
0.301995,85.9989509294076
0.302495,85.8585956978126
0.302995,86.2304340933072
0.303495,86.5405635634957
0.303995,86.4569256465963
0.304495,86.9499574409021
0.304995,86.780353286173
0.305495,87.2386933000439
0.305995,87.3292100724637
0.306495,87.5181711168012
0.306995,87.8681993544846
0.307495,87.5782279075101
0.307995,87.7138198762529
0.308495,88.2479708523146
0.308995,88.4645924466033
0.309495,88.5179339139385
0.309995,88.813472181874
0.310495,88.7925513911259
0.310995,89.5198900834991
0.311495,89.2336211265764
0.311995,89.6947059246956
0.312495,89.5085008476507
0.312995,89.849473691435
0.313495,90.3409459947838
0.313995,90.2725221688725
0.314495,90.541629575283
0.314995,90.7266084458602
0.315495,91.1485734145022
0.315995,91.2538392651441
0.316495,91.4763113889915
0.316995,91.8922521091762
0.317495,91.8930390451688
0.317995,92.4312079174894
0.318495,92.5300802488485
0.318995,92.4779258157638
0.319495,93.2516071207895
0.319995,93.1070920732542
0.320495,93.5028248911377
0.320995,93.7384268855696
0.321495,94.2733389537335
0.321995,94.4641050886739
0.322495,94.3088616274428
0.322995,94.8944287456388
0.323495,94.9481121049682
0.323995,95.74688303336
0.324495,95.8164452322826
0.324995,95.9375247903206
0.325495,96.3430902744628
0.325995,96.6308188960916
0.326495,96.9691931733933
0.326995,97.1107000647605
0.327495,97.4601328305614
0.327995,97.9045880296019
0.328495,98.1271353134939
0.328995,98.2711829755158
0.329495,98.6142891795617
0.329995,98.6384726954481
0.330495,99.4721542321591
0.330995,99.7159629138697
0.331495,99.6491178005831
0.331995,99.858174525564
0.332495,100.739575078105
0.332995,100.885888050356
0.333495,100.932817793296
0.333995,101.462049228163
0.334495,101.772358639959
0.334995,102.181152423659
0.335495,102.48851853369
0.335995,102.552549483508
0.336495,103.45996873646
0.336995,103.411546484593
0.337495,103.781686822854
0.337995,104.046200568399
0.338495,104.438463411583
0.338995,104.610936193021
0.339495,105.241657842424
0.339995,105.682347417471
0.340495,105.795624692622
0.340995,106.553190882923
0.341495,106.722662956072
0.341995,106.824702100935
0.342495,107.451311478438
0.342995,107.762066590917
0.343495,107.867950572553
0.343995,108.343413466942
0.344495,108.709645775826
0.344995,109.073654049136
0.345495,109.6331746957
0.345995,110.375502862592
0.346495,109.948088541195
0.346995,110.515655169215
0.347495,111.204095553727
0.347995,111.402202928074
0.348495,111.764754338962
0.348995,112.110681086247
0.349495,112.561507683962
0.349995,112.895829267562
0.350495,113.486271929515
0.350995,113.631771665724
0.351495,114.047368193237
0.351995,114.576907630312
0.352495,114.996232984728
0.352995,115.139832515469
0.353495,115.94181042073
0.353995,116.380899540671
0.354495,116.221761922605
0.354995,116.99334687363
0.355495,117.000058020864
0.355995,117.808464988419
0.356495,118.139250184628
0.356995,118.630043065784
0.357495,118.997723798751
0.357995,119.401907250583
0.358495,119.469075686697
0.358995,120.261052053417
0.359495,120.464731862179
0.359995,120.966105640104
0.360495,121.611070995139
0.360995,121.643408617479
0.361495,122.451366039717
0.361995,122.713975291499
0.362495,123.334241817589
0.362995,123.688161358606
0.363495,124.311998974543
0.363995,124.667957802421
0.364495,125.216269485764
0.364995,125.91549612591
0.365495,126.078319794359
0.365995,126.472605577369
0.366495,126.709698134804
0.366995,127.436739666453
0.367495,128.06348361951
0.367995,128.685224623315
0.368495,128.684793718472
0.368995,129.523976514862
0.369495,130.121142621368
0.369995,130.300970270661
0.370495,131.045000713794
0.370995,131.402708380349
0.371495,131.764165700803
0.371995,132.657236203148
0.372495,133.000850087103
0.372995,133.247555537559
0.373495,133.924185557931
0.373995,134.300085385164
0.374495,134.937344052622
0.374995,135.46138077017
0.375495,136.489691687204
0.375995,136.616668746225
0.376495,137.51607652511
0.376995,137.664012373913
0.377495,138.545180940609
0.377995,139.238142070707
0.378495,139.201151415013
0.378995,139.987821577703
0.379495,140.379763201955
0.379995,141.102106916687
0.380495,141.348472007477
0.380995,142.012018585633
0.381495,142.746409201805
0.381995,143.237000639841
0.382495,144.228180082693
0.382995,144.713084381608
0.383495,145.143729622476
0.383995,145.010894999179
0.384495,140.178027235673
0.384995,128.90557209035
0.385495,113.90934165445
0.385995,102.189710963937
0.386495,94.1533524761661
0.386995,86.4931940962048
0.387495,80.3364110065074
0.387995,74.1267483762129
0.388495,67.6292634539898
0.388995,61.3285027585466
0.389495,57.117487608314
0.389995,55.0775507494045
0.390495,52.7402724065152
0.390995,50.2460466765611
0.391495,47.745638111809
0.391995,45.4817513712457
0.392495,43.4148586840256
0.392995,41.4117406443754
0.393495,39.7911689837949
0.393995,38.3319304926672
0.394495,37.0437133413076
0.394995,35.7112000172851
0.395495,34.4573549627607
0.395995,33.2708953602537
0.396495,32.1158418177121
0.396995,31.1533920093032
0.397495,30.1991451539606
0.397995,29.4314905874242
0.398495,28.5962168830706
0.398995,27.8074488124257
0.399495,27.0154685589749
0.399995,26.2550755018675
0.400495,25.4676864139856
0.400995,24.6542529508711
0.401495,23.8393006195518
0.401995,23.0318055393338
0.402495,22.2348059265382
0.402995,21.3007298437478
0.403495,20.2461849706269
0.403995,19.1502902746604
0.404495,17.9409619685594
0.404995,16.6884962076632
0.405495,15.3396040646038
0.405995,13.905651104221
0.406495,12.3880297006236
0.406995,10.739193118003
0.407495,9.03359305264809
0.407995,7.18084917274298
0.408495,5.22606716118993
0.408995,3.13332287431346
0.409495,0.892514318220688
0.409995,-1.31867765955548
0.410495,-3.29405501432855
0.410995,-5.16420935563756
0.411495,-7.29343472214915
0.411995,-9.47181416017176
0.412495,-11.7963462136915
0.412995,-14.0308076339426
0.413495,-14.4481514723076
0.413995,-9.04711483403965
0.414495,-8.14478235284296
0.414995,-8.57064750617815
0.415495,-7.35001359169886
0.415995,-6.20150853310537
0.416495,-5.80209556982345
0.416995,-5.37947151077696
0.417495,-5.23856283359736
0.417995,-5.68335043601609
0.418495,-5.77846458282874
0.418995,-5.56499662400471
0.419495,-5.50519961668689
0.419995,-5.71232319836208
0.420495,-5.24607288797556
0.420995,-4.39395500971616
0.421495,-3.8108616388656
0.421995,-3.14968992519398
0.422495,-2.62013097771393
0.422995,-2.31797070492957
0.423495,-2.3059880902361
0.423995,-2.30740151252766
0.424495,-2.1119675435255
0.424995,-2.2692026786737
0.425495,-1.84997507681152
0.425995,-1.49338170220064
0.426495,-1.3236082893085
0.426995,-1.11940978513323
0.427495,-0.781606889974433
0.427995,-0.5513752803457
0.428495,-0.621037834899259
0.428995,-0.431565434901
0.429495,-0.585937636148083
0.429995,-1.00907134030176
0.430495,-1.18519010994493
0.430995,-1.37776515537179
0.431495,-1.40409171611877
0.431995,-1.38125156904885
0.432495,-1.24757725270584
0.432995,-0.950305831803072
0.433495,-0.820548322606745
0.433995,-0.492728504638688
0.434495,-0.39490987530116
0.434995,-0.136871575222141
0.435495,-0.0324184159335884
0.435995,-0.115701637832852
0.436495,-0.0039008451312876
0.436995,-0.0427856529869816
0.437495,-0.313165983720004
0.437995,-0.184780724472911
0.438495,-0.294322851846931
0.438995,-0.403799664556149
0.439495,-0.467498830687092
0.439995,-0.708942834225807
0.440495,-0.866841292659877
0.440995,-0.851765988339084
0.441495,-1.1010207044727
0.441995,-0.894950594886192
0.442495,-1.01811399223849
0.442995,-0.84691427289331
0.443495,-0.738083353913898
0.443995,-0.566466376724508
0.444495,-0.576507587558475
0.444995,-0.462972874502267
0.445495,-0.29538855264085
0.445995,-0.194272764132996
0.446495,-0.601871017295373
0.446995,-0.376209796116081
0.447495,-0.455212558651001
0.447995,-0.38307204907896
0.448495,-0.46142576781387
0.448995,-0.59707645186942
0.449495,-0.585195322878662
0.449995,-0.371668198217874
0.450495,-0.583444475118137
0.450995,-0.787301533617806
0.451495,-0.732266815215966
0.451995,-0.691480506194367
0.452495,-0.758883894880001
0.452995,-0.790466958791868
0.453495,-0.603338964494931
0.453995,-0.608006241244025
0.454495,-0.621413668438702
0.454995,-0.552908013299712
0.455495,-0.310215899490427
0.455995,-0.208377426190491
0.456495,-0.0568475138394296
0.456995,0.148065107961022
0.457495,0.172608158398947
0.457995,0.196271215682809
0.458495,0.159110731927977
0.458995,0.329195439535845
0.459495,0.302748074039814
0.459995,0.209022426885688
0.460495,0.1197012964009
0.460995,0.0462644441011415
0.461495,-0.300282603165639
0.461995,-0.60736264257583
0.462495,-0.780550492659474
0.462995,-1.01651975609194
0.463495,-1.02563891252102
0.463995,-0.946691138351015
0.464495,-1.02860338758217
0.464995,-0.959435256766363
0.465495,-1.1087411377116
0.465995,-0.774229268471133
0.466495,-0.554240782165672
0.466995,-0.1996043722195
0.467495,0.197434014693623
0.467995,0.190374509040799
0.468495,0.485582678794829
0.468995,0.341220465646827
0.469495,0.516082324402355
0.469995,0.562328218261196
0.470495,0.593068610906987
0.470995,0.514875272198057
0.471495,0.318533242244681
0.471995,0.249685048109432
0.472495,-0.0377384551070552
0.472995,-0.547239333500276
0.473495,-0.614662652890568
0.473995,-0.823284819826725
0.474495,-0.85019709903605
0.474995,-1.07972199703158
0.475495,-0.91499103237713
0.475995,-1.05624592628099
0.476495,-0.994534111577018
0.476995,-0.924228583010232
0.477495,-0.654836253121686
0.477995,-0.349236005193258
0.478495,-0.238649094222047
0.478995,0.118124080794186
0.479495,0.160245725947075
0.479995,0.263643560712488
0.480495,0.368860971662487
0.480995,0.569174162241972
0.481495,0.388373493042905
0.481995,0.268852348002066
0.482495,0.146601671571086
0.482995,0.0840435235604302
0.483495,-0.0691808000501795
0.483995,-0.0689649714791828
0.484495,-0.179199491313768
0.484995,-0.0845017084256416
0.485495,-0.401196980541523
0.485995,-0.548278706019996
0.486495,-0.566032247889175
0.486995,-0.43582760158459
0.487495,-0.402171658193763
0.487995,-0.420603655028226
0.488495,-0.100236252120202
0.488995,0.0793305099552822
0.489495,0.337527297524153
0.489995,0.426433090192852
0.490495,0.765600585801722
0.490995,0.812745955676668
0.491495,0.85374247070546
0.491995,0.998323248323818
0.492495,1.18219530452724
0.492995,1.37219933915359
0.493495,1.61441514588671
0.493995,1.55653702441778
0.494495,1.63426900283878
0.494995,1.7030316248495
0.495495,1.97501261677119
0.495995,2.07765762105796
0.496495,1.99802099163778
0.496995,1.78427184163616
0.497495,1.8970086926329
0.497995,1.76302404253295
0.498495,1.64611467092724
0.498995,1.40144835947335
0.499495,1.31403937496817
0.499995,1.14142546421418
0.500495,0.577879910898057
0.500995,0.47231568784508
0.501495,0.0136660423090275
0.501995,-0.313209554762346
0.502495,-0.764974027530238
0.502995,-1.02177386645694
0.503495,-1.34856758604086
0.503995,-1.57975065127856
0.504495,-1.70912827570589
0.504995,-1.76797744017688
0.505495,-1.79620898925193
0.505995,-1.75126244086474
0.506495,-1.84022218173363
0.506995,-1.76583219400039
0.507495,-1.6435633670598
0.507995,-1.50792021253654
0.508495,-1.52037235099452
0.508995,-1.31977887165362
0.509495,-1.16109597331889
0.509995,-0.907810595100582
0.510495,-0.777724853062613
0.510995,-0.617977892347886
0.511495,-0.32713460215978
0.511995,-0.058052973739256
0.512495,0.240694363103349
0.512995,0.326921376602384
0.513495,0.560818837312162
0.513995,0.510930381775416
0.514495,0.739403483230784
0.514995,0.823131305638041
0.515495,0.937560327051671
0.515995,0.925423230369275
0.516495,0.878309190927333
0.516995,0.803558109457331
0.517495,0.544215631496631
0.517995,0.462411557405545
0.518495,0.337941704138449
0.518995,0.325535113528995
0.519495,0.0900424441156999
0.519995,-0.0547523737906874
0.520495,-0.0977865017134342
0.520995,-0.206915791994831
0.521495,-0.153607853543579
0.521995,-0.335922154061802
0.522495,-0.278340323929046
0.522995,-0.49165594207263
0.523495,-0.368949035976981
0.523995,-0.374779673799045
0.524495,-0.271407958640751
0.524995,-0.216245236513459
0.525495,-0.114519961424743
0.525995,0.217574355904094
0.526495,0.280349066535559
0.526995,0.373150542430804
0.527495,0.356393293198193
0.527995,0.497557958520945
0.528495,0.596828280609092
0.528995,0.60976063618382
0.529495,0.787879747521178
0.529995,0.929870703704054
0.530495,0.832681640662721
0.530995,0.936211108410551
0.531495,0.935786352697946
0.531995,0.99166633575886
0.532495,0.822828584772889
0.532995,0.950483446042904
0.533495,0.905529672647985
0.533995,0.983217175953318
0.534495,0.958575093266967
0.534995,1.06059399451659
0.535495,1.18145983377812
0.535995,1.14508427160274
0.536495,1.20201703852798
0.536995,1.20360582809979
0.537495,1.16219432937561
0.537995,0.949452687460006
0.538495,0.950334165631646
0.538995,0.792972871263433
0.539495,0.783519633202801
0.539995,0.669773552151347
0.540495,0.641328066855255
0.540995,0.505470802177684
0.541495,0.361093249411109
0.541995,0.194648173810792
0.542495,0.0432212837015101
0.542995,-0.0642100266504808
0.543495,-0.155924335278211
0.543995,-0.260182569389552
0.544495,-0.0966560558820923
0.544995,-0.23735924576068
0.545495,-0.195623102717527
0.545995,-0.339998896801134
0.546495,-0.224110595163483
0.546995,-0.183656266217037
0.547495,-0.348275078170925
0.547995,-0.0628281004614445
0.548495,0.00362437781282351
0.548995,0.0936922406089982
0.549495,0.118050334556283
0.549995,0.268380030363509
0.550495,0.431092648949555
0.550995,0.481801485932344
0.551495,0.508180292438021
0.551995,0.52930185718891
0.552495,0.558612049384129
0.552995,0.51769322493421
0.553495,0.644981286973825
0.553995,0.720314764553831
0.554495,0.726392763697873
0.554995,0.773231438072284
0.555495,0.853675666876908
0.555995,0.974717818392688
0.556495,0.869686490727341
0.556995,0.964232901840546
0.557495,0.847574169897216
0.557995,0.834847749480999
0.558495,0.787506342394723
0.558995,0.694498947239565
0.559495,0.3375923489233
0.559995,0.222009831651073
0.560495,0.0809159874293529
0.560995,-0.0977974287145726
0.561495,-0.357882889857975
0.561995,-0.488650725777585
0.562495,-0.507594426529906
0.562995,-0.583429034263091
0.563495,-0.6589012454728
0.563995,-0.661199578006174
0.564495,-0.713054165667076
0.564995,-0.788000078738746
0.565495,-0.886762998234454
0.565995,-0.841992357350612
0.566495,-0.835117673576105
0.566995,-0.999254235508784
0.567495,-1.02888636843893
0.567995,-0.982105435321971
0.568495,-0.986321740017149
0.568995,-0.975446207478061
0.569495,-0.803873850107754
0.569995,-0.771142459797326
0.570495,-0.699674333016665
0.570995,-0.78765138585713
0.571495,-0.547463548859683
0.571995,-0.449881584683044
0.572495,-0.285232972511531
0.572995,-0.288774683966627
0.573495,-0.0936890782113485
0.573995,-0.166323642796946
0.574495,-0.177731191210095
0.574995,-0.138480340173258
0.575495,-0.0881355739562437
0.575995,-0.20478601619042
0.576495,-0.128538228416725
0.576995,-0.265729114481104
0.577495,-0.0767771354701946
0.577995,-0.203093347030695
0.578495,-0.178693205521777
0.578995,-0.197527348896113
0.579495,-0.273749480126511
0.579995,-0.366030715559893
0.580495,-0.215099031636218
0.580995,-0.112105437626251
0.581495,-0.176045911555367
0.581995,-0.361549447592618
0.582495,-0.136842298170561
0.582995,-0.334631303376388
0.583495,-0.117290256052383
0.583995,-0.173204158977328
0.584495,-0.209655493362565
0.584995,-0.218552711698555
0.585495,-0.0589915504818091
0.585995,0.0079513730740571
0.586495,0.0875553059255047
0.586995,0.0712738467444839
0.587495,-0.0241777139862764
0.587995,0.0961082391981332
0.588495,-0.0904999461338584
0.588995,-0.0654731194439538
0.589495,-0.000732345772598885
0.589995,-0.114586053996151
0.590495,-0.328012400985288
0.590995,-0.267007402065001
0.591495,-0.257237267138064
0.591995,-0.322292217965138
0.592495,-0.43386245359849
0.592995,-0.538622581897548
0.593495,-0.675243990688476
0.593995,-0.625120700591262
0.594495,-0.671389513583153
0.594995,-0.692365248955719
0.595495,-0.771351848143725
0.595995,-0.479751634617513
0.596495,-0.387446856478863
0.596995,-0.438843510306108
0.597495,-0.416338556289843
0.597995,-0.255280601567971
0.598495,-0.113274039874488
0.598995,-0.0877463357887854
0.599495,-0.0207400208214977
0.599995,-0.0207583900920794
0.600495,0.156772097695306
0.600995,0.317958249987115
0.601495,0.272737402143622
0.601995,0.329255338902326
0.602495,0.295830624447995
0.602995,0.356052235644341
0.603495,0.346087446405801
0.603995,0.155564096762094
0.604495,0.215107038202623
0.604995,0.135587285935287
0.605495,0.246972805446566
0.605995,0.112225048527894
0.606495,0.137599350275535
0.606995,0.154674341781186
0.607495,0.148842421419427
0.607995,-0.0251124334328676
0.608495,0.0260992899176161
0.608995,-0.0425556847494358
0.609495,-0.080534321351305
0.609995,-0.055993222499404
0.610495,-5.94702275995692e-05
0.610995,-0.0504714599787035
0.611495,-0.019541243281471
0.611995,-0.00123292788197723
0.612495,-0.0194605624062744
0.612995,0.0342916790879047
0.613495,0.0845884679373296
0.613995,0.196927581645475
0.614495,0.218527419426546
0.614995,0.355632576904218
0.615495,0.213953954976711
0.615995,0.36152596530706
0.616495,0.382241974434245
0.616995,0.404011575134859
0.617495,0.346081341444651
0.617995,0.354025581386523
0.618495,0.445230172111072
0.618995,0.383810299612712
0.619495,0.523180234137736
0.619995,0.409268362867429
0.620495,0.59225077288988
0.620995,0.574891164877781
0.621495,0.532230810445391
0.621995,0.577406996183115
0.622495,0.544619870613889
0.622995,0.513600484317718
0.623495,0.494008762810407
0.623995,0.523625273709966
0.624495,0.426264227428418
0.624995,0.334128010928776
0.625495,0.368600666977722
0.625995,0.313566827401875
0.626495,0.12570170593192
0.626995,0.0183846452297817
0.627495,0.247772110987643
0.627995,0.0359511238455702
0.628495,0.0424729014836709
0.628995,0.0223223318321882
0.629495,0.186383604953495
0.629995,0.06555743827469
0.630495,-0.00900668418272643
0.630995,-0.0508043391794211
0.631495,-0.0256726059137818
0.631995,-0.108602885679383
0.632495,-0.294255956385143
0.632995,-0.246904810808017
0.633495,-0.248667925542023
0.633995,-0.311444419161985
0.634495,-0.237504254546234
0.634995,-0.242089126777228
0.635495,-0.145121882036471
0.635995,-0.325984980799232
0.636495,-0.231540179871457
0.636995,-0.0634723765066011
0.637495,-0.142215616061185
0.637995,-0.115492836025694
0.638495,-0.0304550457941578
0.638995,-0.0527119380502775
0.639495,-0.0588722594670229
0.639995,0.0114467859611957
0.640495,0.0251573222950925
0.640995,-0.00585710540035315
0.641495,0.057813003638037
0.641995,0.179914183834974
0.642495,0.259283099550432
0.642995,0.303942853074197
0.643495,0.199894854089849
0.643995,0.309016620625173
0.644495,0.346344739457826
0.644995,0.372918583135521
0.645495,0.35807878840081
0.645995,0.410522194288095
0.646495,0.312953302468522
0.646995,0.276104608618268
0.647495,0.174342840971958
0.647995,0.107941261899379
0.648495,0.0059610881829788
0.648995,-0.00797687368026216
0.649495,-0.0764714529835846
0.649995,-0.200471717853385
0.650495,-0.191935313770357
0.650995,-0.11807344351406
0.651495,-0.0999650098735643
0.651995,-0.329233976085783
0.652495,-0.204766009797356
0.652995,-0.148209168183207
0.653495,-0.222204923446293
0.653995,-0.429307638110752
0.654495,-0.42881862543675
0.654995,-0.312882458424318
0.655495,-0.34649740082992
0.655995,-0.487273098330706
0.656495,-0.440680138118556
0.656995,-0.499295993202826
0.657495,-0.503837048524425
0.657995,-0.391095193260243
0.658495,-0.408232075524391
0.658995,-0.346244445677005
0.659495,-0.394332910334972
0.659995,-0.310215462033267
0.660495,-0.275988940836081
0.660995,-0.243593056088986
0.661495,-0.214870887748693
0.661995,-0.316783493834358
0.662495,-0.273868602229411
0.662995,-0.194925972286321
0.663495,-0.177894382427384
0.663995,-0.12975365711152
0.664495,-0.108734108607068
0.664995,-0.105074385748715
0.665495,-0.0465373370328074
0.665995,0.103152272218714
0.666495,0.199564791556869
0.666995,0.100262299660492
0.667495,0.053667426532252
0.667995,0.0737220041615619
0.668495,0.0468387107294182
0.668995,-0.0138333177331768
0.669495,-0.0132013561651975
0.669995,-0.0768418188177586
0.670495,-0.0984204855539291
0.670995,-0.210426525755831
0.671495,-0.199018734490829
0.671995,-0.31949444799993
0.672495,-0.291897854241189
0.672995,-0.3308871346326
0.673495,-0.361857060290513
0.673995,-0.486253575340182
0.674495,-0.415593368421786
0.674995,-0.406539640532937
0.675495,-0.453627311775187
0.675995,-0.504748689643583
0.676495,-0.493176847971077
0.676995,-0.426042518982481
0.677495,-0.465882442878861
0.677995,-0.446130364584369
0.678495,-0.541411346921183
0.678995,-0.349620313910028
0.679495,-0.282689920605347
0.679995,-0.307691915221803
0.680495,-0.156353592294393
0.680995,-0.150698667828141
0.681495,-0.038079760287415
0.681995,0.0226057140107826
0.682495,0.185995395596973
0.682995,0.184101629942413
0.683495,0.336453711835803
0.683995,0.386009155099159
0.684495,0.434664073592639
0.684995,0.590854748581445
0.685495,0.59955625149303
0.685995,0.823957138569779
0.686495,0.691841880182449
0.686995,0.822630654296155
0.687495,0.747583267509253
0.687995,0.81405141185388
0.688495,0.703600525383521
0.688995,0.770596321266927
0.689495,0.750719607272483
0.689995,0.761270939036445
0.690495,0.64816663092818
0.690995,0.571819352073384
0.691495,0.599551164398331
0.691995,0.455283701630612
0.692495,0.538090566361297
0.692995,0.342316563070853
0.693495,0.26184109459587
0.693995,0.252493878773151
0.694495,0.159814633524983
0.694995,0.0285846634236805
0.695495,-0.0361011694867803
0.695995,-0.0821971228559904
0.696495,-0.21394735462919
0.696995,-0.21773351146241
0.697495,-0.447208484475945
0.697995,-0.344735823846357
0.698495,-0.465962390778743
0.698995,-0.343448478185539
0.699495,-0.424630202644549
0.699995,-0.398921943094967
0.700495,-0.363114071436443
0.700995,-0.41202280320992
0.701495,-0.340493071155994
0.701995,-0.460883969652291
0.702495,-0.302349004824764
0.702995,-0.196180542036361
0.703495,-0.286620555772167
0.703995,-0.169954649527123
0.704495,-0.260378709691933
0.704995,-0.0219006643830692
0.705495,-0.0550183289409667
0.705995,0.155553103772308
0.706495,0.159037251093915
0.706995,0.331520077922948
0.707495,0.395710579698607
0.707995,0.528310725210606
0.708495,0.467611375755522
0.708995,0.564495530224052
0.709495,0.617755556125433
0.709995,0.720437710337483
0.710495,0.646611194850054
0.710995,0.582529605456316
0.711495,0.511182255232382
0.711995,0.696062433613128
0.712495,0.592306608036139
0.712995,0.342662927789894
0.713495,0.483392406765008
0.713995,0.516275114373139
0.714495,0.38211321030105
0.714995,0.227056548078011
0.715495,0.208171320286519
0.715995,0.0939581477597385
0.716495,0.0767884908782234
0.716995,0.00611493912533472
0.717495,-0.125318513147892
0.717995,-0.18956909726224
0.718495,-0.269342587868015
0.718995,-0.321237465760761