File: DATA&scripts/1.7-data/h0/11/11_fracture_stress_data.csv
Strain,Fracture Stress (GPa)
0.0,0.639095992524223
0.000494999999999904,0.841626956334579
0.000994999999999923,1.11947317951071
0.00149499999999994,1.48301690752157
0.00199499999999996,1.65882796783314
0.00249499999999998,1.72670074731827
0.00299499999999988,2.24626373836823
0.0034949999999999,2.35712116212795
0.00399499999999992,2.38010141384128
0.00449499999999993,3.02500140742719
0.00499499999999995,3.05673250841949
0.00549499999999997,3.12740135677099
0.00599499999999999,3.77102439136641
0.00649499999999989,3.66206262425481
0.00699499999999991,3.9876015427353
0.00749499999999993,4.36691205097173
0.00799499999999994,4.35670892490471
0.00849499999999996,4.6872700744809
0.00899499999999998,5.06594802238894
0.00949499999999988,5.09893530002921
0.0099949999999999,5.35919701405537
0.0104949999999999,5.70386395351758
0.0109949999999999,5.79927076979816
0.011495,6.02787997636082
0.011995,6.45490848819991
0.012495,6.47817279937852
0.0129949999999999,6.66965039251658
0.0134949999999999,7.06699129419742
0.0139949999999999,7.18163203692166
0.0144949999999999,7.38595177311183
0.014995,7.73945909085868
0.015495,7.85831406417835
0.0159949999999999,7.9909726528341
0.0164949999999999,8.37324990533393
0.0169949999999999,8.53870827180401
0.0174949999999999,8.7093827686131
0.017995,9.05195765548238
0.018495,9.1223602626649
0.018995,9.33979204333167
0.0194949999999999,9.75704716707829
0.0199949999999999,9.81851730718636
0.0204949999999999,9.90540264111354
0.020995,10.3557943990242
0.021495,10.5144884698448
0.021995,10.6383444871729
0.0224949999999999,10.9662335549785
0.0229949999999999,11.022386389664
0.0234949999999999,11.2324212114395
0.0239949999999999,11.6449507116411
0.024495,11.776981209723
0.024995,11.8334906749929
0.0254949999999999,12.1619353378464
0.0259949999999999,12.2652126727192
0.0264949999999999,12.4399091813909
0.0269949999999999,12.8504148601952
0.027495,12.9596526004314
0.027995,13.0828724325312
0.028495,13.3992406649884
0.0289949999999999,13.5458217943625
0.0294949999999999,13.6615264003435
0.0299949999999999,14.0208327011633
0.0304949999999999,14.14578190737
0.030995,14.2479911200518
0.031495,14.5030467154201
0.0319949999999999,14.7562557714672
0.0324949999999999,14.8577161755266
0.0329949999999999,15.1617281485845
0.0334949999999999,15.4282550132691
0.033995,15.4822094093417
0.034495,15.7292551952937
0.034995,15.9622915861789
0.0354949999999999,16.0235605682454
0.0359949999999999,16.2757739475433
0.0364949999999999,16.4971722284621
0.0369949999999999,16.6178304873898
0.037495,16.8567032736607
0.037995,17.0896061482713
0.0384949999999999,17.2609043358156
0.0389949999999999,17.4608606004002
0.0394949999999999,17.6916848906225
0.0399949999999999,17.850704255043
0.040495,18.0457494990357
0.040995,18.2336583661922
0.0414949999999999,18.3950612645003
0.0419949999999999,18.5979816803673
0.0424949999999999,18.807851688695
0.0429949999999999,18.9331402362504
0.043495,19.173738196765
0.043995,19.3560247879132
0.044495,19.5371630891995
0.0449949999999999,19.6966986800345
0.0454949999999999,19.9175839654283
0.0459949999999999,20.0790456319361
0.0464949999999999,20.2772386798525
0.046995,20.4846384303198
0.047495,20.6259500863927
0.047995,20.8144813001643
0.0484949999999999,21.0477371467427
0.0489949999999999,21.1718139805366
0.0494949999999999,21.4394183072249
0.049995,21.6212659283194
0.050495,21.7429670943129
0.050995,21.9511836304236
0.0514949999999999,22.1746915405606
0.0519949999999999,22.2498854983607
0.0524949999999999,22.4779008789102
0.0529949999999999,22.6448777206762
0.053495,22.7787532479531
0.053995,22.9825834078664
0.0544949999999999,23.1690300909242
0.0549949999999999,23.3048252862936
0.0554949999999999,23.4859414295755
0.0559949999999999,23.6835396469056
0.056495,23.852056038968
0.056995,24.0348059743578
0.0574949999999999,24.2170789762959
0.0579949999999999,24.4014591420119
0.0584949999999999,24.5507000135204
0.0589949999999999,24.7642295293871
0.059495,24.9260731186545
0.059995,25.0538241718369
0.060495,25.2612534573238
0.0609949999999999,25.426784697694
0.0614949999999999,25.5603880589124
0.0619949999999999,25.7439293488913
0.0624949999999999,25.9247689136741
0.062995,26.10599702394
0.063495,26.2612501944613
0.0639949999999999,26.4427668559731
0.0644949999999999,26.5745075244849
0.0649949999999999,26.7490036382459
0.0654949999999999,26.9338042493891
0.065995,27.0782329341255
0.066495,27.2829457175033
0.0669949999999999,27.4403335506939
0.0674949999999999,27.5868149482271
0.0679949999999999,27.7706447379177
0.0684949999999999,27.9337039328188
0.0689949999999999,28.0889270739014
0.069495,28.2521524217464
0.069995,28.417999481245
0.0704949999999999,28.5549230648502
0.0709949999999999,28.6952051569145
0.0714949999999999,28.8716670014834
0.0719949999999999,28.9885011996819
0.0724949999999999,29.1319638811481
0.072995,29.3475301299445
0.073495,29.4825539287707
0.0739949999999999,29.6493331453223
0.0744949999999999,29.8463291566806
0.0749949999999999,30.0042947710603
0.075495,30.1251148869787
0.075995,30.3075726712874
0.076495,30.4604813431499
0.0769949999999999,30.6158854514772
0.0774949999999999,30.7840210991739
0.0779949999999999,30.9321826663115
0.0784949999999999,31.0535357695743
0.078995,31.2439704801887
0.079495,31.41046654574
0.0799949999999999,31.5318454027516
0.0804949999999999,31.6757210583467
0.0809949999999999,31.8205187148661
0.0814949999999999,31.9565543921469
0.0819949999999999,32.110658521641
0.082495,32.2814697350954
0.082995,32.4721585061625
0.0834949999999999,32.6067812273872
0.0839949999999999,32.7366859787494
0.0844949999999999,32.8719862903742
0.0849949999999999,32.9986400298577
0.085495,33.1175202513846
0.085995,33.2940748234761
0.086495,33.4415270596626
0.0869949999999999,33.5732866136692
0.0874949999999999,33.7555558931137
0.0879949999999999,33.9219609215606
0.0884949999999999,34.0535212494833
0.088995,34.203052865027
0.089495,34.3242544854749
0.0899949999999999,34.4480944279295
0.0904949999999999,34.6011946116267
0.0909949999999999,34.7684207677184
0.0914949999999999,34.8874430643496
0.091995,35.0158955352297
0.0924949999999999,35.1625555587096
0.0929949999999999,35.2985794739159
0.0934949999999999,35.4651983972445
0.0939949999999999,35.6288947180545
0.0944949999999999,35.7592149100568
0.094995,35.8267070661641
0.095495,35.9464530874399
0.0959949999999999,36.1232181087601
0.0964949999999999,36.2907679602213
0.0969949999999999,36.4587829858414
0.0974949999999999,36.5610195501783
0.0979949999999999,36.622932528264
0.098495,36.7856773866278
0.098995,36.9554735139768
0.0994949999999999,37.1144401417389
0.0999949999999999,37.2213482854177
0.100495,37.311743139529
0.100995,37.4319225701791
0.101495,37.5832375770356
0.101995,37.7518795599673
0.102495,37.8562254672648
0.102995,37.9611952861615
0.103495,38.0842342900735
0.103995,38.2262022963512
0.104495,38.3985098934844
0.104995,38.4984516833898
0.105495,38.60940631117
0.105995,38.7649856001803
0.106495,38.8931792022193
0.106995,38.9647709499917
0.107495,39.0964278690855
0.107995,39.2736873318901
0.108495,39.3769744424098
0.108995,39.4772064104893
0.109495,39.6013685636314
0.109995,39.7345118241074
0.110495,39.8664890753449
0.110995,40.0025101474695
0.111495,40.0848612089067
0.111995,40.1994071900973
0.112495,40.3425485607128
0.112995,40.4464663170712
0.113495,40.5557116119854
0.113995,40.7106465085694
0.114495,40.8168216143781
0.114995,40.9262635580124
0.115495,41.0296386744898
0.115995,41.156583854268
0.116495,41.3024128792545
0.116995,41.4007502519392
0.117495,41.5073546007823
0.117995,41.6182969864366
0.118495,41.7460782872689
0.118995,41.8470778471717
0.119495,41.9651663357012
0.119995,42.0949741897783
0.120495,42.186728464428
0.120995,42.2725659449254
0.121495,42.3926535241988
0.121995,42.5519276114024
0.122495,42.6325902437772
0.122995,42.6829744293681
0.123495,42.8568240940986
0.123995,42.9828334454223
0.124495,43.0318848421037
0.124995,43.1698404185877
0.125495,43.2888315842126
0.125995,43.3847516330019
0.126495,43.4730412710528
0.126995,43.620387023833
0.127495,43.7241170903684
0.127995,43.7779191171011
0.128495,43.9535150858724
0.128995,44.0154634304017
0.129495,44.0656331586845
0.129995,44.2193903041807
0.130495,44.3386556577024
0.130995,44.3743635085357
0.131495,44.5546973292821
0.131995,44.6395726339608
0.132495,44.6723187533763
0.132995,44.8859372103065
0.133495,44.9132384377336
0.133995,45.0055476577152
0.134495,45.1656080507963
0.134995,45.185371664313
0.135495,45.3224288815387
0.135995,45.4189677299298
0.136495,45.480845220429
0.136995,45.6503279866135
0.137495,45.710062285476
0.137995,45.7959310879274
0.138495,45.8949132754685
0.138995,45.9700600109722
0.139495,46.0915409697069
0.139995,46.1971238325399
0.140495,46.2398351894245
0.140995,46.3879032152057
0.141495,46.4288545307955
0.141995,46.5404727087105
0.142495,46.6655078130363
0.142995,46.7112516686375
0.143495,46.8533879469172
0.143995,46.8837541188855
0.144495,46.99953155697
0.144995,47.1132596912258
0.145495,47.1804153956897
0.145995,47.3071284368919
0.146495,47.3489696426657
0.146995,47.443410649146
0.147495,47.5274577477849
0.147995,47.632328017757
0.148495,47.7062766587183
0.148995,47.7930080192932
0.149495,47.8697809508374
0.149995,47.9477085026318
0.150495,48.0374644859193
0.150995,48.120425212025
0.151495,48.2325855506794
0.151995,48.2838291911105
0.152495,48.3755037392932
0.152995,48.4339104815308
0.153495,48.5467084323149
0.153995,48.6658085403778
0.154495,48.7080817143237
0.154995,48.8108565492919
0.155495,48.8510708851074
0.155995,48.9286493675858
0.156495,49.0236133446144
0.156995,49.0701303531762
0.157495,49.1904372864698
0.157995,49.2582761799102
0.158495,49.3464708510601
0.158995,49.4226975419385
0.159495,49.4817914774602
0.159995,49.5964715820701
0.160495,49.6484475756161
0.160995,49.7347752229949
0.161495,49.7864729460474
0.161995,49.8737458391618
0.162495,49.9190096104182
0.162995,50.0402851555698
0.163495,50.046904093728
0.163995,50.1804954422895
0.164495,50.2311919780199
0.164995,50.3227641804117
0.165495,50.3634677032326
0.165995,50.4470359559989
0.166495,50.5085670255247
0.166995,50.6277141512104
0.167495,50.6609895767937
0.167995,50.7537344821614
0.168495,50.7730191685843
0.168995,50.8817331324177
0.169495,50.9369846581082
0.169995,51.0622086804187
0.170495,51.0994420877669
0.170995,51.1429943379683
0.171495,51.212927866888
0.171995,51.2540028197657
0.172495,51.3695309201613
0.172995,51.3967887724589
0.173495,51.5031279817386
0.173995,51.5630726126491
0.174495,51.6095290731814
0.174995,51.6479952484872
0.175495,51.743106599918
0.175995,51.8081272894578
0.176495,51.8674438587433
0.176995,51.9548568675271
0.177495,51.9975219643933
0.177995,52.0668058040905
0.178495,52.0987134157752
0.178995,52.1870293787852
0.179495,52.2331138570883
0.179995,52.3276891483267
0.180495,52.387679147398
0.180995,52.4570278236449
0.181495,52.4946718059843
0.181995,52.5647592537392
0.182495,52.6446447109332
0.182995,52.6462989653246
0.183495,52.7511302548646
0.183995,52.7869947351377
0.184495,52.8510186866363
0.184995,52.8961318111363
0.185495,52.9418248531777
0.185995,53.0396889335357
0.186495,53.0958927970147
0.186995,53.1319813267782
0.187495,53.2081077936614
0.187995,53.2455505800933
0.188495,53.332917622607
0.188995,53.3978188413308
0.189495,53.4229302364071
0.189995,53.4758959167879
0.190495,53.5039136048804
0.190995,53.568129969285
0.191495,53.6465925010965
0.191995,53.6691952346978
0.192495,53.7802351622583
0.192995,53.7930787397489
0.193495,53.8552844906024
0.193995,53.9128119475579
0.194495,53.9610177953161
0.194995,54.0478142324033
0.195495,54.0838337891665
0.195995,54.0803048736667
0.196495,54.1436225913238
0.196995,54.2228233780475
0.197495,54.2632484427466
0.197995,54.3398628509232
0.198495,54.376629846319
0.198995,54.4185011766895
0.199495,54.4928667733058
0.199995,54.5121509958086
0.200495,54.5828331948405
0.200995,54.6390697796713
0.201495,54.6836346096528
0.201995,54.7166589616193
0.202495,54.8165501071171
0.202995,54.8470835021674
0.203495,54.8854511898313
0.203995,54.9663325938427
0.204495,54.9842319781637
0.204995,55.0302816843598
0.205495,55.1321792173026
0.205995,55.1393517702338
0.206495,55.1677565713864
0.206995,55.26824117095
0.207495,55.2971359627792
0.207995,55.3377509422457
0.208495,55.3854182684496
0.208995,55.416426641946
0.209495,55.4673673683425
0.209995,55.5455013309187
0.210495,55.6023162319513
0.210995,55.5964702106956
0.211495,55.6739731821076
0.211995,55.7966826003074
0.212495,55.7579362839625
0.212995,55.7976165575762
0.213495,55.9053553165555
0.213995,55.9416555983737
0.214495,55.9241959818121
0.214995,56.0508228273923
0.215495,56.0992587964876
0.215995,56.0706461495011
0.216495,56.1597621797913
0.216995,56.2228284931465
0.217495,56.2794641276526
0.217995,56.3135635380213
0.218495,56.3959827001581
0.218995,56.3668319340587
0.219495,56.4809659510012
0.219995,56.4780108006598
0.220495,56.5971682256408
0.220995,56.5944585944564
0.221495,56.6496998878
0.221995,56.6191228298696
0.222495,56.6773581374075
0.222995,56.7916883686225
0.223495,56.8664157732667
0.223995,56.8880416055383
0.224495,56.8751140187172
0.224995,56.9508160168768
0.225495,57.0311891456589
0.225995,57.140716309623
0.226495,57.1386480747732
0.226995,57.1359935465806
0.227495,57.1829333926711
0.227995,57.2812485640853
0.228495,57.265043143511
0.228995,57.2962873288183
0.229495,57.3365676943873
0.229995,57.4310430339712
0.230495,57.5509908790516
0.230995,57.5245644093661
0.231495,57.5434951007479
0.231995,57.602173593092
0.232495,57.6128008960336
0.232995,57.7505157190467
0.233495,57.7610434324298
0.233995,57.79204944045
0.234495,57.9191610910798
0.234995,57.9128668642282
0.235495,57.9507230199171
0.235995,58.0136395949862
0.236495,57.9901444385603
0.236995,58.1833815055679
0.237495,58.2005283325978
0.237995,58.2124024925561
0.238495,58.2996188403998
0.238995,58.2910914070057
0.239495,58.2860094066397
0.239995,58.351037970797
0.240495,58.3737280729816
0.240995,58.5273948256733
0.241495,58.5262256875596
0.241995,58.5641388091439
0.242495,58.5874103285978
0.242995,58.7568021161836
0.243495,58.8293611157337
0.243995,58.7913142576937
0.244495,58.8038349195768
0.244995,58.9062548005383
0.245495,58.9647001654476
0.245995,58.9478880152036
0.246495,58.9565574120551
0.246995,59.0467454799915
0.247495,59.1438347001611
0.247995,59.1997006199802
0.248495,59.1610516369143
0.248995,59.3356091618002
0.249495,59.2845602064671
0.249995,59.3516394455322
0.250495,59.4156923644282
0.250995,59.5085842652951
0.251495,59.3981034618471
0.251995,59.638631817778
0.252495,59.681783010561
0.252995,59.7177921585024
0.253495,59.7568086219814
0.253995,59.8000097615716
0.254495,59.6968226206406
0.254995,59.8516796739401
0.255495,59.8609075218959
0.255995,59.9354959824296
0.256495,59.9322163633137
0.256995,60.101772411461
0.257495,60.0816108796935
0.257995,60.2189517013101
0.258495,60.1904131635621
0.258995,60.244576999749
0.259495,60.391670263926
0.259995,60.3611321526977
0.260495,60.4162788584306
0.260995,60.4678606517468
0.261495,60.5509217711624
0.261995,60.5364550700186
0.262495,60.6146668257469
0.262995,60.7534233941433
0.263495,60.7954435970295
0.263995,60.7660557868721
0.264495,60.9079124709723
0.264995,60.7798867591684
0.265495,60.9595361969046
0.265995,61.1146088023088
0.266495,61.1230629991525
0.266995,61.2337452374958
0.267495,61.2106641378261
0.267995,61.3589748962243
0.268495,61.4456147791589
0.268995,61.4623508252162
0.269495,61.4403729129518
0.269995,61.5190076942848
0.270495,61.582442348764
0.270995,61.6545479442333
0.271495,61.6592757216792
0.271995,61.6823072141401
0.272495,61.8924611701299
0.272995,61.955427046752
0.273495,61.9300710525894
0.273995,61.8959771591362
0.274495,62.064585527824
0.274995,62.0762503749717
0.275495,62.2014865616766
0.275995,62.2845217147652
0.276495,62.4425318596559
0.276995,62.5359072711604
0.277495,62.4441987913662
0.277995,62.438833031452
0.278495,62.6189199942945
0.278995,62.7509932942905
0.279495,62.8854072896817
0.279995,62.7991194551038
0.280495,62.8518766855317
0.280995,62.9168188591802
0.281495,62.9104644562004
0.281995,63.1069564527013
0.282495,63.2852641841671
0.282995,63.2750388363977
0.283495,63.3667062943544
0.283995,63.1445715274107
0.284495,63.550599643357
0.284995,63.5135292989699
0.285495,63.6178992980193
0.285995,63.7814369430372
0.286495,63.8056087914683
0.286995,64.0238026900012
0.287495,63.9233925663771
0.287995,64.1993352811018
0.288495,63.991174548376
0.288995,64.2169463753755
0.289495,64.4245294012803
0.289995,64.6950297941105
0.290495,64.4615640742107
0.290995,64.5540608293579
0.291495,64.6110777125509
0.291995,64.7931715981834
0.292495,65.0323967314229
0.292995,65.0303921920964
0.293495,64.8740051363762
0.293995,64.8877360291579
0.294495,65.4180193206091
0.294995,65.4759477804822
0.295495,65.4977962596823
0.295995,65.534349187727
0.296495,65.708627022481
0.296995,65.6719174836242
0.297495,65.9863095031397
0.297995,65.8781642680103
0.298495,65.955950449624
0.298995,66.3195495801927
0.299495,66.4064075838179
0.299995,66.4523550810271
0.300495,66.6741422876688
0.300995,66.8660391943211
0.301495,66.9290808474055
0.301995,66.7719961690647
0.302495,67.1178671797256
0.302995,67.4139323499882
0.303495,67.47726018945
0.303995,67.6586572117543
0.304495,67.5205887943838
0.304995,67.602280245454
0.305495,68.0595317894739
0.305995,68.0621100556097
0.306495,67.9572733799146
0.306995,68.4624478801992
0.307495,68.5738205382215
0.307995,68.4512164897888
0.308495,68.736997335171
0.308995,68.9913350957137
0.309495,69.2383939834284
0.309995,69.294161568676
0.310495,69.7397975103814
0.310995,69.6392562132391
0.311495,69.6470642587433
0.311995,70.0456498693197
0.312495,70.1014651340085
0.312995,70.0598278091978
0.313495,70.3713642942059
0.313995,70.6157736264422
0.314495,70.8968111267794
0.314995,70.9468855970631
0.315495,71.1061185959231
0.315995,71.5244483645081
0.316495,71.3355127069131
0.316995,71.8378778395488
0.317495,71.9090047491639
0.317995,72.0007765061207
0.318495,72.4094407577409
0.318995,72.5187232576536
0.319495,72.6690161919211
0.319995,72.8936094762054
0.320495,73.0513986136446
0.320995,73.3745079290288
0.321495,73.3303518841677
0.321995,73.5595447184345
0.322495,74.3188709250225
0.322995,74.0032810806843
0.323495,74.3764209059824
0.323995,74.6723387959932
0.324495,74.5995849478529
0.324995,75.0343998408603
0.325495,75.3677529310234
0.325995,75.6053203395404
0.326495,75.8805282912103
0.326995,75.9575323223517
0.327495,76.0895236542202
0.327995,76.3803037022367
0.328495,76.5145463212964
0.328995,76.8687365757643
0.329495,77.3012949775137
0.329995,77.5135050651468
0.330495,77.6086245403544
0.330995,77.899997639398
0.331495,78.3610852012188
0.331995,78.3778837979115
0.332495,78.5633102178293
0.332995,79.0558707434692
0.333495,78.9420755808822
0.333995,79.1794256440484
0.334495,79.9651278970428
0.334995,79.8065071614675
0.335495,80.2339093251397
0.335995,80.5347870736577
0.336495,80.6372232990631
0.336995,80.9161100418735
0.337495,81.3073487200123
0.337995,81.5392124069021
0.338495,81.8622216793086
0.338995,82.0296576330298
0.339495,82.4716888317653
0.339995,82.5531563099543
0.340495,82.9039827610675
0.340995,83.2326682099282
0.341495,83.5780820687337
0.341995,83.9457278183181
0.342495,83.9101647300768
0.342995,84.4063774411526
0.343495,84.5245817995818
0.343995,85.0517757439952
0.344495,85.3140538851838
0.344995,85.4498601375314
0.345495,85.8185678333626
0.345995,86.0578939351791
0.346495,86.4261402982153
0.346995,86.5951486705359
0.347495,87.0750734021256
0.347995,87.319483195399
0.348495,87.5332247779533
0.348995,87.9586899299622
0.349495,88.2549976411533
0.349995,88.4879808707926
0.350495,88.9086586882286
0.350995,89.1450292080558
0.351495,89.4565849483459
0.351995,89.9170738255365
0.352495,89.8439949323983
0.352995,90.3725550705928
0.353495,90.7131349921178
0.353995,90.9702215244931
0.354495,91.5354090322843
0.354995,91.6587247358936
0.355495,92.0155084277115
0.355995,92.2476452321612
0.356495,92.9032639085381
0.356995,92.8001712660991
0.357495,93.3203894630828
0.357995,93.6756835059074
0.358495,94.077902386756
0.358995,94.2945305836601
0.359495,94.8042572335662
0.359995,95.141839646636
0.360495,95.4198178774832
0.360995,95.5582696280389
0.361495,95.9116255899439
0.361995,96.4732660150042
0.362495,96.961630828715
0.362995,97.0826318014216
0.363495,97.7155855683551
0.363995,97.8885397512531
0.364495,98.1502895263233
0.364995,98.70867007245
0.365495,98.7893227426531
0.365995,99.1250578922824
0.366495,99.6396357562429
0.366995,100.243246451422
0.367495,100.472298019179
0.367995,100.349054082741
0.368495,101.093736368722
0.368995,101.673618796094
0.369495,102.070340258914
0.369995,101.991663963675
0.370495,102.492912043493
0.370995,103.233034141279
0.371495,103.670661696898
0.371995,103.911112759782
0.372495,104.355804616153
0.372995,104.829543499763
0.373495,105.081599025147
0.373995,105.337203701509
0.374495,105.799071198731
0.374995,106.383818318355
0.375495,106.921473605548
0.375995,107.169125531685
0.376495,107.792573746651
0.376995,108.093645059683
0.377495,108.463736058098
0.377995,108.856499466405
0.378495,109.270024584293
0.378995,109.728985972848
0.379495,110.329854004764
0.379995,110.843803785861
0.380495,111.395900872857
0.380995,111.791385212592
0.381495,112.059920399058
0.381995,112.407741628386
0.382495,112.9090135828
0.382995,113.387576195386
0.383495,113.969115399903
0.383995,114.435949458377
0.384495,114.843420785525
0.384995,115.42965592221
0.385495,115.668567429338
0.385995,116.433766720331
0.386495,116.792216105983
0.386995,117.155755473935
0.387495,117.707219734826
0.387995,118.247367529761
0.388495,118.423776099596
0.388995,117.010116877029
0.389495,111.72400345575
0.389995,102.974880658625
0.390495,92.1398588981148
0.390995,84.0372993608113
0.391495,76.9797304556992
0.391995,69.9690752253348
0.392495,63.4254260101223
0.392995,59.0077556950769
0.393495,55.1930035932071
0.393995,51.6153650518937
0.394495,48.2759680868077
0.394995,44.7952838523956
0.395495,41.822249816807
0.395995,39.2511923409575
0.396495,37.1853730564937
0.396995,35.6151505384546
0.397495,34.4590822568448
0.397995,33.6184823640277
0.398495,32.704663837955
0.398995,31.2286055872971
0.399495,29.8580650474642
0.399995,28.7025911780542
0.400495,27.7241622898273
0.400995,26.8885771033619
0.401495,26.0572216832991
0.401995,25.1918592881836
0.402495,24.3693107184252
0.402995,23.6060095020508
0.403495,22.8305085230311
0.403995,22.0771157288494
0.404495,21.3952471416798
0.404995,20.6822673644882
0.405495,19.9330282738596
0.405995,19.0293511370222
0.406495,18.0365829966333
0.406995,16.9610857168884
0.407495,15.807749531791
0.407995,14.5763808684447
0.408495,13.2481435903782
0.408995,11.8302010937726
0.409495,10.3187148754536
0.409995,8.71519317067276
0.410495,7.02461847093032
0.410995,5.35079044894729
0.411495,3.73880848538459
0.411995,2.20913939741281
0.412495,0.784074755036312
0.412995,-0.660880227368324
0.413495,-2.18948864554104
0.413995,-3.89308932301261
0.414495,-5.75521346369898
0.414995,-7.72971462360719
0.415495,-9.77324139194579
0.415995,-11.7822802673642
0.416495,-13.6344584270743
0.416995,-14.917368927295
0.417495,-13.0935811643025
0.417995,-9.71441327639783
0.418495,-6.7229008541103
0.418995,-4.86143151607155
0.419495,-3.52422152285803
0.419995,-2.06932443039273
0.420495,-1.05197801098577
0.420995,-0.954809088633418
0.421495,-0.792982548911608
0.421995,-1.53029446573391
0.422495,-1.45843070290718
0.422995,-1.43253562263833
0.423495,-1.37050041361779
0.423995,-1.27986914189165
0.424495,-1.01884563936346
0.424995,-0.802816693601908
0.425495,-0.762998736000083
0.425995,-0.518596754259828
0.426495,-0.456396733132625
0.426995,-0.137112869740982
0.427495,0.00158566198590352
0.427995,-0.000767399001795184
0.428495,0.10995801197072
0.428995,0.0321163846139885
0.429495,0.317912026919751
0.429995,0.733525654143606
0.430495,0.832035707143348
0.430995,1.02558650258799
0.431495,1.26521313031733
0.431995,1.35056521217192
0.432495,1.60930498492607
0.432995,1.79706404144685
0.433495,1.74397086753273
0.433995,1.65602174039685
0.434495,1.37113584976014
0.434995,1.14611077399265
0.435495,0.772928972648841
0.435995,0.547368542396362
0.436495,0.468080275221859
0.436995,0.309573478670411
0.437495,0.132120503214621
0.437995,-0.329169896459817
0.438495,-0.592740374761781
0.438995,-0.731869009072559
0.439495,-0.997254025725107
0.439995,-1.30572720682712
0.440495,-1.32240150930172
0.440995,-1.32373347995164
0.441495,-1.46487320121263
0.441995,-1.35032114339957
0.442495,-1.30170731934388
0.442995,-1.14226082113818
0.443495,-0.999981561833756
0.443995,-1.0390003714858
0.444495,-0.83778948853236
0.444995,-0.71380778130118
0.445495,-0.395507242960683
0.445995,-0.0544238605581587
0.446495,0.105747433998819
0.446995,0.292546791924437
0.447495,0.279347746676284
0.447995,0.39406408385793
0.448495,0.51988296839817
0.448995,0.551612324260654
0.449495,0.562470828753851
0.449995,0.774948658646713
0.450495,0.81287034580968
0.450995,0.637524824474733
0.451495,0.663191049874386
0.451995,0.467634044076521
0.452495,0.429307872988783
0.452995,0.501282267004377
0.453495,0.406268920012622
0.453995,0.251998357361371
0.454495,0.156540123730333
0.454995,0.00744607071374912
0.455495,-0.283849483062467
0.455995,-0.159257360971087
0.456495,-0.324368143930507
0.456995,-0.527712122600908
0.457495,-0.414579330330657
0.457995,-0.50630866021514
0.458495,-0.566065913960108
0.458995,-0.385820521757837
0.459495,-0.485061776792109
0.459995,-0.389056643800259
0.460495,-0.52721841420622
0.460995,-0.471404301426928
0.461495,-0.559058428258887
0.461995,-0.516893592555567
0.462495,-0.416224835743223
0.462995,-0.425060612150231
0.463495,-0.615953365041298
0.463995,-0.558507597931676
0.464495,-0.403975063581501
0.464995,-0.384313825178712
0.465495,-0.308269871608453
0.465995,-0.303307332800617
0.466495,-0.213223547648713
0.466995,-0.102245022611998
0.467495,-0.0142707429328958
0.467995,-0.0940786403166294
0.468495,0.0821542374773901
0.468995,0.23968104271028
0.469495,0.139126956206938
0.469995,0.310287967483344
0.470495,0.332971469364303
0.470995,0.318396680467422
0.471495,0.460026456941092
0.471995,0.278431443864801
0.472495,0.213898110008751
0.472995,0.218546836361874
0.473495,0.203574262823408
0.473995,0.0122441528263993
0.474495,0.0611403789840646
0.474995,-0.12356934722193
0.475495,0.0286508520539378
0.475995,0.0341699906548112
0.476495,0.0456870679856641
0.476995,0.00178417009767654
0.477495,0.0880975543532529
0.477995,0.213564368901239
0.478495,0.253000512831982
0.478995,0.27972052385778
0.479495,0.344643477627313
0.479995,0.189778840211125
0.480495,0.202253650256358
0.480995,-0.0166335288136753
0.481495,-0.0372655037684638
0.481995,0.00890990590555187
0.482495,-0.0702091596826448
0.482995,-0.101958120854116
0.483495,-0.169557893724724
0.483995,-0.310405371245501
0.484495,-0.308996793571443
0.484995,-0.331252919145496
0.485495,-0.289616938030717
0.485995,-0.227291120324695
0.486495,-0.202069167284764
0.486995,-0.185042332377413
0.487495,-0.140031974226028
0.487995,-0.0524739161491369
0.488495,-0.0224508230825189
0.488995,0.104571312335941
0.489495,0.292860960780262
0.489995,0.506791275580986
0.490495,0.678731195747569
0.490995,0.772328166102549
0.491495,0.922881319815293
0.491995,0.941363894494056
0.492495,0.993259850316773
0.492995,1.0493645109491
0.493495,1.03808350103512
0.493995,0.858961291815478
0.494495,0.963505560294673
0.494995,0.87549353814329
0.495495,0.714240304484443
0.495995,0.590099926293538
0.496495,0.444533230674814
0.496995,0.281371574643978
0.497495,0.168639407966049
0.497995,-0.0540209154531968
0.498495,-0.31163510862224
0.498995,-0.268908001847961
0.499495,-0.498333990116781
0.499995,-0.633845902398007