File: DATA&scripts/1.7-data/z0/1/1_fracture_stress_data.csv
Strain,Fracture Stress (GPa)
0.0,0.393095480577753
0.000495000000000098,1.0518525828554
0.000994999999999958,1.18453396734979
0.00149500000000011,1.55658075233741
0.00199499999999997,2.14766732377235
0.00249500000000012,1.91903066152565
0.00299499999999998,2.64620271732076
0.00349500000000014,2.86336742012672
0.003995,3.16014492592181
0.00449499999999986,3.5097036857902
0.00499500000000001,3.59577165012733
0.00549499999999987,4.22685524142193
0.00599500000000002,4.47115297745365
0.00649499999999988,4.65255321281733
0.00699500000000003,4.89145767830485
0.00749499999999989,5.46140088760712
0.00799500000000004,5.26172739220455
0.0084949999999999,5.91825735687202
0.00899500000000006,6.07157866462033
0.00949499999999992,6.06888249352278
0.00999500000000007,7.05962301474593
0.0104949999999999,6.94687260427343
0.0109950000000001,7.01592835299342
0.0114949999999999,7.64367763660793
0.0119950000000001,8.07232904204803
0.012495,7.95996645792791
0.0129950000000001,8.10628618036845
0.013495,9.06501437241794
0.0139950000000001,9.05730855304795
0.014495,9.18124991525
0.0149950000000001,9.60428788972235
0.015495,9.87658429557465
0.015995,10.4841460817001
0.016495,10.0291145423145
0.0169949999999999,10.472086188024
0.017495,11.1659618330729
0.0179949999999999,11.2442290791311
0.018495,11.3801142930832
0.0189949999999999,11.6574885483968
0.019495,12.4251672798455
0.0199949999999999,12.2508120906143
0.0204950000000001,12.5676241305278
0.0209949999999999,12.7537911388837
0.0214950000000001,13.2494138302127
0.0219949999999999,13.5926507522527
0.0224950000000001,13.6036692939101
0.0229949999999999,13.8086206432753
0.0234950000000001,14.0142227570576
0.0239949999999999,14.2745640797126
0.0244950000000001,14.9535249939519
0.024995,15.0305941029921
0.0254950000000001,15.3426064401561
0.025995,15.4276669068406
0.0264950000000001,15.6638006999439
0.026995,16.1518550832248
0.0274950000000001,16.3501195470138
0.027995,16.8570619893457
0.028495,17.0158989630112
0.028995,17.2770512196338
0.0294949999999999,17.2812169169763
0.029995,17.2403614599073
0.0304949999999999,17.7242166675472
0.030995,18.0598137211763
0.0314949999999999,18.5422210009726
0.031995,18.7804688541268
0.0324949999999999,18.7466620905396
0.0329950000000001,19.0414784716366
0.0334949999999999,19.1698546228904
0.0339950000000001,19.8234898713558
0.0344949999999999,20.1125798380139
0.0349950000000001,20.3588429591365
0.0354949999999999,20.7170504084273
0.0359950000000001,20.7676972670882
0.036495,20.8778117076884
0.0369950000000001,21.0689962456414
0.037495,21.0706182393046
0.0379950000000001,21.4494832464683
0.038495,21.5602190580367
0.0389950000000001,22.1926782243229
0.039495,22.2396956719132
0.039995,22.7354298115135
0.040495,23.0542075023027
0.0409949999999999,23.1952207561828
0.041495,23.4547561027015
0.0419949999999999,23.5822653416771
0.042495,23.8016204916428
0.0429949999999999,24.0885235904257
0.043495,24.0641463480322
0.0439949999999999,24.5789300059036
0.0444950000000001,24.3516856421643
0.0449949999999999,24.75293315583
0.0454950000000001,25.3045191264252
0.0459949999999999,25.5161120971614
0.0464950000000001,25.9046821872453
0.0469949999999999,26.1110996100661
0.0474950000000001,26.3097954818482
0.0479949999999999,26.7374277771104
0.0484950000000001,26.8550791969038
0.048995,27.264789222239
0.0494950000000001,27.1964703392981
0.049995,27.5160530758702
0.0504950000000001,27.7672728993128
0.050995,27.8383166357347
0.0514950000000001,28.1211491090073
0.051995,28.1616881602931
0.052495,28.6145416344652
0.052995,28.6932084862648
0.053495,28.8310992652515
0.053995,29.2710648133452
0.0544949999999999,29.2319667530108
0.054995,29.4963231100976
0.0554949999999999,29.7134320064943
0.0559950000000001,30.0115080890689
0.0564949999999999,30.2389246332941
0.0569950000000001,30.4086638779707
0.0574949999999999,30.7999930214859
0.0579950000000001,31.0046842595216
0.0584949999999999,31.2688551888758
0.0589950000000001,31.6549757447812
0.0594949999999999,31.7832093665534
0.0599950000000001,32.1543846794427
0.060495,32.2052523389468
0.0609950000000001,32.4857894794598
0.061495,32.7853266022427
0.0619950000000001,32.7861057019748
0.062495,33.21799094323
0.0629950000000001,33.2918502090075
0.063495,33.6094554438978
0.063995,33.898312447237
0.064495,33.7573180817125
0.064995,34.2363039615579
0.065495,34.2434314754508
0.0659949999999999,34.5400942352782
0.066495,34.8292182949122
0.0669949999999999,34.8216528742709
0.067495,35.1668330676388
0.0679949999999999,35.2352052977388
0.0684950000000001,35.5305861625714
0.0689949999999999,35.7877770507758
0.0694950000000001,35.8152716213999
0.0699949999999999,36.2103107475054
0.0704950000000001,36.2493901305314
0.0709949999999999,36.5333440438097
0.0714950000000001,36.5201434115049
0.0719949999999999,36.8292065134224
0.0724950000000001,37.1790733547289
0.072995,37.1501089417409
0.0734950000000001,37.5009159849441
0.073995,37.7117905954209
0.0744950000000001,37.7929596261381
0.074995,38.3821154411614
0.0754950000000001,38.3173079939053
0.075995,38.7070232103127
0.076495,38.8746630057632
0.076995,38.97341104763
0.0774949999999999,39.3502103074487
0.077995,39.2958167387134
0.0784949999999999,39.5149873627082
0.078995,39.6086658638429
0.0794949999999999,39.8208585811702
0.0799950000000001,40.3104208405079
0.0804949999999999,40.3415534317147
0.0809950000000001,40.532909997501
0.0814949999999999,40.8049268238327
0.0819950000000001,40.8688907883417
0.0824949999999999,41.0963099699759
0.0829950000000001,41.2138085521072
0.0834949999999999,41.6652468521688
0.0839950000000001,41.6531487956538
0.084495,41.8792348728509
0.0849950000000001,42.108731365035
0.085495,42.028279413486
0.0859950000000001,42.4081690479265
0.086495,42.5733251055815
0.0869950000000001,42.8204330853659
0.087495,43.0339514636567
0.0879950000000002,43.0361623913995
0.088495,43.3737491416872
0.088995,43.3693233287619
0.089495,43.5458183645038
0.089995,43.8911167399108
0.090495,44.0763201519274
0.0909949999999999,44.4430603661844
0.091495,44.3556339488027
0.0919949999999999,44.6493613825731
0.0924950000000001,44.6659234230566
0.0929949999999999,44.8255607838872
0.0934950000000001,45.2541389434875
0.0939949999999999,45.3918546337266
0.0944950000000001,45.5745504148155
0.0949949999999999,45.6853801012095
0.0954950000000001,45.7018258150097
0.095995,46.011903122337
0.0964950000000001,46.2182287978671
0.096995,46.4334066616182
0.0974950000000001,46.7675759437836
0.097995,46.5190986523237
0.0984950000000001,46.7069591895736
0.098995,46.9839926896672
0.0994950000000001,47.205147400127
0.099995,47.517443968899
0.100495,47.5715601733481
0.100995,47.6609495967399
0.101495,47.7120604795039
0.101995,48.1876161954834
0.102495,48.3645625227671
0.102995,48.3592590954255
0.103495,48.3977505372117
0.103995,48.6879963671672
0.104495,48.9873924015543
0.104995,49.0889240849966
0.105495,49.1854318791405
0.105995,49.2210123039565
0.106495,49.6045469666805
0.106995,49.7328871464664
0.107495,49.8497495089897
0.107995,49.8067693910878
0.108495,50.0641292710143
0.108995,50.4282678643342
0.109495,50.4934802243787
0.109995,50.5723287023691
0.110495,50.57374281786
0.110995,50.8810856498568
0.111495,51.0685763662263
0.111995,51.2185174444877
0.112495,51.4040128695428
0.112995,51.5850347913066
0.113495,51.6815042282602
0.113995,51.796669592719
0.114495,52.0316084302859
0.114995,52.1454510277202
0.115495,52.3366794734456
0.115995,52.6040760664092
0.116495,52.6758733980084
0.116995,52.7026788767548
0.117495,52.9443566866263
0.117995,53.1250155488638
0.118495,53.2829383429563
0.118995,53.3182171334282
0.119495,53.5335777683293
0.119995,53.5819343539206
0.120495,53.7301824175212
0.120995,53.9880822820918
0.121495,53.9132230768774
0.121995,54.1065854859144
0.122495,54.3677579225155
0.122995,54.418896084072
0.123495,54.7271196057152
0.123995,54.743581561576
0.124495,54.838221560167
0.124995,55.0637769944765
0.125495,55.211208586574
0.125995,55.3736628996241
0.126495,55.4061077035945
0.126995,55.6221084695024
0.127495,55.6658441280174
0.127995,55.6898010519533
0.128495,55.99560575338
0.128995,56.1326271479956
0.129495,56.2289445647138
0.129995,56.5747690347612
0.130495,56.595353349526
0.130995,56.637445107596
0.131495,56.6949344967973
0.131995,56.9128753781438
0.132495,57.092955685977
0.132995,57.2470863907261
0.133495,57.3630845680065
0.133995,57.3220501119214
0.134495,57.5471152994819
0.134995,57.8677929883144
0.135495,57.7609199778053
0.135995,57.9677627302022
0.136495,57.8518275500249
0.136995,58.2088313072371
0.137495,58.344044649328
0.137995,58.322486925212
0.138495,58.6598103600638
0.138995,58.7359172016733
0.139495,58.680499503596
0.139995,58.9663564081332
0.140495,58.8665270517855
0.140995,59.2712344739669
0.141495,59.2392872573052
0.141995,59.4609680247802
0.142495,59.5906668048767
0.142995,59.5142899260121
0.143495,59.7799716583153
0.143995,59.7863622170886
0.144495,60.0179544696784
0.144995,60.0664645490457
0.145495,60.1764935172522
0.145995,60.3557578610729
0.146495,60.4353370083515
0.146995,60.4485840870149
0.147495,60.5877272987545
0.147995,60.7508487550722
0.148495,60.8708082543322
0.148995,61.1236285827394
0.149495,60.9210534803906
0.149995,61.0422269070881
0.150495,61.3996756077447
0.150995,61.341397924316
0.151495,61.623292975001
0.151995,61.5195385768241
0.152495,61.8599937541713
0.152995,61.8851424973433
0.153495,61.8102721793178
0.153995,62.1391644625545
0.154495,62.1078201841461
0.154995,62.296267932636
0.155495,62.3561791000549
0.155995,62.5442335514051
0.156495,62.4444326344522
0.156995,62.8002465143238
0.157495,62.542788985012
0.157995,63.0374726107005
0.158495,62.8934857513617
0.158995,63.0974679064228
0.159495,63.1337784149993
0.159995,63.2015692200656
0.160495,63.2827052159544
0.160995,63.3490869908964
0.161495,63.4313762298306
0.161995,63.6768127102773
0.162495,63.7255650400814
0.162995,63.7657340942773
0.163495,63.9033270713796
0.163995,64.0174543506299
0.164495,64.0756902529727
0.164995,64.1817653095861
0.165495,64.2521793044103
0.165995,64.3315146207732
0.166495,64.5101554958282
0.166995,64.7001597102556
0.167495,64.6750157272008
0.167995,64.7838815154575
0.168495,64.7382847538633
0.168995,64.8877170585512
0.169495,65.0514997833408
0.169995,65.0467555991226
0.170495,65.2700076033954
0.170995,65.2004209595376
0.171495,65.4007471468986
0.171995,65.3411441474555
0.172495,65.5651248063834
0.172995,65.5411341517022
0.173495,65.8287014444199
0.173995,65.7652449578852
0.174495,65.7681116535004
0.174995,65.9283289416078
0.175495,65.8639986109888
0.175995,66.0849446903285
0.176495,66.2198670271033
0.176995,66.2286024999895
0.177495,66.4080796184492
0.177995,66.3102612490378
0.178495,66.6393739067297
0.178995,66.5676764159571
0.179495,66.7620601307796
0.179995,66.6466439854048
0.180495,66.8095991889195
0.180995,66.824906983629
0.181495,66.9634533464962
0.181995,67.0123573679087
0.182495,67.2210837055114
0.182995,66.9915558362138
0.183495,67.3883311963093
0.183995,67.1665732346271
0.184495,67.5091240438963
0.184995,67.4290468627077
0.185495,67.6861638995379
0.185995,67.6918489542115
0.186495,67.6095695433968
0.186995,67.8325649593425
0.187495,67.8572361525807
0.187995,68.1531164014358
0.188495,68.0374018102575
0.188995,68.1396268876371
0.189495,68.2888081624658
0.189995,68.1590335407111
0.190495,68.4152591995669
0.190995,68.3743895403134
0.191495,68.3388649419161
0.191995,68.5797390898788
0.192495,68.7196345029792
0.192995,68.5834122155304
0.193495,68.8934842162678
0.193995,68.7170420453357
0.194495,68.9159210416426
0.194995,69.1181165793119
0.195495,69.1778326233444
0.195995,68.9552685208612
0.196495,69.2069556645277
0.196995,69.1457339849793
0.197495,69.1197178166034
0.197995,69.5135955427594
0.198495,69.3356123770469
0.198995,69.5008510503376
0.199495,69.5369665275271
0.199995,69.607362929717
0.200495,69.6305935574008
0.200995,69.6925057060821
0.201495,69.7538806123786
0.201995,69.9847540995064
0.202495,69.9689026230519
0.202995,69.8015268213056
0.203495,70.1943693847175
0.203995,70.1626908510896
0.204495,69.9463877599848
0.204995,70.2455494899575
0.205495,70.3327327995724
0.205995,70.1844159803741
0.206495,70.2775128582879
0.206995,70.6827782082782
0.207495,70.4860694172879
0.207995,70.6731975771424
0.208495,70.5867262527192
0.208995,70.858293402084
0.209495,70.8743571686313
0.209995,70.8048316782925
0.210495,70.8948086092562
0.210995,71.032393005344
0.211495,71.1419610557917
0.211995,71.3335858794068
0.212495,71.2619330667389
0.212995,71.1809725066698
0.213495,71.4052569800134
0.213995,71.5085824436306
0.214495,71.4423078917749
0.214995,71.5993645205164
0.215495,71.5823528018701
0.215995,71.6436840597469
0.216495,71.6298789037074
0.216995,71.8445342844726
0.217495,71.7371151496216
0.217995,71.8942898216152
0.218495,71.9521525241125
0.218995,71.957431634071
0.219495,72.1150083237766
0.219995,71.979029795532
0.220495,72.2221203819744
0.220995,72.2640022312041
0.221495,72.3123885282266
0.221995,72.3936606247346
0.222495,72.498076374263
0.222995,72.4576522414267
0.223495,72.3771742124478
0.223995,72.5670564800275
0.224495,72.6702424460436
0.224995,72.573550993103
0.225495,72.6379699862644
0.225995,72.9918868692709
0.226495,72.927023465871
0.226995,72.6207842075646
0.227495,73.1827326539171
0.227995,73.363031516256
0.228495,72.9349401515431
0.228995,73.11597693567
0.229495,73.1564568401775
0.229995,73.4670729433885
0.230495,73.5422909444668
0.230995,73.386475717026
0.231495,73.363121004302
0.231995,73.384345852064
0.232495,73.5923076084512
0.232995,74.1487580819983
0.233495,73.750415455511
0.233995,73.5283016224202
0.234495,73.9202644518356
0.234995,73.9868124688504
0.235495,73.9264208379248
0.235995,73.7154938663856
0.236495,73.990795948575
0.236995,74.5856664912566
0.237495,74.0655813338477
0.237995,74.5213228097607
0.238495,74.32713015628
0.238995,74.8781266667686
0.239495,74.3208592608611
0.239995,74.7139881423242
0.240495,74.6501164733517
0.240995,74.8637724260687
0.241495,74.4637149849793
0.241995,74.9218693395074
0.242495,74.8819153575288
0.242995,75.4121663751563
0.243495,74.9268744674674
0.243995,74.8447397076668
0.244495,75.1183463912887
0.244995,75.1695588850663
0.245495,75.0486441752504
0.245995,75.4265753156614
0.246495,75.5647698453382
0.246995,75.8929770628818
0.247495,75.6763900598266
0.247995,75.4650362006852
0.248495,75.744094128355
0.248995,76.2841428873145
0.249495,76.0963583776949
0.249995,75.7726889507857
0.250495,75.865051956803
0.250995,75.8403072467449
0.251495,76.1294520620897
0.251995,75.6335324289424
0.252495,76.2666483650274
0.252995,76.1192054793421
0.253495,76.4670845901748
0.253995,76.131381623023
0.254495,76.3154013172847
0.254995,76.4889954697905
0.255495,76.5445575391517
0.255995,76.6463141810848
0.256495,76.6177098769592
0.256995,76.5661939408853
0.257495,76.9292154395797
0.257995,76.9735679814117
0.258495,77.278162226949
0.258995,77.3236355252569
0.259495,76.711572504689
0.259995,76.8117795431778
0.260495,76.9085898070218
0.260995,77.0188108838422
0.261495,77.8286815055029
0.261995,77.4128110086094
0.262495,77.3617061376006
0.262995,77.309687270166
0.263495,78.1039297260045
0.263995,77.9853191661298
0.264495,77.6891386732565
0.264995,77.4480075183968
0.265495,77.8379139582948
0.265995,78.0106318317115
0.266495,78.0112385203291
0.266995,78.2873634346789
0.267495,78.395559756324
0.267995,78.1896981002266
0.268495,78.4155783799488
0.268995,78.3772421168916
0.269495,78.4365518653021
0.269995,78.6030795713986
0.270495,78.8542477227018
0.270995,79.1387744253675
0.271495,78.9070804403
0.271995,78.7844174211462
0.272495,78.9649879475577
0.272995,78.9210787137669
0.273495,79.1107788341669
0.273995,79.5013874340737
0.274495,79.7764991546999
0.274995,79.9669235949292
0.275495,79.8585873239373
0.275995,79.8424347043468
0.276495,79.7344471239947
0.276995,79.5219906624885
0.277495,80.0138630725895
0.277995,79.6704432404633
0.278495,80.1750850615875
0.278995,79.8401576251794
0.279495,80.3923126477878
0.279995,80.5811827377877
0.280495,80.291643208497
0.280995,80.5428265114447
0.281495,80.2406208957531
0.281995,81.0028874830857
0.282495,80.9396294857698
0.282995,80.6198579817667
0.283495,81.2687277132182
0.283995,81.5650612965528
0.284495,81.2643025905972
0.284995,81.0995485821238
0.285495,81.2024882072636
0.285995,81.4137476558803
0.286495,81.134968647702
0.286995,80.8896134560077
0.287495,81.5491437562808
0.287995,81.8543420864071
0.288495,81.6068520970462
0.288995,81.9804781809226
0.289495,81.9451929249963
0.289995,82.266617557342
0.290495,81.4710454722837
0.290995,82.8590051015485
0.291495,82.1329791838527
0.291995,83.0152364280216
0.292495,82.9251066151864
0.292995,82.8088050484348
0.293495,83.2582218812655
0.293995,83.1396513381328
0.294495,83.6040709060703
0.294995,83.429471577221
0.295495,82.9133934716567
0.295995,83.8457856870612
0.296495,83.6692650624203
0.296995,84.0049312526257
0.297495,84.7380291012021
0.297995,84.4929240755653
0.298495,84.7480386530233
0.298995,84.3828294528268
0.299495,83.7260445917698
0.299995,85.2133117429117
0.300495,85.3585858397375
0.300995,85.2866578457131
0.301495,85.0149662446202
0.301995,85.179276270818
0.302495,85.9441486080929
0.302995,85.8221937418103
0.303495,86.4176547321966
0.303995,86.2079066191291
0.304495,86.3389409567765
0.304995,86.1267311049167
0.305495,87.0061003674192
0.305995,86.9537952792608
0.306495,87.8070400755695
0.306995,87.2290699804834
0.307495,87.2670766593205
0.307995,87.8033589688153
0.308495,87.967027148265
0.308995,88.0801470364362
0.309495,88.356630830527
0.309995,87.8961260239901
0.310495,89.2431387329292
0.310995,89.045466531244
0.311495,88.8118487457972
0.311995,89.501294034078
0.312495,89.5407481098958
0.312995,89.2616283684742
0.313495,90.9771880437643
0.313995,89.9515368335612
0.314495,90.2977652210939
0.314995,90.4668858963088
0.315495,90.3156161479958
0.315995,90.5948702532828
0.316495,91.571519651074
0.316995,91.1294016489062
0.317495,92.3424559328561
0.317995,91.2263073355249
0.318495,92.9530446117373
0.318995,92.8062092842015
0.319495,92.2880821614484
0.319995,93.1271728010861
0.320495,93.0433979260383
0.320995,93.9840616889183
0.321495,93.9107236477026
0.321995,93.6638171821431
0.322495,94.3084515922213
0.322995,94.2552380867013
0.323495,95.7144555780437
0.323995,94.2764473908251
0.324495,95.6401829190137
0.324995,95.5046407654827
0.325495,94.9597826507808
0.325995,95.85831156389
0.326495,97.2856291804744
0.326995,96.3226197737136
0.327495,97.9080433270624
0.327995,96.6451569171759
0.328495,97.8265755389007
0.328995,97.5633936776545
0.329495,98.0329655811142
0.329995,99.2549798358008
0.330495,97.6327196628671
0.330995,99.2042316677392
0.331495,100.158673382179
0.331995,100.286250548586
0.332495,100.148516035101
0.332995,100.586385585222
0.333495,100.920335619758
0.333995,101.782502684697
0.334495,101.721403091907
0.334995,102.058170469111
0.335495,101.552098427253
0.335995,102.591858612023
0.336495,103.305118023542
0.336995,103.461604428826
0.337495,103.483830541603
0.337995,103.591761370757
0.338495,104.963146568514
0.338995,105.385762129086
0.339495,104.527247155028
0.339995,106.884665171202
0.340495,104.964400938506
0.340995,106.450776508218
0.341495,106.638312934482
0.341995,107.637583532913
0.342495,107.188244638793
0.342995,107.713052181726
0.343495,108.779196479942
0.343995,107.09345891204
0.344495,109.3392218029
0.344995,108.675441142468
0.345495,109.777958870015
0.345995,109.952911372211
0.346495,110.439825543678
0.346995,111.029046818974
0.347495,110.608624265817
0.347995,112.691537746281
0.348495,111.602903134404
0.348995,111.622386650659
0.349495,113.05072184605
0.349995,112.958600433268
0.350495,114.405917501475
0.350995,113.488883976543
0.351495,115.726136203352
0.351995,115.417797510177
0.352495,114.031668882522
0.352995,115.546936505173
0.353495,115.959458078647
0.353995,115.898285295046
0.354495,117.125215995949
0.354995,117.285474567483
0.355495,117.088583750075
0.355995,117.413829015055
0.356495,118.769634593404
0.356995,119.016694772742
0.357495,118.93206887944
0.357995,120.392718261869
0.358495,120.231194041099
0.358995,119.635216818474
0.359495,121.619492596279
0.359995,121.424378932032
0.360495,120.74920053773
0.360995,122.320684944916
0.361495,123.514126522543
0.361995,122.905368939068
0.362495,123.182627306604
0.362995,125.021343173962
0.363495,124.117630906368
0.363995,124.73438055567
0.364495,125.222150383477
0.364995,125.712093799712
0.365495,127.164821756333
0.365995,127.275248716941
0.366495,126.924162247369
0.366995,127.925368864221
0.367495,127.664330149943
0.367995,128.770832151412
0.368495,130.049797161773
0.368995,130.205176848586
0.369495,129.850400302389
0.369995,130.91021039517
0.370495,131.120792348996
0.370995,131.595230590942
0.371495,131.773063729218
0.371995,132.831512276858
0.372495,133.679239168807
0.372995,134.086247458995
0.373495,133.583084443657
0.373995,135.174168825943
0.374495,134.814411368679
0.374995,137.447335414771
0.375495,137.923876370368
0.375995,137.635623611379
0.376495,138.547208080136
0.376995,139.238853632167
0.377495,138.601741449171
0.377995,138.852283145569
0.378495,138.311954859262
0.378995,140.276880431603
0.379495,141.580754267391
0.379995,141.026211881521
0.380495,141.996426802692
0.380995,142.657864214519
0.381495,142.870652558798
0.381995,143.448742536147
0.382495,144.178523457451
0.382995,144.990826999749
0.383495,145.549981351418
0.383995,146.034236220524
0.384495,146.647714722075
0.384995,147.228957385648
0.385495,148.390848780137
0.385995,148.496779089207
0.386495,149.258537095142
0.386995,148.928256438832
0.387495,150.603816763459
0.387995,151.101703627851
0.388495,152.558465878128
0.388995,152.330343723915
0.389495,153.182949527298
0.389995,154.490546423193
0.390495,155.217823370971
0.390995,154.866770974015
0.391495,155.143992981398
0.391995,155.103470969756
0.392495,156.410362976855
0.392995,156.994873288346
0.393495,158.630700520577
0.393995,158.477418175187
0.394495,160.148304093073
0.394995,158.550737219883
0.395495,133.460234741454
0.395995,94.6691623070436
0.396495,48.2985887152384
0.396995,18.0155047888438
0.397495,-0.903625048577058
0.397995,-5.9647387797059
0.398495,3.40515967898771
0.398995,9.46620784070078
0.399495,5.96445616754264
0.399995,-0.13296536035978
0.400495,0.231416528295448
0.400995,6.19205955686061
0.401495,7.46878378106276
0.401995,3.21450959664422
0.402495,0.831947898146265
0.402995,2.26746769935004
0.403495,5.09996438513262
0.403995,5.27650737819389
0.404495,2.8448217697031
0.404995,1.63513370710158
0.405495,3.41583769154514
0.405995,4.54568370708793
0.406495,3.96160212101288
0.406995,2.31520231077691
0.407495,1.87936223820439
0.407995,3.36932358536748
0.408495,4.34884525674294
0.408995,3.27411599925054
0.409495,2.95097264661386
0.409995,3.04837657961091
0.410495,4.76041903201789
0.410995,4.41302255227183
0.411495,3.51566032134976
0.411995,2.51825816192549
0.412495,3.61307164404078
0.412995,4.84303644635766
0.413495,3.65455852762912
0.413995,3.29944243308503
0.414495,3.52609778003252
0.414995,3.89335048594861
0.415495,3.96208324795217
0.415995,3.65746586393646
0.416495,4.1526357456135
0.416995,4.0528995808569
0.417495,4.79460089265963
0.417995,3.48233622200441
0.418495,4.31915188831628
0.418995,3.86530885815199
0.419495,4.08942994719005
0.419995,4.40450236459206
0.420495,3.70348696537532
0.420995,3.47622768652372
0.421495,4.05369230931461
0.421995,3.82506388915184
0.422495,3.97273119502936
0.422995,3.63526208020241
0.423495,4.06474435219859
0.423995,4.0533478471602
0.424495,3.81894197516877
0.424995,3.30580440853243
0.425495,3.76669683087275
0.425995,4.91200197844127
0.426495,3.64111041611434
0.426995,3.19496470054621
0.427495,3.54483338300667
0.427995,4.44165720818421
0.428495,4.12931961370611
0.428995,3.32363846820616
0.429495,3.36458222101047
0.429995,4.08998136394979
0.430495,4.81880044129265
0.430995,4.22197372385953
0.431495,3.77849584271542
0.431995,2.99877157355829
0.432495,4.17559640740575
0.432995,4.47558983764613
0.433495,4.67714073105955
0.433995,3.68553056521782
0.434495,3.5833943096271
0.434995,4.43413951738324
0.435495,4.61768136070751
0.435995,3.94220681302016
0.436495,4.24339492551217
0.436995,4.38876832285353
0.437495,4.87444166901428
0.437995,4.77701697597452
0.438495,4.58574227062874
0.438995,4.70818381630988
0.439495,4.67250192199627
0.439995,4.85152416548325
0.440495,4.93630937207165
0.440995,4.97233615307848
0.441495,4.89342650477619
0.441995,5.2866289750657
0.442495,5.14379438305939
0.442995,4.72532822184173
0.443495,4.44780263130041
0.443995,5.022023666935
0.444495,4.90954705671452
0.444995,4.52896705126003
0.445495,3.85373160220551
0.445995,4.73009302254836
0.446495,4.22607816133849
0.446995,5.01525234496306
0.447495,4.93299867767571
0.447995,4.64678648191261
0.448495,4.61877294803678
0.448995,4.74191147582528
0.449495,4.58088814096881
0.449995,4.60855764724139
0.450495,5.17254111599143
0.450995,5.32736716360222
0.451495,4.83811249264962
0.451995,5.18886917541312
0.452495,5.42083655287993
0.452995,5.5832886628533
0.453495,5.64943455207022
0.453995,5.64279282911285
0.454495,5.58554421394508
0.454995,5.42186368500141
0.455495,5.87099595382105
0.455995,5.747629294832
0.456495,5.67925695487082
0.456995,5.79144078669507
0.457495,5.72034569745273
0.457995,6.13346855066024
0.458495,6.16750768079148
0.458995,6.0127106444135
0.459495,5.7383463596822
0.459995,5.96431194764924
0.460495,5.91337890915124
0.460995,6.07768847849364
0.461495,6.50517202942068
0.461995,6.12227723690633
0.462495,5.75882074741385
0.462995,5.57096028449047
0.463495,5.96661893377807
0.463995,6.1015753252346
0.464495,5.87597898260023
0.464995,6.31609297117253
0.465495,5.56623719069083
0.465995,5.9542147114099
0.466495,5.99426052638724
0.466995,6.31234591270097
0.467495,6.21227594865532
0.467995,6.21530645500637
0.468495,6.58284939716191
0.468995,6.62667007190172
0.469495,6.45428379099697
0.469995,6.32332231183667
0.470495,6.67722010712474
0.470995,7.12253930485617
0.471495,6.71754046743052
0.471995,6.66691949960361
0.472495,6.5811145572253
0.472995,7.06251081035245
0.473495,7.47607847749696
0.473995,7.06069621169275
0.474495,6.75291346016014
0.474995,7.01793858701156
0.475495,7.20598484476283
0.475995,7.15684601972018
0.476495,6.75682062912963
0.476995,7.33803401666008
0.477495,7.08807131592212
0.477995,7.54698181277936
0.478495,7.21642977018447
0.478995,7.06606168995701
0.479495,7.623950888231
0.479995,7.04246456762984
0.480495,7.33928798248313
0.480995,7.16262458708061
0.481495,7.46294392440075
0.481995,7.55581366168857
0.482495,7.3447007826578
0.482995,6.99342111699166
0.483495,7.49928742771245
0.483995,7.76279960834782
0.484495,7.57186319376671
0.484995,7.7726633687715
0.485495,8.05089327693083
0.485995,7.91019743339633
0.486495,8.09012136457733
0.486995,7.72503386806619
0.487495,8.26006193949664
0.487995,7.78088725508166
0.488495,7.90976118164533
0.488995,8.17494525139943
0.489495,8.66194257519259
0.489995,8.61313085686251
0.490495,7.61091652350186
0.490995,8.22024653895614
0.491495,8.63360401590394
0.491995,8.37474835621857
0.492495,8.49987177321709
0.492995,8.29663510027549
0.493495,8.80896317277833
0.493995,8.89220500156314
0.494495,8.76302018900843
0.494995,8.12797181205472
0.495495,8.33165491822057
0.495995,9.01697130240974
0.496495,8.57226051070385
0.496995,8.79727096762082
0.497495,7.60387557968987
0.497995,4.82652421144606
0.498495,3.61506499251976
0.498995,4.02599366042201
0.499495,5.03669566184897
0.499995,5.28213084617095
0.500495,3.64228498106388
0.500995,3.27372484823081
0.501495,4.26424108760999
0.501995,4.33577419899881
0.502495,4.1780591790431
0.502995,2.86087107082775
0.503495,3.4266489470612
0.503995,4.38888929187374
0.504495,4.00517208797077
0.504995,3.6320063106872
0.505495,2.74991448099327
0.505995,4.07273258981983
0.506495,4.26218636290909
0.506995,4.18576074789328
0.507495,3.61270337132992
0.507995,2.87799106412946
0.508495,4.44105136420045
0.508995,4.44560997184335
0.509495,3.40103767685625
0.509995,3.14710926344432
0.510495,3.66025209035637
0.510995,4.39252444814892
0.511495,3.83231688765684
0.511995,3.78837075816128
0.512495,3.89965467761692
0.512995,4.16786148334754
0.513495,4.3058919562348
0.513995,3.90622407620539
0.514495,3.7187710462851
0.514995,3.25976408108388
0.515495,4.35300988719392
0.515995,4.10377883236371
0.516495,4.18337017264633
0.516995,3.99971898126443
0.517495,3.82255195416691
0.517995,3.71736442557369
0.518495,3.89675988418783
0.518995,3.90998292821787
0.519495,3.88961129876593
0.519995,4.22443965838106
0.520495,3.82062222176693
0.520995,3.80487078828846
0.521495,4.03585060133801
0.521995,4.35240763422051
0.522495,3.61735268285988
0.522995,3.94760805448574
0.523495,4.5970027436003
0.523995,4.60140382481988
0.524495,4.01692088241893
0.524995,3.57980606378982
0.525495,4.54248795935224
0.525995,4.50109035647251
0.526495,4.51431087714423
0.526995,3.74282577959524
0.527495,3.93914031997906
0.527995,4.77946009724334
0.528495,4.46755989768034
0.528995,3.78815573797078
0.529495,4.12739020368809
0.529995,3.88978064171825
0.530495,4.93660000324883
0.530995,4.45983202967765
0.531495,4.48948574138381
0.531995,4.74342681975736
0.532495,4.40581058089027
0.532995,4.61605192209482
0.533495,4.77967543844536
0.533995,4.97069251833318
0.534495,4.53178322880809
0.534995,4.61674471878752
0.535495,4.52981502202166
0.535995,4.68784236033751
0.536495,5.2628187624304
0.536995,4.675731363739
0.537495,4.86299954660109
0.537995,4.51873494395925
0.538495,4.42657957239096
0.538995,5.15887185407202
0.539495,5.31619438692725
0.539995,4.99152634908043
0.540495,4.54156927328262
0.540995,5.03609717326388
0.541495,5.313717526914
0.541995,5.36386925530574
0.542495,5.41616038690247
0.542995,4.58053409518811
0.543495,5.2045697879149
0.543995,5.23136388386575
0.544495,5.35950216639616
0.544995,5.17765205368688
0.545495,5.41140364509326
0.545995,5.82000604336303
0.546495,5.40760307774686
0.546995,5.61711323005021
0.547495,5.25762599711104
0.547995,5.53858842833721
0.548495,5.85038124288594
0.548995,5.47328316136047
0.549495,5.66156433890684
0.549995,4.86305024453091
0.550495,6.07644258660018
0.550995,6.09752169208738
0.551495,5.93792360778924
0.551995,6.00499964411963
0.552495,5.62630236825921
0.552995,5.7757172959358
0.553495,6.378500301543
0.553995,6.20037525668648
0.554495,5.54658022021765
0.554995,5.73421291939865
0.555495,6.14958962590381
0.555995,6.24285880934363
0.556495,5.99437261749458
0.556995,6.17644147082549
0.557495,6.21366096768823
0.557995,6.25305413345135
0.558495,6.43469970807152
0.558995,6.05263520942228
0.559495,6.18229071072501
0.559995,6.20915355434372
0.560495,6.52622961772817
0.560995,6.39866965340736
0.561495,6.26221256634564
0.561995,6.2977309278732
0.562495,6.73837553470153
0.562995,7.01521097939624
0.563495,6.56006893878277
0.563995,7.10763590623845
0.564495,6.73786232381716
0.564995,7.19203899640852
0.565495,6.84340586452579
0.565995,6.96606511345512
0.566495,6.70036402474217
0.566995,7.31583810897255
0.567495,6.89355662990136
0.567995,6.57230398178884
0.568495,6.83774297903044
0.568995,6.89508567052792
0.569495,7.23514260610791
0.569995,7.30981595959762
0.570495,7.30922015602023
0.570995,7.36950421388098
0.571495,7.57331092497429
0.571995,7.12640691883677
0.572495,7.15743736474268
0.572995,7.00038016150617
0.573495,7.0769640822253
0.573995,7.07115447771636
0.574495,7.71232856097159
0.574995,7.68882292546484
0.575495,7.62704242895797
0.575995,7.47134808664587
0.576495,7.58023535800844
0.576995,7.26000055564027
0.577495,7.47670795257737
0.577995,7.72758365703103
0.578495,7.83136816990059
0.578995,7.58922327252227
0.579495,7.80425314800214
0.579995,7.56880979623627
0.580495,8.07447434795321
0.580995,7.62235892041644
0.581495,8.79683797460644
0.581995,8.31971453428457
0.582495,7.69268325776421
0.582995,7.76036074546036
0.583495,8.06831507010461
0.583995,8.17689710770586
0.584495,8.29906627719501
0.584995,8.40218192258289
0.585495,8.02128477814106
0.585995,8.29263994283627
0.586495,7.84983244428738
0.586995,7.87248158772615
0.587495,8.50086335762568
0.587995,8.44234531080899
0.588495,8.55661700691656
0.588995,7.85430869414895
0.589495,7.94787289108857
0.589995,8.69342107324234
0.590495,9.19642473118857
0.590995,8.9484748821801
0.591495,8.01219925796095
0.591995,8.20508702411306
0.592495,8.78984350227635
0.592995,9.0850305896372
0.593495,8.30734909539091
0.593995,7.63960380220998
0.594495,1.28346825060555
0.594995,-2.45463083435568
0.595495,-2.63724619703037
0.595995,0.270441156954566
0.596495,1.76794719360103
0.596995,0.383405888383984
0.597495,-1.02519766709494
0.597995,-0.549697279640876
0.598495,0.647130997393828
0.598995,0.328318946931243
0.599495,-0.642205029773108
0.599995,-0.174676068611388
0.600495,0.906703267664461
0.600995,0.657217726913369
0.601495,-0.66453723548888
0.601995,-1.42488758089436
0.602495,0.0130273503307916
0.602995,0.784255745139337
0.603495,0.485295195587193
0.603995,-0.774098183719695
0.604495,-0.870074333481895
0.604995,0.36477501050172
0.605495,0.539229637154062
0.605995,0.597057882816528
0.606495,-0.219699372635413
0.606995,-0.460805617991599
0.607495,0.256308179471245
0.607995,0.412097487823151
0.608495,-0.251427774642392
0.608995,-0.565333496117529
0.609495,0.266267901954812
0.609995,0.371302737696562
0.610495,-0.0544718892643086
0.610995,-0.863888963812494
0.611495,-0.56365524548113
0.611995,0.604959506337384
0.612495,0.804512923073443
0.612995,-0.132089738021808
0.613495,-0.643296070096669
0.613995,-0.0369640268953904
0.614495,0.511066381756898
0.614995,-0.039627710119514
0.615495,0.13415850078179
0.615995,-0.348920257603718
0.616495,0.191405514723108
0.616995,-0.0550649050516737
0.617495,0.375058019144618
0.617995,-0.309127575568527
0.618495,0.303838790419066
0.618995,-0.010237760532689
0.619495,-0.0547477125850608
0.619995,-7.53733835082843e-05
0.620495,-0.598211385631934
0.620995,0.240104041354264
0.621495,0.199675814980809
0.621995,0.29723286125398
0.622495,-0.220606965577939
0.622995,-0.369751407776988
0.623495,0.233985942484426
0.623995,0.0302722983358275
0.624495,0.086714150291295
0.624995,0.066575063751945
0.625495,-0.266315517185635
0.625995,0.50051424004956
0.626495,-0.276878809427286
0.626995,0.309609047673624
0.627495,-0.406491591988711
0.627995,0.0125010768041206
0.628495,0.476616170439557
0.628995,-0.0242787736456665
0.629495,-0.0928302273939485
0.629995,-0.302246000710842
0.630495,0.173652884740092
0.630995,0.070061640780767
0.631495,-0.137272397313583
0.631995,-0.189636629620822
0.632495,-0.460155730545961
0.632995,0.624483623410893
0.633495,-0.238908507175935
0.633995,0.276063640201599
0.634495,-0.40446340033988
0.634995,0.251250147853523
0.635495,-0.0129454474403512
0.635995,-0.121768998244621
0.636495,0.033166894047813
0.636995,-0.364817131069772
0.637495,-0.029190821139098
0.637995,-0.218123899753624
0.638495,0.528440930788225
0.638995,0.0373153795123376
0.639495,-0.293620809559456
0.639995,-0.637900038742426
0.640495,0.134491409002634
0.640995,0.488106864681879
0.641495,0.114594353258845
0.641995,-0.00853911202426196
0.642495,-0.372995680461006
0.642995,0.11516120363887
0.643495,0.280085034669214
0.643995,0.0583262719903476
0.644495,-0.138837034088805
0.644995,-0.421972064413536
0.645495,0.31033322148072
0.645995,0.226429344800396
0.646495,-0.00358547882534012
0.646995,-0.199246765400783
0.647495,-0.121538332980018
0.647995,0.167999414739619
0.648495,0.16424436117431
0.648995,-0.073567518166545
0.649495,0.046294296762975
0.649995,0.103283230498468
0.650495,0.46195501798699
0.650995,-0.322224341547935
0.651495,0.208610361718554
0.651995,-0.397851203888544
0.652495,-0.374224138587399
0.652995,0.189137870024104
0.653495,0.132501309964276
0.653995,0.216632970817909
0.654495,-0.301676165302564
0.654995,-0.405052542443621
0.655495,0.197085488406564
0.655995,0.148520489137556
0.656495,0.193267355637714
0.656995,-0.296718510337747
0.657495,-0.347663531667768
0.657995,0.0333464245777637
0.658495,0.197048600161464
0.658995,0.435620672667375
0.659495,-0.22018897380883
0.659995,-0.213177736896213
0.660495,-0.556286110171549
0.660995,0.524355141689363
0.661495,-0.155889646812111
0.661995,-0.158664429138982
0.662495,-0.0947833199647483
0.662995,0.145183553675376
0.663495,0.482988630306491
0.663995,-0.198102842303185
0.664495,0.219670634114705
0.664995,-0.0467089637444803
0.665495,-0.0359568187571387
0.665995,-0.149760120994748
0.666495,0.276508407424991
0.666995,0.355600703652808
0.667495,-0.327037541936982
0.667995,-0.0883681877449616