File: DATA&scripts/3.4-data/z/3/3_fracture_stress_data.csv
Strain,Fracture Stress (GPa)
0.0,-0.538037277951094
0.000494999999999903,2.04649164908238
0.000995000000000056,0.195215273989575
0.00149500000000001,2.64554486045107
0.00199499999999997,0.890960906418773
0.00249499999999993,2.46291498859803
0.00299499999999988,3.48430904464637
0.00349499999999984,1.21716233522475
0.003995,4.1472433838399
0.00449499999999995,1.82912517757289
0.00499499999999991,5.00924116583198
0.00549500000000006,2.65821346980291
0.00599500000000002,4.72274775674379
0.00649499999999998,3.84621562684733
0.00699499999999993,5.13610126584532
0.00749499999999989,4.77665091142237
0.00799499999999985,4.57476045392664
0.00849499999999981,6.47606448487652
0.00899499999999996,4.48461461635502
0.00949499999999992,7.1584647183776
0.00999500000000007,4.78274294881548
0.010495,7.64700955314145
0.010995,5.53698804710914
0.0114949999999999,7.7462777045614
0.0119949999999999,6.5884062700543
0.0124949999999999,7.68687616114446
0.0129949999999998,7.14806021943188
0.013495,7.69504839717421
0.0139949999999999,8.646758622502
0.0144950000000001,7.50173879425533
0.014995,9.36988347338871
0.015495,7.97633296677377
0.0159949999999999,9.93615334751417
0.0164949999999999,8.47256386253846
0.0169949999999999,10.1286022891762
0.0174949999999998,9.62531469802997
0.017995,10.0840849165088
0.0184949999999999,10.3893048848544
0.0189950000000001,10.0370222737473
0.019495,11.1684569190107
0.019995,10.3228107114917
0.020495,11.8743763605241
0.0209949999999999,10.8046191655481
0.0214949999999999,12.3172356534065
0.0219949999999998,11.4080988650432
0.022495,12.3165354766571
0.0229949999999999,12.2542071768975
0.0234949999999999,12.3313848769245
0.023995,13.0351929990419
0.024495,12.598124063864
0.024995,13.7756324085554
0.0254949999999999,12.8165965840571
0.0259949999999999,14.0311629136008
0.0264949999999998,13.3286826607405
0.026995,14.7233325463319
0.0274949999999999,14.0094898478975
0.0279949999999999,14.3961105927136
0.0284950000000001,14.5144832019049
0.028995,14.9418463633891
0.029495,15.7451343943946
0.0299949999999999,15.3165073300791
0.0304949999999999,16.152423434833
0.0309949999999998,15.2723650788935
0.031495,16.6254602235855
0.0319949999999999,15.902331547764
0.0324949999999999,16.8991100132969
0.0329950000000001,16.5709586320263
0.033495,17.0084987932095
0.033995,17.1485891750839
0.0344949999999999,17.1677575243567
0.0349949999999999,17.8600064360495
0.0354949999999998,17.4437320040741
0.0359949999999998,18.3682084913617
0.036495,17.9306311689683
0.0369949999999999,18.7488229753282
0.0374950000000001,18.5131054518124
0.037995,18.890964007302
0.038495,18.8042045056042
0.0389949999999999,19.2184409257373
0.0394949999999999,19.5392685729982
0.0399949999999999,19.4921079213733
0.0404949999999998,20.2309850600015
0.040995,19.6706421219597
0.0414949999999999,20.8293683472547
0.0419950000000001,20.1747648332277
0.042495,20.9817494782128
0.042995,20.7852810581272
0.0434949999999999,21.2337538038764
0.0439949999999999,21.0330880321916
0.0444949999999999,21.6131559803183
0.0449949999999998,21.692068091588
0.045495,21.7592772926786
0.0459949999999999,22.5019041106367
0.0464950000000001,22.1597481876126
0.046995,22.8244105801187
0.047495,22.6611306691337
0.0479949999999999,23.0651088131705
0.0484949999999999,23.222509650634
0.0489949999999999,23.3815774827779
0.0494949999999998,23.2384547774052
0.049995,23.7541874509646
0.0504949999999999,23.9919098046564
0.0509949999999999,23.9624491275866
0.051495,24.4510993690756
0.051995,24.5406407224937
0.052495,24.6936497269652
0.0529949999999999,24.9627129031194
0.0534949999999999,25.0914781256715
0.0539949999999998,25.2741240017042
0.054495,25.2377195755003
0.0549949999999999,25.7248658987624
0.0554949999999999,25.9546224104397
0.0559950000000001,26.0566664018127
0.056495,25.8760541876871
0.056995,26.3642764103506
0.0574949999999999,26.6837868955549
0.0579949999999999,26.8625489866695
0.0584949999999998,26.9547025474264
0.0589949999999998,26.9697373468832
0.0594949999999999,27.4352738152556
0.0599949999999999,27.5707450783297
0.0604950000000001,27.8340479783505
0.060995,28.0387217698162
0.061495,28.044172439806
0.0619949999999999,28.3165949050998
0.0624949999999999,28.6705113594058
0.0629949999999998,28.6395783183804
0.0634949999999998,28.8040519057628
0.063995,29.1666417380857
0.0644949999999999,29.3761531183694
0.0649950000000001,29.6143362984548
0.065495,29.4903868050916
0.065995,29.960315183036
0.0664949999999999,29.962887762539
0.0669949999999999,30.1944632032042
0.0674949999999998,30.3046716267965
0.0679949999999998,30.5036684014947
0.068495,30.5339480099841
0.0689949999999999,30.8442335598858
0.0694950000000001,30.9726831948362
0.069995,30.9324430165938
0.070495,31.5621919953899
0.0709949999999999,31.6105199555516
0.0714949999999999,31.8485043820433
0.0719949999999999,31.8082633796638
0.0724949999999998,32.1235962353559
0.072995,32.2820741979213
0.0734949999999999,32.4858610199129
0.0739950000000001,32.7076390745165
0.074495,32.822463752087
0.074995,33.232401025302
0.075495,32.9050456471676
0.0759949999999999,33.557525886601
0.0764949999999999,33.3348531613189
0.0769949999999998,33.9497137993713
0.077495,33.6148617831343
0.0779949999999999,34.2733117920783
0.0784949999999999,33.9109445907274
0.078995,34.5669783902316
0.079495,34.5047221097909
0.079995,34.5567444980299
0.0804949999999999,34.8504267679749
0.0809949999999999,34.7597573366457
0.0814949999999998,35.3063433713339
0.081995,35.1919798272454
0.0824949999999999,35.5177162479756
0.0829949999999999,35.6162780961007
0.083495,36.0678803257815
0.083995,35.911421152549
0.084495,36.2853789145289
0.0849949999999999,36.2516712600502
0.0854949999999999,36.4338815180091
0.0859949999999998,36.761089298437
0.0864949999999998,36.6816492645552
0.0869949999999999,37.1455726064541
0.0874949999999999,37.0285382429267
0.087995,37.2526302688083
0.088495,37.5757066848261
0.088995,37.6606517474233
0.0894949999999999,37.7199898699125
0.0899949999999999,37.6989394497769
0.0904949999999998,37.9900875014795
0.090995,38.0492342450489
0.091495,38.4275674851466
0.0919949999999999,38.4569850527045
0.0924950000000001,38.9465369411583
0.092995,38.6277536786391
0.093495,38.8684394850641
0.0939949999999999,38.9821519238442
0.0944949999999999,39.0810219246198
0.0949949999999998,39.6475896963693
0.0954949999999998,39.5821908188787
0.095995,39.7016547449196
0.0964949999999999,39.7511605273023
0.0969950000000001,40.1093649959568
0.097495,40.1342629549829
0.097995,40.2463199823647
0.0984949999999999,40.3489969892748
0.0989949999999999,40.528747799261
0.0994949999999998,40.8567183359043
0.0999949999999998,40.957610324032
0.100495,40.9646953734827
0.100995,40.8959437899281
0.101495,41.4380028763532
0.101995,41.5649084016857
0.102495,41.5526689840823
0.102995,41.6857594960925
0.103495,41.7772714924269
0.103995,41.9413547058256
0.104495,42.2308893378159
0.104995,42.3763519034354
0.105495,42.3552102931136
0.105995,42.6398080490593
0.106495,42.6879855615341
0.106995,42.8879447411401
0.107495,43.0492049658065
0.107995,43.0271240244036
0.108495,43.2060493147681
0.108995,43.3171142316565
0.109495,43.5002589187958
0.109995,43.6422648522475
0.110495,43.7622008192842
0.110995,43.759487442579
0.111495,44.154089953105
0.111995,44.203066082855
0.112495,44.2914327642366
0.112995,44.4249621371486
0.113495,44.5970670086791
0.113995,44.8512215813509
0.114495,44.7645845767866
0.114995,45.0474518225152
0.115495,44.8773142644308
0.115995,45.2510853173485
0.116495,45.2740939729235
0.116995,45.5069087969952
0.117495,45.5220477682617
0.117995,45.5608580777536
0.118495,45.8765477432794
0.118995,45.9854153691869
0.119495,46.1862532395267
0.119995,46.0926234722589
0.120495,46.3980027579406
0.120995,46.3844951361348
0.121495,46.7660019714172
0.121995,46.5792522781245
0.122495,46.7323593933834
0.122995,46.910341997587
0.123495,47.0435024810277
0.123995,47.2570292041155
0.124495,47.2258908622577
0.124995,47.5375093521659
0.125495,47.5064379031595
0.125995,47.7945098436586
0.126495,47.6416528055962
0.126995,47.8674123061976
0.127495,47.9623132279858
0.127995,48.0450095287108
0.128495,48.2633986662286
0.128995,48.3233670300013
0.129495,48.4637564363198
0.129995,48.3935941486895
0.130495,48.7824880802026
0.130995,48.7556610921293
0.131495,48.9083972285166
0.131995,48.9263963442406
0.132495,49.209577078209
0.132995,49.2002299568567
0.133495,49.204675489726
0.133995,49.4396468461976
0.134495,49.5908133385195
0.134995,49.8309552496844
0.135495,49.7009098514396
0.135995,49.9367251018983
0.136495,49.8862512995838
0.136995,50.006452872859
0.137495,50.0941996078662
0.137995,50.2936998945847
0.138495,50.4672870916015
0.138995,50.5793293277707
0.139495,50.6818273922908
0.139995,50.5292015110586
0.140495,50.9276503483589
0.140995,51.087493758158
0.141495,51.0076798635216
0.141995,51.031460107978
0.142495,51.2505779789198
0.142995,51.6145543151483
0.143495,51.3341463923682
0.143995,51.5751618661262
0.144495,51.6140846359542
0.144995,51.8246039339199
0.145495,51.7089609017424
0.145995,51.9710638334191
0.146495,52.005262780845
0.146995,52.2123185147707
0.147495,52.1639952084862
0.147995,52.2301253127037
0.148495,52.4153275195222
0.148995,52.625854526254
0.149495,52.6305804255988
0.149995,52.6826653911851
0.150495,52.821773798295
0.150995,52.756643569669
0.151495,52.9172527321653
0.151995,53.1000432069774
0.152495,53.143403584342
0.152995,53.2809062911501
0.153495,53.4017656395819
0.153995,53.4747548271286
0.154495,53.4285205175422
0.154995,53.6104187828397
0.155495,53.7780193857233
0.155995,53.7310715278226
0.156495,53.8890568406656
0.156995,53.893127723087
0.157495,54.1021776431328
0.157995,54.1830308974643
0.158495,54.227593107981
0.158995,54.2879904048528
0.159495,54.3427832293779
0.159995,54.6331566779426
0.160495,54.5903332392531
0.160995,54.6301106728303
0.161495,54.7444662184963
0.161995,54.8944631079955
0.162495,54.9377739555253
0.162995,54.9107693563971
0.163495,55.0849895063337
0.163995,55.1362983511232
0.164495,55.1589527667274
0.164995,55.2734471923755
0.165495,55.4177160135775
0.165995,55.4417891207231
0.166495,55.4415926831733
0.166995,55.4953537199312
0.167495,55.7612962071297
0.167995,55.8425123329053
0.168495,55.7823707138679
0.168995,55.8344855412885
0.169495,56.0071746551882
0.169995,56.0427939242816
0.170495,56.0260663101967
0.170995,56.1297242212257
0.171495,56.3881574376751
0.171995,56.3985989235164
0.172495,56.5517801558223
0.172995,56.4458184846464
0.173495,56.615468490739
0.173995,56.5961485938769
0.174495,56.7480368004031
0.174995,56.7666433022742
0.175495,56.8599697458009
0.175995,57.0147001781147
0.176495,57.0325121877115
0.176995,57.0054998730756
0.177495,57.1614745640718
0.177995,57.2122527152324
0.178495,57.1831296271121
0.178995,57.2232459314807
0.179495,57.4661661079398
0.179995,57.4735387079377
0.180495,57.5395184473639
0.180995,57.5846331787764
0.181495,57.7538840908158
0.181995,57.7237743936503
0.182495,57.7549460260632
0.182995,57.7518319747967
0.183495,57.8903190390849
0.183995,58.1000438249209
0.184495,57.9968438464335
0.184995,58.0195574346505
0.185495,58.1609210788801
0.185995,58.2829018445672
0.186495,58.2922014542858
0.186995,58.3340172296022
0.187495,58.3591386701047
0.187995,58.6305518254904
0.188495,58.4148754199898
0.188995,58.5681246939213
0.189495,58.6325615830935
0.189995,58.7839448152793
0.190495,58.7555005776649
0.190995,58.7993923290156
0.191495,58.895031493177
0.191995,58.9323523337395
0.192495,59.048879653395
0.192995,59.0297010159606
0.193495,59.3142129947957
0.193995,59.0803639345378
0.194495,59.3618341811561
0.194995,59.3025144377106
0.195495,59.5763527681344
0.195995,59.4020644058024
0.196495,59.4844552467527
0.196995,59.638558922358
0.197495,59.6444981137452
0.197995,59.6964021593566
0.198495,59.698773633865
0.198995,59.8845622348649
0.199495,59.8527132762231
0.199995,60.0114190854938
0.200495,59.8363015893113
0.200995,60.0734179231818
0.201495,60.1444631753418
0.201995,60.1909390192196
0.202495,60.1975790038729
0.202995,60.171020238225
0.203495,60.2632718378538
0.203995,60.380509543956
0.204495,60.3812498031433
0.204995,60.3822759683639
0.205495,60.6464975421775
0.205995,60.7474466846271
0.206495,60.4377926033371
0.206995,60.6418087951918
0.207495,60.6678769940746
0.207995,60.8487561765773
0.208495,60.7908065128176
0.208995,60.9327256589556
0.209495,60.9015560743061
0.209995,60.9760264603872
0.210495,61.1634035364662
0.210995,61.0057583007961
0.211495,61.0743367959463
0.211995,61.1925779350442
0.212495,61.4247304793793
0.212995,61.2269784078567
0.213495,61.3917845140945
0.213995,61.3658284253894
0.214495,61.6103740331016
0.214995,61.3629348283731
0.215495,61.6182490517008
0.215995,61.601339198487
0.216495,61.7422483119862
0.216995,61.5680384653194
0.217495,61.8429356534529
0.217995,61.8966236734353
0.218495,61.774619320649
0.218995,61.8658956523478
0.219495,61.8558211844321
0.219995,62.1612866185314
0.220495,61.9349638856218
0.220995,62.2095948119422
0.221495,62.003305702483
0.221995,62.2438684527684
0.222495,62.1599448142255
0.222995,62.4880087901364
0.223495,62.3401887839719
0.223995,62.4039740003044
0.224495,62.4111843434443
0.224995,62.608534872356
0.225495,62.6109818871879
0.225995,62.3883105054272
0.226495,62.7294323154349
0.226995,62.7488474207969
0.227495,62.8381946278917
0.227995,62.7416997239646
0.228495,62.9269628011035
0.228995,62.9571988668056
0.229495,63.021033762993
0.229995,63.1403063674343
0.230495,62.8935893272871
0.230995,63.1491852722435
0.231495,63.0100771760088
0.231995,63.4442293184524
0.232495,63.3335924200693
0.232995,63.3507107246458
0.233495,63.2132007627283
0.233995,63.4504808131576
0.234495,63.6862418485533
0.234995,63.397315543189
0.235495,63.5914527150935
0.235995,63.5522016409394
0.236495,63.7785982544395
0.236995,63.7190749656616
0.237495,63.7412669414077
0.237995,63.7345720823861
0.238495,64.1001824552268
0.238995,64.2358041418217
0.239495,63.8714323861024
0.239995,64.0000837089258
0.240495,63.9496793699326
0.240995,64.2809655681701
0.241495,63.9173375558832
0.241995,64.1504091705202
0.242495,64.3857024308563
0.242995,64.4565884693095
0.243495,64.500023825602
0.243995,64.2870939457806
0.244495,64.4773982254361
0.244995,64.3571680965922
0.245495,64.6179986543534
0.245995,64.6841355459585
0.246495,64.88550133185
0.246995,64.8175083410017
0.247495,65.0391212680058
0.247995,64.8545249877163
0.248495,65.061017303698
0.248995,64.888801436936
0.249495,65.0972338388052
0.249995,65.2791566292171
0.250495,65.1750475659856
0.250995,65.2186740304752
0.251495,65.2947254832451
0.251995,65.4051699130086
0.252495,65.3579761479066
0.252995,65.4687349642676
0.253495,65.256668960188
0.253995,65.6454937565361
0.254495,65.780657011259
0.254995,65.7095072260398
0.255495,65.5881883401174
0.255995,65.6285402854876
0.256495,66.067796284351
0.256995,65.8961556902188
0.257495,65.8478756569437
0.257995,65.8601184247493
0.258495,65.8768797834704
0.258995,66.1643367540821
0.259495,66.122023102316
0.259995,66.1635565172708
0.260495,66.1210928617448
0.260995,66.3605072284169
0.261495,66.3613734739075
0.261995,66.4912330469198
0.262495,66.5489446605574
0.262995,66.784120550287
0.263495,66.8429465101076
0.263995,66.5842710193531
0.264495,66.6124303476973
0.264995,66.686837947415
0.265495,66.8698174395964
0.265995,67.1243805438053
0.266495,66.7413471574848
0.266995,67.0814839084671
0.267495,67.0680165149765
0.267995,67.3309087928076
0.268495,67.074332799559
0.268995,67.4974064400373
0.269495,67.605816548461
0.269995,67.3011547058742
0.270495,67.4179959810832
0.270995,67.7416784243073
0.271495,67.7060850568588
0.271995,67.6056842755883
0.272495,67.894619005203
0.272995,67.9295363496996
0.273495,67.774241352341
0.273995,68.2200421852498
0.274495,68.1455249375363
0.274995,67.9490861881581
0.275495,68.0366273583325
0.275995,68.5199996448291
0.276495,68.3949450700124
0.276995,68.1536826472472
0.277495,68.7844625065026
0.277995,68.7405370085568
0.278495,68.9548412060507
0.278995,68.9220057353988
0.279495,68.6503671903212
0.279995,69.1569336570295
0.280495,69.3659578912949
0.280995,68.8889978009765
0.281495,68.9110429327379
0.281995,69.8271103357153
0.282495,69.360520205857
0.282995,69.1529992268094
0.283495,69.5521933235955
0.283995,69.5563340353163
0.284495,69.8042618864352
0.284995,69.9926355723229
0.285495,69.995958753333
0.285995,69.7505406704921
0.286495,69.8376857360714
0.286995,70.5136384601503
0.287495,70.27923071285
0.287995,70.2164753663787
0.288495,70.6610385766229
0.288995,70.3114529855947
0.289495,71.2664203215897
0.289995,70.8493894504659
0.290495,70.5104033178118
0.290995,70.7769900239008
0.291495,70.9889861218565
0.291995,71.0199563339888
0.292495,71.2423206200693
0.292995,71.28995161163
0.293495,71.3428497271162
0.293995,71.6829084407917
0.294495,71.7847323397981
0.294995,71.8625421895983
0.295495,71.8909106676109
0.295995,72.0353559718679
0.296495,72.236652144094
0.296995,72.2112369086594
0.297495,72.0365895994271
0.297995,72.372235017706
0.298495,73.1219980476832
0.298995,72.5709674625845
0.299495,73.0357642430037
0.299995,73.0238592933162
0.300495,73.1498144131918
0.300995,73.2883468390234
0.301495,73.6811964103131
0.301995,73.638416597508
0.302495,73.6667890785348
0.302995,73.8166431581963
0.303495,74.0910881054066
0.303995,74.3692532388759
0.304495,74.1119967128609
0.304995,74.1539074664034
0.305495,74.4302604036046
0.305995,74.4791753387944
0.306495,74.9714130949365
0.306995,74.8244275950973
0.307495,74.9743576703453
0.307995,75.5686547238017
0.308495,75.3032948063497
0.308995,76.0968419032456
0.309495,75.8446704672529
0.309995,75.699794246083
0.310495,76.4550210668832
0.310995,76.1664254898352
0.311495,76.5214256184831
0.311995,77.1379628476088
0.312495,77.1680013180618
0.312995,77.1139081577295
0.313495,77.2566608973575
0.313995,77.7967716262343
0.314495,77.248238282798
0.314995,78.0166709250782
0.315495,77.9969679955739
0.315995,78.1609810649195
0.316495,78.5962564742996
0.316995,78.3375113188815
0.317495,78.8994211756654
0.317995,79.3509462256046
0.318495,79.3417695941874
0.318995,79.6987991945101
0.319495,80.0851423236843
0.319995,79.865275514218
0.320495,80.1874904736449
0.320995,80.3097917812232
0.321495,80.7570143583767
0.321995,80.8878516957664
0.322495,81.1352480049979
0.322995,81.0935921541713
0.323495,81.5633504899174
0.323995,81.8075079582584
0.324495,82.5928751797291
0.324995,82.2087350473951
0.325495,82.3380514268888
0.325995,82.6642769596933
0.326495,83.0867123855998
0.326995,83.3380119167052
0.327495,83.6195222883441
0.327995,83.7724437124927
0.328495,84.1284767969322
0.328995,84.4571570163356
0.329495,84.6445485429997
0.329995,84.7339467858275
0.330495,85.0074569066473
0.330995,85.3281251224155
0.331495,85.6500912336706
0.331995,85.7554025531777
0.332495,86.5039600507831
0.332995,86.0052480502915
0.333495,87.1634399891977
0.333995,86.8686660286046
0.334495,87.4084480902258
0.334995,87.6535721925996
0.335495,88.118549640776
0.335995,88.0566380528361
0.336495,88.6191966229075
0.336995,88.8338648465473
0.337495,89.6253217658118
0.337995,89.3412042403288
0.338495,89.8908728003589
0.338995,90.306858206886
0.339495,90.5496549976793
0.339995,90.3355911754467
0.340495,90.9554824773443
0.340995,91.7500342012064
0.341495,91.4957193518133
0.341995,92.3033127400473
0.342495,92.4039257037021
0.342995,92.1075082605242
0.343495,92.7935978539155
0.343995,92.8761170284078
0.344495,93.5808183787626
0.344995,93.7028317312244
0.345495,94.3507980347191
0.345995,94.0047683518301
0.346495,94.6126550219839
0.346995,95.1820068584874
0.347495,95.6156860556237
0.347995,95.7407820836627
0.348495,96.3900541739487
0.348995,96.3694945325601
0.349495,96.665929490401
0.349995,96.6595017534719
0.350495,97.2819294594791
0.350995,97.6483682903769
0.351495,97.5539326298878
0.351995,98.1549354028919
0.352495,99.252757516676
0.352995,98.9808364713883
0.353495,99.7371953659826
0.353995,99.3820474704736
0.354495,100.356391129569
0.354995,100.653279110363
0.355495,100.655750644086
0.355995,100.919616058611
0.356495,101.700882124142
0.356995,101.99713863314
0.357495,102.251162867434
0.357995,102.629294554496
0.358495,102.822349268511
0.358995,103.800457955717
0.359495,103.53273234759
0.359995,104.231932191077
0.360495,104.645389423031
0.360995,104.879142220005
0.361495,105.373467803831
0.361995,105.141956050447
0.362495,105.780962360592
0.362995,106.363172354125
0.363495,106.988286233935
0.363995,106.846119038419
0.364495,107.26647293804
0.364995,108.150995811034
0.365495,108.355929942
0.365995,107.931113230697
0.366495,108.386194587992
0.366995,109.302579041622
0.367495,109.938179448637
0.367995,110.155810489438
0.368495,110.683885115903
0.368995,111.464251648755
0.369495,112.10359940121
0.369995,112.05936591908
0.370495,112.881241021696
0.370995,112.9806398666
0.371495,112.835872057033
0.371995,113.597762933233
0.372495,114.385825884979
0.372995,114.757357600278
0.373495,114.708076975189
0.373995,115.56840816172
0.374495,115.719366289458
0.374995,116.375720086976
0.375495,117.034191254615
0.375995,117.775413993103
0.376495,117.917135551367
0.376995,118.156256657119
0.377495,118.444590003131
0.377995,119.143933289216
0.378495,119.547590309981
0.378995,120.203713122612
0.379495,120.499286438671
0.379995,121.271219124951
0.380495,121.437482454305
0.380995,122.433958603406
0.381495,122.63420700774
0.381995,122.668803839432
0.382495,123.633467024665
0.382995,123.876877391256
0.383495,124.143599848492
0.383995,124.85427835483
0.384495,126.248637564484
0.384995,126.56520963654
0.385495,127.035582761579
0.385995,127.487419032717
0.386495,125.293605437496
0.386995,117.089828195768
0.387495,98.6287432598986
0.387995,72.1838637289973
0.388495,52.798038959549
0.388995,42.5441912943073
0.389495,36.7178407915612
0.389995,31.6853692494227
0.390495,27.3205791477783
0.390995,22.2455521285281
0.391495,17.1899558307913
0.391995,11.1486991232543
0.392495,4.56639488359149
0.392995,-2.0929598369897
0.393495,-6.6508570944786
0.393995,-10.2119599977828
0.394495,-12.1927191784114
0.394995,-10.454179252588
0.395495,-5.76154185694961
0.395995,-2.81451258941039
0.396495,-0.235087581330085
0.396995,1.36078734516657
0.397495,2.82575430930322
0.397995,3.66101904675652
0.398495,3.89780186593814
0.398995,3.38426060265881
0.399495,2.07373107534087
0.399995,0.673200952628918
0.400495,-0.355457014272457
0.400995,-1.92200048554041
0.401495,-2.52672177003427
0.401995,-3.18465075741675
0.402495,-3.1285644857211
0.402995,-1.86778565417134
0.403495,-0.347745265208853
0.403995,0.289471187168993
0.404495,0.883570086928305
0.404995,1.57156278329772
0.405495,1.80630245456748
0.405995,1.69567306027475
0.406495,1.11404581082715
0.406995,0.691505731697025
0.407495,-0.171150162541357
0.407995,-0.330981960991128
0.408495,-0.487916007987751
0.408995,-1.09294622268113
0.409495,-0.982307021172718
0.409995,-0.93147808655263
0.410495,-0.541480863456068
0.410995,-0.0502424250839104
0.411495,-0.0540295600902419
0.411995,0.365279980702415
0.412495,0.578288770525955
0.412995,0.543014906689827
0.413495,0.597281661750949
0.413995,0.0352675086322741
0.414495,0.0878503780177661
0.414995,0.0365701190684025
0.415495,-0.0298235433419386
0.415995,-0.409605135960813
0.416495,-0.267179969542334
0.416995,-0.311339362802593
0.417495,-0.268857657029813
0.417995,-0.374465883590986
0.418495,-0.366294513685651
0.418995,-0.0444764892056997
0.419495,-0.0539288283795171
0.419995,-0.0270157539422348
0.420495,0.0294094478708502
0.420995,-0.176187146473659
0.421495,0.0651776176006035
0.421995,0.259443040302177
0.422495,0.353736457959756
0.422995,0.315200029370362
0.423495,-0.194078503326569
0.423995,-0.186096001969699
0.424495,-0.338422862859016
0.424995,-0.307930979075457
0.425495,-0.197813467024748
0.425995,-0.333456952440073
0.426495,-0.607992916255835
0.426995,-0.408328384650766
0.427495,-0.233916454357486
0.427995,0.346813767148088
0.428495,0.410509175914388
0.428995,0.114628279166275
0.429495,0.402356276361808
0.429995,0.239994064909881
0.430495,0.14206004471686
0.430995,-0.12723843511679
0.431495,-0.373005707454571
0.431995,-0.401304697050213
0.432495,-0.616205853417585
0.432995,-0.486328199268929
0.433495,-0.414802722254911
0.433995,-0.225609770726615
0.434495,0.12794335580554
0.434995,0.272170473544299
0.435495,0.527867946956476
0.435995,0.508150195010147
0.436495,0.610743009051621
0.436995,0.634055212858379
0.437495,0.205830232446124
0.437995,0.106677138649593
0.438495,-0.0936558027213112
0.438995,-0.472185500447718
0.439495,-0.729301939157916
0.439995,-0.603830683264863
0.440495,-0.526722112290858
0.440995,-0.0636719534509577
0.441495,-0.165455141907117
0.441995,-0.016378783911684
0.442495,0.171492067199462
0.442995,0.582714141675954
0.443495,0.392859688590422
0.443995,0.5742187472353
0.444495,0.205113101118845
0.444995,0.197527665524957
0.445495,-0.132258596459195
0.445995,-0.530631400291571
0.446495,-0.288047905059884
0.446995,-0.505592762447919
0.447495,-0.137788204761418
0.447995,0.025433791043987
0.448495,0.0237035359141527
0.448995,0.185401176164206
0.449495,0.323261948909911
0.449995,0.522216828791209
0.450495,0.392537230620655
0.450995,0.149389125346002
0.451495,-0.12873424421672
0.451995,-0.13288149603294
0.452495,-0.364396793218283
0.452995,-0.329467889699536
0.453495,-0.471869951449303
0.453995,-0.450245008209745
0.454495,-0.254603556978422
0.454995,0.0718540685674342
0.455495,0.236660825609666
0.455995,0.203761847518165
0.456495,0.467198538234493
0.456995,0.717856106394197
0.457495,0.677824868766825
0.457995,0.258761021884736
0.458495,0.150997731605692
0.458995,0.00732048810731223
0.459495,0.0617130269496076
0.459995,-0.296754074813936
0.460495,-0.542597691840966
0.460995,-0.526567436879277
0.461495,-0.380181840526768
0.461995,-0.161553258242447
0.462495,-0.074658363319544
0.462995,-0.147633871910886
0.463495,0.145109949443788
0.463995,0.337162297263542
0.464495,0.346879937342041
0.464995,0.259682307468276
0.465495,0.316622930043433
0.465995,0.191341696392317
0.466495,0.0121852229057977
0.466995,-0.326516650331222
0.467495,-0.522337899636175
0.467995,-0.221507799756998
0.468495,-0.216172771609599
0.468995,-0.211719843518353
0.469495,-0.0563656802694496
0.469995,-0.167119005859121
0.470495,0.21124919766716
0.470995,0.265734657718439
0.471495,0.238584367109394
0.471995,0.0488006921805514
0.472495,-0.0333039441331263
0.472995,0.158821153489423
0.473495,-0.13949957006934
0.473995,-0.0461446594424968
0.474495,-0.28459002048769
0.474995,-0.128233900953765
0.475495,-0.0526035456062153
0.475995,0.34595954698883
0.476495,0.122559473300588
0.476995,0.160748791517209
0.477495,0.131448327183838
0.477995,0.371412174968486
0.478495,0.180465825346089
0.478995,0.0844055896718041
0.479495,0.0594462719377114
0.479995,-0.0462988549914074
0.480495,-0.192377063971316
0.480995,0.0423572198951398
0.481495,-0.168230425453303
0.481995,-0.172569256288864
0.482495,0.05432843468787
0.482995,0.032862252420476
0.483495,0.113020563471802
0.483995,0.065802504712358
0.484495,0.0824538198956821
0.484995,0.34848647582223
0.485495,-0.173330977848754
0.485995,-0.103764319097155
0.486495,-0.0497929216920515
0.486995,-0.0990775871441946
0.487495,-0.115218997615459
0.487995,-0.257654673493417
0.488495,-0.181154513496857
0.488995,-0.146627006490403
0.489495,0.103424627994788
0.489995,0.0668902959077294
0.490495,0.269238273857245
0.490995,0.0425103220747267
0.491495,0.157867030170467
0.491995,0.20835607837573
0.492495,0.120076174400463
0.492995,0.120687410822173
0.493495,0.0441532622968652
0.493995,-0.0295550847599538
0.494495,-0.253634381789474
0.494995,-0.048251002256976
0.495495,-0.132087627972986
0.495995,0.00741611786322131
0.496495,-0.463535239159574
0.496995,-0.0593544771529927
0.497495,0.0881467497943976
0.497995,-0.146205197619209
0.498495,-0.151062508983133
0.498995,-0.0857143151086846
0.499495,0.240912128515979
0.499995,0.222176549522143