File: DATA&scripts/1.7-data/z/15/15_fracture_stress_data.csv
Strain,Fracture Stress (GPa)
-1.56278871039692e-16,1.27785267330093
0.000494999999999708,1.40788837444121
0.000994999999999977,-2.71117940014757
0.00149499999999993,0.551777902803932
0.00199499999999989,-1.02118076241726
0.00249499999999985,4.16533712474876
0.00299499999999981,4.50656794096564
0.00349499999999976,5.44552861534545
0.00399499999999972,1.32690035875243
0.00449499999999983,1.859576464462
0.00499499999999995,2.06546352320716
0.00549499999999991,3.10266711407105
0.00599499999999986,5.8931020644901
0.00649499999999982,5.44428748858984
0.00699499999999978,4.62472196898768
0.00749499999999973,4.84101998724385
0.00799499999999969,6.33017482957576
0.00849499999999996,6.95173878919647
0.00899499999999992,6.99683628053289
0.00949499999999988,7.00438035575623
0.00999499999999983,6.30048008652314
0.0104949999999998,7.18378297693253
0.0109949999999997,7.04020289090176
0.0114949999999997,7.20846915853607
0.011995,8.10747089294228
0.0124949999999999,8.27789401574149
0.0129949999999999,9.11442243785699
0.0134949999999998,9.53681840017594
0.0139949999999998,9.8915976980278
0.0144949999999998,9.53861776599723
0.0149949999999997,9.66311832191005
0.0154949999999998,9.96029606553397
0.0159949999999999,9.88848982814004
0.0164949999999999,10.5615585754064
0.0169949999999999,10.3925015169254
0.0174949999999998,11.2494312959458
0.0179949999999998,11.1465440824186
0.0184949999999997,11.8754583695879
0.0189949999999997,12.3225385386793
0.019495,12.4233819213364
0.0199949999999999,12.8140532366794
0.0204949999999999,12.5225252885267
0.0209949999999998,13.0183761088928
0.0214949999999998,12.7786117121043
0.0219949999999997,13.4760657092229
0.0224949999999997,13.6498145911618
0.022995,13.9459203251333
0.0234949999999999,14.477023780582
0.0239949999999999,14.3922070558731
0.0244949999999998,15.0023803691729
0.0249949999999998,14.9893510707846
0.0254949999999998,15.5745801465076
0.0259949999999997,15.5147893398291
0.0264949999999998,15.8162578763083
0.0269949999999999,15.8891131958042
0.0274949999999999,16.2157252770137
0.0279949999999999,16.608386349315
0.0284949999999998,16.8475828918185
0.0289949999999998,17.1391328346325
0.0294949999999997,17.1742962311024
0.0299949999999997,17.5198763473344
0.030495,17.7904951340409
0.0309949999999999,17.9730786248888
0.0314949999999999,18.5291168900972
0.0319949999999998,18.4495434233002
0.0324949999999998,18.9949660046657
0.0329949999999997,18.9633611719155
0.0334949999999997,19.3222308051449
0.033995,19.399420377124
0.0344949999999999,19.8022909426286
0.0349949999999999,19.9378082898646
0.0354949999999998,20.1373777767185
0.0359949999999998,20.3382324495312
0.0364949999999998,20.7721496234634
0.0369949999999997,21.0561140012599
0.0374949999999997,21.3627665732618
0.0379949999999999,21.5706795975825
0.0384949999999999,21.8678414393817
0.0389949999999999,21.8574081994245
0.0394949999999998,22.0918405319469
0.0399949999999998,22.3343886988468
0.0404949999999997,22.5890194294178
0.0409949999999997,22.8164312989573
0.041495,23.0561062511667
0.0419949999999999,23.4375075691598
0.0424949999999999,23.6299245105926
0.0429949999999998,23.8931206327427
0.0434949999999998,24.084522708071
0.0439949999999997,24.3806876390133
0.0444949999999997,24.5055126219461
0.044995,24.7443081979266
0.0454949999999999,25.0173882096146
0.0459949999999999,25.185669346967
0.0464949999999998,25.2992397356869
0.0469949999999998,25.8454176964773
0.0474949999999998,26.0369641041329
0.0479949999999997,26.2876814324506
0.048495,26.3752005484083
0.0489949999999999,26.620883220146
0.0494949999999999,26.8758297598013
0.0499949999999999,27.0651294908994
0.0504949999999998,27.3793274586141
0.0509949999999998,27.5122086308809
0.0514949999999997,27.8552579700276
0.0519949999999997,27.9981852751564
0.052495,28.3821009574472
0.0529949999999999,28.4181000116309
0.0534949999999999,28.9058879326873
0.0539949999999998,28.9137389987029
0.0544949999999998,29.1571416916352
0.0549949999999997,29.2764099197957
0.0554949999999997,29.6988731695118
0.055995,29.8249943266858
0.0564949999999999,30.0238177465449
0.0569949999999999,30.1871274913972
0.0574949999999998,30.6678425229623
0.0579949999999998,30.6108245497148
0.0584949999999997,30.9541861300569
0.0589949999999997,31.0638378100201
0.0594949999999997,31.5918517439084
0.0599949999999999,31.5008578766628
0.0604949999999999,31.9049858692524
0.0609949999999998,31.9280321324314
0.0614949999999998,32.2905469203008
0.0619949999999998,32.3339704396851
0.0624949999999997,32.6476757303943
0.0629949999999997,32.7677518208252
0.063495,33.2168139973124
0.0639949999999999,33.3602582608022
0.0644949999999999,33.5270928027873
0.0649949999999998,33.7306251701985
0.0654949999999998,33.9716868388232
0.0659949999999997,34.1609213446972
0.0664949999999997,34.4038948507496
0.066995,34.5564086139761
0.0674949999999999,34.8642935320438
0.0679949999999999,34.9672789807906
0.0684949999999998,35.2647862110977
0.0689949999999998,35.3457224135166
0.0694949999999998,35.6830256860828
0.0699949999999997,35.8913833937987
0.0704949999999997,36.1324723280915
0.0709949999999999,36.3425659493747
0.0714949999999999,36.5198682716599
0.0719949999999999,36.6610763211351
0.0724949999999998,36.8994041238811
0.0729949999999998,37.1330444922873
0.0734949999999997,37.3171459276954
0.0739949999999997,37.5166725012456
0.074495,37.6608167314482
0.0749949999999999,37.9305517966952
0.0754949999999999,38.1719523469242
0.0759949999999998,38.22291275857
0.0764949999999998,38.5171354703069
0.0769949999999997,38.6084016046801
0.0774949999999997,39.0382844472567
0.077995,39.0715014435504
0.0784949999999999,39.3380703543537
0.0789949999999999,39.4494299224715
0.0794949999999998,39.7718410780146
0.0799949999999998,39.9600608425725
0.0804949999999997,40.1224317371574
0.0809949999999997,40.3366964293908
0.0814949999999997,40.647689501498
0.0819949999999999,40.7272693908937
0.0824949999999999,40.8098001306718
0.0829949999999998,40.9104591174808
0.0834949999999998,41.2601657438392
0.0839949999999998,41.3942254699851
0.0844949999999997,41.6943529555153
0.0849949999999997,41.8241753513995
0.0854949999999999,42.0569007253481
0.0859949999999999,42.1678038702912
0.0864949999999999,42.4603270090232
0.0869949999999998,42.4510906341479
0.0874949999999998,42.8094998275075
0.0879949999999997,42.9268820704129
0.0884949999999997,43.164041284194
0.0889949999999998,43.2924788723749
0.0894949999999999,43.4775189300142
0.0899949999999999,43.6590268874937
0.0904949999999998,43.9041139657927
0.0909949999999998,43.9271593210228
0.0914949999999997,44.1929604833676
0.0919949999999997,44.4410455263325
0.0924949999999997,44.7516754944968
0.0929949999999999,44.8351212240819
0.0934949999999999,44.8638390578011
0.0939949999999998,45.0115767753812
0.0944949999999998,45.276399500232
0.0949949999999998,45.5375533869256
0.0954949999999997,45.6420002592248
0.0959949999999997,45.76639287391
0.0964949999999999,45.9438937303662
0.0969949999999999,46.2176939257778
0.0974949999999999,46.3481582852011
0.0979949999999998,46.4781334003939
0.0984949999999998,46.7145783251094
0.0989949999999997,46.8935452486755
0.0994949999999997,47.1490565686013
0.099995,47.1237874924489
0.100495,47.437270975605
0.100995,47.4884167274621
0.101495,47.7335725661074
0.101995,47.8832260598679
0.102495,48.0505205754081
0.102995,48.1616919378351
0.103495,48.4995841404138
0.103995,48.5415656676658
0.104495,48.7862592605279
0.104995,48.8650418046781
0.105495,49.1173564194413
0.105995,49.202293400099
0.106495,49.5025574001346
0.106995,49.5122414682262
0.107495,49.7853574952316
0.107995,49.7636651607883
0.108495,50.0586243468587
0.108995,50.1397140582985
0.109495,50.4628936643859
0.109995,50.399053577974
0.110495,50.7385270574719
0.110995,50.7644442487727
0.111495,51.0974432644658
0.111995,51.0574969149571
0.112495,51.2522816654289
0.112995,51.4060263111954
0.113495,51.7219594618158
0.113995,51.7880175954399
0.114495,51.8297791022645
0.114995,52.0494117588079
0.115495,52.2128746839185
0.115995,52.37137539053
0.116495,52.4162030975657
0.116995,52.6677366456552
0.117495,52.8470520621291
0.117995,53.0716329832668
0.118495,53.1199074264425
0.118995,53.2660632339369
0.119495,53.3528497719322
0.119995,53.6501697114232
0.120495,53.7630137515984
0.120995,53.8678507959747
0.121495,53.8639461753776
0.121995,54.1689924477154
0.122495,54.3658936555838
0.122995,54.5041291228934
0.123495,54.4853105190897
0.123995,54.7111579523197
0.124495,54.7422649119736
0.124995,54.991897887092
0.125495,55.1193826479583
0.125995,55.3021342124785
0.126495,55.3084467480171
0.126995,55.6120802737612
0.127495,55.677304294006
0.127995,55.9147064284545
0.128495,56.0059521308358
0.128995,56.108450485292
0.129495,56.1816995918846
0.129995,56.3766896886698
0.130495,56.6210194200702
0.130995,56.5900498660693
0.131495,56.781101558719
0.131995,56.8598941741962
0.132495,57.0844137379532
0.132995,57.017746160354
0.133495,57.3485414140735
0.133995,57.4013428249668
0.134495,57.5861742412566
0.134995,57.645379030402
0.135495,57.8261095161175
0.135995,57.9692003863574
0.136495,58.0614295357213
0.136995,58.1547278897231
0.137495,58.2233671086327
0.137995,58.4259365715068
0.138495,58.5106113613523
0.138995,58.7775057635199
0.139495,58.7836529924779
0.139995,58.9510190977741
0.140495,59.0122053124151
0.140995,59.2623094696459
0.141495,59.2590290848905
0.141995,59.447549098461
0.142495,59.4582176753093
0.142995,59.6758966165739
0.143495,59.7516948273488
0.143995,59.97697991217
0.144495,59.990232547509
0.144995,60.1025811514634
0.145495,60.3081032198984
0.145995,60.2441949156456
0.146495,60.6120374192882
0.146995,60.5142084012874
0.147495,60.7701090689254
0.147995,60.6914774830647
0.148495,60.9989543086627
0.148995,61.0065445546395
0.149495,61.2410324355776
0.149995,61.2252425632156
0.150495,61.4799818792385
0.150995,61.5052007074101
0.151495,61.5951660777988
0.151995,61.6986441789134
0.152495,61.8580741171725
0.152995,61.9788088010125
0.153495,61.8886706543176
0.153995,62.2093054987943
0.154495,62.1722478714857
0.154995,62.3961395969318
0.155495,62.3186515384466
0.155995,62.6670416341831
0.156495,62.6151600324239
0.156995,62.7726803258619
0.157495,62.7841308791843
0.157995,63.0185855245721
0.158495,63.0842278195431
0.158995,63.11892587751
0.159495,63.2947903412975
0.159995,63.3088435957827
0.160495,63.5838085626872
0.160995,63.4850295131216
0.161495,63.7155740208697
0.161995,63.6828832745812
0.162495,63.9576255059308
0.162995,63.9356598522401
0.163495,64.1492653291978
0.163995,64.1075767230074
0.164495,64.2340663395513
0.164995,64.3912516284578
0.165495,64.4362205307365
0.165995,64.5854845546624
0.166495,64.5274471826196
0.166995,64.8090476498025
0.167495,64.7618936244321
0.167995,64.9386354205089
0.168495,64.8949885623843
0.168995,65.1852563761199
0.169495,65.1770649092682
0.169995,65.2497984292117
0.170495,65.383813580456
0.170995,65.4484405050949
0.171495,65.6291111657043
0.171995,65.4958143499646
0.172495,65.8374601764058
0.172995,65.6691949069212
0.173495,66.0279255349262
0.173995,65.8055106124574
0.174495,66.181501332502
0.174995,66.1131429744874
0.175495,66.2369571657468
0.175995,66.3551517037567
0.176495,66.3290047863225
0.176995,66.6083683489195
0.177495,66.4182691441866
0.177995,66.7846710608891
0.178495,66.6107737242537
0.178995,66.9580009537809
0.179495,66.7777418892546
0.179995,67.1813768263012
0.180495,66.9726847770522
0.180995,67.1570025477193
0.181495,67.237374202275
0.181995,67.2702279211477
0.182495,67.4479602491962
0.182995,67.2870081097739
0.183495,67.5551382741484
0.183995,67.4711853594671
0.184495,67.8809931801186
0.184995,67.6641730405482
0.185495,67.8328083711729
0.185995,67.7741637797251
0.186495,68.0492616558667
0.186995,68.0608034128457
0.187495,68.1541497414561
0.187995,68.2281793029236
0.188495,68.1771954453046
0.188995,68.4902616798851
0.189495,68.288667950475
0.189995,68.6114530972867
0.190495,68.4500894680913
0.190995,68.7334756209993
0.191495,68.6693342750771
0.191995,68.7487463462479
0.192495,68.8947326474863
0.192995,68.8218490996782
0.193495,68.9977045941384
0.193995,69.0398645691593
0.194495,69.3116312474354
0.194995,69.0965549527189
0.195495,69.2724246374959
0.195995,69.1961893284716
0.196495,69.5408648064385
0.196995,69.520733080601
0.197495,69.4846505299035
0.197995,69.7552135928159
0.198495,69.6361049651488
0.198995,69.7545037863271
0.199495,69.6329010143787
0.199995,69.9867888258289
0.200495,69.965501271182
0.200995,70.0229703077336
0.201495,70.0655893229317
0.201995,70.1405640002174
0.202495,70.2424771542424
0.202995,70.1962274901978
0.203495,70.4488670475085
0.203995,70.3675773656611
0.204495,70.5312331271045
0.204995,70.4903733787166
0.205495,70.5507963523616
0.205995,70.6190237797
0.206495,70.7137566366665
0.206995,70.8048157282518
0.207495,70.8766329814938
0.207995,70.9792863704573
0.208495,70.9068252552404
0.208995,71.0519902695603
0.209495,71.0895161590235
0.209995,71.1824071599984
0.210495,71.1827232066725
0.210995,71.3388841417959
0.211495,71.3812684469734
0.211995,71.366155584699
0.212495,71.4872999224578
0.212995,71.4960006130949
0.213495,71.5660009445121
0.213995,71.6870250261756
0.214495,71.8006785167232
0.214995,71.6899602825802
0.215495,71.7825949621111
0.215995,71.8884886718471
0.216495,71.9395963190449
0.216995,72.0373656464819
0.217495,71.9983278753019
0.217995,72.1390509860999
0.218495,72.1693598570806
0.218995,72.2484695770253
0.219495,72.2265014149613
0.219995,72.3908421799619
0.220495,72.4406679428593
0.220995,72.4766095666978
0.221495,72.5674454734203
0.221995,72.6015971893208
0.222495,72.725249644255
0.222995,72.7461171517988
0.223495,72.7539651865194
0.223995,72.8614849785548
0.224495,72.8961826940123
0.224995,72.9253406091631
0.225495,73.0065412696921
0.225995,73.082588308663
0.226495,73.1514540373246
0.226995,73.170667269495
0.227495,73.2418835682603
0.227995,73.3289728529539
0.228495,73.3141796581648
0.228995,73.5530258764873
0.229495,73.4147199701165
0.229995,73.5356273239557
0.230495,73.5567135444256
0.230995,73.7413749781803
0.231495,73.6852417816313
0.231995,73.7540958536003
0.232495,73.7704392929792
0.232995,73.8974021728681
0.233495,73.9969502174949
0.233995,74.0571699636786
0.234495,74.0911967946541
0.234995,74.1256255831468
0.235495,74.3005716619917
0.235995,74.1953114163192
0.236495,74.3414323136214
0.236995,74.4002193689963
0.237495,74.4511021806515
0.237995,74.4239009282782
0.238495,74.5109143245284
0.238995,74.5948210529828
0.239495,74.5678686060291
0.239995,74.6748042149701
0.240495,74.7931005179359
0.240995,74.8605577844275
0.241495,74.9180693260542
0.241995,74.9588259426125
0.242495,74.9573409712284
0.242995,75.0689400019091
0.243495,75.2947173443192
0.243995,75.1081017376053
0.244495,75.2813332477472
0.244995,75.25429572045
0.245495,75.3153553169198
0.245995,75.4541764188398
0.246495,75.5661182453061
0.246995,75.5285591652979
0.247495,75.6920909814599
0.247995,75.7245141358125
0.248495,75.6736855227479
0.248995,75.5876180148293
0.249495,75.7662762437298
0.249995,75.8525103769046
0.250495,75.9184697562278
0.250995,75.9948898663644
0.251495,76.0693635775583
0.251995,76.3383350720929
0.252495,76.1974090217895
0.252995,76.2243231766977
0.253495,76.3245690334332
0.253995,76.3921914297634
0.254495,76.5736555897196
0.254995,76.5208068596385
0.255495,76.5325072799581
0.255995,76.8445852458445
0.256495,76.8383755591535
0.256995,76.9152106638758
0.257495,76.8589916292838
0.257995,76.9697280337864
0.258495,77.0071655777964
0.258995,77.24339548672
0.259495,77.1283491577928
0.259995,77.3054752979772
0.260495,77.2965458991476
0.260995,77.3666537652364
0.261495,77.4299175555102
0.261995,77.4891901539561
0.262495,77.5879085596339
0.262995,77.6114982161657
0.263495,77.6245558381143
0.263995,77.7622759041989
0.264495,77.9160594424669
0.264995,77.931542357942
0.265495,78.0360552204136
0.265995,78.0850307324295
0.266495,78.2020320910443
0.266995,78.0866928484299
0.267495,78.2588836965716
0.267995,78.3741566433495
0.268495,78.3748780085555
0.268995,78.5199101609755
0.269495,78.6719663308928
0.269995,78.6056625800149
0.270495,78.8537762177037
0.270995,78.8619773590745
0.271495,78.9688451542492
0.271995,78.8732129989057
0.272495,79.1541750537191
0.272995,79.084247124828
0.273495,79.2278983991481
0.273995,79.3215938673714
0.274495,79.3777658767705
0.274995,79.5348014242183
0.275495,79.6396638033425
0.275995,79.6945793809808
0.276495,79.6892947393598
0.276995,79.8534918833959
0.277495,79.9558130446327
0.277995,80.0988277574628
0.278495,80.171348665212
0.278995,80.1584990989863
0.279495,80.2030545490543
0.279995,80.3654567511281
0.280495,80.4299825575145
0.280995,80.579764151969
0.281495,80.6832263515815
0.281995,80.7226699879084
0.282495,80.8721587446295
0.282995,80.907891725635
0.283495,81.1781398289896
0.283995,81.3130876891641
0.284495,81.3337834067111
0.284995,81.5248622039181
0.285495,81.3999381406246
0.285995,81.6130221857318
0.286495,81.5713834011803
0.286995,81.933962652837
0.287495,81.7928792937188
0.287995,82.0228473619909
0.288495,82.257664265602
0.288995,82.3387484684519
0.289495,82.2900518302335
0.289995,82.4377289194231
0.290495,82.4994351194142
0.290995,82.6253347522008
0.291495,82.8808267603257
0.291995,82.8566456349173
0.292495,83.2224356246785
0.292995,83.2763946219992
0.293495,83.2820763960649
0.293995,83.4259745253293
0.294495,83.4396208494788
0.294995,83.8211057908493
0.295495,83.8070834305307
0.295995,83.9139332151298
0.296495,84.0346406901235
0.296995,84.0840987107351
0.297495,84.2543629644157
0.297995,84.6908741970451
0.298495,84.6996355301189
0.298995,84.9405368670044
0.299495,84.9549255188139
0.299995,85.0188270371131
0.300495,85.300067195716
0.300995,85.5290019550812
0.301495,85.7839604093808
0.301995,85.79571343628
0.302495,86.1880453692573
0.302995,86.1412239054847
0.303495,86.1743860273315
0.303995,86.6072402397276
0.304495,86.7405476556623
0.304995,86.6733594150547
0.305495,87.1864441043871
0.305995,87.1531899399285
0.306495,87.2216137101982
0.306995,87.6261778352415
0.307495,87.9951434735955
0.307995,87.967435741825
0.308495,87.9704103224714
0.308995,88.3136222713495
0.309495,88.3867920835789
0.309995,88.8147873246779
0.310495,88.8798692211429
0.310995,89.0405271543518
0.311495,89.4019200457041
0.311995,89.4077499995198
0.312495,89.9625964131579
0.312995,89.7227607127161
0.313495,90.2211685991985
0.313995,90.5342154919501
0.314495,90.45403470619
0.314995,90.9712440629201
0.315495,91.1754742439898
0.315995,91.0414886464856
0.316495,91.536741484935
0.316995,91.5773572804605
0.317495,92.0133037234665
0.317995,92.5151323063172
0.318495,92.5393893197793
0.318995,92.9948657994065
0.319495,92.9209508372093
0.319995,93.2852949573226
0.320495,93.5728280288711
0.320995,93.5613677238883
0.321495,94.2557315210008
0.321995,94.1059644030421
0.322495,94.9010084877108
0.322995,94.672779211129
0.323495,95.1230560327479
0.323995,95.3806679884082
0.324495,95.7586862161913
0.324995,95.9831387709554
0.325495,96.2871813051057
0.325995,96.7324539762299
0.326495,96.9106282455328
0.326995,97.0357578218157
0.327495,97.4796670339722
0.327995,97.7605813752341
0.328495,98.0537462368288
0.328995,98.2806398379414
0.329495,98.6469897506899
0.329995,98.7330489748065
0.330495,99.460924045077
0.330995,99.4389275008546
0.331495,99.8130059157344
0.331995,100.276263667725
0.332495,100.501357584525
0.332995,100.745603286873
0.333495,101.111894557711
0.333995,101.558507633996
0.334495,101.679550951465
0.334995,102.157654041087
0.335495,102.548013210151
0.335995,102.558279030146
0.336495,103.179466376013
0.336995,103.456773965632
0.337495,103.649793630843
0.337995,103.993220366797
0.338495,104.533640969052
0.338995,105.005375349187
0.339495,105.187003577317
0.339995,105.492132621565
0.340495,106.076710664524
0.340995,106.285341378148
0.341495,106.549280714674
0.341995,106.833276438155
0.342495,107.177188005488
0.342995,107.721440751834
0.343495,108.291182828842
0.343995,108.202927043686
0.344495,108.798462004259
0.344995,109.29683127886
0.345495,109.67134025628
0.345995,109.971341471385
0.346495,110.394004248132
0.346995,110.428984254094
0.347495,111.209721180864
0.347995,111.016041120412
0.348495,111.656093069577
0.348995,111.965979072413
0.349495,112.740281224282
0.349995,112.898514359573
0.350495,113.338374604645
0.350995,114.066925930017
0.351495,114.140427990734
0.351995,114.444908903011
0.352495,115.002660833866
0.352995,115.134925996246
0.353495,115.775053336249
0.353995,115.804113405041
0.354495,116.376225998051
0.354995,116.868534975177
0.355495,117.124281483689
0.355995,117.804565638158
0.356495,117.799380158656
0.356995,118.772349427784
0.357495,119.1613780856
0.357995,119.054008906188
0.358495,120.055240949117
0.358995,120.282344510961
0.359495,120.405859397798
0.359995,121.12437995895
0.360495,121.487296623773
0.360995,122.17621350416
0.361495,122.263907295331
0.361995,122.682900246586
0.362495,123.533756535899
0.362995,123.653347912055
0.363495,124.054338017253
0.363995,124.835122517038
0.364495,125.282540896975
0.364995,125.58506964728
0.365495,125.914981329256
0.365995,126.584794359829
0.366495,127.269299209073
0.366995,127.32841207327
0.367495,127.915585108896
0.367995,128.442703931198
0.368495,128.640536124561
0.368995,129.360333660154
0.369495,129.785637751792
0.369995,130.011688927749
0.370495,130.638730573489
0.370995,131.120364768905
0.371495,131.839184990115
0.371995,132.42155503841
0.372495,132.945999046624
0.372995,133.527735832121
0.373495,134.117841196213
0.373995,134.448902160423
0.374495,134.915282374449
0.374995,135.735686415545
0.375495,136.15387358338
0.375995,136.876245364037
0.376495,137.112423101144
0.376995,137.79194895561
0.377495,138.456519727644
0.377995,139.004994270941
0.378495,139.620566963011
0.378995,140.311837312206
0.379495,140.484396534085
0.379995,141.434443043668
0.380495,141.717050084175
0.380995,142.450828901412
0.381495,142.884943603879
0.381995,143.541831687496
0.382495,144.267336116403
0.382995,144.603309614867
0.383495,144.003338058672
0.383995,140.203860123213
0.384495,132.005885733141
0.384995,124.391771381109
0.385495,119.112370108966
0.385995,114.039941166393
0.386495,109.548587143202
0.386995,105.750319492746
0.387495,102.019089037101
0.387995,98.5596757293908
0.388495,95.3815165918593
0.388995,92.0582746858844
0.389495,88.6988633595493
0.389995,85.606221042786
0.390495,82.4531128055735
0.390995,79.3804757665235
0.391495,76.4764156279269
0.391995,73.7593209562065
0.392495,70.8771776267748
0.392995,68.0292245444626
0.393495,65.4632426982034
0.393995,63.0844794753101
0.394495,60.58114835871
0.394995,58.3108781457765
0.395495,56.2931141188609
0.395995,54.4501065177302
0.396495,52.7588462570502
0.396995,51.2368382347033
0.397495,49.8618951472608
0.397995,48.6347104537
0.398495,47.5420632350665
0.398995,46.654820168395
0.399495,45.7649677340772
0.399995,44.9369735327236
0.400495,44.174408150115
0.400995,43.404594616723
0.401495,42.6440378500228
0.401995,41.8861475769751
0.402495,41.1634001296414
0.402995,40.4389532801422
0.403495,39.7300516312219
0.403995,39.0037281906807
0.404495,38.3181205957962
0.404995,37.669729094247
0.405495,36.9995754587928
0.405995,36.332759169319
0.406495,35.7239227151631
0.406995,35.1166028220695
0.407495,34.5211704799643
0.407995,33.9271074132524
0.408495,33.3481415576855
0.408995,32.7658479460246
0.409495,32.2024067293441
0.409995,31.6225010795545
0.410495,31.0814317931964
0.410995,30.5347145038081
0.411495,29.982440460168
0.411995,29.4444564141603
0.412495,28.8989529114837
0.412995,28.3454140151365
0.413495,27.6912596651944
0.413995,26.9699970291272
0.414495,26.2155726193106
0.414995,25.4297500007479
0.415495,24.5794528985619
0.415995,23.7011368338833
0.416495,22.7841469492423
0.416995,21.8342578223682
0.417495,20.8365992284058
0.417995,19.769194950926
0.418495,18.663878527344
0.418995,17.4965048053267
0.419495,16.2935271654692
0.419995,15.0386862242597
0.420495,13.724871794357
0.420995,12.357357039536
0.421495,10.9420794443905
0.421995,9.46587258575978
0.422495,7.93706148935294
0.422995,6.3090948528748
0.423495,4.71673147682703
0.423995,3.27351879592128
0.424495,1.98611889509849
0.424995,0.702471489080746
0.425495,-0.581071080244679
0.425995,-1.84544343964074
0.426495,-3.22228734124394
0.426995,-4.71015669809259
0.427495,-6.30399222757161
0.427995,-7.97222656666242
0.428495,-9.73179834951079
0.428995,-11.5697889050207
0.429495,-13.3970644187114
0.429995,-14.4351841349656
0.430495,-11.7998366504564
0.430995,-10.5257155572084
0.431495,-10.9977973911607
0.431995,-10.8225767725937
0.432495,-10.7192024906361
0.432995,-9.70574754544082
0.433495,-9.24930628904258
0.433995,-7.98665435277934
0.434495,-6.48563833846586
0.434995,-5.60666775115382
0.435495,-5.15388291582794
0.435995,-4.49464691976761
0.436495,-4.29833535229052
0.436995,-3.94059768990099
0.437495,-3.68992893810181
0.437995,-3.37850803944304
0.438495,-3.52514553025899
0.438995,-4.11589191172065
0.439495,-4.3500229179397
0.439995,-4.59819819892314
0.440495,-4.46504737789485
0.440995,-4.50667211754085
0.441495,-4.01739297824834
0.441995,-3.41645790475288
0.442495,-2.96525016688012
0.442995,-2.27618128793722
0.443495,-1.42179010321427
0.443995,-1.15798426726259
0.444495,-1.15480356924036
0.444995,-0.71711833539843
0.445495,-0.530683217797183
0.445995,-0.605894501128104
0.446495,-1.07740482451717
0.446995,-1.19153866742176
0.447495,-1.46796042580147
0.447995,-1.12663273701727
0.448495,-0.908452347089076
0.448994999999999,-0.930907452126045
0.449495,-0.669316195415133
0.449995,-0.131502041853034
0.450495,-0.046975709137996
0.450995,0.210892746846817
0.451495,0.227843324656386
0.451995,0.0181244188506635
0.452495,0.0326103539987823
0.452995,-0.300604952975671
0.453495,-0.520499052665213
0.453995,-0.703555506774666
0.454495,-0.867556589770212
0.454995,-1.01290865751497
0.455495,-1.16874540481994
0.455995,-1.20636874808809
0.456494999999999,-1.09438779812248
0.456995,-1.24981027018357
0.457495,-1.28970483010845
0.457995,-1.41845596877208
0.458495,-1.28647461818423
0.458995,-1.3271603884995
0.459495,-1.40072874811731
0.459995,-1.36419528891138
0.460495,-1.22107908731726
0.460995,-1.08930553210243
0.461495,-0.853876111634991
0.461995,-0.606593352847563
0.462495,-0.370508451638091
0.462995,-0.598620099608429
0.463494999999999,-0.428483813954545
0.463995,-0.453451297055938
0.464495,-0.40745872317435
0.464995,-0.221900576794878
0.465495,-0.0119730431890594
0.465995,-0.197641297436945
0.466495,-0.495063454079334
0.466995,-0.652443503760496
0.467495,-1.18154604335348
0.467995,-1.262345880805
0.468495,-1.54280342164015
0.468995,-1.3711236121327
0.469495,-1.59102211604397
0.469995,-1.67084001290671
0.470495,-1.49721967006648
0.470994999999999,-1.45544128777511
0.471495,-1.16111962660198
0.471995,-1.28313625865546
0.472495,-1.08170082974325
0.472995,-0.771409669920889
0.473495,-0.715839394859208
0.473995,-0.317660551308409
0.474495,-0.349595767997574
0.474995,0.0118796688709618
0.475495,0.0586894217619741
0.475995,0.219003995107882
0.476495,0.142833057231635
0.476995,0.00818596645793505
0.477495,0.0187916385552489
0.477995,-0.32616150194796
0.478495,-0.478012515498304
0.478995,-0.659963971019985
0.479495,-0.863579405432103
0.479995,-1.09296801294424
0.480495,-0.983626650475362
0.480995,-0.975412003384884
0.481495,-0.83469964501467
0.481995,-0.683785800876909
0.482495,-0.552193635075908
0.482995,-0.428429724961094
0.483495,-0.271373074421337
0.483995,-0.085989356677978
0.484495,0.0841851384812225
0.484995,0.299970383722709
0.485495,0.465042262633459
0.485995,0.664364590886669
0.486495,0.758065041761044
0.486995,0.778934268206176
0.487495,0.648757888535622
0.487995,0.453245904930775
0.488495,0.0770479967996356
0.488995,-0.0670131594225767
0.489495,-0.344301134656984
0.489995,-0.356578499490545
0.490495,-0.549785869271412
0.490995,-0.65851904555934
0.491495,-0.808308604266403
0.491995,-0.925708614142614
0.492495,-1.12383846507139
0.492995,-1.11282260149027
0.493495,-1.03427975823386
0.493995,-0.913819931278261
0.494495,-1.00369741162607
0.494995,-0.518958475288021
0.495495,-0.680465948377867
0.495995,-0.424364372566448
0.496495,-0.392473294591946
0.496995,-0.311226599443588
0.497495,-0.586421517921815
0.497995,-0.61646882240566
0.498495,-0.29532207072401
0.498995,-0.35715205716913
0.499495,-0.20863720094115
0.499995,-0.278440776435298
0.500495,-0.0450720591724644
0.500995,0.0417488385538206
0.501495,-0.0573050751840812
0.501995,-0.0313909345324903
0.502495,-0.302069656393097
0.502995,-0.373730205463527
0.503495,-0.388400702499153
0.503995,-0.412184930066724
0.504495,-0.62537606270844
0.504995,-0.592382960192798
0.505495,-0.686991640378602
0.505995,-0.586172553836316
0.506495,-0.67083891804325
0.506995,-0.812425683394237
0.507495,-0.831947517843298
0.507995,-0.776766802426168
0.508495,-0.80214577656174
0.508995,-0.627718916782466
0.509495,-0.584900171270964
0.509995,-0.417592383646868
0.510495,-0.492760984683866
0.510995,-0.354160547343843
0.511495,-0.294615739650855
0.511995,-0.366829053309943
0.512495,-0.154770184531557
0.512995,-0.146642150532205
0.513495,-0.155893660954777
0.513995,-0.0867909431745061
0.514494999999999,-0.19098769160113
0.514995,-0.0787189285096645
0.515495,-0.259518861883109
0.515995,-0.114320766571278
0.516495,-0.27920062061504
0.516995,-0.329516375880448
0.517495,-0.466469509419839
0.517995,-0.599729824753929
0.518495,-0.651771085706746
0.518995,-0.696837684489048
0.519495,-0.703053501863072
0.519995,-0.694181816251176
0.520495,-0.543294138249788
0.520995,-0.635027867312126
0.521495,-0.558950593243509
0.521995,-0.468289155707014
0.522495,-0.425616903068977
0.522995,-0.488975462298162
0.523495,-0.333307882102084
0.523995,-0.210491455700675
0.524495,-0.137665482494344
0.524995,-0.118218774131992
0.525495,-0.112304037437201
0.525994999999999,-0.0795502340936966
0.526495,-0.0708081392406028
0.526995,-0.144802453449161
0.527495,0.0145839124257142
0.527995,-0.0116735969171961
0.528495,0.0598023350377812
0.528995,-0.0921146824089644
0.529495,0.0869925619611194
0.529995,0.1387568500366
0.530495,0.183657427298807
0.530995,0.202747244940849
0.531495,0.275293234062268
0.531995,0.345380061596003
0.532494999999999,0.337499763480543
0.532995,0.357769611249637
0.533495,0.327979470006497
0.533995,0.167543570706484
0.534495,0.342963017648807
0.534995,0.252181775149749
0.535495,0.245406030878081
0.535995,-0.0368732696976833
0.536495,0.0127645616917931
0.536995,-0.176300737848456
0.537494999999999,-0.22273801138127
0.537995,-0.445553910587946
0.538495,-0.461697166048588
0.538995,-0.551060201865076
0.539495,-0.438827549989002
0.539995,-0.542972022823616
0.540495,-0.587293274193188
0.540995,-0.560869332116498
0.541495,-0.449353335569429
0.541995,-0.530719324313598
0.542495,-0.434990054428959
0.542995,-0.478165174461419
0.543495,-0.301596590265293
0.543994999999999,-0.379036496927272
0.544495,-0.255028232146565
0.544995,-0.325473828998191
0.545495,-0.202604968238696
0.545995,-0.101670835412161
0.546495,0.00577852070223873
0.546995,0.0794431673017276
0.547495,0.114160958144127
0.547995,0.101872231728023
0.548494999999999,0.145834541658776
0.548995,0.11508259213846
0.549495,0.0478091682209331
0.549995,-0.0554431173511118
0.550495,-0.100759770755968
0.550995,-0.156494762372674
0.551495,-0.238049119316483
0.551995,-0.287441144532385
0.552495,-0.396525875451038
0.552995,-0.356951266605355
0.553495,-0.423145831542998
0.553995,-0.519272048145507
0.554495,-0.515034717603509
0.554994999999999,-0.506681725344676
0.555494999999999,-0.58195528656843
0.555995,-0.512390548206859
0.556495,-0.49995155929663
0.556995,-0.606929018107656
0.557495,-0.479847759268721
0.557995,-0.414755905251586
0.558495,-0.340260235868389
0.558995,-0.328644930280145
0.559495,-0.189853841053339
0.559995,-0.12686701624416
0.560495,-0.150651082858087
0.560995,0.0111944508983877
0.561495,0.024230224374755
0.561995,0.207818554574911
0.562495,0.0113182246979404
0.562995,0.090412830799277
0.563495,-0.0299282849231027
0.563995,-0.0585846148739025
0.564495,0.0424645095727741
0.564995,-0.187567964014644
0.565495,-0.135070753872837
0.565995,-0.271887989296959
0.566494999999999,-0.276091379985605
0.566995,-0.390074879392913
0.567495,-0.306842596784941
0.567995,-0.34703374544146
0.568495,-0.463200298297257
0.568995,-0.431677492088121
0.569495,-0.45314202807438
0.569995,-0.329806020500591
0.570495,-0.21623817833275
0.570995,-0.225036132019436
0.571495,-0.287364445646807
0.571995,-0.290668318040295
0.572495,-0.292922438955605
0.572994999999999,-0.231867480906824
0.573495,-0.300609627901626
0.573995,-0.319002689012513
0.574495,-0.384002229336327
0.574995,-0.43524191893183
0.575495,-0.412213569349156
0.575995,-0.408909225768018
0.576495,-0.390934578529798
0.576994999999999,-0.344111438784455
0.577494999999999,-0.503522366017895
0.577995,-0.527712890770257
0.578495,-0.674344717186055
0.578995,-0.525647310804246
0.579495,-0.452725991878438
0.579995,-0.377731162535196
0.580495,-0.413569045669634
0.580995,-0.187898653086518
0.581495,-0.206407268645671
0.581995,-0.11067531867418
0.582495,-0.056320924141617
0.582995,0.00102363459830112
0.583495,-0.0417274921141039
0.583994999999999,-0.000532499333078183
0.584494999999999,0.0725657956564935
0.584995,0.0897174094873148
0.585495,0.0822385016720549
0.585995,0.147990166790673
0.586495,0.165832776262904
0.586995,0.166322550807291
0.587495,0.0185722821297707
0.587995,0.138254334704431
0.588495,0.121122341352817
0.588995,0.0907200493814304
0.589495,0.155392383117311
0.589995,0.0391967990269534
0.590495,-0.0644055522556309
0.590995,-0.160546274681993
0.591495,-0.0383088692052429
0.591995,-0.226087952589218
0.592495,-0.254540331060774
0.592995,-0.207058244959958
0.593495,-0.26452240274446
0.593995,-0.19965516690364
0.594495,-0.35812326635135
0.594995,-0.297788640564183
0.595494999999999,-0.305644467919414
0.595995,-0.378275408693314
0.596495,-0.410879161196836
0.596995,-0.281801776396706
0.597495,-0.187894050484754
0.597995,-0.2728020221784
0.598495,-0.142941285987371
0.598995,-0.0775467752356812
0.599494999999999,-0.0171131191110662
0.599994999999999,0.0319973252336335
0.600495,0.170954881111813
0.600995,0.142873297199751
0.601495,0.161160958006033
0.601995,0.099983825171129
0.602495,0.182401333817329
0.602995,0.1705625636914
0.603495,0.190645038478358
0.603995,0.232889403453414
0.604495,0.296626201463091
0.604995,0.230406734143252
0.605495,0.154678354329207
0.605995,0.284424642789296
0.606494999999999,0.386286534634114
0.606994999999999,0.261849713579645
0.607495,0.285124671342127
0.607995,0.316106380024671
0.608495,0.265246555987224
0.608995,0.203192417013447
0.609495,0.194444204135845
0.609995,0.173672182388077
0.610495,0.134128541890663
0.610995,0.150295758694516
0.611495,0.17072416369207
0.611995,0.133026821069166
0.612495,0.0821183858348484
0.612995,0.108749906855591
0.613494999999999,0.120903393660787
0.613995,0.132705884736047
0.614495,0.0666939039453441
0.614995,0.105770277961253
0.615495,0.149038340810054
0.615995,0.203401817467152
0.616495,0.282993403164392
0.616995,0.43911642234911
0.617495,0.421241651577918
0.617995,0.5252819947496
0.618495,0.486271997974897
0.618995,0.464573897659764
0.619495,0.479220041411775
0.619995,0.632963319533424
0.620495,0.810992307833816
0.620995,0.879929690336605
0.621495,0.971026962459425
0.621994999999999,1.01985191667392
0.622495,0.939261479485729
0.622995,0.951459799132274
0.623495,0.962150181238785
0.623995,0.919820835348459
0.624494999999999,0.863190228703392
0.624994999999999,0.771606860344292
0.625495,0.729990263354001
0.625995,0.574974172374218
0.626495,0.295826992079332
0.626995,0.313076749948456
0.627495,0.331096888662973
0.627995,0.253451944834419
0.628494999999999,0.242195717180997
0.628994999999999,0.16823595835379
0.629495,0.195192932809639
0.629995,0.150309398147311
0.630495,0.0684176445468943
0.630995,0.0685178238411876
0.631494999999999,-0.130879316265514
0.631995,-0.191831982026715
0.632495,-0.291890434928332
0.632995,-0.228329128889193
0.633495,-0.279930061090713
0.633995,-0.325698833073478
0.634495,-0.211103728487205
0.634995,-0.106593776312456
0.635494999999999,-0.0871376722331694
0.635994999999999,0.0735584318831737
0.636495,0.174026882882551
0.636995,0.36242799939784
0.637495,0.410687206830992
0.637995,0.622490609893287
0.638495,0.699619866831613
0.638995,0.81401319836381
0.639495,0.857753432740666
0.639995,0.82376209600452
0.640495,0.945217037708762
0.640995,1.06109524254052
0.641495,1.23220966459028
0.641995,1.19878909608205
0.642494999999999,1.40910747344215
0.642994999999999,1.37112460915495
0.643495,1.46702244906532
0.643995,1.46066199417224
0.644495,1.36880452905142
0.644995,1.37401713020494
0.645495,1.27693229355267
0.645995,1.38614359260933
0.646495,1.20693229258013
0.646995,1.31860461002904
0.647495,1.07713138324652
0.647995,1.14488699307271
0.648495,1.01225852117153
0.648995,0.918443796184252
0.649495,0.947764258005839
0.649995,0.820156894652372
0.650495,0.721378039237608
0.650994999999999,0.582389652120962
0.651495,0.506720221732056
0.651995,0.288754722598928
0.652495,0.194458369691095
0.652995,-0.0595251637831471
0.653494999999999,-0.0782756707447405
0.653994999999999,-0.15379093934286
0.654495,-0.212672392584408
0.654995,-0.171695084206035
0.655495,-0.13897363092334
0.655995,-0.28790555182551
0.656495,-0.312736203650395
0.656995,-0.230695771470863
0.657494999999999,-0.285298800934667
0.657994999999999,-0.319395885937207
0.658495,-0.283879938410119
0.658995,-0.249764469700101
0.659495,-0.429352044529899
0.659995,-0.308566831009745
0.660494999999999,-0.269703926079226
0.660995,-0.0954819541213607
0.661495,-0.0227718549332661
0.661995,-0.00548431492692524
0.662495,-0.208273042620913
0.662995,-0.0995470342004585
0.663495,-0.0425950723965255
0.663995,-0.15176659735819
0.664495,-0.00733133599492049
0.664994999999999,-0.065227752589842
0.665494999999999,-0.0113293588299945
0.665995,-0.0815605843243499
0.666495,0.00110158728529448
0.666995,0.00788859625066586
0.667495,-0.0156941308558895
0.667995,0.00801282019055418
0.668495,-0.0625741480135957
0.668995,0.115291640161708
0.669495,0.138539868238899
0.669995,0.113944862440714
0.670495,0.130540778487445
0.670995,0.0764300315819772
0.671495,-0.0736347868778801
0.671994999999999,-0.10464653017334
0.672495,-0.0514762709303999
0.672995,-0.117962362086679
0.673494999999999,-0.186672078022196
0.673995,-0.228481928564005
0.674495,-0.482082883271292
0.674995,-0.379473789399423
0.675495,-0.553782753242917
0.675995,-0.645711224247967
0.676494999999999,-0.719027378595053
0.676995,-0.739006609662082
0.677495,-0.687014348997921
0.677995,-0.782901128895464
0.678495,-0.872665737709338
0.678995,-0.838405281606534
0.679495,-0.843477952972057
0.679994999999999,-0.894421922048543
0.680494999999999,-0.964045740606256
0.680995,-0.837719189830675
0.681495,-0.853447400253468
0.681995,-0.984250426973801
0.682495,-0.786174061674424
0.682994999999999,-0.721429568004726
0.683494999999999,-0.761853215436026
0.683995,-0.780920718228561
0.684495,-0.74579598444625
0.684995,-0.758964125607139
0.685495,-0.72523376015533
0.685995,-0.787638954437869
0.686495,-0.662155871811282
0.686994999999999,-0.750851302624021
0.687494999999999,-0.860138760036153
0.687995,-0.777441363824004
0.688495,-0.681412749809823
0.688995,-0.583728408766637
0.689495,-0.616498044444604
0.689995,-0.514648483885125
0.690495,-0.424424578982235
0.690995,-0.288649577870984
0.691495,-0.174365605185387
0.691995,-0.101492171179549
0.692495,-0.0420446130253451
0.692995,0.208614453873281
0.693495,0.154058970206911
0.693994999999999,0.284888835343582
0.694494999999999,0.29808253727564
0.694995,0.257834950941378
0.695495,0.279248045905582
0.695995,0.372368858034195
0.696495,0.464167264237117
0.696995,0.343737768021359
0.697495,0.478703295542988
0.697995,0.376634688051706
0.698495,0.382233158276437
0.698995,0.381993874499345
0.699495,0.462321324996055
0.699995,0.390677573193282
0.700495,0.444212213132607
0.700994999999999,0.530201063176507
0.701495,0.595547460517734
0.701994999999999,0.601954205713761
0.702494999999999,0.513198546220392
0.702995,0.667637451299896
0.703495,0.717071149715064
0.703995,0.707599935263707
0.704495,0.749615557667229
0.704995,0.719535577081488
0.705495,0.713099008725407
0.705995,0.629557905837118
0.706495,0.712698642578172
0.706995,0.621094881493255
0.707495,0.615596876862646
0.707995,0.62465704194798
0.708495,0.693933170215305
0.708995,0.550549919629869
0.709494999999999,0.62472175266081
0.709995,0.591393012487693
0.710495,0.544435326469587
0.710995,0.47589820107421
0.711495,0.425493206844778
0.711995,0.460408640425592
0.712495,0.494716015776067
0.712995,0.529763999863342
0.713495,0.426077872486622
0.713995,0.419823342322782
0.714495,0.581945212072254
0.714995,0.354263717453696
0.715495,0.414523219344682
0.715994999999999,0.455073923890999
0.716494999999999,0.325106380617583
0.716995,0.329965274636198
0.717495,0.213402974991653
0.717995,0.254100047876559
0.718495,0.16779360468733
0.718994999999999,0.200148758896354
0.719495,0.192882313477177
0.719995,0.104867577841708
0.720495,0.102190963464769
0.720995,0.0836156662580104
0.721495,0.117994291116934
0.721995,0.0749496580130448
0.722495,0.222853710958906
0.722994999999999,0.144433179829028
0.723494999999999,0.122375091395134
0.723995,0.335179072353954
0.724495,0.328804003757327
0.724995,0.310742615967494
0.725495,0.20199691976809
0.725995,0.280508827453715
0.726495,0.355163922609418
0.726995,0.312921683817053
0.727495,0.3236137588624
0.727995,0.380235382814511
0.728495,0.378626993446885
0.728995,0.396972090164435
0.729495,0.413290434781354
0.729995,0.424460518479692
0.730494999999999,0.3747495152169
0.730995,0.363509254631639
0.731495,0.389981760592903
0.731994999999999,0.437540004170315
0.732495,0.390209525822564
0.732995,0.423224818229233
0.733495,0.430239458984591
0.733995,0.488498518324884
0.734495,0.631749334267052
0.734995,0.534874134021891
0.735495,0.65224567983427
0.735995,0.643462091376574
0.736495,0.608103055047485
0.736995,0.571982754485849
0.737495,0.586327784046021
0.737995,0.551732729197311
0.738494999999999,0.550575910750388
0.738994999999999,0.471812466463282
0.739495,0.490130981092275
0.739995,0.442655188376518
0.740495,0.377414554657559
0.740995,0.205133429195853
0.741495,0.19041892642303
0.741994999999999,0.151483444829808
0.742495,0.0182060635048913
0.742995,0.00132556563733496
0.743495,-0.0805215051552106
0.743995,-0.149907017647576
0.744495,-0.270980959050297
0.744995,-0.344790959357759
0.745494999999999,-0.345918634950428