File: DATA&scripts/1.7-data/z/17/17_fracture_stress_data.csv
Strain,Fracture Stress (GPa)
0.0,1.27785628250595
0.000995000000000079,-2.68577198190261
0.0019949999999999,-1.06649427523887
0.002995,4.48938858054719
0.0039950000000001,1.31885990081675
0.00499499999999992,2.10154121939602
0.00599500000000002,5.88550358039582
0.00699500000000012,4.58662192436518
0.00799499999999994,6.35910524104248
0.00899500000000004,7.11440240440446
0.009995,6.21034408059082
0.010995,7.05309419387487
0.0119950000000001,8.05065131826351
0.0129949999999999,9.06782726265114
0.013995,9.84377942167503
0.0149950000000001,9.69527298465065
0.0159949999999999,9.97624766654583
0.016995,10.4636477016827
0.0179950000000001,11.3703073588065
0.0189949999999999,12.1784879448879
0.019995,12.7225432235429
0.0209950000000001,12.9327704194701
0.0219949999999999,13.4207825268181
0.022995,13.8915155097744
0.023995,14.3827141584204
0.024995,15.1203852622787
0.0259950000000001,15.4804498893481
0.0269949999999999,15.9139905179114
0.027995,16.599365013418
0.0289950000000001,17.0197710953453
0.0299949999999999,17.5090087413482
0.030995,18.1066334927627
0.0319950000000001,18.3917220142014
0.0329949999999999,18.8779057379138
0.033995,19.58527438167
0.0349950000000001,20.0386446532461
0.0359949999999999,20.4661189201989
0.036995,21.1302325939983
0.037995,21.5515724553068
0.038995,21.9683540531877
0.0399950000000001,22.3258742869043
0.0409949999999999,22.8120729016315
0.041995,23.3638322141101
0.0429950000000001,23.8490428174819
0.0439949999999999,24.3326256075141
0.044995,24.642601754754
0.0459950000000001,25.2469862392229
0.0469949999999999,25.7059324554158
0.047995,26.2120471931167
0.0489950000000001,26.4686471812235
0.0499949999999999,27.0292245565918
0.050995,27.5487376937569
0.051995,28.0889079975901
0.052995,28.548028853602
0.0539950000000001,29.0024493000589
0.0549949999999999,29.4227303031926
0.055995,29.7478991263387
0.0569950000000001,30.3159686841182
0.0579949999999999,30.6915475490805
0.058995,31.246966040712
0.0599950000000001,31.6949454218922
0.0609949999999999,32.0302089473748
0.061995,32.365146456785
0.0629950000000001,32.819735365634
0.0639949999999999,33.3960662101711
0.064995,33.7655250669495
0.065995,34.2745014194152
0.066995,34.5229681088359
0.0679950000000001,34.970862376416
0.068995,35.3498428137825
0.069995,35.9305754041701
0.0709950000000001,36.1810199154025
0.0719949999999999,36.6324572881426
0.072995,36.9982273398836
0.0739950000000001,37.578334682934
0.0749949999999999,37.8354446985648
0.075995,38.3230801511112
0.0769950000000001,38.7181702330115
0.0779949999999999,38.9997324390296
0.078995,39.5092402487901
0.079995,39.7808860574789
0.080995,40.3168350076193
0.0819950000000001,40.6431881548586
0.0829949999999999,41.0848878273387
0.083995,41.4359719962424
0.0849950000000001,41.7152403932653
0.0859949999999999,42.162327122616
0.086995,42.5296208106362
0.0879950000000001,42.8530504479023
0.0889949999999999,43.2882195426301
0.089995,43.6530212557039
0.0909950000000001,44.0328485371244
0.0919949999999999,44.3665332733279
0.092995,44.7311131547349
0.093995,45.0343191848384
0.094995,45.510434856367
0.0959950000000001,45.7879260065881
0.096995,46.1533519024421
0.097995,46.5870592495719
0.0989950000000001,46.7769567424624
0.0999949999999999,47.1456202893833
0.100995,47.5507290275844
0.101995,47.8463175363931
0.102995,48.2170383344943
0.103995,48.6125320172902
0.104995,48.906824322125
0.105995,49.136076678752
0.106995,49.6397331255529
0.107995,49.8505164762824
0.108995,50.305881419533
0.109995,50.4607895282132
0.110995,50.8831550609207
0.111995,51.1788000165567
0.112995,51.4541839047045
0.113995,51.7900845291007
0.114995,52.0691642949651
0.115995,52.3784666770111
0.116995,52.6949897628185
0.117995,52.98766596304
0.118995,53.3014627103714
0.119995,53.5768826744252
0.120995,53.8558338206001
0.121995,54.0413300169514
0.122995,54.5372481586251
0.123995,54.6733111378638
0.124995,55.0239739178827
0.125995,55.287492083022
0.126995,55.508238596042
0.127995,55.8888371902652
0.128995,56.0987300219305
0.129995,56.4074462845023
0.130995,56.6123993948238
0.131995,56.931381736156
0.132995,57.1434846059442
0.133995,57.2476530435304
0.134995,57.7459817444568
0.135995,57.9592935366528
0.136995,58.1868155562659
0.137995,58.3331697565526
0.138995,58.6669446685242
0.139995,58.9344414104849
0.140995,59.1829046311595
0.141995,59.4439893176429
0.142995,59.643604508382
0.143995,59.9864176869632
0.144995,60.1419332071196
0.145995,60.3666892156505
0.146995,60.5136487922603
0.147995,60.8163276598566
0.148995,61.0140019936886
0.149995,61.258859657115
0.150995,61.4567507119904
0.151995,61.6345446001694
0.152995,61.9711020423267
0.153995,62.1799730148185
0.154995,62.334762082183
0.155995,62.5379840945041
0.156995,62.8579821942292
0.157995,62.9919044739421
0.158995,63.2913667890843
0.159995,63.3702131852077
0.160995,63.5985937219745
0.161995,63.734348147059
0.162995,63.9439919889746
0.163995,64.1662879195316
0.164995,64.3825916394658
0.165995,64.4951588864421
0.166995,64.6995872257689
0.167995,65.0276454980812
0.168995,65.1441242749461
0.169995,65.2854830232983
0.170995,65.4773324450605
0.171995,65.6058968103819
0.172995,65.7827739302642
0.173995,66.015314699693
0.174995,66.15826155033
0.175995,66.296478158223
0.176995,66.4376488316825
0.177995,66.5869632715549
0.178995,66.7629080791845
0.179995,66.9439202784816
0.180995,67.1433413758791
0.181995,67.2401605367189
0.182995,67.4925219064905
0.183995,67.5760724042935
0.184995,67.8382100687603
0.185995,67.9104016286897
0.186995,68.0987617397026
0.187995,68.1973251560946
0.188995,68.2991029064463
0.189995,68.5266488033543
0.190995,68.5921025497389
0.191995,68.8477333904968
0.192995,68.869804612593
0.193995,69.1161915419181
0.194995,69.2043064187164
0.195995,69.2814656020438
0.196995,69.468128857004
0.197995,69.6353381222548
0.198995,69.7188823865104
0.199995,69.8215922309307
0.200995,70.0130575525384
0.201995,70.1107420074315
0.202995,70.2549609279206
0.203995,70.4119945577111
0.204995,70.5546722223108
0.205995,70.6456300140678
0.206995,70.7439878781702
0.207995,70.9873487410444
0.208995,71.043907212498
0.209995,71.1286353006461
0.210995,71.2200870583289
0.211995,71.4286740330114
0.212995,71.522019592821
0.213995,71.6298913492867
0.214995,71.7578305884642
0.215995,71.9204347434161
0.216995,72.0177408482754
0.217995,72.1190903111181
0.218995,72.2735875209682
0.219995,72.3360129757854
0.220995,72.5157813281528
0.221995,72.5151802777505
0.222995,72.7581006576526
0.223995,72.8096606547178
0.224995,72.908615540212
0.225995,73.0673426044277
0.226995,73.2488973522441
0.227995,73.4173159093938
0.228995,73.2609249622632
0.229995,73.4556038163548
0.230995,73.5739387910776
0.231995,73.7850539827551
0.232995,73.9159392366067
0.233995,74.0102754858714
0.234995,74.1968650733819
0.235995,74.2329367530119
0.236995,74.3269588958409
0.237995,74.5336225210593
0.238995,74.6300163001197
0.239995,74.7033819639592
0.240995,74.7244731654476
0.241995,74.8445853705682
0.242995,75.1021650543951
0.243995,75.2385541248659
0.244995,75.4037487513593
0.245995,75.5012306778225
0.246995,75.5117694295515
0.247995,75.7222511114234
0.248995,75.7583341340395
0.249995,75.797820564788
0.250995,76.0286402340705
0.251995,76.1231475165666
0.252995,76.2664308939824
0.253995,76.3719345873054
0.254995,76.5954407729742
0.255995,76.6953847633584
0.256995,76.829323856098
0.257995,76.8847627379854
0.258995,77.0282171567536
0.259995,77.1933787242971
0.260995,77.4066987899889
0.261995,77.3427302457548
0.262995,77.6982377749645
0.263995,77.798769227773
0.264995,78.0300831391952
0.265995,78.0595344077391
0.266995,78.2995525338913
0.267995,78.4561398686854
0.268995,78.4736673198751
0.269995,78.7010064616239
0.270995,78.7737362793859
0.271995,78.978012465987
0.272995,79.0786361426148
0.273995,79.2684924234816
0.274995,79.534428672806
0.275995,79.6822650158424
0.276995,79.9096895064079
0.277995,80.0073949212371
0.278995,80.1888788040544
0.279995,80.3432996878159
0.280995,80.3446653222907
0.281995,80.7857581904453
0.282995,80.9423965997541
0.283995,81.1984253268006
0.284995,81.4418331823699
0.285995,81.5059220117137
0.286995,81.9127500315999
0.287995,82.1134284584483
0.288995,82.3143198643274
0.289995,82.4447605743217
0.290995,82.7697143309092
0.291995,82.9105898849672
0.292995,83.2110016715356
0.293995,83.4156835775885
0.294995,83.6865082974437
0.295995,83.7492161996236
0.296995,84.6306541871141
0.297995,84.5734070799428
0.298995,84.8342810946713
0.299995,85.219891183624
0.300995,85.3717345826662
0.301995,85.7701704150752
0.302995,86.1047843336483
0.303995,86.5656005152321
0.304995,86.7918896978735
0.305995,87.3766889579452
0.306995,87.590503303119
0.307995,88.0271387996952
0.308995,88.1936239462111
0.309995,88.9870254060818
0.310995,89.1820898529363
0.311995,89.463530533396
0.312995,89.8560419692853
0.313995,90.2938296866375
0.314995,90.8796944961726
0.315995,91.5094535873135
0.316995,91.8589500038773
0.317995,92.1250376467718
0.318995,92.9690997891559
0.319995,93.3024610209318
0.320995,93.9354618580718
0.321995,94.2191420484425
0.322995,94.7797012130362
0.323995,95.3985455888539
0.324995,96.184832193076
0.325995,96.4438900002422
0.326995,97.0076217057306
0.327995,97.595810282085
0.328995,98.579568905366
0.329995,99.2288096881334
0.330995,99.5848124038828
0.331995,100.054183903402
0.332995,100.594725621833
0.333995,101.405690255024
0.334995,102.257082889149
0.335995,102.582826428645
0.336995,103.661232313883
0.337995,103.928858812241
0.338995,104.807475378571
0.339995,105.40171497692
0.340995,106.344073520553
0.341995,107.228632759835
0.342995,107.897974788813
0.343995,108.530468711767
0.344995,109.123226674306
0.345995,110.016608882161
0.346995,110.625535142459
0.347995,111.145057757347
0.348995,111.953557555736
0.349995,112.818067091663
0.350995,113.413081170997
0.351995,114.538307834585
0.352995,115.186148373648
0.353995,116.159465958386
0.354995,116.838729611314
0.355995,118.021397674617
0.356995,118.335812245367
0.357995,119.53411802782
0.358995,119.815166349977
0.359995,120.988674725677
0.360995,122.051334006019
0.361995,122.884992058673
0.362995,123.973862281455
0.363995,124.706182452576
0.364995,125.512286846131
0.365995,126.749036026751
0.366995,127.533508209604
0.367995,128.274206688876
0.368995,129.543902069322
0.369995,130.446376575902
0.370995,131.455726596899
0.371995,132.50362596753
0.372995,133.528444956669
0.373995,134.370065279706
0.374995,135.727277452165
0.375995,136.751205495416
0.376995,137.732117801502
0.377995,138.90827263583
0.378995,139.958944571601
0.379995,141.268013921839
0.380995,142.093714809528
0.381995,138.391548037493
0.382995,127.650291159923
0.383995,119.234939823983
0.384995,111.930605065124
0.385995,105.643995240241
0.386995,99.7890367342101
0.387995,94.2668646991896
0.388995,88.7922449852672
0.389995,83.6195878673367
0.390995,78.7766771492143
0.391995,74.3352939840746
0.392995,69.9346427035284
0.393995,66.0678390221124
0.394995,62.3421889654682
0.395995,59.0819774398576
0.396995,56.1490208654261
0.397995,53.5677081547181
0.398995,51.3391337741522
0.399995,49.5240757264814
0.400995,47.9727767853384
0.401995,46.6483894752821
0.402995,45.3471288887777
0.403995,44.1274328503357
0.404995,42.8871369395296
0.405995,41.6852332686763
0.406995,40.5410580792823
0.407995,39.4148136738217
0.408995,38.3717779992601
0.409995,37.3284146545675
0.410995,36.3726102324215
0.411995,35.3841960484492
0.412995,34.421282274539
0.413995,33.4911879263841
0.414995,32.5950558064336
0.415995,31.6913184985532
0.416995,30.8490532754686
0.417995,29.8574024450923
0.418995,28.723058641169
0.419995,27.4686976264892
0.420995,26.0583955137972
0.421995,24.5584425091465
0.422995,22.9169433094368
0.423995,21.1870619015257
0.424995,19.2936311974213
0.425995,17.2840323476255
0.426995,15.0657169813558
0.427995,12.7835565504278
0.428995,10.3152022821416
0.429995,7.65154865805032
0.430995,5.22523281696789
0.431995,2.98000002781318
0.432995,0.814698929290616
0.433995,-1.34570798496453
0.434995,-3.62220178090483
0.435995,-6.26698648240755
0.436995,-9.16559061905611
0.437995,-12.2137603998132
0.438995,-13.078528553178
0.439995,-11.2605602042112
0.440995,-11.1294638197055
0.441995,-10.3960809721506
0.442995,-8.69150181910343
0.443995,-6.41347457907713
0.444995,-4.73872095285264
0.445995,-4.09852839854411
0.446995,-3.81338894803805
0.447995,-3.6380090191638
0.448995,-3.71270656680383
0.449995,-4.1838014199036
0.450995,-4.62587134704341
0.451995,-3.99062583509268
0.452995,-3.36914274301143
0.453995,-2.59534524716865
0.454995,-1.96973565795438
0.455995,-1.27793407975309
0.456995,-0.68423229162606
0.457995,-0.333284252257675
0.458995,0.0209400742284778
0.459995,0.585357996173648
0.460995,0.786326464271718
0.461995,0.894473824365401
0.462995,0.745015070851044
0.463995,0.411171969068123
0.464995,-0.245349241696286
0.465995,-0.381617928604106
0.466995,-0.737393907848892
0.467995,-1.25438119377581
0.468995,-1.41291351403818
0.469995,-1.55996775183331
0.470995,-1.66327947740206
0.471995,-1.51520010518191
0.472995,-1.59885534072345
0.473995,-1.0756415642556
0.474995,-0.786010039150721
0.475995,-0.20902812575402
0.476995,0.191625634264979
0.477995,0.60715160898831
0.478995,0.736211398450221
0.479995,0.544543256156804
0.480995,0.495462199544906
0.481995,0.387059781793423
0.482995,-0.0164540349976931
0.483995,-0.548040039344406
0.484995,-0.94471123780428
0.485995,-1.15457415718595
0.486995,-1.22628373008397
0.487995,-1.11746783315567
0.488995,-1.29658487243311
0.489995,-1.21765066542934
0.490995,-0.99943955232762
0.491995,-0.36608614909382
0.492995,-0.222238816818692
0.493995,-0.160648859640318
0.494995,-0.4528914128944
0.495995,-0.348494766751786
0.496995,-0.743601738668638
0.497995,-0.798502230533298
0.498995,-0.573856077119905
0.499995,-0.451990442809125
0.500995,-0.316374297872244
0.501995,-0.370395678540664
0.502995,-0.252748077685175
0.503995,-0.241778766572109
0.504995,-0.230092433398634
0.505995,-0.376763648868123
0.506995,-0.485316902061697
0.507995,-0.677485163674869
0.508995,-0.737932379633564
0.509995,-0.658943637596847
0.510995,-0.746162503049986
0.511995,-0.446183693527356
0.512995,-0.467469069209252
0.513995,-0.0948760307384663
0.514995,-0.109452360630995
0.515995,0.0845034896405486
0.516995,0.102457320665221
0.517995,-0.01952650002963
0.518995,-0.0818585377866573
0.519995,-0.123254571631364
0.520995,-0.196057451309456
0.521995,-0.320917161477989
0.522995,-0.34405648867642
0.523995,-0.28027361184559
0.524995,-0.418872850272438
0.525995,-0.260049190351778
0.526995,-0.209006880371401
0.527995,-0.141377882503888
0.528995,-0.304475880160758
0.529995,-0.31244158385617
0.530995,-0.43046737815725
0.531995,-0.209518760549806
0.532995,-0.390107490004824
0.533995,-0.315024859761719
0.534995,-0.28542655770701
0.535995,-0.268410004123783
0.536995,-0.170652050761328
0.537995,-0.0953838525083911
0.538995,-0.180941319975227
0.539995,-0.113406100046924
0.540995,-0.0643117994662846
0.541995,-0.014852788065512
0.542995,0.0294433996874843
0.543995,-0.210922826472238
0.544995,-0.398827855990999
0.545995,-0.491150503140718
0.546995,-0.483182669957408
0.547995,-0.529870657875766
0.548995,-0.419036995620049
0.549995,-0.444415387982595
0.550995,-0.492112386190139
0.551995,-0.400645415130912
0.552995,-0.574336161844498
0.553995,-0.480165934672706
0.554995,-0.335421884797484
0.555995,-0.27307980106274
0.556995,-0.221527920897115
0.557995,-0.190408730882878
0.558995,-0.165358356395929
0.559995,-0.105080883035268
0.560995,-0.14088361375053
0.561995,-0.126826837785617
0.562995,-0.10500656228114
0.563995,0.0922273893275428
0.564995,0.130970449107097
0.565995,0.216302405998094
0.566995,0.195086915034517
0.567995,0.12126914129511
0.568995,0.120355464412155
0.569995,0.114355152260716
0.570995,0.0850700634411874
0.571995,0.0929236687658107
0.572995,0.109165425380849
0.573995,-0.161105210528897
0.574995,-0.0724355521744331
0.575995,-0.244387568943933
0.576995,-0.197012652202207
0.577995,-0.330591210879313
0.578995,-0.331345901142083
0.579995,-0.426395186404429
0.580995,-0.570796521325475
0.581995,-0.437966027115574
0.582995,-0.504643499638967
0.583995,-0.273303360398798
0.584995,-0.325183928286818
0.585995,-0.231505366638464
0.586995,-0.181284628556059
0.587995,-0.159539957551666
0.588995,-0.114451067479484
0.589995,-0.0628518186802543
0.590995,-0.117901999261743
0.591995,-0.102761366969633
0.592995,-0.0734665692820871
0.593995,-0.0299287487308424
0.594995,-0.0465121386759417
0.595995,-0.247038195946352
0.596995,-0.241504010837048
0.597995,-0.617532155735159
0.598995,-0.439558828507313
0.599995,-0.515762088334753
0.600995,-0.325233919762761
0.601995,-0.439614289336197
0.602995,-0.315160077417051
0.603995,-0.309801781521647
0.604995,-0.284262908654677
0.605995,-0.0598253126074864
0.606995,-5.10537947594591e-05
0.607995,0.125314665916096
0.608995,0.0645588505368253
0.609995,0.0707289917857551
0.610995,0.21015076204165
0.611995,0.164770122300005
0.612995,0.00146139112721141
0.613995,-0.123658505722913
0.614995,-0.222525826825053
0.615995,-0.146361348229967
0.616995,-0.141557285402049
0.617995,0.0468620604386008
0.618995,0.00783092778029583
0.619995,0.00209752381634005
0.620995,0.207207970892655
0.621995,0.22365521604782
0.622995,0.191231894590006
0.623995,0.00702042059754491
0.624995,-0.0190266583301896
0.625995,-0.199814012311138
0.626995,-0.154162933058987
0.627995,-0.336396970537711
0.628995,-0.33258341290912
0.629995,-0.30893541677329
0.630995,-0.400735151008052
0.631995,-0.307725544878026
0.632995,-0.104720347762433
0.633995,-0.040934131945514
0.634995,0.101684134150245
0.635995,-0.0448407323445749
0.636995,-0.000716926492731546
0.637995,0.0491945995415753
0.638995,-0.0231680459307927
0.639995,-0.165670459943099
0.640995,-0.0852210088097991
0.641995,-0.237657488785736
0.642995,-0.311561591781525
0.643995,-0.430134151232777
0.644995,-0.324185729391986
0.645995,-0.368199362563614
0.646995,-0.279726511162169
0.647995,-0.221519208834892
0.648995,-0.309500824408801
0.649995,-0.15370995823227
0.650995,-0.0781220874647972
0.651995,-0.00759048914268229
0.652995,0.121693184138779
0.653995,0.158813329377571
0.654995,0.118238003907078
0.655995,0.119650527852506
0.656995,-0.045704003871529
0.657995,-0.0692717035867024
0.658995,-0.170953197424077
0.659995,-0.0848668027000659
0.660995,-0.0488576019561738
0.661995,-0.0342457987362408
0.662995,-0.121401188948729
0.663995,-0.236214397757182
0.664995,-0.240489603636301
0.665995,-0.228677697989985
0.666995,-0.157757298408773
0.667995,-0.0646478967218464
0.668995,0.0460299867355386
0.669995,0.0840933475484314
0.670995,0.154277431956259
0.671995,0.103874183452728
0.672995,0.0521502606844238
0.673995,0.220688918946046
0.674995,0.180262553298644
0.675995,0.052185607643923
0.676995,-0.0778690404161284
0.677995,-0.188487119707
0.678995,-0.190314346924272
0.679995,-0.278312282009219
0.680995,-0.19362330740641
0.681995,-0.0571626620951068
0.682995,-0.0278338394305078
0.683995,0.0303944544773731
0.684995,0.00835745367561694
0.685995,-0.0327197176766702
0.686995,-0.126873591372755
0.687995,-0.133399860419528
0.688995,-0.11244156859674
0.689995,-0.217299648756259
0.690995,-0.145419441121092
0.691995,-0.129271330749143
0.692995,-0.152321672734802
0.693995,-0.206179576628783
0.694995,-0.227727823600155
0.695995,-0.0346478467087924
0.696995,-0.0569511118592595
0.697995,0.202257088985184
0.698995,0.20937301547955
0.699995,0.214846931956844
0.700995,0.0529697720340315
0.701995,0.0944289563939605
0.702995,0.077555615089457
0.703995,0.0278276109506372
0.704995,0.0871035863806172
0.705995,-0.137037399837561
0.706995,-0.146397678654368
0.707995,-0.273149753427993
0.708995,-0.273925456622376
0.709995,-0.255675198792169
0.710995,-0.204888520851993
0.711995,-0.127277048331478
0.712995,-0.151903344799659
0.713995,-0.0650709723126428
0.714995,-0.130939421977372
0.715995,-0.0540314591402009
0.716995,-0.0263661199303309
0.717995,0.02005799411101
0.718995,0.0525146316038077
0.719995,0.0551603885771283
0.720995,0.0951847387174981
0.721995,0.103717489017304
0.722995,0.0286566625863101
0.723995,0.0505740656831682
0.724995,-0.0757838422215235
0.725995,-0.248141183374989
0.726995,-0.234469589914805
0.727995,-0.319122375126963
0.728995,-0.342274327663368
0.729995,-0.455471073416499
0.730995,-0.467975922076561
0.731995,-0.41396638538797
0.732995,-0.393634879683929
0.733995,-0.248752416647839
0.734995,-0.141184810994139
0.735995,-0.00392865491299883
0.736995,0.0960940086041637
0.737995,0.0993699126033366
0.738995,0.076096207766592
0.739995,0.0947335308903393
0.740995,0.137543885279223
0.741995,0.164137582313107
0.742995,0.295788616816789
0.743995,0.236730781367471
0.744995,0.315553745747147
0.745995,0.0495933122108474
0.746995,0.10996245991593
0.747995,-0.173285498433812
0.748995,-0.165081828240301
0.749995,-0.307403965074613
0.750995,-0.182100704924658
0.751995,-0.219124136224379
0.752995,-0.322010858339562
0.753995,-0.333212279254779
0.754995,-0.272899490000121
0.755995,-0.301670221974508
0.756995,-0.136649382948674
0.757995,-0.105288235425374
0.758995,-0.000284460377205261
0.759995,-0.0413366491565193
0.760995,-0.0172682916364699
0.761995,-0.0341249263626012
0.762995,-0.0594792186958764
0.763995,0.0137720307988485
0.764995,0.0588109116657115
0.765995,0.029714938613112
0.766995,0.134260786878447
0.767995,-0.017153705124408
0.768995,-0.0147370987253782
0.769995,-0.0567537472405073
0.770995,0.0435202030656252
0.771995,-0.0394893190452793
0.772995,-0.0218113514123178
0.773995,-0.0651840330052446
0.774995,-0.0490214681824959
0.775995,0.00185022456247144
0.776995,-0.200860509281229
0.777995,-0.184662169325327
0.778995,-0.168067391697393
0.779995,-0.0568027750662805
0.780995,-0.0757788271534253
0.781995,-0.168083896165035
0.782995,-0.0729815137076737
0.783995,-0.163560908579532
0.784995,-0.0855473957573665
0.785995,-0.0401689176385534
0.786995,-0.0925064088148178
0.787995,-0.0222679860185744
0.788995,0.0340538152582212
0.789995,0.0355651672443429
0.790995,0.0345905173699161
0.791995,0.0863363814896323
0.792995,0.222938777837522
0.793995,0.264296613369254
0.794995,0.300625756695945
0.795995,0.375445511253566
0.796995,0.32962562779175
0.797995,0.3010251564204
0.798495,0.340716202814756